Workbook
Name TournamentName: Settings!$D$2
Name SheetIds: #REF!
Name LockinTimerLength: Settings!$D$14
Name DoublePick: Settings!$D$17
Name ForumPostLink: Settings!$D$11
Name RollRules: Settings!$D$21
Name MappoolSettings: Settings!$G$3:$I$21
Name DoubleBan: Settings!$D$18
Name TeamSize: Settings!$D$5
Name UseNF: Settings!$D$9
Name GameMode: Settings!$D$6
Name ExclNMDouble: Settings!$D$19
Name TeamList: TeamTimes!$B$3:$D$68
Name Format: Settings!$D$4
Name MainSheetLink: Settings!$D$12
Name NoShow2: Settings!$D$16
Name Schedules: Schedule!$D$4:$L$98
Name TeamList: 'Team List'!$B$3:$E$68
Name TeamMode: Settings!$D$7
Name Maps: Mappools!$F$4:$H$109
Name PickTimerLength: Settings!$D$13
Name ScoreMode: Settings!$D$8
Name NoShow1: Settings!$D$15
Name FmRules: Settings!$D$20
Name TournamentAbbr: Settings!$D$3

Sheet Setup
B2: A Menu called "Ref Sheets" will appear at the top of the screen after the sheet has finished loading | F2: =IMAGE("https://i.imgur.com/vky4PfO.png")
B4: This sheet contains example values for Settings, Mappools and Schedules. Please replace them with your own data accordingly.
B5: One-time | C5: {=SEQUENCE(COUNTA(D5:D9),1)} -> 1 | D5: Set all of your required values in the "Settings" sheet. Notes are left for every relevant field, please take a look at them!
C6: 2 | D6: Set your schedules in the "Schedules" sheet.
B7: Weekly | C7: 3 | D7: Set/Update your mappool in the "Mappools" sheet.
C8: 4 | D8: Set the Stage in the "Template" sheet to the current stage
C9: 5 | D9: Generate the matches by going to the menu, then select a method of choice.
J10: IceDynamix Sheets

Sheet _sheetIds
A1: Setup | B1: 0
A2: _sheetIds | B2: 1164269104
A3: -------- | B3: 986140543
A4: Settings | B4: 1796023905
A5: Mappools | B5: 1885578373
A6: Seedings | B6: 939879221
A7: Chrono Schedule | B7: 719222685
A8: Schedule | B8: 1684621565
A9: Team List | B9: 1213771913
A10: TeamTimes | B10: 1316795276
A11: Template | B11: 822251654
A12: 49 | B12: 1563491274
A13: 41 | B13: 204771935
A14: 1 | B14: 589469785
A15: 2 | B15: 125335995
A16: 3 | B16: 742342573
A17: 4 | B17: 877939657
A18: 5 | B18: 7632610
A19: 6 | B19: 1722600134
A20: 7 | B20: 969379779
A21: 8 | B21: 103196645
A22: 9 | B22: 717100364
A23: 10 | B23: 499445887
... A74: 63 | B74: 2042544145

Sheet --------

Sheet Settings
B2: General Settings | C2: Tournament Name | D2: Pekonya Trinity Encounters | F2: Mappool Settings | G2: Stage | H2: Bo | I2: Bans
C3: Tournament Abbreviation | D3: PTE | G3: Round of 32 | H3: 9 | I3: 1
C4: Tournament team format | D4: Team | G4: Round of 16 | H4: 9 | I4: 1
C5: # playing per team | D5: 2 | G5: Quarterfinals | H5: 11 | I5: 2
C6: Gamemode | D6: 0 | G6: Semifinals | H6: 11 | I6: 2
C7: Teammode | D7: 2 | G7: Finals | H7: 13 | I7: 2
C8: Scoremode | D8: 3 | G8: Grand Finals | H8: 13 | I8: 2
C9: Use NoFail Mod | D9: TRUE
B11: Specific Rules | C11: Forum Post URL | D11: https://osu.ppy.sh/community/forums/topics/1790898?n=1?
C12: Main Spreadsheet URL | D12: https://docs.google.com/spreadsheets/d/1u1R-0YeX71qksHP7hWq8QkjcpECX-9LSvskalZ8hxdg/edit?usp=sharing
C13: Pick Timer Length | D13: 90
C14: Lineup Lock-In Timer Length | D14: 90
C15: Bans Lost After ___ Minutes | D15: -
C16: Match FF After ___ Minutes | D16: 15
C17: Double Pick allowed? | D17: FALSE
C18: Double Ban allowed? | D18: FALSE
C19: Exclude NM from double rules? | D19: TRUE
C20: Freemod Rules | D20: FM rule || P1: HD, EZ, HDEZ,FL || P2 : HR, HDHR || EZ = 1.7x , FL 1.5x
C21: Roll Rules | D21: Winner of the roll will have a chance to choose between first pick / second ban or first ban / second pick order.

Sheet Mappools
B2: Input | F2: Auto-generated
B3: Stage | C3: Mod# | D3: Map ID | E3: Map Name | F3: String | G3: Map Command | H3: Mod Command
B4: Round of 32 | C4: NM1 | D4: 2277989 | E4: Hazuki - Uso to Shinjitsu [Insane] | F4: {=IF(C4:C109="",,HYPERLINK("https://osu.ppy.sh/b/"&D4:D109,C4:C109&": "&E4:E109))} -> NM1: Hazuki - Uso to Shinjitsu [Insane] | G4: {=IF(D4:D109="",,"!mp map "&D4:D109&" "&GameMode)} -> !mp map 2277989 0 | H4: {=IF(C4:C109="",,"!mp mods "&IFS(LEFT(C4:C109,2)="NM",IF(UseNF,"NF",""),LEFT(C4:C109,2)="FM","Freemod",LEFT(C4:C109,2)="TB","Freemod",TRUE,TRIM(LEFT(C4:C109,2)&" "&IF(UseNF,"NF",""))))} -> !mp mods NF
B5: Round of 32 | C5: NM2 | D5: 3297107 | E5: Jun Kuroda - Terpsichore [Dancer's Delight] | F5: NM2: Jun Kuroda - Terpsichore [Dancer's Delight] | G5: !mp map 3297107 0 | H5: !mp mods NF
B6: Round of 32 | C6: NM3 | D6: 2440455 | E6: PUP - Anaphylaxis [Insane] | F6: NM3: PUP - Anaphylaxis [Insane] | G6: !mp map 2440455 0 | H6: !mp mods NF
B7: Round of 32 | C7: NM4 | D7: 3248876 | E7: ISOMERZ (DJ Raisei + seatrus) - Symmetric [BOUYAAA's Insane] | F7: NM4: ISOMERZ (DJ Raisei + seatrus) - Symmetric [BOUYAAA's Insane] | G7: !mp map 3248876 0 | H7: !mp mods NF
B8: Round of 32 | C8: NM5 | D8: 1989991 | E8: Pastel*Palettes - Happy Synthesizer [Insane] | F8: NM5: Pastel*Palettes - Happy Synthesizer [Insane] | G8: !mp map 1989991 0 | H8: !mp mods NF
B9: Round of 32 | C9: HD1 | D9: 3280686 | E9: Tsumiki - phony [Hatsune Miku's Insane] | F9: HD1: Tsumiki - phony [Hatsune Miku's Insane] | G9: !mp map 3280686 0 | H9: !mp mods HD NF
B10: Round of 32 | C10: HD2 | D10: 134141 | E10: P*Light - Poppin' Shower [Hyper] | F10: HD2: P*Light - Poppin' Shower [Hyper] | G10: !mp map 134141 0 | H10: !mp mods HD NF
B11: Round of 32 | C11: HR1 | D11: 2659337 | E11: Omoi - Teo [waji's Insane] | F11: HR1: Omoi - Teo [waji's Insane] | G11: !mp map 2659337 0 | H11: !mp mods HR NF
B12: Round of 32 | C12: HR2 | D12: 2110801 | E12: Silentroom - NULCTRL [Pattern 03a "exHRD" LMT] | F12: HR2: Silentroom - NULCTRL [Pattern 03a "exHRD" LMT] | G12: !mp map 2110801 0 | H12: !mp mods HR NF
B13: Round of 32 | C13: DT1 | D13: 2044893 | E13: mafumafu - Moudoku ga Osou [Hard] | F13: DT1: mafumafu - Moudoku ga Osou [Hard] | G13: !mp map 2044893 0 | H13: !mp mods DT NF
B14: Round of 32 | C14: DT2 | D14: 2366848 | E14: ARForest - Aoba [Hard] | F14: DT2: ARForest - Aoba [Hard] | G14: !mp map 2366848 0 | H14: !mp mods DT NF
B15: Round of 32 | C15: DT3 | D15: 3396305 | E15: xi - Mirage Garden [PaRaDogi's Hard] | F15: DT3: xi - Mirage Garden [PaRaDogi's Hard] | G15: !mp map 3396305 0 | H15: !mp mods DT NF
B16: Round of 32 | C16: FM1 | D16: 846261 | E16: Shawn Wasabi - Marble Soda [Narcissu's Insane] | F16: FM1: Shawn Wasabi - Marble Soda [Narcissu's Insane] | G16: !mp map 846261 0 | H16: !mp mods Freemod
... B19: Round of 16 | C19: NM1 | D19: 2827293 | E19: Yorushika - Thoughtcrime [Akitoshi's Insane] | F19: NM1: Yorushika - Thoughtcrime [Akitoshi's Insane] | G19: !mp map 2827293 0 | H19: !mp mods NF
A20: c | B20: Round of 16 | C20: NM2 | D20: 2004679 | E20: Fractal Dreamers - Gardens Under A Spring Sky [Hyper] | F20: NM2: Fractal Dreamers - Gardens Under A Spring Sky [Hyper] | G20: !mp map 2004679 0 | H20: !mp mods NF
B21: Round of 16 | C21: NM3 | D21: 3239199 | E21: Tsukuyomi - Dareka no Shinzou ni Nareta nara [too's Insane] | F21: NM3: Tsukuyomi - Dareka no Shinzou ni Nareta nara [too's Insane] | G21: !mp map 3239199 0 | H21: !mp mods NF
B22: Round of 16 | C22: NM4 | D22: 2794904 | E22: sakuraburst - Glacierfall (Park Remix) [haruto x ancel's ins*ne] | F22: NM4: sakuraburst - Glacierfall (Park Remix) [haruto x ancel's ins*ne] | G22: !mp map 2794904 0 | H22: !mp mods NF
B23: Round of 16 | C23: NM5 | D23: 2853477 | E23: sekai - Zange Mairi [Voice's Insane] | F23: NM5: sekai - Zange Mairi [Voice's Insane] | G23: !mp map 2853477 0 | H23: !mp mods NF
B24: Round of 16 | C24: HD1 | D24: 1733441 | E24: Police Piccadilly feat. Hatsune Miku - Kire Carry On [negusver's Insane] | F24: HD1: Police Piccadilly feat. Hatsune Miku - Kire Carry On [negusver's Insane] | G24: !mp map 1733441 0 | H24: !mp mods HD NF
B25: Round of 16 | C25: HD2 | D25: 3460069 | E25: Siren - Polaris [8 is not a low ar guys] | F25: HD2: Siren - Polaris [8 is not a low ar guys] | G25: !mp map 3460069 0 | H25: !mp mods HD NF
B26: Round of 16 | C26: HR1 | D26: 1956568 | E26: PSYQUI feat. Such - Senchimentaruhatoboi [Insane] | F26: HR1: PSYQUI feat. Such - Senchimentaruhatoboi [Insane] | G26: !mp map 1956568 0 | H26: !mp mods HR NF
B27: Round of 16 | C27: HR2 | D27: 295650 | E27: Perfume - Laser Beam [Mixagji] | F27: HR2: Perfume - Laser Beam [Mixagji] | G27: !mp map 295650 0 | H27: !mp mods HR NF
B28: Round of 16 | C28: DT1 | D28: 3446883 | E28: Yumeno Yuki - First Time [KoldNoodl's Hard] | F28: DT1: Yumeno Yuki - First Time [KoldNoodl's Hard] | G28: !mp map 3446883 0 | H28: !mp mods DT NF
B29: Round of 16 | C29: DT2 | D29: 1521209 | E29: YUC'e - Future Candy [Hard] | F29: DT2: YUC'e - Future Candy [Hard] | G29: !mp map 1521209 0 | H29: !mp mods DT NF
B30: Round of 16 | C30: DT3 | D30: 3616100 | E30: tarolabo - eth ken [hard] | F30: DT3: tarolabo - eth ken [hard] | G30: !mp map 3616100 0 | H30: !mp mods DT NF
B31: Round of 16 | C31: FM1 | D31: 2151207 | E31: OISHII - ONIGIRI FREEWAY [LUKAS' INSANE] | F31: FM1: OISHII - ONIGIRI FREEWAY [LUKAS' INSANE] | G31: !mp map 2151207 0 | H31: !mp mods Freemod
B32: Round of 16 | C32: FM2 | D32: 417898 | E32: Giga-P - Electric Angel [Sonnyc's Insane] | F32: FM2: Giga-P - Electric Angel [Sonnyc's Insane] | G32: !mp map 417898 0 | H32: !mp mods Freemod
... B109: Grand Finals | C109: TB1 | D109: 862338 | E109: Camellia - d:for the DELTA [Delirium] | F109: TB1: Camellia - d:for the DELTA [Delirium] | G109: !mp map 862338 0 | H109: !mp mods Freemod

Sheet Seedings
A1: small wiener club | B1: {=SEQUENCE(counta(A1:A1000),1)} -> 1
A2: :MIPINGA: | B2: 2
A3: foxy1919191919's basement | B3: 3
A4: Homossexual Students | B4: 4
A5: female ass wrestling | B5: 5
A6: Tom and Jerry | B6: 6
A7: The Mat Munchers | B7: 7
A8: The 3-star Threats | B8: 8
A9: placeholder teamname | B9: 9
A10: Ghost the Angel | B10: 10
A11: Faz o L | B11: 11
A12: Sightread Buff | B12: 12
A13: cake | B13: 13
... A32: lowrank is my love | B32: 32

Sheet Chrono Schedule
D2: Meta | G2: Participants | I2: Staff | M2: Results | P2: Timezones
B3: Link | D3: Match ID | E3: Date | F3: Time | G3: {=IF(Format="Solo","Player","Team")&" "&{1,2}} -> Team 1 | H3: Team 2 | I3: Referee | J3: Streamer | K3: Comm. 1 | L3: Comm. 2 | M3: {=G3:H3} -> Team 1 | N3: Team 2 | O3: MP-Link | P3: Team 1 Timezone | Q3: Team 2 Timezone | R3: Team 2 Availtime | S3: Team 2 Avail time
B4: 4 | D4: {=sort(Schedule!D4:O98,2,1,3,1)} -> 4 | E4: 45156 | F4: 0.54166667 | G4: placeholder teamname | H4: Mewo My Waifu | I4: Emerald Ages | M4: 5 | N4: 1 | O4: https://osu.ppy.sh/community/matches/110051132 | P4: {=INDEX(IF(G4:H98="",,IFNA(VLOOKUP(G4:H98,TeamTimes!B3:D98,2,0),"")),0)} -> UTC+8 | Q4: UTC+2 | R4: {=INDEX(IF(G4:H98="",,IFNA(VLOOKUP(G4:H98,TeamTimes!B3:D98,3,0),"")),0)} -> 11:00 UTC, 12:00 UTC, 13:00 UTC, 14:00 UTC, 15:00 UTC, 16:00 UTC | S4: 12:00 UTC, 13:00 UTC, 14:00 UTC, 15:00 UTC, 18:00 UTC, 19:00 UTC
B5: 1 | D5: 1 | E5: 45156 | F5: 0.58333333 | G5: small wiener club | H5: lowrank is my love | I5: Emerald Ages | M5: 5 | N5: 0 | O5: https://osu.ppy.sh/community/matches/110051880 | P5: UTC+2 | Q5: UTC +3 | R5: 12:00 UTC, 13:00 UTC, 14:00 UTC, 15:00 UTC, 16:00 UTC, 17:00 UTC, 18:00 UTC, 19:00 UTC | S5: 15:00 UTC, 16:00 UTC, 17:00 UTC, 18:00 UTC, 19:00 UTC, 20:00 UTC
B6: 12 | D6: 12 | E6: 45156 | F6: 0.58333333 | G6: Ghost the Angel | H6: PES E9L9 | I6: Emerald Ages | M6: 5 | N6: 3 | O6: https://osu.ppy.sh/community/matches/110051882 | P6: UTC+7 | Q6: UTC+8 | R6: 7:00 UTC, 8:00 UTC, 9:00 UTC, 13:00 UTC, 14:00 UTC, 15:00 UTC, 16:00 UTC | S6: 8:00 UTC, 9:00 UTC, 10:00 UTC, 11:00 UTC, 12:00 UTC, 13:00 UTC, 14:00 UTC, 15:00 UTC, 16:00 UTC
B7: 15 | D7: 15 | E7: 45157 | F7: 0.25 | G7: Tom and Jerry | H7: Lovers + 3rd wheel | I7: Mewo_ | M7: 5 | N7: 4 | O7: https://osu.ppy.sh/community/matches/110063252 | P7: UTC+7 | Q7: UTC-7 | R7: 8:00 UTC, 9:00 UTC, 10:00 UTC, 11:00 UTC, 12:00 UTC, 13:00 UTC, 14:00 UTC | S7: 15:00 UTC, 16:00 UTC, 17:00 UTC, 18:00 UTC, 19:00 UTC, 20:00 UTC, 21:00 UTC
B8: 2 | D8: 2 | E8: 45157 | F8: 0.5 | G8: middle-schooler wife | H8: PLDT ANO NAAA | I8: Gamillie | M8: 5 | N8: 1 | O8: https://osu.ppy.sh/mp/110066290 | P8: UTC+8 | Q8: UTC+8 | R8: 1:00 UTC, 2:00 UTC, 3:00 UTC, 4:00 UTC, 5:00 UTC, 6:00 UTC, 7:00 UTC, 8:00 UTC, 9:00 UTC, 10:00 UTC, 13:00 UTC, 14:00 UTC | S8: 1:00 UTC, 2:00 UTC, 3:00 UTC, 4:00 UTC, 5:00 UTC, 6:00 UTC, 7:00 UTC, 8:00 UTC, 9:00 UTC, 10:00 UTC, 11:00 UTC, 12:00 UTC, 13:00 UTC
B9: 7 | D9: 7 | E9: 45157 | F9: 0.54166667 | G9: female ass wrestling | H9: BOCCHER | I9: Pischok | M9: 5 | N9: 1 | O9: https://osu.ppy.sh/mp/110067010 | P9: UTC+2 | Q9: UTC+2 | R9: 17:00 UTC, 18:00 UTC, 19:00 UTC, 20:00 UTC, 21:00 UTC, 22:00 UTC | S9: 13:00 UTC, 14:00 UTC, 15:00 UTC, 16:00 UTC, 17:00 UTC, 18:00 UTC, 19:00 UTC
B10: 8 | D10: 8 | E10: 45157 | F10: 0.58333333 | G10: Sightread Buff | H10: VN+1 | I10: Gamillie | M10: 2 | N10: 5 | O10: https://osu.ppy.sh/mp/110067659 | P10: UTC +2 | Q10: UTC+7 | R10: 14:00 UTC, 15:00 UTC, 16:00 UTC, 17:00 UTC, 18:00 UTC, 19:00 UTC, 20:00 UTC | S10: 11:00 UTC, 12:00 UTC, 13:00 UTC, 14:00 UTC, 15:00 UTC, 16:00 UTC, 17:00 UTC
B11: 14 | D11: 14 | E11: 45157 | F11: 0.58333333 | G11: match in 15 | H11: 3000CombinedHours | I11: Gamillie | M11: 5 | N11: 2 | O11: https://osu.ppy.sh/community/matches/110067582 | P11: UTC+8 | Q11: UTC+5 | R11: 13:00 UTC, 14:00 UTC, 15:00 UTC, 16:00 UTC, 17:00 UTC, 18:00 UTC, 19:00 UTC, 20:00 UTC, 21:00 UTC, 22:00 UTC | S11: 6:00 UTC, 7:00 UTC, 8:00 UTC, 12:00 UTC, 13:00 UTC, 14:00 UTC, 15:00 UTC, 16:00 UTC
B12: 10 | D12: 10 | E12: 45157 | F12: 0.625 | G12: Dino Nuggies | H12: Chocomaid | I12: Fuwub | M12: 1 | N12: 5 | O12: https://osu.ppy.sh/community/matches/110068687 | P12: UTC-4 | Q12: UTC+8 | R12: 15:00 UTC, 16:00 UTC, 17:00 UTC, 18:00 UTC, 19:00 UTC, 20:00 UTC, 21:00 UTC | S12: 12:00 UTC, 13:00 UTC, 14:00 UTC, 15:00 UTC, 16:00 UTC, 17:00 UTC
B13: 6 | D13: 6 | E13: 45158 | F13: 0.041666667 | G13: cake | H13: equipe câo | I13: Emerald Ages | M13: 5 | N13: 1 | O13: https://osu.ppy.sh/community/matches/110076817 | P13: UTC+3 | Q13: UTC-3 | R13: 3:00 UTC, 4:00 UTC, 13:00 UTC, 15:00 UTC, 16:00 UTC, 20:00 UTC | S13: 17:00 UTC, 18:00 UTC, 19:00 UTC, 21:00 UTC, 22:00 UTC, 23:00 UTC
B14: 13 | D14: 13 | E14: 45158 | F14: 0.083333333 | G14: foxy1919191919's basement | H14: Here Forever | I14: BlooMertz | M14: 5 | N14: 1 | O14: https://osu.ppy.sh/community/matches/110077387 | P14: UTC+9 | Q14: UTC-5 | R14: 6:00 UTC, 7:00 UTC, 8:00 UTC, 9:00 UTC, 10:00 UTC, 11:00 UTC, 12:00 UTC, 13:00 UTC, 14:00 UTC | S14: 0:00 UTC / 24:00 UTC, 1:00 UTC, 2:00 UTC, 3:00 UTC, 4:00 UTC, 5:00 UTC, 15:00 UTC, 16:00 UTC, 23:00 UTC
B15: 9 | D15: 9 | E15: 45158 | F15: 0.125 | G15: :MIPINGA: | H15: Beancurd | I15: play hd3 | M15: 5 | N15: 0 | O15: https://osu.ppy.sh/community/matches/110077688 | P15: UTC -5 | Q15: UTC+0 | R15: 0:00 UTC / 24:00 UTC, 1:00 UTC, 2:00 UTC, 19:00 UTC, 20:00 UTC, 21:00 UTC, 22:00 UTC, 23:00 UTC | S15: 5:00 UTC, 6:00 UTC, 7:00 UTC, 13:00 UTC, 14:00 UTC, 15:00 UTC
B16: 11 | D16: 11 | E16: 45158 | F16: 0.625 | G16: The Mat Munchers | H16: Team name pending xd | I16: Emerald Ages | M16: 0 | N16: 5 | O16: https://osu.ppy.sh/community/matches/110085247 | P16: UTC+1 | Q16: UTC+8 | R16: 18:00 UTC, 19:00 UTC, 20:00 UTC, 21:00 UTC, 22:00 UTC, 23:00 UTC | S16: 6:00 UTC, 7:00 UTC, 8:00 UTC, 13:00 UTC, 14:00 UTC, 15:00 UTC
... B29: 29 | D29: 29 | E29: 45165 | F29: 0.10416667 | G29: :MIPINGA: | H29: Chocomaid | I29: play hd3 | M29: 5 | N29: 1 | O29: https://osu.ppy.sh/community/matches/110184531 | P29: UTC -5 | Q29: UTC+8 | R29: 0:00 UTC / 24:00 UTC, 1:00 UTC, 2:00 UTC, 19:00 UTC, 20:00 UTC, 21:00 UTC, 22:00 UTC, 23:00 UTC | S29: 12:00 UTC, 13:00 UTC, 14:00 UTC, 15:00 UTC, 16:00 UTC, 17:00 UTC
B30: 24 | D30: 24 | E30: 45165 | F30: 0.16666667 | G30: Lovers + 3rd wheel | H30: Faz o L | M30: 2 | N30: 5 | O30: https://osu.ppy.sh/community/matches/110185577 | P30: UTC-7 | Q30: UTC -3 | R30: 15:00 UTC, 16:00 UTC, 17:00 UTC, 18:00 UTC, 19:00 UTC, 20:00 UTC, 21:00 UTC | S30: 18:00 UTC, 19:00 UTC, 20:00 UTC, 21:00 UTC, 22:00 UTC, 23:00 UTC
B31: 19 | D31: 19 | E31: 45165 | F31: 0.54166667 | G31: Better HD Abusers | H31: equipe câo | I31: reforna | M31: 0 | N31: 5 | O31: https://osu.ppy.sh/community/matches/110190490 | P31: UTC-6 | Q31: UTC-3 | R31: 0:00 UTC / 24:00 UTC, 1:00 UTC, 2:00 UTC, 21:00 UTC, 22:00 UTC, 23:00 UTC | S31: 17:00 UTC, 18:00 UTC, 19:00 UTC, 21:00 UTC, 22:00 UTC, 23:00 UTC
B32: 25 | D32: 25 | E32: 45165 | F32: 0.54166667 | G32: small wiener club | H32: middle-schooler wife | I32: reforna | M32: 5 | N32: 3 | O32: https://osu.ppy.sh/community/matches/110190477 | P32: UTC+2 | Q32: UTC+8 | R32: 12:00 UTC, 13:00 UTC, 14:00 UTC, 15:00 UTC, 16:00 UTC, 17:00 UTC, 18:00 UTC, 19:00 UTC | S32: 1:00 UTC, 2:00 UTC, 3:00 UTC, 4:00 UTC, 5:00 UTC, 6:00 UTC, 7:00 UTC, 8:00 UTC, 9:00 UTC, 10:00 UTC, 13:00 UTC, 14:00 UTC
B33: 28 | D33: 28 | E33: 45165 | F33: 0.58333333 | G33: female ass wrestling | H33: VN+1 | I33: RudderFish07 | M33: 5 | N33: 1 | O33: https://osu.ppy.sh/community/matches/110191205 | P33: UTC+2 | Q33: UTC+7 | R33: 17:00 UTC, 18:00 UTC, 19:00 UTC, 20:00 UTC, 21:00 UTC, 22:00 UTC | S33: 11:00 UTC, 12:00 UTC, 13:00 UTC, 14:00 UTC, 15:00 UTC, 16:00 UTC, 17:00 UTC
B34: 20 | D34: 20 | E34: 45165 | F34: 0.75 | G34: BOCCHER | H34: Sightread Buff | I34: Ninja Mejster | M34: 1 | N34: 5 | O34: https://osu.ppy.sh/community/matches/110194908 | P34: UTC+2 | Q34: UTC +2 | R34: 13:00 UTC, 14:00 UTC, 15:00 UTC, 16:00 UTC, 17:00 UTC, 18:00 UTC, 19:00 UTC | S34: 14:00 UTC, 15:00 UTC, 16:00 UTC, 17:00 UTC, 18:00 UTC, 19:00 UTC, 20:00 UTC
B35: 17 | D35: 17 | E35: 45166 | F35: 0.54166667 | G35: lowrank is my love | H35: PLDT ANO NAAA | I35: Azasapag | M35: 1 | N35: 5 | O35: https://osu.ppy.sh/community/matches/110206456 | P35: UTC +3 | Q35: UTC+8 | R35: 15:00 UTC, 16:00 UTC, 17:00 UTC, 18:00 UTC, 19:00 UTC, 20:00 UTC | S35: 1:00 UTC, 2:00 UTC, 3:00 UTC, 4:00 UTC, 5:00 UTC, 6:00 UTC, 7:00 UTC, 8:00 UTC, 9:00 UTC, 10:00 UTC, 11:00 UTC, 12:00 UTC, 13:00 UTC
B36: 36 | D36: 36 | E36: 45171 | F36: 0.0625 | G36: VN+1 | H36: Dino Nuggies | I36: play hd3 | M36: 6 | N36: 0 | O36: https://osu.ppy.sh/community/matches/110275875 | P36: UTC+7 | Q36: UTC-4 | R36: 11:00 UTC, 12:00 UTC, 13:00 UTC, 14:00 UTC, 15:00 UTC, 16:00 UTC, 17:00 UTC | S36: 15:00 UTC, 16:00 UTC, 17:00 UTC, 18:00 UTC, 19:00 UTC, 20:00 UTC, 21:00 UTC
B37: 45 | D37: 45 | E37: 45171 | F37: 0.54166667 | G37: small wiener club | H37: placeholder teamname | I37: Emerald Ages | M37: 2 | N37: 6 | O37: https://osu.ppy.sh/community/matches/110282200 | P37: UTC+2 | Q37: UTC+8 | R37: 12:00 UTC, 13:00 UTC, 14:00 UTC, 15:00 UTC, 16:00 UTC, 17:00 UTC, 18:00 UTC, 19:00 UTC | S37: 11:00 UTC, 12:00 UTC, 13:00 UTC, 14:00 UTC, 15:00 UTC, 16:00 UTC
B38: 37 | D38: 37 | E38: 45171 | F38: 0.58333333 | G38: Chocomaid | H38: Sightread Buff | I38: Emerald Ages | M38: 6 | N38: 1 | O38: https://osu.ppy.sh/community/matches/110283000 | P38: UTC+8 | Q38: UTC +2 | R38: 12:00 UTC, 13:00 UTC, 14:00 UTC, 15:00 UTC, 16:00 UTC, 17:00 UTC | S38: 14:00 UTC, 15:00 UTC, 16:00 UTC, 17:00 UTC, 18:00 UTC, 19:00 UTC, 20:00 UTC
B39: 40 | D39: 40 | E39: 45171 | F39: 0.58333333 | G39: Kittens | H39: PLDT ANO NAAA | I39: Emerald Ages | M39: 6 | N39: 3 | O39: https://osu.ppy.sh/community/matches/110283001 | P39: UTC+2 | Q39: UTC+8 | R39: 14:00 UTC, 15:00 UTC, 16:00 UTC, 17:00 UTC, 18:00 UTC, 19:00 UTC, 20:00 UTC, 21:00 UTC, 22:00 UTC | S39: 1:00 UTC, 2:00 UTC, 3:00 UTC, 4:00 UTC, 5:00 UTC, 6:00 UTC, 7:00 UTC, 8:00 UTC, 9:00 UTC, 10:00 UTC, 11:00 UTC, 12:00 UTC, 13:00 UTC
B40: 38 | D40: 38 | E40: 45171 | F40: 0.625 | G40: Team name pending xd | H40: equipe câo | I40: Emerald Ages | M40: 6 | N40: 4 | O40: https://osu.ppy.sh/community/matches/110283874 | P40: UTC+8 | Q40: UTC-3 | R40: 6:00 UTC, 7:00 UTC, 8:00 UTC, 13:00 UTC, 14:00 UTC, 15:00 UTC | S40: 17:00 UTC, 18:00 UTC, 19:00 UTC, 21:00 UTC, 22:00 UTC, 23:00 UTC
B41: 47 | D41: 47 | E41: 45171 | F41: 0.625 | G41: :MIPINGA: | H41: Ghost the Angel | I41: Pischok | M41: 0 | N41: -1 | P41: UTC -5 | Q41: UTC+7 | R41: 0:00 UTC / 24:00 UTC, 1:00 UTC, 2:00 UTC, 19:00 UTC, 20:00 UTC, 21:00 UTC, 22:00 UTC, 23:00 UTC | S41: 7:00 UTC, 8:00 UTC, 9:00 UTC, 13:00 UTC, 14:00 UTC, 15:00 UTC, 16:00 UTC
B42: 34 | D42: 34 | E42: 45171 | F42: 0.95833333 | G42: The 3-star Threats | H42: Here Forever | I42: play hd3 | M42: 6 | N42: 3 | O42: https://osu.ppy.sh/community/matches/110291479 | P42: UTC-4 | Q42: UTC-5 | R42: 0:00 UTC / 24:00 UTC, 18:00 UTC, 19:00 UTC, 20:00 UTC, 21:00 UTC, 22:00 UTC, 23:00 UTC | S42: 0:00 UTC / 24:00 UTC, 1:00 UTC, 2:00 UTC, 3:00 UTC, 4:00 UTC, 5:00 UTC, 15:00 UTC, 16:00 UTC, 23:00 UTC
B43: 41c | D43: 41c | E43: 45172 | F43: 0.16666667 | G43: Here Forever | H43: middle-schooler wife | P43: UTC-5 | Q43: UTC+8 | R43: 0:00 UTC / 24:00 UTC, 1:00 UTC, 2:00 UTC, 3:00 UTC, 4:00 UTC, 5:00 UTC, 15:00 UTC, 16:00 UTC, 23:00 UTC | S43: 1:00 UTC, 2:00 UTC, 3:00 UTC, 4:00 UTC, 5:00 UTC, 6:00 UTC, 7:00 UTC, 8:00 UTC, 9:00 UTC, 10:00 UTC, 13:00 UTC, 14:00 UTC
B44: 44c | D44: 44c | E44: 45172 | F44: 0.33333333 | G44: PLDT ANO NAAA | H44: foxy1919191919's basement | P44: UTC+8 | Q44: UTC+9 | R44: 1:00 UTC, 2:00 UTC, 3:00 UTC, 4:00 UTC, 5:00 UTC, 6:00 UTC, 7:00 UTC, 8:00 UTC, 9:00 UTC, 10:00 UTC, 11:00 UTC, 12:00 UTC, 13:00 UTC | S44: 6:00 UTC, 7:00 UTC, 8:00 UTC, 9:00 UTC, 10:00 UTC, 11:00 UTC, 12:00 UTC, 13:00 UTC, 14:00 UTC
B45: 42b | D45: 42b | E45: 45172 | F45: 0.5 | G45: VN+1 | H45: PES E9L9 | P45: UTC+7 | Q45: UTC+8 | R45: 11:00 UTC, 12:00 UTC, 13:00 UTC, 14:00 UTC, 15:00 UTC, 16:00 UTC, 17:00 UTC | S45: 8:00 UTC, 9:00 UTC, 10:00 UTC, 11:00 UTC, 12:00 UTC, 13:00 UTC, 14:00 UTC, 15:00 UTC, 16:00 UTC
B46: 48 | D46: 48 | E46: 45172 | F46: 0.5 | G46: match in 15 | H46: Tom and Jerry | I46: reforna | M46: 6 | N46: 2 | O46: https://osu.ppy.sh/community/matches/110299252 | P46: UTC+8 | Q46: UTC+7 | R46: 13:00 UTC, 14:00 UTC, 15:00 UTC, 16:00 UTC, 17:00 UTC, 18:00 UTC, 19:00 UTC, 20:00 UTC, 21:00 UTC, 22:00 UTC | S46: 8:00 UTC, 9:00 UTC, 10:00 UTC, 11:00 UTC, 12:00 UTC, 13:00 UTC, 14:00 UTC
B47: 39 | D47: 39 | E47: 45172 | F47: 0.52083333 | G47: foxy1919191919's basement | H47: The sleepers | I47: Pischok | M47: -1 | N47: 0 | O47: https://osu.ppy.sh/community/matches/110299202 | P47: UTC+9 | Q47: UTC+2 | R47: 6:00 UTC, 7:00 UTC, 8:00 UTC, 9:00 UTC, 10:00 UTC, 11:00 UTC, 12:00 UTC, 13:00 UTC, 14:00 UTC | S47: 0:00 UTC / 24:00 UTC, 15:00 UTC, 16:00 UTC, 17:00 UTC, 18:00 UTC, 19:00 UTC, 20:00 UTC
B48: 33 | D48: 33 | E48: 45172 | F48: 0.58333333 | G48: middle-schooler wife | H48: Faz o L | M48: 6 | N48: 2 | O48: https://osu.ppy.sh/community/matches/110301082 | P48: UTC+8 | Q48: UTC -3 | R48: 1:00 UTC, 2:00 UTC, 3:00 UTC, 4:00 UTC, 5:00 UTC, 6:00 UTC, 7:00 UTC, 8:00 UTC, 9:00 UTC, 10:00 UTC, 13:00 UTC, 14:00 UTC | S48: 18:00 UTC, 19:00 UTC, 20:00 UTC, 21:00 UTC, 22:00 UTC, 23:00 UTC
B49: 43 | D49: 43 | E49: 45172 | F49: 0.58333333 | G49: Team name pending xd | H49: Chocomaid | I49: reforna | M49: 0 | N49: 6 | O49: https://osu.ppy.sh/community/matches/110298939 | P49: UTC+8 | Q49: UTC+8 | R49: 6:00 UTC, 7:00 UTC, 8:00 UTC, 13:00 UTC, 14:00 UTC, 15:00 UTC | S49: 12:00 UTC, 13:00 UTC, 14:00 UTC, 15:00 UTC, 16:00 UTC, 17:00 UTC
B50: 43a | D50: 43a | E50: 45172 | F50: 0.58333333 | G50: Team name pending xd | H50: Chocomaid | P50: UTC+8 | Q50: UTC+8 | R50: 6:00 UTC, 7:00 UTC, 8:00 UTC, 13:00 UTC, 14:00 UTC, 15:00 UTC | S50: 12:00 UTC, 13:00 UTC, 14:00 UTC, 15:00 UTC, 16:00 UTC, 17:00 UTC
B51: 43b | D51: 43b | E51: 45172 | F51: 0.58333333 | G51: Team name pending xd | H51: Sightread Buff | P51: UTC+8 | Q51: UTC +2 | R51: 6:00 UTC, 7:00 UTC, 8:00 UTC, 13:00 UTC, 14:00 UTC, 15:00 UTC | S51: 14:00 UTC, 15:00 UTC, 16:00 UTC, 17:00 UTC, 18:00 UTC, 19:00 UTC, 20:00 UTC
B52: 44 | D52: 44 | E52: 45172 | F52: 0.58333333 | G52: Kittens | H52: The sleepers | I52: Emerald Ages | M52: 4 | N52: 6 | O52: https://osu.ppy.sh/community/matches/110300869 | P52: UTC+2 | Q52: UTC+2 | R52: 14:00 UTC, 15:00 UTC, 16:00 UTC, 17:00 UTC, 18:00 UTC, 19:00 UTC, 20:00 UTC, 21:00 UTC, 22:00 UTC | S52: 0:00 UTC / 24:00 UTC, 15:00 UTC, 16:00 UTC, 17:00 UTC, 18:00 UTC, 19:00 UTC, 20:00 UTC
B53: 44a | D53: 44a | E53: 45172 | F53: 0.58333333 | G53: Kittens | H53: foxy1919191919's basement | P53: UTC+2 | Q53: UTC+9 | R53: 14:00 UTC, 15:00 UTC, 16:00 UTC, 17:00 UTC, 18:00 UTC, 19:00 UTC, 20:00 UTC, 21:00 UTC, 22:00 UTC | S53: 6:00 UTC, 7:00 UTC, 8:00 UTC, 9:00 UTC, 10:00 UTC, 11:00 UTC, 12:00 UTC, 13:00 UTC, 14:00 UTC
...

Sheet Schedule
D2: Meta | G2: Participants | I2: Staff | M2: Results | P2: Timezones
B3: Link | D3: Match ID | E3: Date | F3: Time | G3: {=IF(Format="Solo","Player","Team")&" "&{1,2}} -> Team 1 | H3: Team 2 | I3: Referee | J3: Streamer | K3: Comm. 1 | L3: Comm. 2 | M3: {=G3:H3} -> Team 1 | N3: Team 2 | O3: MP-Link | P3: Team 1 Timezone | Q3: Team 2 Timezone | R3: Team 2 Availtime | S3: Team 2 Avail time
B4: 1 | D4: 1 | E4: 45156 | F4: 0.58333333 | G4: =IFERROR(__xludf.DUMMYFUNCTION("IMPORTRANGE(""1OcmMKanhpJggZ2wC7WM2iuGUr_0D1ZyYK8JGx81NzUE"",""Ro32DE!F2:G96"")"),"small wiener club") -> small wiener club | H4: =IFERROR(__xludf.DUMMYFUNCTION("""COMPUTED_VALUE"""),"lowrank is my love") -> lowrank is my love | I4: Emerald Ages | M4: {=IFERROR(IF(D4="",,{INDIRECT("'"&D4&"'!C3"),INDIRECT("'"&D4&"'!E3"),INDIRECT("'"&D4&"'!I3")}),"")&T(NOW())} -> 5 | N4: 0 | O4: https://osu.ppy.sh/community/matches/110051880 | P4: {=INDEX(IF(G4:H98="",,IFNA(VLOOKUP(G4:H98,TeamTimes!B3:D98,2,0),"")),0)} -> UTC+2 | Q4: UTC +3 | R4: {=INDEX(IF(G4:H98="",,IFNA(VLOOKUP(G4:H98,TeamTimes!B3:D98,3,0),"")),0)} -> 12:00 UTC, 13:00 UTC, 14:00 UTC, 15:00 UTC, 16:00 UTC, 17:00 UTC, 18:00 UTC, 19:00 UTC | S4: 15:00 UTC, 16:00 UTC, 17:00 UTC, 18:00 UTC, 19:00 UTC, 20:00 UTC
B5: 2 | D5: 2 | E5: 45157 | F5: 0.5 | G5: =IFERROR(__xludf.DUMMYFUNCTION("""COMPUTED_VALUE"""),"middle-schooler wife") -> middle-schooler wife | H5: =IFERROR(__xludf.DUMMYFUNCTION("""COMPUTED_VALUE"""),"PLDT ANO NAAA") -> PLDT ANO NAAA | I5: Gamillie | M5: {=IFERROR(IF(D5="",,{INDIRECT("'"&D5&"'!C3"),INDIRECT("'"&D5&"'!E3"),INDIRECT("'"&D5&"'!I3")}),"")&T(NOW())} -> 5 | N5: 1 | O5: https://osu.ppy.sh/mp/110066290 | P5: UTC+8 | Q5: UTC+8 | R5: 1:00 UTC, 2:00 UTC, 3:00 UTC, 4:00 UTC, 5:00 UTC, 6:00 UTC, 7:00 UTC, 8:00 UTC, 9:00 UTC, 10:00 UTC, 13:00 UTC, 14:00 UTC | S5: 1:00 UTC, 2:00 UTC, 3:00 UTC, 4:00 UTC, 5:00 UTC, 6:00 UTC, 7:00 UTC, 8:00 UTC, 9:00 UTC, 10:00 UTC, 11:00 UTC, 12:00 UTC, 13:00 UTC
B6: 3 | D6: 3 | E6: 45158 | F6: 0.875 | G6: =IFERROR(__xludf.DUMMYFUNCTION("""COMPUTED_VALUE"""),"The 3-star Threats") -> The 3-star Threats | H6: =IFERROR(__xludf.DUMMYFUNCTION("""COMPUTED_VALUE"""),"The sleepers") -> The sleepers | I6: Mewo_ | M6: {=IFERROR(IF(D6="",,{INDIRECT("'"&D6&"'!C3"),INDIRECT("'"&D6&"'!E3"),INDIRECT("'"&D6&"'!I3")}),"")&T(NOW())} -> 5 | N6: 1 | O6: https://osu.ppy.sh/mp/110090518 | P6: UTC-4 | Q6: UTC+2 | R6: 0:00 UTC / 24:00 UTC, 18:00 UTC, 19:00 UTC, 20:00 UTC, 21:00 UTC, 22:00 UTC, 23:00 UTC | S6: 0:00 UTC / 24:00 UTC, 15:00 UTC, 16:00 UTC, 17:00 UTC, 18:00 UTC, 19:00 UTC, 20:00 UTC
B7: 4 | D7: 4 | E7: 45156 | F7: 0.54166667 | G7: =IFERROR(__xludf.DUMMYFUNCTION("""COMPUTED_VALUE"""),"placeholder teamname") -> placeholder teamname | H7: =IFERROR(__xludf.DUMMYFUNCTION("""COMPUTED_VALUE"""),"Mewo My Waifu") -> Mewo My Waifu | I7: Emerald Ages | M7: {=IFERROR(IF(D7="",,{INDIRECT("'"&D7&"'!C3"),INDIRECT("'"&D7&"'!E3"),INDIRECT("'"&D7&"'!I3")}),"")&T(NOW())} -> 5 | N7: 1 | O7: https://osu.ppy.sh/community/matches/110051132 | P7: UTC+8 | Q7: UTC+2 | R7: 11:00 UTC, 12:00 UTC, 13:00 UTC, 14:00 UTC, 15:00 UTC, 16:00 UTC | S7: 12:00 UTC, 13:00 UTC, 14:00 UTC, 15:00 UTC, 18:00 UTC, 19:00 UTC
B8: 5 | D8: 5 | E8: 45158 | F8: 0.75 | G8: =IFERROR(__xludf.DUMMYFUNCTION("""COMPUTED_VALUE"""),"Homossexual Students") -> Homossexual Students | H8: =IFERROR(__xludf.DUMMYFUNCTION("""COMPUTED_VALUE"""),"Better HD Abusers") -> Better HD Abusers | I8: Mewo_ | M8: {=IFERROR(IF(D8="",,{INDIRECT("'"&D8&"'!C3"),INDIRECT("'"&D8&"'!E3"),INDIRECT("'"&D8&"'!I3")}),"")&T(NOW())} -> 5 | N8: 2 | O8: https://osu.ppy.sh/community/matches/110087766 | P8: UTC-3 | Q8: UTC-6 | R8: 0:00 UTC / 24:00 UTC, 1:00 UTC, 11:00 UTC, 12:00 UTC, 13:00 UTC, 14:00 UTC, 15:00 UTC, 16:00 UTC, 17:00 UTC, 18:00 UTC, 19:00 UTC, 20:00 UTC, 21:00 UTC, 22:00 UTC, 23:00 UTC | S8: 0:00 UTC / 24:00 UTC, 1:00 UTC, 2:00 UTC, 21:00 UTC, 22:00 UTC, 23:00 UTC
B9: 6 | D9: 6 | E9: 45158 | F9: 0.041666667 | G9: =IFERROR(__xludf.DUMMYFUNCTION("""COMPUTED_VALUE"""),"cake") -> cake | H9: =IFERROR(__xludf.DUMMYFUNCTION("""COMPUTED_VALUE"""),"equipe câo") -> equipe câo | I9: Emerald Ages | M9: {=IFERROR(IF(D9="",,{INDIRECT("'"&D9&"'!C3"),INDIRECT("'"&D9&"'!E3"),INDIRECT("'"&D9&"'!I3")}),"")&T(NOW())} -> 5 | N9: 1 | O9: https://osu.ppy.sh/community/matches/110076817 | P9: UTC+3 | Q9: UTC-3 | R9: 3:00 UTC, 4:00 UTC, 13:00 UTC, 15:00 UTC, 16:00 UTC, 20:00 UTC | S9: 17:00 UTC, 18:00 UTC, 19:00 UTC, 21:00 UTC, 22:00 UTC, 23:00 UTC
B10: 7 | D10: 7 | E10: 45157 | F10: 0.54166667 | G10: =IFERROR(__xludf.DUMMYFUNCTION("""COMPUTED_VALUE"""),"female ass wrestling") -> female ass wrestling | H10: =IFERROR(__xludf.DUMMYFUNCTION("""COMPUTED_VALUE"""),"BOCCHER") -> BOCCHER | I10: Pischok | M10: {=IFERROR(IF(D10="",,{INDIRECT("'"&D10&"'!C3"),INDIRECT("'"&D10&"'!E3"),INDIRECT("'"&D10&"'!I3")}),"")&T(NOW())} -> 5 | N10: 1 | O10: https://osu.ppy.sh/mp/110067010 | P10: UTC+2 | Q10: UTC+2 | R10: 17:00 UTC, 18:00 UTC, 19:00 UTC, 20:00 UTC, 21:00 UTC, 22:00 UTC | S10: 13:00 UTC, 14:00 UTC, 15:00 UTC, 16:00 UTC, 17:00 UTC, 18:00 UTC, 19:00 UTC
B11: 8 | D11: 8 | E11: 45157 | F11: 0.58333333 | G11: =IFERROR(__xludf.DUMMYFUNCTION("""COMPUTED_VALUE"""),"Sightread Buff") -> Sightread Buff | H11: =IFERROR(__xludf.DUMMYFUNCTION("""COMPUTED_VALUE"""),"VN+1") -> VN+1 | I11: Gamillie | M11: {=IFERROR(IF(D11="",,{INDIRECT("'"&D11&"'!C3"),INDIRECT("'"&D11&"'!E3"),INDIRECT("'"&D11&"'!I3")}),"")&T(NOW())} -> 2 | N11: 5 | O11: https://osu.ppy.sh/mp/110067659 | P11: UTC +2 | Q11: UTC+7 | R11: 14:00 UTC, 15:00 UTC, 16:00 UTC, 17:00 UTC, 18:00 UTC, 19:00 UTC, 20:00 UTC | S11: 11:00 UTC, 12:00 UTC, 13:00 UTC, 14:00 UTC, 15:00 UTC, 16:00 UTC, 17:00 UTC
B12: 9 | D12: 9 | E12: 45158 | F12: 0.125 | G12: =IFERROR(__xludf.DUMMYFUNCTION("""COMPUTED_VALUE"""),":MIPINGA:") -> :MIPINGA: | H12: =IFERROR(__xludf.DUMMYFUNCTION("""COMPUTED_VALUE"""),"Beancurd") -> Beancurd | I12: play hd3 | M12: {=IFERROR(IF(D12="",,{INDIRECT("'"&D12&"'!C3"),INDIRECT("'"&D12&"'!E3"),INDIRECT("'"&D12&"'!I3")}),"")&T(NOW())} -> 5 | N12: 0 | O12: https://osu.ppy.sh/community/matches/110077688 | P12: UTC -5 | Q12: UTC+0 | R12: 0:00 UTC / 24:00 UTC, 1:00 UTC, 2:00 UTC, 19:00 UTC, 20:00 UTC, 21:00 UTC, 22:00 UTC, 23:00 UTC | S12: 5:00 UTC, 6:00 UTC, 7:00 UTC, 13:00 UTC, 14:00 UTC, 15:00 UTC
B13: 10 | D13: 10 | E13: 45157 | F13: 0.625 | G13: =IFERROR(__xludf.DUMMYFUNCTION("""COMPUTED_VALUE"""),"Dino Nuggies") -> Dino Nuggies | H13: =IFERROR(__xludf.DUMMYFUNCTION("""COMPUTED_VALUE"""),"Chocomaid") -> Chocomaid | I13: Fuwub | M13: {=IFERROR(IF(D13="",,{INDIRECT("'"&D13&"'!C3"),INDIRECT("'"&D13&"'!E3"),INDIRECT("'"&D13&"'!I3")}),"")&T(NOW())} -> 1 | N13: 5 | O13: https://osu.ppy.sh/community/matches/110068687 | P13: UTC-4 | Q13: UTC+8 | R13: 15:00 UTC, 16:00 UTC, 17:00 UTC, 18:00 UTC, 19:00 UTC, 20:00 UTC, 21:00 UTC | S13: 12:00 UTC, 13:00 UTC, 14:00 UTC, 15:00 UTC, 16:00 UTC, 17:00 UTC
B14: 11 | D14: 11 | E14: 45158 | F14: 0.625 | G14: =IFERROR(__xludf.DUMMYFUNCTION("""COMPUTED_VALUE"""),"The Mat Munchers") -> The Mat Munchers | H14: =IFERROR(__xludf.DUMMYFUNCTION("""COMPUTED_VALUE"""),"Team name pending xd") -> Team name pending xd | I14: Emerald Ages | M14: {=IFERROR(IF(D14="",,{INDIRECT("'"&D14&"'!C3"),INDIRECT("'"&D14&"'!E3"),INDIRECT("'"&D14&"'!I3")}),"")&T(NOW())} -> 0 | N14: 5 | O14: https://osu.ppy.sh/community/matches/110085247 | P14: UTC+1 | Q14: UTC+8 | R14: 18:00 UTC, 19:00 UTC, 20:00 UTC, 21:00 UTC, 22:00 UTC, 23:00 UTC | S14: 6:00 UTC, 7:00 UTC, 8:00 UTC, 13:00 UTC, 14:00 UTC, 15:00 UTC
B15: 12 | D15: 12 | E15: 45156 | F15: 0.58333333 | G15: =IFERROR(__xludf.DUMMYFUNCTION("""COMPUTED_VALUE"""),"Ghost the Angel") -> Ghost the Angel | H15: =IFERROR(__xludf.DUMMYFUNCTION("""COMPUTED_VALUE"""),"PES E9L9") -> PES E9L9 | I15: Emerald Ages | M15: {=IFERROR(IF(D15="",,{INDIRECT("'"&D15&"'!C3"),INDIRECT("'"&D15&"'!E3"),INDIRECT("'"&D15&"'!I3")}),"")&T(NOW())} -> 5 | N15: 3 | O15: https://osu.ppy.sh/community/matches/110051882 | P15: UTC+7 | Q15: UTC+8 | R15: 7:00 UTC, 8:00 UTC, 9:00 UTC, 13:00 UTC, 14:00 UTC, 15:00 UTC, 16:00 UTC | S15: 8:00 UTC, 9:00 UTC, 10:00 UTC, 11:00 UTC, 12:00 UTC, 13:00 UTC, 14:00 UTC, 15:00 UTC, 16:00 UTC
B16: 13 | D16: 13 | E16: 45158 | F16: 0.083333333 | G16: =IFERROR(__xludf.DUMMYFUNCTION("""COMPUTED_VALUE"""),"foxy1919191919's basement") -> foxy1919191919's basement | H16: =IFERROR(__xludf.DUMMYFUNCTION("""COMPUTED_VALUE"""),"Here Forever") -> Here Forever | I16: BlooMertz | M16: {=IFERROR(IF(D16="",,{INDIRECT("'"&D16&"'!C3"),INDIRECT("'"&D16&"'!E3"),INDIRECT("'"&D16&"'!I3")}),"")&T(NOW())} -> 5 | N16: 1 | O16: https://osu.ppy.sh/community/matches/110077387 | P16: UTC+9 | Q16: UTC-5 | R16: 6:00 UTC, 7:00 UTC, 8:00 UTC, 9:00 UTC, 10:00 UTC, 11:00 UTC, 12:00 UTC, 13:00 UTC, 14:00 UTC | S16: 0:00 UTC / 24:00 UTC, 1:00 UTC, 2:00 UTC, 3:00 UTC, 4:00 UTC, 5:00 UTC, 15:00 UTC, 16:00 UTC, 23:00 UTC
B17: 14 | D17: 14 | E17: 45157 | F17: 0.58333333 | G17: =IFERROR(__xludf.DUMMYFUNCTION("""COMPUTED_VALUE"""),"match in 15") -> match in 15 | H17: =IFERROR(__xludf.DUMMYFUNCTION("""COMPUTED_VALUE"""),"3000CombinedHours") -> 3000CombinedHours | I17: Gamillie | M17: {=IFERROR(IF(D17="",,{INDIRECT("'"&D17&"'!C3"),INDIRECT("'"&D17&"'!E3"),INDIRECT("'"&D17&"'!I3")}),"")&T(NOW())} -> 5 | N17: 2 | O17: https://osu.ppy.sh/community/matches/110067582 | P17: UTC+8 | Q17: UTC+5 | R17: 13:00 UTC, 14:00 UTC, 15:00 UTC, 16:00 UTC, 17:00 UTC, 18:00 UTC, 19:00 UTC, 20:00 UTC, 21:00 UTC, 22:00 UTC | S17: 6:00 UTC, 7:00 UTC, 8:00 UTC, 12:00 UTC, 13:00 UTC, 14:00 UTC, 15:00 UTC, 16:00 UTC
B18: 15 | D18: 15 | E18: 45157 | F18: 0.25 | G18: =IFERROR(__xludf.DUMMYFUNCTION("""COMPUTED_VALUE"""),"Tom and Jerry") -> Tom and Jerry | H18: =IFERROR(__xludf.DUMMYFUNCTION("""COMPUTED_VALUE"""),"Lovers + 3rd wheel") -> Lovers + 3rd wheel | I18: Mewo_ | M18: {=IFERROR(IF(D18="",,{INDIRECT("'"&D18&"'!C3"),INDIRECT("'"&D18&"'!E3"),INDIRECT("'"&D18&"'!I3")}),"")&T(NOW())} -> 5 | N18: 4 | O18: https://osu.ppy.sh/community/matches/110063252 | P18: UTC+7 | Q18: UTC-7 | R18: 8:00 UTC, 9:00 UTC, 10:00 UTC, 11:00 UTC, 12:00 UTC, 13:00 UTC, 14:00 UTC | S18: 15:00 UTC, 16:00 UTC, 17:00 UTC, 18:00 UTC, 19:00 UTC, 20:00 UTC, 21:00 UTC
B19: 16 | D19: 16 | E19: 45158 | F19: 0.8125 | G19: =IFERROR(__xludf.DUMMYFUNCTION("""COMPUTED_VALUE"""),"Faz o L") -> Faz o L | H19: =IFERROR(__xludf.DUMMYFUNCTION("""COMPUTED_VALUE"""),"Kittens") -> Kittens | I19: -PeKoRa- | M19: {=IFERROR(IF(D19="",,{INDIRECT("'"&D19&"'!C3"),INDIRECT("'"&D19&"'!E3"),INDIRECT("'"&D19&"'!I3")}),"")&T(NOW())} -> 3 | N19: 5 | O19: https://osu.ppy.sh/community/matches/110089262 | P19: UTC -3 | Q19: UTC+2 | R19: 18:00 UTC, 19:00 UTC, 20:00 UTC, 21:00 UTC, 22:00 UTC, 23:00 UTC | S19: 14:00 UTC, 15:00 UTC, 16:00 UTC, 17:00 UTC, 18:00 UTC, 19:00 UTC, 20:00 UTC, 21:00 UTC, 22:00 UTC
B20: 17 | D20: 17 | E20: 45166 | F20: 0.54166667 | G20: =IFERROR(__xludf.DUMMYFUNCTION("""COMPUTED_VALUE"""),"lowrank is my love") -> lowrank is my love | H20: =IFERROR(__xludf.DUMMYFUNCTION("""COMPUTED_VALUE"""),"PLDT ANO NAAA") -> PLDT ANO NAAA | I20: Azasapag | M20: {=IFERROR(IF(D20="",,{INDIRECT("'"&D20&"'!C3"),INDIRECT("'"&D20&"'!E3"),INDIRECT("'"&D20&"'!I3")}),"")&T(NOW())} -> 1 | N20: 5 | O20: https://osu.ppy.sh/community/matches/110206456 | P20: UTC +3 | Q20: UTC+8 | R20: 15:00 UTC, 16:00 UTC, 17:00 UTC, 18:00 UTC, 19:00 UTC, 20:00 UTC | S20: 1:00 UTC, 2:00 UTC, 3:00 UTC, 4:00 UTC, 5:00 UTC, 6:00 UTC, 7:00 UTC, 8:00 UTC, 9:00 UTC, 10:00 UTC, 11:00 UTC, 12:00 UTC, 13:00 UTC
B21: 18 | D21: 18 | E21: 45164 | F21: 0.75 | G21: =IFERROR(__xludf.DUMMYFUNCTION("""COMPUTED_VALUE"""),"The sleepers") -> The sleepers | H21: =IFERROR(__xludf.DUMMYFUNCTION("""COMPUTED_VALUE"""),"Mewo My Waifu") -> Mewo My Waifu | I21: play hd3 | M21: {=IFERROR(IF(D21="",,{INDIRECT("'"&D21&"'!C3"),INDIRECT("'"&D21&"'!E3"),INDIRECT("'"&D21&"'!I3")}),"")&T(NOW())} -> 5 | N21: 2 | O21: https://osu.ppy.sh/community/matches/110178185 | P21: UTC+2 | Q21: UTC+2 | R21: 0:00 UTC / 24:00 UTC, 15:00 UTC, 16:00 UTC, 17:00 UTC, 18:00 UTC, 19:00 UTC, 20:00 UTC | S21: 12:00 UTC, 13:00 UTC, 14:00 UTC, 15:00 UTC, 18:00 UTC, 19:00 UTC
B22: 19 | D22: 19 | E22: 45165 | F22: 0.54166667 | G22: =IFERROR(__xludf.DUMMYFUNCTION("""COMPUTED_VALUE"""),"Better HD Abusers") -> Better HD Abusers | H22: =IFERROR(__xludf.DUMMYFUNCTION("""COMPUTED_VALUE"""),"equipe câo") -> equipe câo | I22: reforna | M22: {=IFERROR(IF(D22="",,{INDIRECT("'"&D22&"'!C3"),INDIRECT("'"&D22&"'!E3"),INDIRECT("'"&D22&"'!I3")}),"")&T(NOW())} -> 0 | N22: 5 | O22: https://osu.ppy.sh/community/matches/110190490 | P22: UTC-6 | Q22: UTC-3 | R22: 0:00 UTC / 24:00 UTC, 1:00 UTC, 2:00 UTC, 21:00 UTC, 22:00 UTC, 23:00 UTC | S22: 17:00 UTC, 18:00 UTC, 19:00 UTC, 21:00 UTC, 22:00 UTC, 23:00 UTC
B23: 20 | D23: 20 | E23: 45165 | F23: 0.75 | G23: =IFERROR(__xludf.DUMMYFUNCTION("""COMPUTED_VALUE"""),"BOCCHER") -> BOCCHER | H23: =IFERROR(__xludf.DUMMYFUNCTION("""COMPUTED_VALUE"""),"Sightread Buff") -> Sightread Buff | I23: Ninja Mejster | M23: {=IFERROR(IF(D23="",,{INDIRECT("'"&D23&"'!C3"),INDIRECT("'"&D23&"'!E3"),INDIRECT("'"&D23&"'!I3")}),"")&T(NOW())} -> 1 | N23: 5 | O23: https://osu.ppy.sh/community/matches/110194908 | P23: UTC+2 | Q23: UTC +2 | R23: 13:00 UTC, 14:00 UTC, 15:00 UTC, 16:00 UTC, 17:00 UTC, 18:00 UTC, 19:00 UTC | S23: 14:00 UTC, 15:00 UTC, 16:00 UTC, 17:00 UTC, 18:00 UTC, 19:00 UTC, 20:00 UTC
B24: 21 | D24: 21 | E24: 45164 | F24: 0.625 | G24: =IFERROR(__xludf.DUMMYFUNCTION("""COMPUTED_VALUE"""),"Beancurd") -> Beancurd | H24: =IFERROR(__xludf.DUMMYFUNCTION("""COMPUTED_VALUE"""),"Dino Nuggies") -> Dino Nuggies | I24: reforna | M24: {=IFERROR(IF(D24="",,{INDIRECT("'"&D24&"'!C3"),INDIRECT("'"&D24&"'!E3"),INDIRECT("'"&D24&"'!I3")}),"")&T(NOW())} -> 2 | N24: 5 | O24: https://osu.ppy.sh/community/matches/110175433 | P24: UTC+0 | Q24: UTC-4 | R24: 5:00 UTC, 6:00 UTC, 7:00 UTC, 13:00 UTC, 14:00 UTC, 15:00 UTC | S24: 15:00 UTC, 16:00 UTC, 17:00 UTC, 18:00 UTC, 19:00 UTC, 20:00 UTC, 21:00 UTC
B25: 22 | D25: 22 | E25: 45164 | F25: 0.58333333 | G25: =IFERROR(__xludf.DUMMYFUNCTION("""COMPUTED_VALUE"""),"The Mat Munchers") -> The Mat Munchers | H25: =IFERROR(__xludf.DUMMYFUNCTION("""COMPUTED_VALUE"""),"PES E9L9") -> PES E9L9 | I25: reforna | M25: {=IFERROR(IF(D25="",,{INDIRECT("'"&D25&"'!C3"),INDIRECT("'"&D25&"'!E3"),INDIRECT("'"&D25&"'!I3")}),"")&T(NOW())} -> 2 | N25: 5 | O25: https://osu.ppy.sh/community/matches/110174567 | P25: UTC+1 | Q25: UTC+8 | R25: 18:00 UTC, 19:00 UTC, 20:00 UTC, 21:00 UTC, 22:00 UTC, 23:00 UTC | S25: 8:00 UTC, 9:00 UTC, 10:00 UTC, 11:00 UTC, 12:00 UTC, 13:00 UTC, 14:00 UTC, 15:00 UTC, 16:00 UTC
B26: 23 | D26: 23 | E26: 45164 | F26: 0.70833333 | G26: =IFERROR(__xludf.DUMMYFUNCTION("""COMPUTED_VALUE"""),"Here Forever") -> Here Forever | H26: =IFERROR(__xludf.DUMMYFUNCTION("""COMPUTED_VALUE"""),"3000CombinedHours") -> 3000CombinedHours | I26: play hd3 | M26: {=IFERROR(IF(D26="",,{INDIRECT("'"&D26&"'!C3"),INDIRECT("'"&D26&"'!E3"),INDIRECT("'"&D26&"'!I3")}),"")&T(NOW())} -> 5 | N26: 0 | O26: https://osu.ppy.sh/community/matches/110177686 | P26: UTC-5 | Q26: UTC+5 | R26: 0:00 UTC / 24:00 UTC, 1:00 UTC, 2:00 UTC, 3:00 UTC, 4:00 UTC, 5:00 UTC, 15:00 UTC, 16:00 UTC, 23:00 UTC | S26: 6:00 UTC, 7:00 UTC, 8:00 UTC, 12:00 UTC, 13:00 UTC, 14:00 UTC, 15:00 UTC, 16:00 UTC
B27: 24 | D27: 24 | E27: 45165 | F27: 0.16666667 | G27: =IFERROR(__xludf.DUMMYFUNCTION("""COMPUTED_VALUE"""),"Lovers + 3rd wheel") -> Lovers + 3rd wheel | H27: =IFERROR(__xludf.DUMMYFUNCTION("""COMPUTED_VALUE"""),"Faz o L") -> Faz o L | M27: {=IFERROR(IF(D27="",,{INDIRECT("'"&D27&"'!C3"),INDIRECT("'"&D27&"'!E3"),INDIRECT("'"&D27&"'!I3")}),"")&T(NOW())} -> 2 | N27: 5 | O27: https://osu.ppy.sh/community/matches/110185577 | P27: UTC-7 | Q27: UTC -3 | R27: 15:00 UTC, 16:00 UTC, 17:00 UTC, 18:00 UTC, 19:00 UTC, 20:00 UTC, 21:00 UTC | S27: 18:00 UTC, 19:00 UTC, 20:00 UTC, 21:00 UTC, 22:00 UTC, 23:00 UTC
B28: 25 | D28: 25 | E28: 45165 | F28: 0.54166667 | G28: =IFERROR(__xludf.DUMMYFUNCTION("""COMPUTED_VALUE"""),"small wiener club") -> small wiener club | H28: =IFERROR(__xludf.DUMMYFUNCTION("""COMPUTED_VALUE"""),"middle-schooler wife") -> middle-schooler wife | I28: reforna | M28: {=IFERROR(IF(D28="",,{INDIRECT("'"&D28&"'!C3"),INDIRECT("'"&D28&"'!E3"),INDIRECT("'"&D28&"'!I3")}),"")&T(NOW())} -> 5 | N28: 3 | O28: https://osu.ppy.sh/community/matches/110190477 | P28: UTC+2 | Q28: UTC+8 | R28: 12:00 UTC, 13:00 UTC, 14:00 UTC, 15:00 UTC, 16:00 UTC, 17:00 UTC, 18:00 UTC, 19:00 UTC | S28: 1:00 UTC, 2:00 UTC, 3:00 UTC, 4:00 UTC, 5:00 UTC, 6:00 UTC, 7:00 UTC, 8:00 UTC, 9:00 UTC, 10:00 UTC, 13:00 UTC, 14:00 UTC
B29: 26 | D29: 26 | E29: 45164 | F29: 0.66666667 | G29: =IFERROR(__xludf.DUMMYFUNCTION("""COMPUTED_VALUE"""),"The 3-star Threats") -> The 3-star Threats | H29: =IFERROR(__xludf.DUMMYFUNCTION("""COMPUTED_VALUE"""),"placeholder teamname") -> placeholder teamname | I29: reforna | M29: {=IFERROR(IF(D29="",,{INDIRECT("'"&D29&"'!C3"),INDIRECT("'"&D29&"'!E3"),INDIRECT("'"&D29&"'!I3")}),"")&T(NOW())} -> 1 | N29: 5 | O29: https://osu.ppy.sh/community/matches/110176380 | P29: UTC-4 | Q29: UTC+8 | R29: 0:00 UTC / 24:00 UTC, 18:00 UTC, 19:00 UTC, 20:00 UTC, 21:00 UTC, 22:00 UTC, 23:00 UTC | S29: 11:00 UTC, 12:00 UTC, 13:00 UTC, 14:00 UTC, 15:00 UTC, 16:00 UTC
B30: 27 | D30: 27 | E30: 45164 | F30: 0.79166667 | G30: =IFERROR(__xludf.DUMMYFUNCTION("""COMPUTED_VALUE"""),"Homossexual Students") -> Homossexual Students | H30: =IFERROR(__xludf.DUMMYFUNCTION("""COMPUTED_VALUE"""),"cake") -> cake | I30: play hd3 | M30: {=IFERROR(IF(D30="",,{INDIRECT("'"&D30&"'!C3"),INDIRECT("'"&D30&"'!E3"),INDIRECT("'"&D30&"'!I3")}),"")&T(NOW())} -> 5 | N30: 4 | O30: https://osu.ppy.sh/community/matches/110179406 | P30: UTC-3 | Q30: UTC+3 | R30: 0:00 UTC / 24:00 UTC, 1:00 UTC, 11:00 UTC, 12:00 UTC, 13:00 UTC, 14:00 UTC, 15:00 UTC, 16:00 UTC, 17:00 UTC, 18:00 UTC, 19:00 UTC, 20:00 UTC, 21:00 UTC, 22:00 UTC, 23:00 UTC | S30: 3:00 UTC, 4:00 UTC, 13:00 UTC, 15:00 UTC, 16:00 UTC, 20:00 UTC
B31: 28 | D31: 28 | E31: 45165 | F31: 0.58333333 | G31: =IFERROR(__xludf.DUMMYFUNCTION("""COMPUTED_VALUE"""),"female ass wrestling") -> female ass wrestling | H31: =IFERROR(__xludf.DUMMYFUNCTION("""COMPUTED_VALUE"""),"VN+1") -> VN+1 | I31: RudderFish07 | M31: {=IFERROR(IF(D31="",,{INDIRECT("'"&D31&"'!C3"),INDIRECT("'"&D31&"'!E3"),INDIRECT("'"&D31&"'!I3")}),"")&T(NOW())} -> 5 | N31: 1 | O31: https://osu.ppy.sh/community/matches/110191205 | P31: UTC+2 | Q31: UTC+7 | R31: 17:00 UTC, 18:00 UTC, 19:00 UTC, 20:00 UTC, 21:00 UTC, 22:00 UTC | S31: 11:00 UTC, 12:00 UTC, 13:00 UTC, 14:00 UTC, 15:00 UTC, 16:00 UTC, 17:00 UTC
B32: 29 | D32: 29 | E32: 45165 | F32: 0.10416667 | G32: =IFERROR(__xludf.DUMMYFUNCTION("""COMPUTED_VALUE"""),":MIPINGA:") -> :MIPINGA: | H32: =IFERROR(__xludf.DUMMYFUNCTION("""COMPUTED_VALUE"""),"Chocomaid") -> Chocomaid | I32: play hd3 | M32: {=IFERROR(IF(D32="",,{INDIRECT("'"&D32&"'!C3"),INDIRECT("'"&D32&"'!E3"),INDIRECT("'"&D32&"'!I3")}),"")&T(NOW())} -> 5 | N32: 1 | O32: https://osu.ppy.sh/community/matches/110184531 | P32: UTC -5 | Q32: UTC+8 | R32: 0:00 UTC / 24:00 UTC, 1:00 UTC, 2:00 UTC, 19:00 UTC, 20:00 UTC, 21:00 UTC, 22:00 UTC, 23:00 UTC | S32: 12:00 UTC, 13:00 UTC, 14:00 UTC, 15:00 UTC, 16:00 UTC, 17:00 UTC
B33: 30 | D33: 30 | E33: 45163 | F33: 0.54166667 | G33: =IFERROR(__xludf.DUMMYFUNCTION("""COMPUTED_VALUE"""),"Team name pending xd") -> Team name pending xd | H33: =IFERROR(__xludf.DUMMYFUNCTION("""COMPUTED_VALUE"""),"Ghost the Angel") -> Ghost the Angel | I33: Lunexia | M33: {=IFERROR(IF(D33="",,{INDIRECT("'"&D33&"'!C3"),INDIRECT("'"&D33&"'!E3"),INDIRECT("'"&D33&"'!I3")}),"")&T(NOW())} -> 2 | N33: 5 | O33: https://osu.ppy.sh/community/matches/110157424 | P33: UTC+8 | Q33: UTC+7 | R33: 6:00 UTC, 7:00 UTC, 8:00 UTC, 13:00 UTC, 14:00 UTC, 15:00 UTC | S33: 7:00 UTC, 8:00 UTC, 9:00 UTC, 13:00 UTC, 14:00 UTC, 15:00 UTC, 16:00 UTC
B34: 31 | D34: 31 | E34: 45163 | F34: 0.45833333 | G34: =IFERROR(__xludf.DUMMYFUNCTION("""COMPUTED_VALUE"""),"foxy1919191919's basement") -> foxy1919191919's basement | H34: =IFERROR(__xludf.DUMMYFUNCTION("""COMPUTED_VALUE"""),"match in 15") -> match in 15 | I34: Azasapag | M34: {=IFERROR(IF(D34="",,{INDIRECT("'"&D34&"'!C3"),INDIRECT("'"&D34&"'!E3"),INDIRECT("'"&D34&"'!I3")}),"")&T(NOW())} -> 2 | N34: 5 | O34: https://osu.ppy.sh/community/matches/110156344 | P34: UTC+9 | Q34: UTC+8 | R34: 6:00 UTC, 7:00 UTC, 8:00 UTC, 9:00 UTC, 10:00 UTC, 11:00 UTC, 12:00 UTC, 13:00 UTC, 14:00 UTC | S34: 13:00 UTC, 14:00 UTC, 15:00 UTC, 16:00 UTC, 17:00 UTC, 18:00 UTC, 19:00 UTC, 20:00 UTC, 21:00 UTC, 22:00 UTC
B35: 32 | D35: 32 | E35: 45164 | F35: 0.58333333 | G35: =IFERROR(__xludf.DUMMYFUNCTION("""COMPUTED_VALUE"""),"Tom and Jerry") -> Tom and Jerry | H35: =IFERROR(__xludf.DUMMYFUNCTION("""COMPUTED_VALUE"""),"Kittens") -> Kittens | I35: reforna | M35: {=IFERROR(IF(D35="",,{INDIRECT("'"&D35&"'!C3"),INDIRECT("'"&D35&"'!E3"),INDIRECT("'"&D35&"'!I3")}),"")&T(NOW())} -> 5 | N35: 3 | O35: https://osu.ppy.sh/community/matches/110174570 | P35: UTC+7 | Q35: UTC+2 | R35: 8:00 UTC, 9:00 UTC, 10:00 UTC, 11:00 UTC, 12:00 UTC, 13:00 UTC, 14:00 UTC | S35: 14:00 UTC, 15:00 UTC, 16:00 UTC, 17:00 UTC, 18:00 UTC, 19:00 UTC, 20:00 UTC, 21:00 UTC, 22:00 UTC
B36: 33 | D36: 33 | E36: 45172 | F36: 0.58333333 | G36: =IFERROR(__xludf.DUMMYFUNCTION("""COMPUTED_VALUE"""),"middle-schooler wife") -> middle-schooler wife | H36: =IFERROR(__xludf.DUMMYFUNCTION("""COMPUTED_VALUE"""),"Faz o L") -> Faz o L | M36: {=IFERROR(IF(D36="",,{INDIRECT("'"&D36&"'!C3"),INDIRECT("'"&D36&"'!E3"),INDIRECT("'"&D36&"'!I3")}),"")&T(NOW())} -> 6 | N36: 2 | O36: https://osu.ppy.sh/community/matches/110301082 | P36: UTC+8 | Q36: UTC -3 | R36: 1:00 UTC, 2:00 UTC, 3:00 UTC, 4:00 UTC, 5:00 UTC, 6:00 UTC, 7:00 UTC, 8:00 UTC, 9:00 UTC, 10:00 UTC, 13:00 UTC, 14:00 UTC | S36: 18:00 UTC, 19:00 UTC, 20:00 UTC, 21:00 UTC, 22:00 UTC, 23:00 UTC
B37: 34 | D37: 34 | E37: 45171 | F37: 0.95833333 | G37: =IFERROR(__xludf.DUMMYFUNCTION("""COMPUTED_VALUE"""),"The 3-star Threats") -> The 3-star Threats | H37: =IFERROR(__xludf.DUMMYFUNCTION("""COMPUTED_VALUE"""),"Here Forever") -> Here Forever | I37: play hd3 | M37: {=IFERROR(IF(D37="",,{INDIRECT("'"&D37&"'!C3"),INDIRECT("'"&D37&"'!E3"),INDIRECT("'"&D37&"'!I3")}),"")&T(NOW())} -> 6 | N37: 3 | O37: https://osu.ppy.sh/community/matches/110291479 | P37: UTC-4 | Q37: UTC-5 | R37: 0:00 UTC / 24:00 UTC, 18:00 UTC, 19:00 UTC, 20:00 UTC, 21:00 UTC, 22:00 UTC, 23:00 UTC | S37: 0:00 UTC / 24:00 UTC, 1:00 UTC, 2:00 UTC, 3:00 UTC, 4:00 UTC, 5:00 UTC, 15:00 UTC, 16:00 UTC, 23:00 UTC
B38: 35 | D38: 35 | E38: 45172 | F38: 0.60416667 | G38: =IFERROR(__xludf.DUMMYFUNCTION("""COMPUTED_VALUE"""),"cake") -> cake | H38: =IFERROR(__xludf.DUMMYFUNCTION("""COMPUTED_VALUE"""),"PES E9L9") -> PES E9L9 | I38: Pischok | M38: {=IFERROR(IF(D38="",,{INDIRECT("'"&D38&"'!C3"),INDIRECT("'"&D38&"'!E3"),INDIRECT("'"&D38&"'!I3")}),"")&T(NOW())} -> 4 | N38: 6 | O38: https://osu.ppy.sh/community/matches/110301327 | P38: UTC+3 | Q38: UTC+8 | R38: 3:00 UTC, 4:00 UTC, 13:00 UTC, 15:00 UTC, 16:00 UTC, 20:00 UTC | S38: 8:00 UTC, 9:00 UTC, 10:00 UTC, 11:00 UTC, 12:00 UTC, 13:00 UTC, 14:00 UTC, 15:00 UTC, 16:00 UTC
B39: 36 | D39: 36 | E39: 45171 | F39: 0.0625 | G39: =IFERROR(__xludf.DUMMYFUNCTION("""COMPUTED_VALUE"""),"VN+1") -> VN+1 | H39: =IFERROR(__xludf.DUMMYFUNCTION("""COMPUTED_VALUE"""),"Dino Nuggies") -> Dino Nuggies | I39: play hd3 | M39: {=IFERROR(IF(D39="",,{INDIRECT("'"&D39&"'!C3"),INDIRECT("'"&D39&"'!E3"),INDIRECT("'"&D39&"'!I3")}),"")&T(NOW())} -> 6 | N39: 0 | O39: https://osu.ppy.sh/community/matches/110275875 | P39: UTC+7 | Q39: UTC-4 | R39: 11:00 UTC, 12:00 UTC, 13:00 UTC, 14:00 UTC, 15:00 UTC, 16:00 UTC, 17:00 UTC | S39: 15:00 UTC, 16:00 UTC, 17:00 UTC, 18:00 UTC, 19:00 UTC, 20:00 UTC, 21:00 UTC
B40: 37 | D40: 37 | E40: 45171 | F40: 0.58333333 | G40: =IFERROR(__xludf.DUMMYFUNCTION("""COMPUTED_VALUE"""),"Chocomaid") -> Chocomaid | H40: =IFERROR(__xludf.DUMMYFUNCTION("""COMPUTED_VALUE"""),"Sightread Buff") -> Sightread Buff | I40: Emerald Ages | M40: {=IFERROR(IF(D40="",,{INDIRECT("'"&D40&"'!C3"),INDIRECT("'"&D40&"'!E3"),INDIRECT("'"&D40&"'!I3")}),"")&T(NOW())} -> 6 | N40: 1 | O40: https://osu.ppy.sh/community/matches/110283000 | P40: UTC+8 | Q40: UTC +2 | R40: 12:00 UTC, 13:00 UTC, 14:00 UTC, 15:00 UTC, 16:00 UTC, 17:00 UTC | S40: 14:00 UTC, 15:00 UTC, 16:00 UTC, 17:00 UTC, 18:00 UTC, 19:00 UTC, 20:00 UTC
B41: 38 | D41: 38 | E41: 45171 | F41: 0.625 | G41: =IFERROR(__xludf.DUMMYFUNCTION("""COMPUTED_VALUE"""),"Team name pending xd") -> Team name pending xd | H41: =IFERROR(__xludf.DUMMYFUNCTION("""COMPUTED_VALUE"""),"equipe câo") -> equipe câo | I41: Emerald Ages | M41: {=IFERROR(IF(D41="",,{INDIRECT("'"&D41&"'!C3"),INDIRECT("'"&D41&"'!E3"),INDIRECT("'"&D41&"'!I3")}),"")&T(NOW())} -> 6 | N41: 4 | O41: https://osu.ppy.sh/community/matches/110283874 | P41: UTC+8 | Q41: UTC-3 | R41: 6:00 UTC, 7:00 UTC, 8:00 UTC, 13:00 UTC, 14:00 UTC, 15:00 UTC | S41: 17:00 UTC, 18:00 UTC, 19:00 UTC, 21:00 UTC, 22:00 UTC, 23:00 UTC
...

Sheet Team List
C1: Captain
B2: Team Name | C2: {="Player "&SEQUENCE(1,3)} -> Player 1 | D2: Player 2 | E2: Player 3
B3: PoorQuaIityMeatpilow | C3: PoorQuaIityMeat | D3: Pilllow
B4: Sightread Buff | C4: O_re_O | D4: depict1 | E4: NemiTrailRider
B5: Ghost the Angel | C5: BCraftMG | D5: Lugost Angel | E5: quay4
B6: foxy1919191919's basement | C6: Faceie | D6: Flare_Drake | E6: vortexta
B7: Lovers + 3rd wheel | C7: TeddyFine | D7: Entro | E7: BubblyQT
B8: copium abusers | C8: PapaAinsley | D8: Josiper
B9: The One 100s | C9: Ugetora | D9: Zeon_beyond | E9: bunnytoro
B10: Nameless Waifulovers | C10: Feroshi | D10: Scaly007 | E10: yunasky
B11: noodle team | C11: Lowuki | D11: Kuw
B12: Ahjin | C12: TzJake | D12: rafaeldel7 | E12: -Darklune-
B13: PES E9L9 | C13: Kochindera | D13: Hoshifurii | E13: Gamillie
B14: phony :) | C14: AZKi | D14: SomeLongName
B15: BOCCHER | C15: SkyprimeLp | D15: Knax | E15: uhzyk
B16: Mewo My Waifu | C16: Mewo_ | D16: Zertoaster | E16: Lol3270
B17: Beancurd | C17: Tsekyro | D17: GeneralMayo | E17: Carsoon
B18: Koteykaaa team | C18: Aria Holmes | D18: Regihorn | E18: FurryWolf_RU
B19: Retired Aces | C19: Todi37 | D19: Flaming_Galaxy | E19: MomoNagi
B20: 3000CombinedHours | C20: RakiMiku | D20: WorstGamer | E20: C L O N E
B21: Team name pending xd | C21: BlooMertz | D21: cxyren | E21: Dragonslash354
B22: middle-schooler wife | C22: euouae_ | D22: HecaRegina | E22: Onii karma
B23: Better HD Abusers | C23: HD Abuser | D23: Ultima_ | E23: Kaeldori
B24: DSE victims | C24: Himman | D24: C00KI3C00KIY | E24: Cola1228
B25: Flexgang | C25: lipefree | D25: Darvgaea
B26: blpka | C26: - Enkidu - | D26: dffTu
B27: Side Characters | C27: Heaki | D27: miimo__miimo | E27: karimovic
B28: Homossexual Students | C28: DUM4L77 | D28: Simabuco | E28: Loopyng
B29: Chocomaid | C29: Frui Ludo | D29: Chokecomint | E29: Azcazay
B30: Kittens | C30: Rurup | D30: Shaddie_ | E30: DzikaSwinia
B31: PLDT ANO NAAA | C31: Shion Yorigami | D31: iSimp22 | E31: BluNuggets
B32: lowrank is my love | C32: Rev1vall | D32: Sosedov
B33: китирики | C33: Kl4dys | D33: KWIzYiii | E33: Petrovkosta
B34: VN+1 | C34: fnugus | D34: RaiRei | E34: Elfie125
B35: hmmmm | C35: VMPR13 | D35: u-litay
B36: match in 15 | C36: X-ill | D36: marshysxn | E36: felixgg
B37: animefoot69 | C37: cyclone290 | D37: Aever
B38: CocoaGoats | C38: Tohkura | D38: pika_Zero | E38: Glaucia
B39: female ass wrestling | C39: aespect | D39: qiyo | E39: not_peder
B40: The Mat Munchers | C40: foxy1919191919 | D40: SneakyDingus | E40: Gwnet
...

Sheet TeamTimes
C1: Captain
B2: Team Name | C2: Timezone | D2: Availability
B3: PoorQuaIityMeatpilow | C3: UTC+2 | D3: 0:00 UTC / 24:00 UTC, 6:00 UTC, 11:00 UTC, 15:00 UTC, 19:00 UTC, 23:00 UTC
B4: Sightread Buff | C4: UTC +2 | D4: 14:00 UTC, 15:00 UTC, 16:00 UTC, 17:00 UTC, 18:00 UTC, 19:00 UTC, 20:00 UTC
B5: Ghost the Angel | C5: UTC+7 | D5: 7:00 UTC, 8:00 UTC, 9:00 UTC, 13:00 UTC, 14:00 UTC, 15:00 UTC, 16:00 UTC
B6: foxy1919191919's basement | C6: UTC+9 | D6: 6:00 UTC, 7:00 UTC, 8:00 UTC, 9:00 UTC, 10:00 UTC, 11:00 UTC, 12:00 UTC, 13:00 UTC, 14:00 UTC
B7: Lovers + 3rd wheel | C7: UTC-7 | D7: 15:00 UTC, 16:00 UTC, 17:00 UTC, 18:00 UTC, 19:00 UTC, 20:00 UTC, 21:00 UTC
B8: copium abusers | C8: UTC+1 | D8: 12:00 UTC, 13:00 UTC, 14:00 UTC, 15:00 UTC, 16:00 UTC, 17:00 UTC, 18:00 UTC, 19:00 UTC, 20:00 UTC
B9: The One 100s | C9: UTC-7 | D9: 15:00 UTC, 16:00 UTC, 17:00 UTC, 18:00 UTC, 19:00 UTC, 20:00 UTC
B10: Nameless Waifulovers | C10: UTC+2 | D10: 14:00 UTC, 15:00 UTC, 16:00 UTC, 17:00 UTC, 18:00 UTC, 19:00 UTC, 20:00 UTC
B11: noodle team | C11: UTC+3 | D11: 14:00 UTC, 15:00 UTC, 16:00 UTC, 17:00 UTC, 18:00 UTC, 19:00 UTC
B12: Ahjin | C12: UTC-5 | D12: 0:00 UTC / 24:00 UTC, 1:00 UTC, 2:00 UTC, 21:00 UTC, 22:00 UTC, 23:00 UTC
B13: PES E9L9 | C13: UTC+8 | D13: 8:00 UTC, 9:00 UTC, 10:00 UTC, 11:00 UTC, 12:00 UTC, 13:00 UTC, 14:00 UTC, 15:00 UTC, 16:00 UTC
... B64: Minor assault squad | C64: UTC+2 | D64: 15:00 UTC, 16:00 UTC, 17:00 UTC, 18:00 UTC, 19:00 UTC, 20:00 UTC

Sheet Template
B2: Status | C2: =IFNA(VLOOKUP(I2,Schedules,4,0),"") | D2: vs | E2: =IFNA(VLOOKUP(I2,Schedules,5,0),"") | G2: Information | H2: Match | M2: Mappool | N2: Stage | O2: Round of 16
C3: =IF(D6="Blue",-1,COUNTIF(E14:E26,"Red")) -> 0 | D3: =VLOOKUP(O2,MappoolSettings,2,0) -> 9 | E3: =IF(D6="Red",-1,COUNTIF(E14:E26,"Blue")) -> 0 | H3: MP-Link | N3: Map | O3: Map Command | P3: Mod Command
C4: Status | D4: =IFERROR(__xludf.DUMMYFUNCTION("IFS( I2="""",""ERROR: Match ID missing"", O2="""",""ERROR: Stage missing"", D6<>"""",TRIM(JOIN(CHAR(13),""**""&O2&"": Match ""&I2&""**"","""",""Win by default for ""&SWITCH(D6,""Red"",C2,""Blue"",E2,""Tiebreaker""))), I3="""",""Step: Setup a room and ente"&"r the MP-link"", OR(COUNTA(D9:E9)>I16,COUNTA(D10:E10)>I16),""ERROR: Too many bans"", MAX(ARRAYFORMULA(IF(D9:E10="""",0,COUNTIF(D9:E10,D9:E10))))>1,""ERROR: Duplicate bans"", OR(AND(NOT(DoubleBan),D9<>"""",LEFT(D9,2)=LEFT(E9,2),NOT(AND(ExclNMDouble,LEFT(D9"&",2)=""NM""))),AND(NOT(DoubleBan),D10<>"""",LEFT(D10,2)=LEFT(E10,2),NOT(AND(ExclNMDouble,LEFT(D10,2)=""NM"")))),""ERROR: Double ban not allowed"", COUNTIF(ARRAYFORMULA(LEFT(D9:E10,2)),""TB"")>0,""ERROR: Banned tiebreaker"", OR(COUNTA(D9:E9)<I16,COUNTA(D10:"&"E10)<I16),""Step: Enter bans"", D11="""",""Step: Enter first pick"", COUNTA(E14:E26)>COUNTA(D14:D26),""ERROR: More points than maps picked"", COUNTA(E14:E26)>D3,""ERROR: Too many maps picked"", COUNTA(D14:D26)>COUNTA(E14:E26)+1,""ERROR: No winner entered"&""", COUNTIF(ARRAYFORMULA(LEFT(D14:D26,2)),""TB"")>2,""ERROR: Too many tiebreakers"", AND(C3+E3<D3-1,COUNTIF(ARRAYFORMULA(LEFT(D14:D26,2)),""TB"")>0),""ERROR: Tiebreaker picked early"", MAX(ARRAYFORMULA(IF(D9:E10="""",0,COUNTIF(D14:D26,D9:E10))))>0,""ERROR"&": Picked banned map"", MAX(ARRAYFORMULA(COUNTIF(D14:D26,D14:D26)))>1,""ERROR: Duplicate pick"", OR(INDEX(IFNA(NOT(DoublePick)*((LEFT(QUERY(D14:D26,""select * where D is not null skipping 2""),2)={LEFT(QUERY(D14:D26,""select * where D is not null skipping "&"2 offset 1""),2);""""}))*((NOT(ExclNMDouble)+(LEFT(QUERY(D14:D26,""select * where D is not null skipping 2""),2)<>""NM""))>0)>0,FALSE)),INDEX(IFNA(NOT(DoublePick)*((LEFT(QUERY(D15:D26,""select * where D is not null skipping 2""),2)={LEFT(QUERY(D15:D26,""s"&"elect * where D is not null skipping 2 offset 1""),2);""""}))*((NOT(ExclNMDouble)+(LEFT(QUERY(D15:D26,""select * where D is not null skipping 2""),2)<>""NM""))>0)>0,FALSE))),""ERROR: Double pick not allowed"",,""ERROR: Double pick not allowed"", COUNTA(D1"&"4:D26)=COUNTA(E14:E26)+1,""Match ongoing"", MAX(C3,E3)<D3/2,IF(LEFT(C2)=""!"",""'"","""")&C2&"" | ""&C3&"" : ""&E3&"" | ""&E2&"" // Next to pick: ""&SWITCH(INDEX(C14:C26,C3+E3+1,1),""Red"",C2,""Blue"",E2,""Tiebreaker""), TRUE,TRIM(JOIN(CHAR(13), ""**""&O2"&"&"": Match ""&I2&""**"", ""<""&I3&"">"", """", "":red_square: ""&IF(REGEXMATCH(C2,""^:[\w\d]+:$""),""\"","""")&C2&"" | ""&C3&"" : ""&E3&"" | ""&E2&"" :blue_square:"", """", C2&"" ban""&IF(I16=1,"""",""s"")&"" | ""&TRIM(JOIN("" "",INDEX(IFNA(REGEXEXTRACT(D"&"9:E9,""(.*): ""))))), E2&"" ban""&IF(I16=1,"""",""s"")&"" | ""&TRIM(JOIN("" "",INDEX(IFNA(REGEXEXTRACT(D10:E10,""(.*): ""))))), """", ""First pick | ""&SWITCH(C14,""Red"",C2,""Blue"",E2,""Tiebreaker""), """", INDEX(IF(E14:E26="""",,"":""&LOWER(E14:E26)&"""&"_square: | ""&D14:D26)) )) )"),"ERROR: Match ID missing") -> ERROR: Match ID missing | H4: Referee | I4: =IFNA(VLOOKUP(I2,Schedules,6,0),"") | N4: =IFERROR(__xludf.DUMMYFUNCTION("IF(O2="""",,ARRAY_CONSTRAIN(FILTER(Maps,Mappools!B4:B27=O2),25,3))"),"NM1: Yorushika - Thoughtcrime [Akitoshi's Insane]") -> NM1: Yorushika - Thoughtcrime [Akitoshi's Insane] | O4: =IFERROR(__xludf.DUMMYFUNCTION("""COMPUTED_VALUE"""),"!mp map 2827293 0") -> !mp map 2827293 0 | P4: =IFERROR(__xludf.DUMMYFUNCTION("""COMPUTED_VALUE"""),"!mp mods NF") -> !mp mods NF
C5: Current Map | D5: {=IFERROR(VLOOKUP(INDEX($D$14:$D$26,COUNTA($D$14:$D$26)),$N$4:$P$26,{2,3},0),"")} | H5: Date/Time | I5: {=IFNA(SUM(VLOOKUP(I2,Schedules,{2,3},0)),"")} | N5: =IFERROR(__xludf.DUMMYFUNCTION("""COMPUTED_VALUE"""),"NM2: Fractal Dreamers - Gardens Under A Spring Sky [Hyper]") -> NM2: Fractal Dreamers - Gardens Under A Spring Sky [Hyper] | O5: =IFERROR(__xludf.DUMMYFUNCTION("""COMPUTED_VALUE"""),"!mp map 2004679 0") -> !mp map 2004679 0 | P5: =IFERROR(__xludf.DUMMYFUNCTION("""COMPUTED_VALUE"""),"!mp mods NF") -> !mp mods NF
C6: Win by Default | N6: =IFERROR(__xludf.DUMMYFUNCTION("""COMPUTED_VALUE"""),"NM3: Tsukuyomi - Dareka no Shinzou ni Nareta nara [too's Insane]") -> NM3: Tsukuyomi - Dareka no Shinzou ni Nareta nara [too's Insane] | O6: =IFERROR(__xludf.DUMMYFUNCTION("""COMPUTED_VALUE"""),"!mp map 3239199 0") -> !mp map 3239199 0 | P6: =IFERROR(__xludf.DUMMYFUNCTION("""COMPUTED_VALUE"""),"!mp mods NF") -> !mp mods NF
G7: Commands | H7: Room Command | I7: ="!mp make "&TournamentAbbr&": ("&C2&") vs ("&E2&")" -> !mp make PTE: () vs () | N7: =IFERROR(__xludf.DUMMYFUNCTION("""COMPUTED_VALUE"""),"NM4: sakuraburst - Glacierfall (Park Remix) [haruto x ancel's ins*ne]") -> NM4: sakuraburst - Glacierfall (Park Remix) [haruto x ancel's ins*ne] | O7: =IFERROR(__xludf.DUMMYFUNCTION("""COMPUTED_VALUE"""),"!mp map 2794904 0") -> !mp map 2794904 0 | P7: =IFERROR(__xludf.DUMMYFUNCTION("""COMPUTED_VALUE"""),"!mp mods NF") -> !mp mods NF
B8: Picks/Bans | C8: =IF(Format="Solo","Player","Team") -> Team | D8: Ban 1 | E8: Ban 2 | H8: Room Settings | I8: =IFERROR(__xludf.DUMMYFUNCTION("IF(I2="""",,JOIN("" "",""!mp"",""set"",TeamMode,ScoreMode,TeamSize*2+IF(Format=""Solo"",1,3)))"),"") | N8: =IFERROR(__xludf.DUMMYFUNCTION("""COMPUTED_VALUE"""),"NM5: sekai - Zange Mairi [Voice's Insane]") -> NM5: sekai - Zange Mairi [Voice's Insane] | O8: =IFERROR(__xludf.DUMMYFUNCTION("""COMPUTED_VALUE"""),"!mp map 2853477 0") -> !mp map 2853477 0 | P8: =IFERROR(__xludf.DUMMYFUNCTION("""COMPUTED_VALUE"""),"!mp mods NF") -> !mp mods NF
C9: =C2 | H9: Settings | I9: !mp settings | N9: =IFERROR(__xludf.DUMMYFUNCTION("""COMPUTED_VALUE"""),"HD1: Police Piccadilly feat. Hatsune Miku - Kire Carry On [negusver's Insane]") -> HD1: Police Piccadilly feat. Hatsune Miku - Kire Carry On [negusver's Insane] | O9: =IFERROR(__xludf.DUMMYFUNCTION("""COMPUTED_VALUE"""),"!mp map 1733441 0") -> !mp map 1733441 0 | P9: =IFERROR(__xludf.DUMMYFUNCTION("""COMPUTED_VALUE"""),"!mp mods HD NF") -> !mp mods HD NF
