Workbook
Name ApiHeader: '_api'!$B$2:$BR$2
Name ApiRange: '_api'!$AT$3:$BR$1007
Name SPACER: LAMBDA(range, n, TRANSPOSE(SPLIT(JOIN(REPT(",",n+1),range),",",,0)))
Name FILTER_EMPTY: LAMBDA(range, FILTER(range,INDEX(range,1)<>""))
Name MAPDATA: LAMBDA(id, attr, ARRAYFORMULA(IFNA(VLOOKUP(id,'_api'!$B$3:$BW,MATCH(attr,'_api'!$B$2:$BW$2,0),0)) ))
Name MAPDATA_MODDED: LAMBDA(id, attr, mod, ARRAYFORMULA(IFNA(VLOOKUP(id,'_api'!$B$3:$BX,IFNA(MATCH(attr&"_"&LEFT(mod,2),'_api'!$B$2:$2,0),MATCH(attr,'_api'!$B$2:$2,0)),0)) ))

Sheet Settings
S1: c
B2: List of Poolers | D2: Use | E2: Mappool | F2: Abbreviation | G2: Best of | H2: Bans | I2: NM | J2: HD | K2: HR | L2: DT | M2: FM | N2: EZ | O2: HT | P2: TB | Q2: Sum | R2: Tentative SR
B3: play hd3 | D3: TRUE | E3: Qualifiers | F3: Quals | I3: 4 | J3: 2 | K3: 2 | L3: 2 | Q3: =SUM(I3:P3) -> 10 | R3: 5
B4: purl | D4: FALSE
B5: levica | D5: FALSE
B6: Aizenh | D6: FALSE
B7: shironai14 | D7: TRUE | E7: Round of 32 | F7: RO32 | G7: 9 | H7: 1 | I7: 5 | J7: 2 | K7: 2 | L7: 3 | M7: 2 | P7: 1 | Q7: =SUM(I7:P7) -> 15 | R7: 4.7
B8: sedi__ | D8: TRUE | E8: Round of 16 | F8: RO16 | G8: 9 | H8: 1 | I8: 5 | J8: 2 | K8: 2 | L8: 3 | M8: 2 | P8: 1 | Q8: =SUM(I8:P8) -> 15 | R8: 4.9
B9: matalisfangirl | D9: TRUE | E9: Quarterfinals | F9: QF | G9: 11 | H9: 2 | I9: 6 | J9: 3 | K9: 3 | L9: 3 | M9: 2 | P9: 1 | Q9: =SUM(I9:P9) -> 18 | R9: 5.1
B10: therealdeathmatch | D10: TRUE | E10: Semifinals | F10: SF | G10: 11 | H10: 2 | I10: 6 | J10: 3 | K10: 3 | L10: 3 | M10: 2 | P10: 1 | Q10: =SUM(I10:P10) -> 18 | R10: 5.3
B11: yillow | D11: TRUE | E11: Finals | F11: F | G11: 13 | H11: 2 | I11: 6 | J11: 3 | K11: 3 | L11: 4 | M11: 3 | P11: 1 | Q11: =SUM(I11:P11) -> 20 | R11: 5.5
B12: lunexia | D12: TRUE | E12: Grand Finals | F12: GF | G12: 13 | H12: 2 | I12: 6 | J12: 3 | K12: 3 | L12: 4 | M12: 3 | P12: 1 | Q12: =SUM(I12:P12) -> 20 | R12: 5.7
B13: Fuwub
B14: aoi hinami

Sheet Template
B2: Group Stage | C2: Best of | D2: =IFERROR(VLOOKUP(B2,Settings!E3:H12,3,0),"") | E2: Bans | F2: =IFERROR(VLOOKUP(B2,Settings!E3:H12,4,0),"")
B3: Suggestions | J3: Pool Assembly
B4: Map Link | C4: ID | D4: Mod | E4: Suggestor | F4: Map | H4: Notes | J4: Note | K4: ID | L4: Mod | M4: Map | O4: SR | P4: BPM | Q4: Length | R4: CS | S4: AR | T4: OD | U4: HP | V4: Mapper | W4: ID
F5: {=MAP(C5:C104,LAMBDA(id,IFNA(IMAGE(MAPDATA(id,"cover_url")),"")))} | G5: {=IFNA(HYPERLINK(VLOOKUP(C5:C104,'_api'!B3:BC104,MATCH("url",'_api'!B2:X2,0),0),VLOOKUP(C5:C104,'_api'!B3:BC104,MATCH("string",'_api'!B2:X2,0),0)),"")} | L5: =IFERROR(__xludf.DUMMYFUNCTION("TRANSPOSE(SPLIT(JOIN("","",MAP(TRANSPOSE(Settings!I2:P2),TRANSPOSE(INDEX(Settings!I3:P12,MATCH(B2,Settings!E3:E12,0))),LAMBDA(mod,n,JOIN("","",ARRAYFORMULA(IF(n=0,"""",mod&SEQUENCE(n))))))),"",""))"),"#VALUE!") -> #VALUE! | M5: {=MAP(K5:K104,LAMBDA(id,IFNA(IMAGE(MAPDATA(id,"cover_url")),"")))} | N5: =IFNA(MAPDATA(K5:K104,"string_url"),"") | O5: {=IFNA(MAPDATA_MODDED(K5:K104,{"difficultyrating","bpm","hit_length"},L5:L104),"")} -> #VALUE! | P5: #VALUE! | Q5: #VALUE! | R5: {=IFNA(MAPDATA_MODDED(K5:K104,"diff_"&{"size","approach","overall","drain"},L5:L104),"")} -> #VALUE! | S5: #VALUE! | T5: #VALUE! | U5: #VALUE! | V5: {=IFNA(MAPDATA(K5:K104,{"creator","beatmap_id"}),"")}

Sheet Quals
B2: Qualifiers | C2: Best of | D2: =IFERROR(VLOOKUP(B2,Settings!E3:H12,3,0),"") | E2: Bans | F2: =IFERROR(VLOOKUP(B2,Settings!E3:H12,4,0),"")
B3: Suggestions | J3: Pool Assembly
B4: Map Link | C4: ID | D4: Mod | E4: Suggestor | F4: Map | H4: Notes | J4: Note | K4: ID | L4: Mod | M4: Map | O4: SR | P4: BPM | Q4: Length | R4: CS | S4: AR | T4: OD | U4: Mapper | V4: ID
B5: https://osu.ppy.sh/beatmapsets/1658910#osu/3924030 | C5: =IFERROR(__xludf.DUMMYFUNCTION("ArrayFormula(IFERROR(VALUE(REGEXEXTRACT(B5:B104&"""",""\d+$""))))"),3924030.0) -> 3924030 | D5: NM | E5: shironai14 | F5: {=MAP(C5:C104,LAMBDA(id,IFNA(IMAGE(MAPDATA(id,"cover_url")),"")))} | G5: {=IFNA(HYPERLINK(VLOOKUP(C5:C298,'_api'!B3:BC104,MATCH("url",'_api'!B2:W2,0),0),VLOOKUP(C5:C298,'_api'!B3:BC104,MATCH("string",'_api'!B2:W2,0),0)),"")} -> nonoc - Relive [Insane] | K5: 3924030 | L5: =IFERROR(__xludf.DUMMYFUNCTION("TRANSPOSE(SPLIT(JOIN("","",MAP(TRANSPOSE(Settings!I2:P2),TRANSPOSE(INDEX(Settings!I3:P12,MATCH(B2,Settings!E3:E12,0))),LAMBDA(mod,n,JOIN("","",ARRAYFORMULA(IF(n=0,"""",mod&SEQUENCE(n))))))),"",""))"),"NM1") -> NM1 | M5: {=MAP(K5:K104,LAMBDA(id,IFNA(IMAGE(MAPDATA(id,"cover_url")),"")))} | N5: =IFNA(MAPDATA(K5:K104,"string_url"),"") -> nonoc - Relive [Insane] | O5: {=IFNA(MAPDATA_MODDED(K5:K104,{"difficultyrating","bpm","hit_length"},L5:L104),"")} -> 5.04539 | P5: 196 | Q5: 0.0025347222 | R5: {=IFNA(MAPDATA_MODDED(K5:K104,"diff_"&{"size","approach","overall"},L5:L104),"")} -> 3.5 | S5: 9 | T5: 8 | U5: {=IFNA(MAPDATA(K5:K104,{"creator","beatmap_id"}),"")} -> SkyFlame | V5: 3924030
B6: https://osu.ppy.sh/beatmapsets/1570531#osu/3207049 | C6: =IFERROR(__xludf.DUMMYFUNCTION("""COMPUTED_VALUE"""),3207049.0) -> 3207049 | D6: NM | E6: shironai14 | G6: Trerey-U - ::vexations [::insane] | I6: c | K6: 908887 | L6: =IFERROR(__xludf.DUMMYFUNCTION("""COMPUTED_VALUE"""),"NM2") -> NM2 | N6: void - Crisscrosser [Insane] | O6: 5.06513 | P6: 170 | Q6: 0.0013194444 | R6: 4 | S6: 9 | T6: 8 | U6: ouranhshc | V6: 908887
B7: https://osu.ppy.sh/beatmapsets/1975119#osu/4113699 | C7: =IFERROR(__xludf.DUMMYFUNCTION("""COMPUTED_VALUE"""),4113699.0) -> 4113699 | D7: NM | E7: shironai14 | G7: ATARASHII GAKKO! - OTONABLUE [-ktrihc's the last the fost [Insano waza]] | K7: 3035501 | L7: =IFERROR(__xludf.DUMMYFUNCTION("""COMPUTED_VALUE"""),"NM3") -> NM3 | N7: Sangatsu no Phantasia - Koufuku na Wagamama [Insane] | O7: 4.88183 | P7: 135 | Q7: 0.0024421296 | R7: 4 | S7: 9 | T7: 8 | U7: Jiysea | V7: 3035501
B8: https://osu.ppy.sh/beatmapsets/1544866#osu/3737825 | C8: =IFERROR(__xludf.DUMMYFUNCTION("""COMPUTED_VALUE"""),3737825.0) -> 3737825 | D8: NM | E8: matalisfangirl | G8: PSYQUI - Education [sorciere's Insane] | K8: 3737825 | L8: =IFERROR(__xludf.DUMMYFUNCTION("""COMPUTED_VALUE"""),"NM4") -> NM4 | N8: PSYQUI - Education [sorciere's Insane] | O8: 4.71109 | P8: 180 | Q8: 0.0024884259 | R8: 4 | S8: 9 | T8: 8 | U8: JeZag | V8: 3737825
B9: https://osu.ppy.sh/beatmapsets/1207286#osu/2514122 | C9: =IFERROR(__xludf.DUMMYFUNCTION("""COMPUTED_VALUE"""),2514122.0) -> 2514122 | D9: HD | E9: sedi__ | G9: Wagakki Band - Kagerou Days [Ducky-'s Insane] | K9: 2094462 | L9: =IFERROR(__xludf.DUMMYFUNCTION("""COMPUTED_VALUE"""),"HD1") -> HD1 | N9: Ax feat. Natsukawa Yoko - Sakimori Renka [Insane] | O9: 5.05371 | P9: 170 | Q9: 0.0020023148 | R9: 4.5 | S9: 9 | T9: 8 | U9: Yusomi | V9: 2094462
B10: https://osu.ppy.sh/beatmapsets/1238190#osu/2619929 | C10: =IFERROR(__xludf.DUMMYFUNCTION("""COMPUTED_VALUE"""),2619929.0) -> 2619929 | D10: HD | E10: play hd3 | G10: Amane - BOOZEHOUND [Down's Insane] | H10: hd2 | K10: 2619929 | L10: =IFERROR(__xludf.DUMMYFUNCTION("""COMPUTED_VALUE"""),"HD2") -> HD2 | N10: Amane - BOOZEHOUND [Down's Insane] | O10: 4.61004 | P10: 165 | Q10: 0.0016550926 | R10: 5 | S10: 8 | T10: 7 | U10: Luscent | V10: 2619929
B11: https://osu.ppy.sh/beatmapsets/1918243#osu/3958395 | C11: =IFERROR(__xludf.DUMMYFUNCTION("""COMPUTED_VALUE"""),3958395.0) -> 3958395 | D11: HR | E11: shironai14 | G11: Numakura Manami - Sakebe [Mrgglock's Insane] | H11: hr1 | K11: 2027623 | L11: =IFERROR(__xludf.DUMMYFUNCTION("""COMPUTED_VALUE"""),"HR1") -> HR1 | N11: THE ORAL CIGARETTES - Wagamama de Gomakasanaide [Panda & Melwoine's Insane] | O11: 5.00382 | P11: 142 | Q11: 0.0029166667 | R11: 4.94 | S11: 10 | T11: 10 | U11: DeviousPanda | V11: 2027623
B12: https://osu.ppy.sh/beatmapsets/721320#osu/1523138 | C12: =IFERROR(__xludf.DUMMYFUNCTION("""COMPUTED_VALUE"""),1523138.0) -> 1523138 | D12: HR | E12: yillow | G12: Kajiura Yuki - Sis puella magica! [Tea Party] | H12: hr2 | K12: 1523138 | L12: =IFERROR(__xludf.DUMMYFUNCTION("""COMPUTED_VALUE"""),"HR2") -> HR2 | N12: Kajiura Yuki - Sis puella magica! [Tea Party] | O12: 4.44079 | P12: 155.42 | Q12: 0.0016782407 | R12: 6.5 | S12: 10 | T12: 10 | U12: Asonate | V12: 1523138
B13: https://osu.ppy.sh/beatmapsets/1977605#osu/4105349 | C13: =IFERROR(__xludf.DUMMYFUNCTION("""COMPUTED_VALUE"""),4105349.0) -> 4105349 | D13: DT | E13: shironai14 | G13: ICHIKO - YOU'RE THE ONE [ANDREA & ASUKO'S HARD] | K13: 4105349 | L13: =IFERROR(__xludf.DUMMYFUNCTION("""COMPUTED_VALUE"""),"DT1") -> DT1 | N13: ICHIKO - YOU'RE THE ONE [ANDREA & ASUKO'S HARD] | O13: 5.08077 | P13: 235.5 | Q13: 0.0017052469 | R13: 3.8 | S13: 9.6666667 | T13: 8.4166667 | U13: Andrea | V13: 4105349
B14: https://osu.ppy.sh/beatmapsets/1670325#osu/3411549 | C14: =IFERROR(__xludf.DUMMYFUNCTION("""COMPUTED_VALUE"""),3411549.0) -> 3411549 | D14: DT | E14: shironai14 | G14: Ardolf - Split EX [HARD] | K14: 3533589 | L14: =IFERROR(__xludf.DUMMYFUNCTION("""COMPUTED_VALUE"""),"DT2") -> DT2 | N14: DIANA - Beethoven Virus [Aranel's Hard] | O14: 4.78925 | P14: 234 | Q14: 0.0016512346 | R14: 3.6 | S14: 9 | T14: 8.6833333 | U14: Orkay | V14: 3533589
B15: https://osu.ppy.sh/beatmapsets/1061614#osu/2395972 | C15: =IFERROR(__xludf.DUMMYFUNCTION("""COMPUTED_VALUE"""),2395972.0) -> 2395972 | D15: HD | E15: sedi__ | G15: Hanabusa Sumireko (CV: Arakawa Miho) - Inochi no Karakuri [Insane] | H15: HD1 tapping
B16: https://osu.ppy.sh/beatmapsets/1807986#osu/3720541 | C16: =IFERROR(__xludf.DUMMYFUNCTION("""COMPUTED_VALUE"""),3720541.0) -> 3720541 | D16: HD | E16: sedi__ | G16: SID - Mousou Nikki 2 [Miy's Insane] | H16: HD1
B17: https://osu.ppy.sh/beatmapsets/1496416#osu/3081261 | C17: =IFERROR(__xludf.DUMMYFUNCTION("""COMPUTED_VALUE"""),3081261.0) -> 3081261 | D17: NM | E17: sedi__ | G17: Co shu Nie - Yume o Kin'iro ni Somete [Insane ft. Kujinn] | H17: NM4
B18: https://osu.ppy.sh/beatmapsets/1712992#osu/3684386 | C18: =IFERROR(__xludf.DUMMYFUNCTION("""COMPUTED_VALUE"""),3684386.0) -> 3684386 | D18: HD | E18: shironai14 | G18: S3RL feat. Sara - Dopamine [Insane]
B19: https://osu.ppy.sh/beatmapsets/1841846#osu/3783139 | C19: =IFERROR(__xludf.DUMMYFUNCTION("""COMPUTED_VALUE"""),3783139.0) -> 3783139 | D19: HD | E19: shironai14 | G19: cYsmix - triangles [shime's absolutno another]
B20: https://osu.ppy.sh/beatmapsets/932567#osu/2027623 | C20: =IFERROR(__xludf.DUMMYFUNCTION("""COMPUTED_VALUE"""),2027623.0) -> 2027623 | D20: HR | E20: shironai14 | G20: THE ORAL CIGARETTES - Wagamama de Gomakasanaide [Panda & Melwoine's Insane]
B21: https://osu.ppy.sh/beatmapsets/1089678#osu/2305346 | C21: =IFERROR(__xludf.DUMMYFUNCTION("""COMPUTED_VALUE"""),2305346.0) -> 2305346 | D21: NM | E21: shironai14 | G21: Juggernaut. - Apocaliptix [PaRaDogi's Insane]
B22: https://osu.ppy.sh/beatmapsets/1212359#osu/3310401 | C22: =IFERROR(__xludf.DUMMYFUNCTION("""COMPUTED_VALUE"""),3310401.0) -> 3310401 | D22: NM | E22: shironai14 | G22: siromaru + cranky - conflict [Yoshino's Insane]
B23: https://osu.ppy.sh/beatmaps/4121042 | C23: =IFERROR(__xludf.DUMMYFUNCTION("""COMPUTED_VALUE"""),4121042.0) -> 4121042 | D23: DT | E23: shironai14 | G23: Dance Gavin Dance - Deception [Sebas' Hard]
B24: https://osu.ppy.sh/beatmapsets/357800#osu/908887 | C24: =IFERROR(__xludf.DUMMYFUNCTION("""COMPUTED_VALUE"""),908887.0) -> 908887 | D24: NM | E24: lunexia | G24: void - Crisscrosser [Insane]
B25: https://osu.ppy.sh/beatmapsets/1724615#osu/3533589 | C25: =IFERROR(__xludf.DUMMYFUNCTION("""COMPUTED_VALUE"""),3533589.0) -> 3533589 | D25: DT | G25: DIANA - Beethoven Virus [Aranel's Hard]
B26: https://osu.ppy.sh/beatmapsets/998415#osu/2094462 | C26: =IFERROR(__xludf.DUMMYFUNCTION("""COMPUTED_VALUE"""),2094462.0) -> 2094462 | D26: HD | G26: Ax feat. Natsukawa Yoko - Sakimori Renka [Insane]
B27: https://osu.ppy.sh/beatmapsets/1478828#osu/3035501 | C27: =IFERROR(__xludf.DUMMYFUNCTION("""COMPUTED_VALUE"""),3035501.0) -> 3035501 | D27: NM | G27: Sangatsu no Phantasia - Koufuku na Wagamama [Insane]
D28: HD

Sheet RO32
B2: Round of 32 | C2: Best of | D2: =IFERROR(VLOOKUP(B2,Settings!E3:H12,3,0),"") -> 9 | E2: Bans | F2: =IFERROR(VLOOKUP(B2,Settings!E3:H12,4,0),"") -> 1
B3: Suggestions | J3: Pool Assembly
B4: Map Link | C4: ID | D4: Mod | E4: Suggestor | F4: Map | H4: Notes | J4: Note | K4: ID | L4: Mod | M4: Map | O4: SR | P4: BPM | Q4: Length | R4: CS | S4: AR | T4: OD | U4: Mapper | V4: ID
C5: =IFERROR(__xludf.DUMMYFUNCTION("ArrayFormula(IFERROR(VALUE(REGEXEXTRACT(B5:B104&"""",""\d+$""))))"),"") | D5: NM | E5: play hd3 | F5: {=MAP(C5:C104,LAMBDA(id,IFNA(IMAGE(MAPDATA(id,"cover_url")),"")))} | G5: {=IFNA(HYPERLINK(VLOOKUP(C5:C104,'_api'!B3:BC104,MATCH("url",'_api'!B2:W2,0),0),VLOOKUP(C5:C104,'_api'!B3:BC104,MATCH("string",'_api'!B2:W2,0),0)),"")} | J5: Sedi didn't help | K5: 2277989 | L5: =IFERROR(__xludf.DUMMYFUNCTION("TRANSPOSE(SPLIT(JOIN("","",MAP(TRANSPOSE(Settings!I2:P2),TRANSPOSE(INDEX(Settings!I3:P12,MATCH(B2,Settings!E3:E12,0))),LAMBDA(mod,n,JOIN("","",ARRAYFORMULA(IF(n=0,"""",mod&SEQUENCE(n))))))),"",""))"),"NM1") -> NM1 | M5: {=MAP(K5:K104,LAMBDA(id,IFNA(IMAGE(MAPDATA(id,"cover_url")),"")))} | N5: =IFNA(MAPDATA(K5:K104,"string_url"),"") -> Hazuki - Uso to Shinjitsu [Insane] | O5: {=IFNA(MAPDATA_MODDED(K5:K104,{"difficultyrating","bpm","hit_length"},L5:L104),"")} -> 4.71288 | P5: 190 | Q5: 0.0027430556 | R5: {=IFNA(MAPDATA_MODDED(K5:K104,"diff_"&{"size","approach","overall"},L5:L104),"")} -> 3.8 | S5: 9 | T5: 7.5 | U5: {=IFNA(MAPDATA(K5:K104,{"creator","beatmap_id"}),"")} -> Akitoshi | V5: 2277989
B6: https://osu.ppy.sh/beatmapsets/1859662#osu/3823691 | C6: =IFERROR(__xludf.DUMMYFUNCTION("""COMPUTED_VALUE"""),3823691.0) -> 3823691 | D6: HD | E6: sedi__ | G6: Len - GHOST (feat. Such) [Amateurre's Insane] | H6: HD1 | I6: c | J6: Stream/Burst | K6: 3297107 | L6: =IFERROR(__xludf.DUMMYFUNCTION("""COMPUTED_VALUE"""),"NM2") -> NM2 | N6: Jun Kuroda - Terpsichore [Dancer's Delight] | O6: 4.74275 | P6: 181 | Q6: 0.001412037 | R6: 4 | S6: 9 | T6: 7.6 | U6: Quag | V6: 3297107
B7: https://osu.ppy.sh/beatmapsets/1435157#osu/2995193 | C7: =IFERROR(__xludf.DUMMYFUNCTION("""COMPUTED_VALUE"""),2995193.0) -> 2995193 | D7: NM | E7: sedi__ | G7: Street - Sakura Fubuki [99's Insane] | H7: NM2 | J7: Mixed alt | K7: 2440455 | L7: =IFERROR(__xludf.DUMMYFUNCTION("""COMPUTED_VALUE"""),"NM3") -> NM3 | N7: PUP - Anaphylaxis [Insane] | O7: 4.59244 | P7: 252 | Q7: 0.0019328704 | R7: 4 | S7: 9 | T7: 7.7 | U7: Hobbes2 | V7: 2440455
B8: https://osu.ppy.sh/beatmapsets/932654#osu/2016938 | C8: =IFERROR(__xludf.DUMMYFUNCTION("""COMPUTED_VALUE"""),2016938.0) -> 2016938 | D8: DT | G8: Pastel*Palettes - Happy Synthesizer [Mikan's Hard] | H8: DT3 | J8: Control / Slideraim | K8: 3248876 | L8: =IFERROR(__xludf.DUMMYFUNCTION("""COMPUTED_VALUE"""),"NM4") -> NM4 | N8: ISOMERZ (DJ Raisei + seatrus) - Symmetric [BOUYAAA's Insane] | O8: 4.42076 | P8: 200 | Q8: 0.001412037 | R8: 4 | S8: 9 | T8: 8 | U8: Realazy | V8: 3248876
B9: 2340750 | C9: =IFERROR(__xludf.DUMMYFUNCTION("""COMPUTED_VALUE"""),2340750.0) -> 2340750 | D9: NM | E9: play hd3 | G9: Yorushika - Itte. [Insane] | H9: NM1 aim focus | J9: Lower ar/Alt | K9: 1989991 | L9: =IFERROR(__xludf.DUMMYFUNCTION("""COMPUTED_VALUE"""),"NM5") -> NM5 | N9: Pastel*Palettes - Happy Synthesizer [Insane] | O9: 4.58083 | P9: 127 | Q9: 0.0015393519 | R9: 4 | S9: 8.3 | T9: 7 | U9: ktgster | V9: 1989991
B10: 3297107 | C10: =IFERROR(__xludf.DUMMYFUNCTION("""COMPUTED_VALUE"""),3297107.0) -> 3297107 | D10: NM | E10: lunexia | G10: Jun Kuroda - Terpsichore [Dancer's Delight] | H10: NM2 stream/burst/fingercontrol mix | J10: Awkward aim / Slideraim | K10: 3280686 | L10: =IFERROR(__xludf.DUMMYFUNCTION("""COMPUTED_VALUE"""),"HD1") -> HD1 | N10: Tsumiki - phony [Hatsune Miku's Insane] | O10: 4.75975 | P10: 170 | Q10: 0.0020138889 | R10: 3.3 | S10: 9 | T10: 8 | U10: Ryuusei Aika | V10: 3280686
B11: 2440455 | C11: =IFERROR(__xludf.DUMMYFUNCTION("""COMPUTED_VALUE"""),2440455.0) -> 2440455 | D11: NM | E11: play hd3 | G11: PUP - Anaphylaxis [Insane] | H11: NM3 mixed alt | J11: Aim/Burst | K11: 134141 | L11: =IFERROR(__xludf.DUMMYFUNCTION("""COMPUTED_VALUE"""),"HD2") -> HD2 | N11: P*Light - Poppin' Shower [Hyper] | O11: 4.33398 | P11: 175 | Q11: 0.0012268519 | R11: 4 | S11: 8 | T11: 6 | U11: Reisen Udongein | V11: 134141
B12: 3248876 | C12: =IFERROR(__xludf.DUMMYFUNCTION("""COMPUTED_VALUE"""),3248876.0) -> 3248876 | D12: NM | E12: play hd3 | G12: ISOMERZ (DJ Raisei + seatrus) - Symmetric [BOUYAAA's Insane] | H12: NM4 Fingercontrol and Slideraim mix | J12: Consistency | K12: 2659337 | L12: =IFERROR(__xludf.DUMMYFUNCTION("""COMPUTED_VALUE"""),"HR1") -> HR1 | N12: Omoi - Teo [waji's Insane] | O12: 4.597 | P12: 185 | Q12: 0.0019907407 | R12: 5.2 | S12: 10 | T12: 9.8 | U12: Shmiklak | V12: 2659337
B13: 1989991 | C13: =IFERROR(__xludf.DUMMYFUNCTION("""COMPUTED_VALUE"""),1989991.0) -> 1989991 | D13: NM | E13: play hd3 | G13: Pastel*Palettes - Happy Synthesizer [Insane] | H13: NM5 Alt | J13: Linear AIm | K13: 2110801 | L13: =IFERROR(__xludf.DUMMYFUNCTION("""COMPUTED_VALUE"""),"HR2") -> HR2 | N13: Silentroom - NULCTRL [Pattern 03a "exHRD" LMT] | O13: 4.26034 | P13: 100 | Q13: 0.0016666667 | R13: 6.5 | S13: 10 | T13: 9.8 | U13: Nerova Riuz GX | V13: 2110801
B14: 3280686 | C14: =IFERROR(__xludf.DUMMYFUNCTION("""COMPUTED_VALUE"""),3280686.0) -> 3280686 | D14: HD | E14: play hd3 | G14: Tsumiki - phony [Hatsune Miku's Insane] | H14: HD1 Bit awkward aim bit slideraim | J14: Farm kekw | K14: 2044893 | L14: =IFERROR(__xludf.DUMMYFUNCTION("""COMPUTED_VALUE"""),"DT1") -> DT1 | N14: mafumafu - Moudoku ga Osou [Hard] | O14: 4.67429 | P14: 234 | Q14: 0.0015740741 | R14: 4 | S14: 9.6666667 | T14: 8.4166667 | U14: Namki | V14: 2044893
B15: 3396305 | C15: =IFERROR(__xludf.DUMMYFUNCTION("""COMPUTED_VALUE"""),3396305.0) -> 3396305 | D15: DT | E15: yillow | G15: xi - Mirage Garden [PaRaDogi's Hard] | H15: DT3 Fingercontrol (quite speddie) | J15: "Speed" | K15: 2366848 | L15: =IFERROR(__xludf.DUMMYFUNCTION("""COMPUTED_VALUE"""),"DT2") -> DT2 | N15: ARForest - Aoba [Hard] | O15: 4.72202 | P15: 225 | Q15: 0.0011342593 | R15: 3.5 | S15: 9.6666667 | T15: 8.4166667 | U15: Niva | V15: 2366848
B16: 3446761 | C16: =IFERROR(__xludf.DUMMYFUNCTION("""COMPUTED_VALUE"""),3446761.0) -> 3446761 | D16: TB | E16: lunexia | G16: Ata - Euphoria [Aiq's Insane] | H16: TB Mixed, including an alt section, pooled twice | J16: Finger control | K16: 3396305 | L16: =IFERROR(__xludf.DUMMYFUNCTION("""COMPUTED_VALUE"""),"DT3") -> DT3 | N16: xi - Mirage Garden [PaRaDogi's Hard] | O16: 4.66036 | P16: 234 | Q16: 0.0010570988 | R16: 3.8 | S16: 9.6666667 | T16: 9.0833333 | U16: DeviousPanda | V16: 3396305
B17: 2044893 | C17: =IFERROR(__xludf.DUMMYFUNCTION("""COMPUTED_VALUE"""),2044893.0) -> 2044893 | D17: DT | E17: lunexia | G17: mafumafu - Moudoku ga Osou [Hard] | H17: DT1 Farm YEP | J17: Balanced | K17: 846261 | L17: =IFERROR(__xludf.DUMMYFUNCTION("""COMPUTED_VALUE"""),"FM1") -> FM1 | N17: Shawn Wasabi - Marble Soda [Narcissu's Insane] | O17: 4.40919 | P17: 168 | Q17: 0.001712963 | R17: 4 | S17: 9 | T17: 7.5 | U17: Len | V17: 846261
B18: 3044231 | C18: =IFERROR(__xludf.DUMMYFUNCTION("""COMPUTED_VALUE"""),3044231.0) -> 3044231 | D18: FM | E18: play hd3 | G18: Zekk - Duplication [Insane] | H18: FM1 Techy/Speed | J18: Anti mod | K18: 3743202 | L18: =IFERROR(__xludf.DUMMYFUNCTION("""COMPUTED_VALUE"""),"FM2") -> FM2 | N18: -45 - Total Eclipse of The Sun [Hard] | O18: 3.73927 | P18: 120 | Q18: 0.0015277778 | R18: 5 | S18: 8 | T18: 6 | U18: Matrix | V18: 3743202
B19: 57384 | C19: =IFERROR(__xludf.DUMMYFUNCTION("""COMPUTED_VALUE"""),57384.0) -> 57384 | D19: FM | E19: lunexia | G19: K'naan - Wavin' Flag [Shuna's Flag!] | H19: FM2 Antimod weird mapping | J19: Aim/Stream/Alt | K19: 3446761 | L19: =IFERROR(__xludf.DUMMYFUNCTION("""COMPUTED_VALUE"""),"TB1") -> TB1 | N19: Ata - Euphoria [Aiq's Insane] | O19: 5.07342 | P19: 190 | Q19: 0.0035185185 | R19: 4 | S19: 9.2 | T19: 8.6 | U19: -Cermia | V19: 3446761
B20: 2110801 | C20: =IFERROR(__xludf.DUMMYFUNCTION("""COMPUTED_VALUE"""),2110801.0) -> 2110801 | D20: HR | E20: yillow | G20: Silentroom - NULCTRL [Pattern 03a "exHRD" LMT] | H20: HR2 linear / grid aim
B21: 2366848 | C21: =IFERROR(__xludf.DUMMYFUNCTION("""COMPUTED_VALUE"""),2366848.0) -> 2366848 | D21: DT | E21: play hd3 | G21: ARForest - Aoba [Hard] | H21: DT2 """"Speed""""
B22: 2694599 | C22: =IFERROR(__xludf.DUMMYFUNCTION("""COMPUTED_VALUE"""),2694599.0) -> 2694599 | D22: HD | E22: yillow | G22: Sound Souler - Eternalism 2 [Gibune's Insane] | H22: Slowstream HD2
B23: https://osu.ppy.sh/beatmapsets/42527#osu/134141 | C23: =IFERROR(__xludf.DUMMYFUNCTION("""COMPUTED_VALUE"""),134141.0) -> 134141 | D23: HD | E23: play hd3 | G23: P*Light - Poppin' Shower [Hyper] | H23: HD2 Old-style mirror mapping
B24: https://osu.ppy.sh/beatmapsets/80214#osu/250577 | C24: =IFERROR(__xludf.DUMMYFUNCTION("""COMPUTED_VALUE"""),250577.0) -> 250577 | D24: HR | E24: yillow | G24: Wotamin - Gigantic O.T.N [Hard] | H24: HR1 Old-style gridmapping
B25: 2161153 | C25: =IFERROR(__xludf.DUMMYFUNCTION("""COMPUTED_VALUE"""),2161153.0) -> 2161153 | D25: DT | E25: play hd3 | G25: OISHII - ONIGIRI FREEWAY [HARD] | H25: dt3 if no nm5
B26: 2795818 | C26: =IFERROR(__xludf.DUMMYFUNCTION("""COMPUTED_VALUE"""),2795818.0) -> 2795818 | D26: NM | E26: sedi__ | G26: the peggies - Neverland [Insane] | H26: NM1 aim focus
B27: 3941210 | C27: =IFERROR(__xludf.DUMMYFUNCTION("""COMPUTED_VALUE"""),3941210.0) -> 3941210 | D27: NM | E27: sedi__ | G27: kessoku band - Wasurete Yaranai [Amachama's Insane] | H27: NM2 fingercontrol focus
B28: 3742030 | C28: =IFERROR(__xludf.DUMMYFUNCTION("""COMPUTED_VALUE"""),3742030.0) -> 3742030 | D28: FM | G28: Risa Yuzuki - Cinderella Maker [Mindmaster's Hard]
B29: 846261 | C29: =IFERROR(__xludf.DUMMYFUNCTION("""COMPUTED_VALUE"""),846261.0) -> 846261 | D29: FM | E29: play hd3 | G29: Shawn Wasabi - Marble Soda [Narcissu's Insane]
B30: 2659337 | C30: =IFERROR(__xludf.DUMMYFUNCTION("""COMPUTED_VALUE"""),2659337.0) -> 2659337 | D30: HR | E30: yillow | G30: Omoi - Teo [waji's Insane]
B31: 2277989 | C31: =IFERROR(__xludf.DUMMYFUNCTION("""COMPUTED_VALUE"""),2277989.0) -> 2277989 | D31: NM | E31: play hd3 | G31: Hazuki - Uso to Shinjitsu [Insane]
B32: https://osu.ppy.sh/beatmapsets/1782707#osu/3743202 | C32: =IFERROR(__xludf.DUMMYFUNCTION("""COMPUTED_VALUE"""),3743202.0) -> 3743202 | D32: FM | G32: -45 - Total Eclipse of The Sun [Hard]

Sheet RO16
B2: Round of 16 | C2: Best of | D2: =IFERROR(VLOOKUP(B2,Settings!E3:H12,3,0),"") -> 9 | E2: Bans | F2: =IFERROR(VLOOKUP(B2,Settings!E3:H12,4,0),"") -> 1
B3: Suggestions | J3: Pool Assembly
B4: Map Link | C4: ID | D4: Mod | E4: Suggestor | F4: Map | H4: Notes | J4: Note | K4: ID | L4: Mod | M4: Map | O4: SR | P4: BPM | Q4: Length | R4: CS | S4: AR | T4: OD | U4: Mapper | V4: ID
B5: https://osu.ppy.sh/beatmapsets/111611#osu/306038 | C5: =IFERROR(__xludf.DUMMYFUNCTION("ArrayFormula(IFERROR(VALUE(REGEXEXTRACT(B5:B104&"""",""\d+$""))))"),306038.0) -> 306038 | D5: NM | E5: yillow | F5: {=MAP(C5:C104,LAMBDA(id,IFNA(IMAGE(MAPDATA(id,"cover_url")),"")))} | G5: {=IFNA(HYPERLINK(VLOOKUP(C5:C104,'_api'!B3:BC104,MATCH("url",'_api'!B2:W2,0),0),VLOOKUP(C5:C104,'_api'!B3:BC104,MATCH("string",'_api'!B2:W2,0),0)),"")} -> ZUN - Kobito of the Shining Needle ~ Little Princess [Lunatic] | H5: low bpm streams | J5: Consistency | K5: 2827293 | L5: =IFERROR(__xludf.DUMMYFUNCTION("TRANSPOSE(SPLIT(JOIN("","",MAP(TRANSPOSE(Settings!I2:P2),TRANSPOSE(INDEX(Settings!I3:P12,MATCH(B2,Settings!E3:E12,0))),LAMBDA(mod,n,JOIN("","",ARRAYFORMULA(IF(n=0,"""",mod&SEQUENCE(n))))))),"",""))"),"NM1") -> NM1 | M5: {=MAP(K5:K104,LAMBDA(id,IFNA(IMAGE(MAPDATA(id,"cover_url")),"")))} | N5: =IFNA(MAPDATA(K5:K104,"string_url"),"") -> Yorushika - Thoughtcrime [Akitoshi's Insane] | O5: {=IFNA(MAPDATA_MODDED(K5:K104,{"difficultyrating","bpm","hit_length"},L5:L104),"")} -> 4.88906 | P5: 200 | Q5: 0.0026851852 | R5: {=IFNA(MAPDATA_MODDED(K5:K104,"diff_"&{"size","approach","overall"},L5:L104),"")} -> 3.8 | S5: 9 | T5: 7.8 | U5: {=IFNA(MAPDATA(K5:K104,{"creator","beatmap_id"}),"")} -> Meg | V5: 2827293
B6: https://osu.ppy.sh/beatmapsets/1743257#osu/3563790 | C6: =IFERROR(__xludf.DUMMYFUNCTION("""COMPUTED_VALUE"""),3563790.0) -> 3563790 | D6: NM | E6: sedi__ | G6: Electronic Boutique - Miles [Minimal] | H6: NM3 | I6: c | J6: Stamina/Streams | K6: 2004679 | L6: =IFERROR(__xludf.DUMMYFUNCTION("""COMPUTED_VALUE"""),"NM2") -> NM2 | N6: Fractal Dreamers - Gardens Under A Spring Sky [Hyper] | O6: 4.90416 | P6: 195 | Q6: 0.0014351852 | R6: 4.5 | S6: 9 | T6: 8 | U6: Lasse | V6: 2004679
B7: https://osu.ppy.sh/beatmapsets/1528914#osu/3496410 | C7: =IFERROR(__xludf.DUMMYFUNCTION("""COMPUTED_VALUE"""),3496410.0) -> 3496410 | D7: TB | E7: sedi__ | G7: Shimotsuki Haruka, Chata, Katakiri Rekka - Suishou ni Utsuru Himegimi [Collab Insane] | H7: HD1 | J7: Alt consistency | K7: 3239199 | L7: =IFERROR(__xludf.DUMMYFUNCTION("""COMPUTED_VALUE"""),"NM3") -> NM3 | N7: Tsukuyomi - Dareka no Shinzou ni Nareta nara [too's Insane] | O7: 4.71336 | P7: 143 | Q7: 0.0026273148 | R7: 4 | S7: 9 | T7: 8 | U7: Mononymous | V7: 3239199
B8: https://osu.ppy.sh/beatmapsets/1758376#osu/3887774 | C8: =IFERROR(__xludf.DUMMYFUNCTION("""COMPUTED_VALUE"""),3887774.0) -> 3887774 | D8: HD | E8: sedi__ | G8: Noah - Purification of soul [Flame Haze's Insane] | J8: Slider aim | K8: 2794904 | L8: =IFERROR(__xludf.DUMMYFUNCTION("""COMPUTED_VALUE"""),"NM4") -> NM4 | N8: sakuraburst - Glacierfall (Park Remix) [haruto x ancel's ins*ne] | O8: 4.57912 | P8: 170 | Q8: 0.0016435185 | R8: 4 | S8: 9 | T8: 7.5 | U8: ScubDomino | V8: 2794904
B9: https://osu.ppy.sh/beatmapsets/1358622#osu/2827293 | C9: =IFERROR(__xludf.DUMMYFUNCTION("""COMPUTED_VALUE"""),2827293.0) -> 2827293 | D9: NM | E9: play hd3 | G9: Yorushika - Thoughtcrime [Akitoshi's Insane] | H9: skeleton nm1 | J9: Low ar/bpm finger control | K9: 2853477 | L9: =IFERROR(__xludf.DUMMYFUNCTION("""COMPUTED_VALUE"""),"NM5") -> NM5 | N9: sekai - Zange Mairi [Voice's Insane] | O9: 4.6484 | P9: 140 | Q9: 0.0020717593 | R9: 4.4 | S9: 8.3 | T9: 7 | U9: Yugu | V9: 2853477
B10: https://osu.ppy.sh/beatmapsets/956716#osu/2004679 | C10: =IFERROR(__xludf.DUMMYFUNCTION("""COMPUTED_VALUE"""),2004679.0) -> 2004679 | D10: NM | E10: lunexia | G10: Fractal Dreamers - Gardens Under A Spring Sky [Hyper] | H10: skeleton nm2 | J10: Consistency | K10: 1733441 | L10: =IFERROR(__xludf.DUMMYFUNCTION("""COMPUTED_VALUE"""),"HD1") -> HD1 | N10: Police Piccadilly feat. Hatsune Miku - Kire Carry On [negusver's Insane] | O10: 4.95838 | P10: 170 | Q10: 0.001724537 | R10: 4 | S10: 9 | T10: 8 | U10: Sinnoh | V10: 1733441
B11: https://osu.ppy.sh/beatmapsets/1508883#osu/3117101 | C11: =IFERROR(__xludf.DUMMYFUNCTION("""COMPUTED_VALUE"""),3117101.0) -> 3117101 | D11: NM | E11: play hd3 | G11: Yorushika - Dakara Boku wa Ongaku o Yameta [I'm not mistaken?] | H11: skeleton nm3 | J11: Reading/Streams | K11: 3460069 | L11: =IFERROR(__xludf.DUMMYFUNCTION("""COMPUTED_VALUE"""),"HD2") -> HD2 | N11: Siren - Polaris [8 is not a low ar guys] | O11: 4.42032 | P11: 174 | Q11: 0.0012731481 | R11: 4 | S11: 8 | T11: 7 | U11: -Cermia | V11: 3460069
B12: https://osu.ppy.sh/beatmapsets/564329#osu/1489274 | C12: =IFERROR(__xludf.DUMMYFUNCTION("""COMPUTED_VALUE"""),1489274.0) -> 1489274 | D12: NM | E12: play hd3 | G12: YUC'e - Sengoku HOP [apple's Insane] | H12: skeleton nm4 | J12: Consistency + Banger | K12: 1956568 | L12: =IFERROR(__xludf.DUMMYFUNCTION("""COMPUTED_VALUE"""),"HR1") -> HR1 | N12: PSYQUI feat. Such - Senchimentaruhatoboi [Insane] | O12: 4.85394 | P12: 160 | Q12: 0.0025 | R12: 4.94 | S12: 10 | T12: 10 | U12: eeezzzeee | V12: 1956568
B13: https://osu.ppy.sh/beatmapsets/1968201#osu/4082310 | C13: =IFERROR(__xludf.DUMMYFUNCTION("""COMPUTED_VALUE"""),4082310.0) -> 4082310 | D13: NM | E13: play hd3 | G13: chelmico - Easy Breezy [ezier bz] | H13: skeleton nm5 | J13: High CS/Wide angle jumps | K13: 295650 | L13: =IFERROR(__xludf.DUMMYFUNCTION("""COMPUTED_VALUE"""),"HR2") -> HR2 | N13: Perfume - Laser Beam [Mixagji] | O13: 4.62781 | P13: 135 | Q13: 0.0022453704 | R13: 6.5 | S13: 10 | T13: 9.8 | U13: Raging Bull | V13: 295650
B14: https://osu.ppy.sh/beatmapsets/50462#osu/155064 | C14: =IFERROR(__xludf.DUMMYFUNCTION("""COMPUTED_VALUE"""),155064.0) -> 155064 | D14: HD | E14: play hd3 | G14: Lon - Yuru Fuwa Jukai Girl [Insane] | H14: skeletion hd1 | J14: Burst heavy Consitency | K14: 3446883 | L14: =IFERROR(__xludf.DUMMYFUNCTION("""COMPUTED_VALUE"""),"DT1") -> DT1 | N14: Yumeno Yuki - First Time [KoldNoodl's Hard] | O14: 4.94646 | P14: 193.5 | Q14: 0.0016820988 | R14: 3.8 | S14: 9.6666667 | T14: 9.0833333 | U14: ImpurePug | V14: 3446883
B15: https://osu.ppy.sh/beatmapsets/1932625#osu/4024821 | C15: =IFERROR(__xludf.DUMMYFUNCTION("""COMPUTED_VALUE"""),4024821.0) -> 4024821 | D15: HD | E15: play hd3 | G15: Zemfira - kto? [riffy's insane] | H15: skeleton hd2 | J15: Alt/Bursts | K15: 1521209 | L15: =IFERROR(__xludf.DUMMYFUNCTION("""COMPUTED_VALUE"""),"DT2") -> DT2 | N15: YUC'e - Future Candy [Hard] | O15: 4.76186 | P15: 270 | Q15: 0.0013348765 | R15: 3.5 | S15: 9.6666667 | T15: 8.4166667 | U15: Nathan | V15: 1521209
B16: https://osu.ppy.sh/beatmapsets/1316097#osu/2729314 | C16: =IFERROR(__xludf.DUMMYFUNCTION("""COMPUTED_VALUE"""),2729314.0) -> 2729314 | D16: HR | E16: play hd3 | G16: Kaede To Kyo Aki Ame Kuzu - Q [Insane] | H16: skeleton hr1 | J16: Fingercontrol(?) | K16: 3616100 | L16: =IFERROR(__xludf.DUMMYFUNCTION("""COMPUTED_VALUE"""),"DT3") -> DT3 | N16: tarolabo - eth ken [hard] | O16: 4.72433 | P16: 189 | Q16: 0.00094135802 | R16: 3.6 | S16: 9.6666667 | T16: 8.75 | U16: DeviousPanda | V16: 3616100
B17: https://osu.ppy.sh/beatmapsets/25580#osu/87319 | C17: =IFERROR(__xludf.DUMMYFUNCTION("""COMPUTED_VALUE"""),87319.0) -> 87319 | D17: HR | E17: play hd3 | G17: Kakeru Hotarubi - Fanshi 3 Kami Goranshin [Insane] | H17: skeleton hr2 | J17: Speed CS3 | K17: 2151207 | L17: =IFERROR(__xludf.DUMMYFUNCTION("""COMPUTED_VALUE"""),"FM1") -> FM1 | N17: OISHII - ONIGIRI FREEWAY [LUKAS' INSANE] | O17: 4.63282 | P17: 210 | Q17: 0.0017592593 | R17: 3 | S17: 9 | T17: 8 | U17: Hazu- | V17: 2151207
B18: https://osu.ppy.sh/beatmapsets/914691#osu/1913099 | C18: =IFERROR(__xludf.DUMMYFUNCTION("""COMPUTED_VALUE"""),1913099.0) -> 1913099 | D18: DT | E18: play hd3 | G18: S3RL - MTC (Different Heaven Remix) [Hard] | H18: skeleton dt1 | J18: Grid Antimod | K18: 417898 | L18: =IFERROR(__xludf.DUMMYFUNCTION("""COMPUTED_VALUE"""),"FM2") -> FM2 | N18: Giga-P - Electric Angel [Sonnyc's Insane] | O18: 4.3997 | P18: 150 | Q18: 0.0015856481 | R18: 5 | S18: 8 | T18: 7 | U18: koreapenguin | V18: 417898
B19: https://osu.ppy.sh/beatmapsets/546820#osu/1521209 | C19: =IFERROR(__xludf.DUMMYFUNCTION("""COMPUTED_VALUE"""),1521209.0) -> 1521209 | D19: DT | E19: play hd3 | G19: YUC'e - Future Candy [Hard] | H19: skeleton dt2 | J19: Don't sighread :tf: | K19: 1857415 | L19: =IFERROR(__xludf.DUMMYFUNCTION("""COMPUTED_VALUE"""),"TB1") -> TB1 | N19: Au5 - Moonland [Collab Another] | O19: 5.08792 | P19: 170 | Q19: 0.0034027778 | R19: 4 | S19: 9 | T19: 8 | U19: DTM9 Nowa | V19: 1857415
B20: https://osu.ppy.sh/beatmapsets/1285447#osu/2967720 | C20: =IFERROR(__xludf.DUMMYFUNCTION("""COMPUTED_VALUE"""),2967720.0) -> 2967720 | D20: DT | E20: play hd3 | G20: hololive IDOL PROJECT - Koyoi wa Halloween Night! [sleepy's Hard] | H20: skeleton dt3
B21: https://osu.ppy.sh/beatmapsets/701330#osu/1498150 | C21: =IFERROR(__xludf.DUMMYFUNCTION("""COMPUTED_VALUE"""),1498150.0) -> 1498150 | D21: FM | E21: play hd3 | G21: I SEE MONSTAS - Holdin On (Skrillex and Nero Remix) [Insane] | H21: skeleton fm1
B22: https://osu.ppy.sh/beatmapsets/172900#osu/417898 | C22: =IFERROR(__xludf.DUMMYFUNCTION("""COMPUTED_VALUE"""),417898.0) -> 417898 | D22: FM | E22: play hd3 | G22: Giga-P - Electric Angel [Sonnyc's Insane] | H22: skeleton fm2
B23: https://osu.ppy.sh/beatmapsets/25802#osu/87369 | C23: =IFERROR(__xludf.DUMMYFUNCTION("""COMPUTED_VALUE"""),87369.0) -> 87369 | D23: HR | E23: yillow | G23: Hatsune Miku - Netoge Haijin Sprechchor [Insane] | H23: hr1 - streamy prob too hard
B24: https://osu.ppy.sh/beatmapsets/1157572#osu/2530278 | C24: =IFERROR(__xludf.DUMMYFUNCTION("""COMPUTED_VALUE"""),2530278.0) -> 2530278 | D24: HR | E24: yillow | G24: Hino Isuka - Moonheart (Mameyudoufu Remix) [Insane] | H24: hr1 - bursty "light tech"
B25: https://osu.ppy.sh/beatmapsets/409898#osu/892543 | C25: =IFERROR(__xludf.DUMMYFUNCTION("""COMPUTED_VALUE"""),892543.0) -> 892543 | D25: HR | E25: yillow | G25: Komiya Mao - (can you) understand me? [insane?] | H25: hr1 - just aim
B26: 3714964 | C26: =IFERROR(__xludf.DUMMYFUNCTION("""COMPUTED_VALUE"""),3714964.0) -> 3714964 | D26: HR | E26: play hd3 | G26: BotchiBoromaru - Otose Thunder [Shiny Braixen's Insane] | H26: hr1
B27: https://osu.ppy.sh/beatmapsets/1046876#osu/2200330 | C27: =IFERROR(__xludf.DUMMYFUNCTION("""COMPUTED_VALUE"""),2200330.0) -> 2200330 | D27: HD | E27: play hd3 | G27: nana(Sevencolors) - chameleon [Insane] | H27: hd2
B28: https://osu.ppy.sh/beatmapsets/824959#osu/1733441 | C28: =IFERROR(__xludf.DUMMYFUNCTION("""COMPUTED_VALUE"""),1733441.0) -> 1733441 | D28: HD | E28: play hd3 | G28: Police Piccadilly feat. Hatsune Miku - Kire Carry On [negusver's Insane] | H28: hd1
B29: https://osu.ppy.sh/beatmapsets/1759764#osu/3601684 | C29: =IFERROR(__xludf.DUMMYFUNCTION("""COMPUTED_VALUE"""),3601684.0) -> 3601684 | D29: NM | E29: play hd3 | G29: sekai - God-ish [Setu's Insane] | H29: nm3
B30: https://osu.ppy.sh/beatmapsets/123354#osu/315101 | C30: =IFERROR(__xludf.DUMMYFUNCTION("""COMPUTED_VALUE"""),315101.0) -> 315101 | D30: DT | E30: play hd3 | G30: DECO*27 - Ai Kotoba II [Insane] | H30: dt1
B31: https://osu.ppy.sh/beatmapsets/841634#osu/1761258 | C31: =IFERROR(__xludf.DUMMYFUNCTION("""COMPUTED_VALUE"""),1761258.0) -> 1761258 | D31: NM | E31: play hd3 | G31: HACHI feat. Hatsune Miku - Suna no Wakusei [Insane] | H31: nm5
B32: https://osu.ppy.sh/beatmapsets/1203052#osu/2701775 | C32: =IFERROR(__xludf.DUMMYFUNCTION("""COMPUTED_VALUE"""),2701775.0) -> 2701775 | D32: FM | G32: Chibanyan vs. Otogibara Era - GOMIKASU -Original Mix- [Insane] | H32: FM1
B33: https://osu.ppy.sh/beatmapsets/1693295#osu/3460069 | C33: =IFERROR(__xludf.DUMMYFUNCTION("""COMPUTED_VALUE"""),3460069.0) -> 3460069 | D33: HD | E33: lunexia | G33: Siren - Polaris [8 is not a low ar guys]
B34: https://osu.ppy.sh/beatmapsets/1488532#osu/3053637 | C34: =IFERROR(__xludf.DUMMYFUNCTION("""COMPUTED_VALUE"""),3053637.0) -> 3053637 | D34: DT | E34: play hd3 | G34: FROZEN QUALIA - Birthday [Hard]
B35: https://osu.ppy.sh/beatmapsets/1632817#osu/3332932 | C35: =IFERROR(__xludf.DUMMYFUNCTION("""COMPUTED_VALUE"""),3332932.0) -> 3332932 | D35: HR | E35: play hd3 | G35: Lil Nas X - THATS WHAT I WANT [GOKUGOHAN12468'S INSANE]
B36: https://osu.ppy.sh/beatmapsets/996628#osu/2151207 | C36: =IFERROR(__xludf.DUMMYFUNCTION("""COMPUTED_VALUE"""),2151207.0) -> 2151207 | D36: FM | E36: play hd3 | G36: OISHII - ONIGIRI FREEWAY [LUKAS' INSANE]
B37: https://osu.ppy.sh/beatmapsets/1494548#osu/3169863 | C37: =IFERROR(__xludf.DUMMYFUNCTION("""COMPUTED_VALUE"""),3169863.0) -> 3169863 | D37: NM | G37: DE DE MOUSE - Silly Love [0pp's Insane]
B38: https://osu.ppy.sh/beatmapsets/1401651#osu/2891411 | C38: =IFERROR(__xludf.DUMMYFUNCTION("""COMPUTED_VALUE"""),2891411.0) -> 2891411 | D38: HR | G38: kozato - Tsuki -Yue- [Kuse's Insane]
B39: https://osu.ppy.sh/beatmapsets/1329045#osu/2794904 | C39: =IFERROR(__xludf.DUMMYFUNCTION("""COMPUTED_VALUE"""),2794904.0) -> 2794904 | D39: NM | E39: play hd3 | G39: sakuraburst - Glacierfall (Park Remix) [haruto x ancel's ins*ne]
B40: https://osu.ppy.sh/beatmapsets/106568#osu/295650 | C40: =IFERROR(__xludf.DUMMYFUNCTION("""COMPUTED_VALUE"""),295650.0) -> 295650 | D40: HR | E40: therealdeathmatch | G40: Perfume - Laser Beam [Mixagji]
B41: https://osu.ppy.sh/beatmapsets/924701#osu/1956568 | C41: =IFERROR(__xludf.DUMMYFUNCTION("""COMPUTED_VALUE"""),1956568.0) -> 1956568 | D41: HR | E41: play hd3 | G41: PSYQUI feat. Such - Senchimentaruhatoboi [Insane]
...

Sheet QF
A1: aaa
B2: Quarterfinals | C2: Best of | D2: =IFERROR(VLOOKUP(B2,Settings!E3:H12,3,0),"") -> 11 | E2: Bans | F2: =IFERROR(VLOOKUP(B2,Settings!E3:H12,4,0),"") -> 2
B3: Suggestions | J3: Pool Assembly
B4: Map Link | C4: ID | D4: Mod | E4: Suggestor | F4: Map | H4: Notes | J4: Note | K4: ID | L4: Mod | M4: Map | O4: SR | P4: BPM | Q4: Length | R4: CS | S4: AR | T4: OD | U4: Mapper | V4: ID
B5: https://osu.ppy.sh/beatmapsets/1615650#osu/3298592 | C5: =IFERROR(__xludf.DUMMYFUNCTION("ArrayFormula(IFERROR(VALUE(REGEXEXTRACT(B5:B104&"""",""\d+$""))))"),3298592.0) -> 3298592 | D5: HD | F5: {=MAP(C5:C104,LAMBDA(id,IFNA(IMAGE(MAPDATA(id,"cover_url")),"")))} | G5: {=IFNA(HYPERLINK(VLOOKUP(C5:C104,'_api'!B3:BC104,MATCH("url",'_api'!B2:W2,0),0),VLOOKUP(C5:C104,'_api'!B3:BC104,MATCH("string",'_api'!B2:W2,0),0)),"")} -> kors k - SigSig [Luscent's Insane] | H5: hd2 | J5: no modification one | K5: 1965654 | L5: =IFERROR(__xludf.DUMMYFUNCTION("TRANSPOSE(SPLIT(JOIN("","",MAP(TRANSPOSE(Settings!I2:P2),TRANSPOSE(INDEX(Settings!I3:P12,MATCH(B2,Settings!E3:E12,0))),LAMBDA(mod,n,JOIN("","",ARRAYFORMULA(IF(n=0,"""",mod&SEQUENCE(n))))))),"",""))"),"NM1") -> NM1 | M5: {=MAP(K5:K104,LAMBDA(id,IFNA(IMAGE(MAPDATA(id,"cover_url")),"")))} | N5: =IFNA(MAPDATA(K5:K104,"string_url"),"") -> Sangatsu no Phantasia - Pink Lemonade [Insane] | O5: {=IFNA(MAPDATA_MODDED(K5:K104,{"difficultyrating","bpm","hit_length"},L5:L104),"")} -> 5.08315 | P5: 191 | Q5: 0.0028703704 | R5: {=IFNA(MAPDATA_MODDED(K5:K104,"diff_"&{"size","approach","overall"},L5:L104),"")} -> 4 | S5: 9 | T5: 7 | U5: {=IFNA(MAPDATA(K5:K104,{"creator","beatmap_id"}),"")} -> Chirony | V5: 1965654
B6: https://osu.ppy.sh/beatmapsets/4404#osu/63604 | C6: =IFERROR(__xludf.DUMMYFUNCTION("""COMPUTED_VALUE"""),63604.0) -> 63604 | D6: HD | G6: Comp - Gensou no Satellite [Insane] | I6: c | J6: streams | K6: 1838159 | L6: =IFERROR(__xludf.DUMMYFUNCTION("""COMPUTED_VALUE"""),"NM2") -> NM2 | N6: Thaehan - Doki-Doki [rockstarrzz' Insane] | O6: 5.15169 | P6: 180 | Q6: 0.0011805556 | R6: 3.8 | S6: 9 | T6: 7.5 | U6: Mr HeliX | V6: 1838159
B7: https://osu.ppy.sh/beatmapsets/1270156#osu/2690081 | C7: =IFERROR(__xludf.DUMMYFUNCTION("""COMPUTED_VALUE"""),2690081.0) -> 2690081 | D7: FM | G7: Tenjin Kotone - Darling Dance [UjiMatcha's Insane] | H7: fm1 | J7: alt | K7: 2568756 | L7: =IFERROR(__xludf.DUMMYFUNCTION("""COMPUTED_VALUE"""),"NM3") -> NM3 | N7: Meguro Shoji feat. Lyn - Last Surprise -Scramble- [Expert] | O7: 4.81073 | P7: 123 | Q7: 0.0025115741 | R7: 3.6 | S7: 9.1 | T7: 8 | U7: moph | V7: 2568756
B8: https://osu.ppy.sh/beatmapsets/941246#osu/1965654 | C8: =IFERROR(__xludf.DUMMYFUNCTION("""COMPUTED_VALUE"""),1965654.0) -> 1965654 | D8: NM | E8: play hd3 | G8: Sangatsu no Phantasia - Pink Lemonade [Insane] | H8: nm1 | J8: tech | K8: 3341368 | L8: =IFERROR(__xludf.DUMMYFUNCTION("""COMPUTED_VALUE"""),"NM4") -> NM4 | N8: Nekomata Master+ - squall [0pp's Insane (Tournament Edit)] | O8: 4.59923 | P8: 190 | Q8: 0.0013888889 | R8: 4 | S8: 9.2 | T8: 7 | U8: Kyrian | V8: 3341368
B9: https://osu.ppy.sh/beatmapsets/1507979#osu/3118794 | C9: =IFERROR(__xludf.DUMMYFUNCTION("""COMPUTED_VALUE"""),3118794.0) -> 3118794 | D9: NM | E9: aoi hinami | G9: DIALOGUE+ - Jinsei Easy? [LV.20 Finshie's Insane] | H9: nm3 | J9: speed | K9: 4215637 | L9: =IFERROR(__xludf.DUMMYFUNCTION("""COMPUTED_VALUE"""),"NM5") -> NM5 | N9: the Art of Mankind - Unexisted [Insane] | O9: 5.01002 | P9: 217 | Q9: 0.0021412037 | R9: 4 | S9: 9 | T9: 8 | U9: quantumvortex | V9: 4215637
B10: https://osu.ppy.sh/beatmapsets/1586738#osu/3248255 | C10: =IFERROR(__xludf.DUMMYFUNCTION("""COMPUTED_VALUE"""),3248255.0) -> 3248255 | D10: HR | E10: yillow | G10: NICODE & M2U - Predawn [Mixagji's Insane] | H10: hr3 | J10: funny ar | K10: 3821597 | L10: =IFERROR(__xludf.DUMMYFUNCTION("""COMPUTED_VALUE"""),"NM6") -> NM6 | N10: Franz Ferdinand - This Fffire (TV Size) [enri's iNnnsane] | O10: 4.11281 | P10: 146.5 | Q10: 0.00096064815 | R10: 5 | S10: 6.9 | T10: 6.9 | U10: ninore | V10: 3821597
B11: https://osu.ppy.sh/beatmapsets/776928#osu/1635864 | C11: =IFERROR(__xludf.DUMMYFUNCTION("""COMPUTED_VALUE"""),1635864.0) -> 1635864 | D11: HD | E11: yillow | G11: NIVIRO - Memes (Speed Up Ver.) [moph's Insane] | H11: hd3 | J11: hidden modification one | K11: 2671048 | L11: =IFERROR(__xludf.DUMMYFUNCTION("""COMPUTED_VALUE"""),"HD1") -> HD1 | N11: Usada Pekora - Discommunication Alien [Ayyken's Another] | O11: 5.08091 | P11: 170 | Q11: 0.0023958333 | R11: 4.5 | S11: 9 | T11: 8.5 | U11: Yugu | V11: 2671048
B12: https://osu.ppy.sh/beatmapsets/660630#osu/1404975 | C12: =IFERROR(__xludf.DUMMYFUNCTION("""COMPUTED_VALUE"""),1404975.0) -> 1404975 | D12: HD | E12: yillow | G12: Ocelot - KAEDE [Kalindraz's EX] | H12: hd3 - probably too hard | J12: bursts/stream | K12: 105978 | L12: =IFERROR(__xludf.DUMMYFUNCTION("""COMPUTED_VALUE"""),"HD2") -> HD2 | N12: BRZion - Game Brain [Insane] | O12: 4.51204 | P12: 190 | Q12: 0.001712963 | R12: 4 | S12: 8 | T12: 6 | U12: Zapy | V12: 105978
B13: https://osu.ppy.sh/beatmapsets/737728#osu/1687599 | C13: =IFERROR(__xludf.DUMMYFUNCTION("""COMPUTED_VALUE"""),1687599.0) -> 1687599 | D13: NM | E13: play hd3 | G13: Camellia - Lunatic Rough Party!! [LCFC's HYPER] | H13: nm4 | J13: alt/tech | K13: 1491793 | L13: =IFERROR(__xludf.DUMMYFUNCTION("""COMPUTED_VALUE"""),"HD3") -> HD3 | N13: succducc - me & u [sing's insane] | O13: 4.95782 | P13: 160 | Q13: 0.0018865741 | R13: 4 | S13: 9 | T13: 8 | U13: Nathan | V13: 1491793
B14: https://osu.ppy.sh/b/2072245 | C14: =IFERROR(__xludf.DUMMYFUNCTION("""COMPUTED_VALUE"""),2072245.0) -> 2072245 | D14: NM | E14: lunexia | G14: Fractal Dreamers - Gardens Under A Spring Sky [Insane] | H14: nm2 | J14: simple consistency | K14: 3913591 | L14: =IFERROR(__xludf.DUMMYFUNCTION("""COMPUTED_VALUE"""),"HR1") -> HR1 | N14: kessoku band - Guitar to Kodoku to Aoi Hoshi [kuuti's Insane] | O14: 5.01388 | P14: 193 | Q14: 0.0024305556 | R14: 5.2 | S14: 10 | T14: 10 | U14: Shurelia | V14: 3913591
B15: https://osu.ppy.sh/beatmapsets/749096#osu/1596086 | C15: =IFERROR(__xludf.DUMMYFUNCTION("""COMPUTED_VALUE"""),1596086.0) -> 1596086 | D15: HD | E15: shironai14 | G15: Uinyasu, Occhoko Bunny - Aa Kenran no Yume ga Gotoku (Epsilon Remix) [Dailycare's Insane] | H15: HD1 | J15: yeah | K15: 37750 | L15: =IFERROR(__xludf.DUMMYFUNCTION("""COMPUTED_VALUE"""),"HR2") -> HR2 | N15: Cranky - Luvin' You [Alazy's Another] | O15: 4.74237 | P15: 160 | Q15: 0.0013541667 | R15: 6.5 | S15: 9.8 | T15: 9.8 | U15: avira0922 | V15: 37750
B16: https://osu.ppy.sh/beatmapsets/591635#osu/1251955 | C16: =IFERROR(__xludf.DUMMYFUNCTION("""COMPUTED_VALUE"""),1251955.0) -> 1251955 | D16: HD | E16: shironai14 | G16: M2U - Wicked Fate [LV.10] | H16: HD3 ar9 with hd2 gameplay | J16: alt flow | K16: 3248255 | L16: =IFERROR(__xludf.DUMMYFUNCTION("""COMPUTED_VALUE"""),"HR3") -> HR3 | N16: NICODE & M2U - Predawn [Mixagji's Insane] | O16: 4.87767 | P16: 140 | Q16: 0.0014236111 | R16: 5.2 | S16: 10 | T16: 10 | U16: Hishiro Chizuru | V16: 3248255
B17: https://osu.ppy.sh/beatmapsets/1186066#osu/2472143 | C17: =IFERROR(__xludf.DUMMYFUNCTION("""COMPUTED_VALUE"""),2472143.0) -> 2472143 | D17: FM | E17: shironai14 | G17: Self Deception - Weight Of The World [Insane] | H17: FM1 sliders aim | J17: double time modification one | K17: 674080 | L17: =IFERROR(__xludf.DUMMYFUNCTION("""COMPUTED_VALUE"""),"DT1") -> DT1 | N17: Reol - Asymmetry [pk's Hard] | O17: 5.0485 | P17: 276 | Q17: 0.0019135802 | R17: 4 | S17: 9.6666667 | T17: 8.4166667 | U17: Gaia | V17: 674080
B18: https://osu.ppy.sh/beatmapsets/1496234#osu/3221246 | C18: =IFERROR(__xludf.DUMMYFUNCTION("""COMPUTED_VALUE"""),3221246.0) -> 3221246 | D18: NM | E18: shironai14 | G18: tokiwa - wasurena feat. Sennzai [remembrance] | H18: NM4 banger song | J18: speed | K18: 3299370 | L18: =IFERROR(__xludf.DUMMYFUNCTION("""COMPUTED_VALUE"""),"DT2") -> DT2 | N18: -45 - System Sun [Hard] | O18: 4.96093 | P18: 228 | Q18: 0.0016975309 | R18: 4 | S18: 9.6666667 | T18: 9.0833333 | U18: Lasse | V18: 3299370
B19: https://osu.ppy.sh/beatmapsets/1855321#osu/3822120 | C19: =IFERROR(__xludf.DUMMYFUNCTION("""COMPUTED_VALUE"""),3822120.0) -> 3822120 | D19: HR | E19: shironai14 | G19: WAGAMAMA RAKIA - GR4VITY G4ME [LOG OFF B4NTER'S INS4NE] | H19: HR1 a bit speed with aim | J19: slider stuff | K19: 3822599 | L19: =IFERROR(__xludf.DUMMYFUNCTION("""COMPUTED_VALUE"""),"DT3") -> DT3 | N19: Nekomata Master+ - chaos eater -IIDX edition- [HARD] | O19: 4.91921 | P19: 315 | Q19: 0.00083333333 | R19: 3.5 | S19: 9.6666667 | T19: 8.4166667 | U19: pocket- | V19: 3822599
B20: https://osu.ppy.sh/beatmapsets/12469#osu/48215 | C20: =IFERROR(__xludf.DUMMYFUNCTION("""COMPUTED_VALUE"""),48215.0) -> 48215 | D20: HR | E20: shironai14 | G20: onoken - Quinine -A2D SIDE- [Lunatic] | H20: HR2 | J20: free modification one | K20: 3274886 | L20: =IFERROR(__xludf.DUMMYFUNCTION("""COMPUTED_VALUE"""),"FM1") -> FM1 | N20: Two Door Cinema Club - Cigarettes in the Theatre [Insane] | O20: 4.70593 | P20: 169 | Q20: 0.0021875 | R20: 4.2 | S20: 8.7 | T20: 8.2 | U20: entsetzen | V20: 3274886
B21: https://osu.ppy.sh/beatmapsets/1695872#osu/3616425 | C21: =IFERROR(__xludf.DUMMYFUNCTION("""COMPUTED_VALUE"""),3616425.0) -> 3616425 | D21: NM | E21: shironai14 | G21: BABYMETAL - Arkadia [Collab Expert] | H21: NM5 the map have 38 sec for skip in the beginning | J21: anti mod | K21: 3804111 | L21: =IFERROR(__xludf.DUMMYFUNCTION("""COMPUTED_VALUE"""),"FM2") -> FM2 | N21: Hiiragi Magnetite - Marshall Maximizer feat. KAFU [Hyper] | O21: 4.323 | P21: 190 | Q21: 0.0017824074 | R21: 5 | S21: 8 | T21: 7 | U21: Ixcors | V21: 3804111
B22: https://osu.ppy.sh/beatmapsets/1215814#osu/2532230 | C22: =IFERROR(__xludf.DUMMYFUNCTION("""COMPUTED_VALUE"""),2532230.0) -> 2532230 | D22: NM | E22: shironai14 | G22: BLANKFIELD - THE WORLD REVOLVING [Insane] | H22: more short nm5 | J22: hype tb | K22: 577517 | L22: =IFERROR(__xludf.DUMMYFUNCTION("""COMPUTED_VALUE"""),"TB1") -> TB1 | N22: Halozy - Genryuu Kaiko [Melody of Sanzu] | O22: 5.38366 | P22: 173 | Q22: 0.0034722222 | R22: 4 | S22: 9.2 | T22: 8 | U22: Mira-san | V22: 577517
B23: https://osu.ppy.sh/beatmapsets/1413965#osu/2986144 | C23: =IFERROR(__xludf.DUMMYFUNCTION("""COMPUTED_VALUE"""),2986144.0) -> 2986144 | D23: NM | E23: shironai14 | G23: Jibaku Shounen Band - No.7 [Stack's Insane] | H23: NM1 or HD1 second option
B24: https://osu.ppy.sh/beatmapsets/932901#osu/1975970 | C24: =IFERROR(__xludf.DUMMYFUNCTION("""COMPUTED_VALUE"""),1975970.0) -> 1975970 | D24: HD | E24: shironai14 | G24: Mili - Ga1ahad and Scientific Witchery [KKip's Insane] | H24: HD3 tapping
B25: https://osu.ppy.sh/beatmapsets/1847288#osu/3912466 | C25: =IFERROR(__xludf.DUMMYFUNCTION("""COMPUTED_VALUE"""),3912466.0) -> 3912466 | D25: NM | E25: shironai14 | G25: Mori Calliope - MERA MERA [frozz's Insane] | H25: vtuber nm3
B26: https://osu.ppy.sh/beatmapsets/756815#osu/1600995 | C26: =IFERROR(__xludf.DUMMYFUNCTION("""COMPUTED_VALUE"""),1600995.0) -> 1600995 | D26: NM | E26: shironai14 | G26: PUP - DVP [Lasse's Insane] | H26: NM3
B27: https://osu.ppy.sh/beatmaps/2800663 | C27: =IFERROR(__xludf.DUMMYFUNCTION("""COMPUTED_VALUE"""),2800663.0) -> 2800663 | D27: NM | E27: shironai14 | G27: Maison book girl - snow irony_ [deppy's insane_] | H27: NM6 NO
B28: https://osu.ppy.sh/beatmapsets/31480#osu/103476 | C28: =IFERROR(__xludf.DUMMYFUNCTION("""COMPUTED_VALUE"""),103476.0) -> 103476 | D28: HD | G28: Yuma Mizonokuchi - akasha-simulater [Insane] | H28: HD2
B29: https://osu.ppy.sh/beatmapsets/1880072#osu/3870932 | C29: =IFERROR(__xludf.DUMMYFUNCTION("""COMPUTED_VALUE"""),3870932.0) -> 3870932 | D29: NM | G29: Kikuo - Yousei no Kiri [Insane] | H29: nm6
D30: NM | H30: nm6
B31: https://osu.ppy.sh/beatmapsets/1888886#osu/3913591 | C31: =IFERROR(__xludf.DUMMYFUNCTION("""COMPUTED_VALUE"""),3913591.0) -> 3913591 | D31: HR | E31: play hd3 | G31: kessoku band - Guitar to Kodoku to Aoi Hoshi [kuuti's Insane]
B32: https://osu.ppy.sh/beatmapsets/292077#osu/674080 | C32: =IFERROR(__xludf.DUMMYFUNCTION("""COMPUTED_VALUE"""),674080.0) -> 674080 | D32: DT | E32: play hd3 | G32: Reol - Asymmetry [pk's Hard]
B33: https://osu.ppy.sh/beatmapsets/1207286#osu/2514122 | C33: =IFERROR(__xludf.DUMMYFUNCTION("""COMPUTED_VALUE"""),2514122.0) -> 2514122 | D33: FM | G33: Wagakki Band - Kagerou Days [Ducky-'s Insane]
B34: https://osu.ppy.sh/beatmapsets/1668789#osu/3407970 | C34: =IFERROR(__xludf.DUMMYFUNCTION("""COMPUTED_VALUE"""),3407970.0) -> 3407970 | D34: HR | G34: City Girl - L2M (feat. Kelsey Kuan) [Niva's Insane]
B35: https://osu.ppy.sh/beatmapsets/1415788#osu/2917786 | C35: =IFERROR(__xludf.DUMMYFUNCTION("""COMPUTED_VALUE"""),2917786.0) -> 2917786 | D35: HR | G35: Cro - Wie ich bin [Trust]
B36: https://osu.ppy.sh/beatmapsets/1181343#osu/2671048 | C36: =IFERROR(__xludf.DUMMYFUNCTION("""COMPUTED_VALUE"""),2671048.0) -> 2671048 | D36: HD | E36: play hd3 | G36: Usada Pekora - Discommunication Alien [Ayyken's Another]
B37: https://osu.ppy.sh/beatmapsets/20817#osu/74778 | C37: =IFERROR(__xludf.DUMMYFUNCTION("""COMPUTED_VALUE"""),74778.0) -> 74778 | D37: FM | G37: Megpoid GUMI - Mozaik Role [epa-]
B38: https://osu.ppy.sh/beatmapsets/1682134#osu/3530469 | C38: =IFERROR(__xludf.DUMMYFUNCTION("""COMPUTED_VALUE"""),3530469.0) -> 3530469 | D38: HD | G38: SHK - Halloween Party [Heilia's Insane]
B39: https://osu.ppy.sh/beatmapsets/699749#osu/1491793 | C39: =IFERROR(__xludf.DUMMYFUNCTION("""COMPUTED_VALUE"""),1491793.0) -> 1491793 | D39: HD | E39: play hd3 | G39: succducc - me & u [sing's insane]
B40: https://osu.ppy.sh/beatmapsets/1574603#osu/3291796 | C40: =IFERROR(__xludf.DUMMYFUNCTION("""COMPUTED_VALUE"""),3291796.0) -> 3291796 | D40: NM | G40: VeetaCrush - Mole [Kyutei's Insane]
...

Sheet SF
B2: Semifinals | C2: Best of | D2: =IFERROR(VLOOKUP(B2,Settings!E3:H12,3,0),"") -> 11 | E2: Bans | F2: =IFERROR(VLOOKUP(B2,Settings!E3:H12,4,0),"") -> 2
B3: Suggestions | J3: Pool Assembly
B4: Map Link | C4: ID | D4: Mod | E4: Suggestor | F4: Map | H4: Notes | J4: Note | K4: ID | L4: Mod | M4: Map | O4: SR | P4: BPM | Q4: Length | R4: CS | S4: AR | T4: OD | U4: Mapper | V4: ID
B5: https://osu.ppy.sh/beatmapsets/663255#osu/1405094 | C5: =IFERROR(__xludf.DUMMYFUNCTION("ArrayFormula(IFERROR(VALUE(REGEXEXTRACT(B5:B104&"""",""\d+$""))))"),1405094.0) -> 1405094 | D5: HR | E5: yillow | F5: {=MAP(C5:C104,LAMBDA(id,IFNA(IMAGE(MAPDATA(id,"cover_url")),"")))} | G5: {=IFNA(HYPERLINK(VLOOKUP(C5:C104,'_api'!B3:BC104,MATCH("url",'_api'!B2:W2,0),0),VLOOKUP(C5:C104,'_api'!B3:BC104,MATCH("string",'_api'!B2:W2,0),0)),"")} -> Camellia - Routing [Another] | H5: hr3 | J5: nanahira | K5: 1717844 | L5: =IFERROR(__xludf.DUMMYFUNCTION("TRANSPOSE(SPLIT(JOIN("","",MAP(TRANSPOSE(Settings!I2:P2),TRANSPOSE(INDEX(Settings!I3:P12,MATCH(B2,Settings!E3:E12,0))),LAMBDA(mod,n,JOIN("","",ARRAYFORMULA(IF(n=0,"""",mod&SEQUENCE(n))))))),"",""))"),"NM1") -> NM1 | M5: {=MAP(K5:K104,LAMBDA(id,IFNA(IMAGE(MAPDATA(id,"cover_url")),"")))} | N5: =IFNA(MAPDATA(K5:K104,"string_url"),"") -> t+pazolite - Party in the HOLLOWood feat. Nanahira [INSane] | O5: {=IFNA(MAPDATA_MODDED(K5:K104,{"difficultyrating","bpm","hit_length"},L5:L104),"")} -> 5.37201 | P5: 178 | Q5: 0.0026041667 | R5: {=IFNA(MAPDATA_MODDED(K5:K104,"diff_"&{"size","approach","overall"},L5:L104),"")} -> 4 | S5: 9 | T5: 8 | U5: {=IFNA(MAPDATA(K5:K104,{"creator","beatmap_id"}),"")} -> eiri- | V5: 1717844
B6: https://osu.ppy.sh/beatmapsets/1763440#osu/3841174 | C6: =IFERROR(__xludf.DUMMYFUNCTION("""COMPUTED_VALUE"""),3841174.0) -> 3841174 | D6: HR | E6: play hd3 | G6: Pmarusama. - S'il vous President [Teages's Insane] | I6: c | J6: long streams | K6: 3656173 | L6: =IFERROR(__xludf.DUMMYFUNCTION("""COMPUTED_VALUE"""),"NM2") -> NM2 | N6: GIVEON - Favourite Mistake [Halogenix Edit] [Insane] | O6: 5.19532 | P6: 172 | Q6: 0.0015740741 | R6: 4 | S6: 9.1 | T6: 8 | U6: quantumvortex | V6: 3656173
B7: https://osu.ppy.sh/beatmapsets/315299#osu/703042 | C7: =IFERROR(__xludf.DUMMYFUNCTION("""COMPUTED_VALUE"""),703042.0) -> 703042 | D7: HR | E7: yillow | G7: Rita - Dream Walker [Quilt's Insane] | H7: hr1 - consistency + streams | J7: aim alt | K7: 2715749 | L7: =IFERROR(__xludf.DUMMYFUNCTION("""COMPUTED_VALUE"""),"NM3") -> NM3 | N7: ALI - Wild Side [Squilly's Insane] | O7: 5.03898 | P7: 134 | Q7: 0.0016550926 | R7: 3 | S7: 9.2 | T7: 8 | U7: fieryrage | V7: 2715749
B8: 2514122 | C8: =IFERROR(__xludf.DUMMYFUNCTION("""COMPUTED_VALUE"""),2514122.0) -> 2514122 | D8: FM | E8: play hd3 | G8: Wagakki Band - Kagerou Days [Ducky-'s Insane] | J8: long sliders | K8: 3291796 | L8: =IFERROR(__xludf.DUMMYFUNCTION("""COMPUTED_VALUE"""),"NM4") -> NM4 | N8: VeetaCrush - Mole [Kyutei's Insane] | O8: 4.70195 | P8: 172 | Q8: 0.0015625 | R8: 3.8 | S8: 9 | T8: 8.6 | U8: JeZag | V8: 3291796
B9: https://osu.ppy.sh/beatmapsets/1659194#osu/3399446 | C9: =IFERROR(__xludf.DUMMYFUNCTION("""COMPUTED_VALUE"""),3399446.0) -> 3399446 | D9: HD | E9: yillow | G9: Yooh - Heracles [Another] | H9: hd3 | J9: speed | K9: 3187491 | L9: =IFERROR(__xludf.DUMMYFUNCTION("""COMPUTED_VALUE"""),"NM5") -> NM5 | N9: Camellia - Killerbeast [Spiritual] | O9: 5.1866 | P9: 220 | Q9: 0.0024537037 | R9: 3.8 | S9: 9.2 | T9: 8 | U9: Subokuu | V9: 3187491
B10: https://osu.ppy.sh/beatmapsets/1140943#osu/2383229 | C10: =IFERROR(__xludf.DUMMYFUNCTION("""COMPUTED_VALUE"""),2383229.0) -> 2383229 | D10: HD | E10: yillow | G10: aran - Sunny After Rain [feat. Kanata.N] [Rainbow] | H10: hd3 | J10: ar7 stop and go | K10: 3990086 | L10: =IFERROR(__xludf.DUMMYFUNCTION("""COMPUTED_VALUE"""),"NM6") -> NM6 | N10: Kai - Junk Lady [Deppy and Wanpachi's Insane] | O10: 4.56568 | P10: 174 | Q10: 0.0013657407 | R10: 3.8 | S10: 7 | T10: 7 | U10: Deppyforce | V10: 3990086
B11: https://osu.ppy.sh/beatmapsets/927758#osu/1972425 | C11: =IFERROR(__xludf.DUMMYFUNCTION("""COMPUTED_VALUE"""),1972425.0) -> 1972425 | D11: HD | E11: yillow | G11: Aso Natsuko - Perfect-area complete! [Asuka_-'s Insane] | H11: hd1 | J11: anti aim | K11: 1972425 | L11: =IFERROR(__xludf.DUMMYFUNCTION("""COMPUTED_VALUE"""),"HD1") -> HD1 | N11: Aso Natsuko - Perfect-area complete! [Asuka_-'s Insane] | O11: 5.21311 | P11: 183 | Q11: 0.0024537037 | R11: 3.7 | S11: 9.3 | T11: 8 | U11: gary00737 | V11: 1972425
B12: https://osu.ppy.sh/beatmapsets/1574603#osu/3291796 | C12: =IFERROR(__xludf.DUMMYFUNCTION("""COMPUTED_VALUE"""),3291796.0) -> 3291796 | D12: NM | G12: VeetaCrush - Mole [Kyutei's Insane] | H12: nm4 | J12: ar8 | K12: 2277128 | L12: =IFERROR(__xludf.DUMMYFUNCTION("""COMPUTED_VALUE"""),"HD2") -> HD2 | N12: Kola Kid - timer [Insane] | O12: 4.71265 | P12: 180 | Q12: 0.0013657407 | R12: 4 | S12: 8 | T12: 7 | U12: Mirash | V12: 2277128
B13: https://osu.ppy.sh/beatmapsets/1785134#osu/3656173 | C13: =IFERROR(__xludf.DUMMYFUNCTION("""COMPUTED_VALUE"""),3656173.0) -> 3656173 | D13: NM | G13: GIVEON - Favourite Mistake [Halogenix Edit] [Insane] | J13: light tech | K13: 2044890 | L13: =IFERROR(__xludf.DUMMYFUNCTION("""COMPUTED_VALUE"""),"HD3") -> HD3 | N13: YUC'e - POISON -KO3 Remix- [Insane] | O13: 5.03191 | P13: 170 | Q13: 0.0022222222 | R13: 3.8 | S13: 9.1 | T13: 8 | U13: JrSzZ | V13: 2044890
B14: https://osu.ppy.sh/beatmapsets/1436167#osu/2992124 | C14: =IFERROR(__xludf.DUMMYFUNCTION("""COMPUTED_VALUE"""),2992124.0) -> 2992124 | D14: NM | G14: BPM15Q - Go Shoot! [Melo's Insane] | J14: slider consistency | K14: 3454421 | L14: =IFERROR(__xludf.DUMMYFUNCTION("""COMPUTED_VALUE"""),"HR1") -> HR1 | N14: Harumaki Gohan feat. Hatsune Miku - Hotaru wa Inakatta [Kuse's Insane] | O14: 5.19533 | P14: 206 | Q14: 0.0023148148 | R14: 5.2 | S14: 10 | T14: 10 | U14: Irin | V14: 3454421
B15: https://osu.ppy.sh/beatmapsets/1871920#osu/3986899 | C15: =IFERROR(__xludf.DUMMYFUNCTION("""COMPUTED_VALUE"""),3986899.0) -> 3986899 | D15: NM | G15: ZAQ - Dance In The Game [Light's Insane] | J15: 1/3rd cs6.5 | K15: 2917786 | L15: =IFERROR(__xludf.DUMMYFUNCTION("""COMPUTED_VALUE"""),"HR2") -> HR2 | N15: Cro - Wie ich bin [Trust] | O15: 4.85907 | P15: 130 | Q15: 0.0019791667 | R15: 6.5 | S15: 10 | T15: 10 | U15: Cacturne | V15: 2917786
B16: https://osu.ppy.sh/beatmapsets/1030737#osu/2200110 | C16: =IFERROR(__xludf.DUMMYFUNCTION("""COMPUTED_VALUE"""),2200110.0) -> 2200110 | D16: NM | G16: Irreversible Mechanism - Cold Winds [Insane] | J16: alt | K16: 1405094 | L16: =IFERROR(__xludf.DUMMYFUNCTION("""COMPUTED_VALUE"""),"HR3") -> HR3 | N16: Camellia - Routing [Another] | O16: 5.0835 | P16: 144 | Q16: 0.0012731481 | R16: 4.55 | S16: 10 | T16: 10 | U16: Mir | V16: 1405094
B17: https://osu.ppy.sh/beatmapsets/1901819#osu/3990086 | C17: =IFERROR(__xludf.DUMMYFUNCTION("""COMPUTED_VALUE"""),3990086.0) -> 3990086 | D17: NM | G17: Kai - Junk Lady [Deppy and Wanpachi's Insane] | J17: consistency | K17: 1592512 | L17: =IFERROR(__xludf.DUMMYFUNCTION("""COMPUTED_VALUE"""),"DT1") -> DT1 | N17: 96neko - Primitive emotion [Hard] | O17: 5.31524 | P17: 285 | Q17: 0.0016126543 | R17: 4 | S17: 9.6666667 | T17: 8.75 | U17: Lasse | V17: 1592512
B18: https://osu.ppy.sh/beatmapsets/1283387#osu/2666261 | C18: =IFERROR(__xludf.DUMMYFUNCTION("""COMPUTED_VALUE"""),2666261.0) -> 2666261 | D18: HD | G18: Akatsuki Records - KARMANATIONS [Insane] | J18: bursts | K18: 2388648 | L18: =IFERROR(__xludf.DUMMYFUNCTION("""COMPUTED_VALUE"""),"DT2") -> DT2 | N18: umu. - Dareka no Shinzou ni Nareta Nara [Hard] | O18: 5.127 | P18: 217.5 | Q18: 0.0016975309 | R18: 3.8 | S18: 9.6666667 | T18: 9.0833333 | U18: xbopost | V18: 2388648
B19: https://osu.ppy.sh/beatmapsets/25802#osu/87369 | C19: =IFERROR(__xludf.DUMMYFUNCTION("""COMPUTED_VALUE"""),87369.0) -> 87369 | D19: HD | G19: Hatsune Miku - Netoge Haijin Sprechchor [Insane] | J19: finger control | K19: 3819183 | L19: =IFERROR(__xludf.DUMMYFUNCTION("""COMPUTED_VALUE"""),"DT3") -> DT3 | N19: AAAA + Umeboshi Chazuke - Cait Sith [Setu's Hard] | O19: 5.16896 | P19: 255 | Q19: 0.0013503086 | R19: 3.5 | S19: 9.6666667 | T19: 8.4166667 | U19: bob | V19: 3819183
B20: https://osu.ppy.sh/beatmapsets/295225#osu/667685 | C20: =IFERROR(__xludf.DUMMYFUNCTION("""COMPUTED_VALUE"""),667685.0) -> 667685 | D20: HR | G20: Reol - Plus Danshi ver Reol [Lunatic] | J20: perfect stacks | K20: 2514122 | L20: =IFERROR(__xludf.DUMMYFUNCTION("""COMPUTED_VALUE"""),"FM1") -> FM1 | N20: Wagakki Band - Kagerou Days [Ducky-'s Insane] | O20: 4.95233 | P20: 200 | Q20: 0.0025810185 | R20: 3 | S20: 9 | T20: 8 | U20: IOException | V20: 2514122
B21: https://osu.ppy.sh/beatmapsets/853045#osu/1782851 | C21: =IFERROR(__xludf.DUMMYFUNCTION("""COMPUTED_VALUE"""),1782851.0) -> 1782851 | D21: HR | G21: Kajiura Yuki - Pugna cum maga [Insane] | J21: finger control | K21: 28366 | L21: =IFERROR(__xludf.DUMMYFUNCTION("""COMPUTED_VALUE"""),"FM2") -> FM2 | N21: Brandy - Cross Time !! [DJPop Mix] | O21: 4.71486 | P21: 160 | Q21: 0.0016203704 | R21: 5 | S21: 8 | T21: 8 | U21: buraimaster1234 | V21: 28366
B22: https://osu.ppy.sh/beatmapsets/755512#osu/1592512 | C22: =IFERROR(__xludf.DUMMYFUNCTION("""COMPUTED_VALUE"""),1592512.0) -> 1592512 | D22: DT | G22: 96neko - Primitive emotion [Hard] | J22: banger | K22: 1248147 | L22: =IFERROR(__xludf.DUMMYFUNCTION("""COMPUTED_VALUE"""),"TB1") -> TB1 | N22: Camellia - EXiT this Earths Atomosphere [Astral] | O22: 5.47932 | P22: 170 | Q22: 0.0035648148 | R22: 4 | S22: 9.4 | T22: 8 | U22: DWShin | V22: 1248147
B23: https://osu.ppy.sh/beatmapsets/1848926#osu/3819183 | C23: =IFERROR(__xludf.DUMMYFUNCTION("""COMPUTED_VALUE"""),3819183.0) -> 3819183 | D23: DT | G23: AAAA + Umeboshi Chazuke - Cait Sith [Setu's Hard]
B24: https://osu.ppy.sh/beatmapsets/1272023#osu/2643263 | C24: =IFERROR(__xludf.DUMMYFUNCTION("""COMPUTED_VALUE"""),2643263.0) -> 2643263 | D24: FM | G24: Shawn Wasabi - LEMONS feat. kennedi [lemonade]
B25: https://osu.ppy.sh/beatmapsets/663220#osu/1403845 | C25: =IFERROR(__xludf.DUMMYFUNCTION("""COMPUTED_VALUE"""),1403845.0) -> 1403845 | G25: HyperJuice - City Lights feat. EVO+, Jinmenusagi (Zekk Remix) [C00L & Yamicchi's Another]
B26: https://osu.ppy.sh/beatmapsets/1391326#osu/2872861 | C26: =IFERROR(__xludf.DUMMYFUNCTION("""COMPUTED_VALUE"""),2872861.0) -> 2872861 | D26: HD | G26: Rude-a - Paradise [Lobelia's Insane]
