Workbook
Name Scoremode: 'Qualifiers settings'!$C$7
Name TeamList: 'Ref & Team list'!$C$3:$F$36
Name Gamemode: 'Qualifiers settings'!$C$5
Name TourneyAbb: 'Qualifiers settings'!$C$3

Sheet Qualifiers settings
B2: Tournament Name | C2: Pekonya Trinity Encounters
B3: Tournament Abbereviation | C3: PTE
B4: Scoremode | C4: 0
B5: Gamemode | C5: 3
B6: No. of players max in lobby | C6: 15
B8: Use NF | C8: TRUE
B10: Forum Post Link | C10: https://osu.ppy.sh/community/forums/topics/1790898?n=1?
B11: Mainsheet Link | C11: https://docs.google.com/spreadsheets/d/1u1R-0YeX71qksHP7hWq8QkjcpECX-9LSvskalZ8hxdg/edit?usp=sharing
B13: Time preparing for each map | C13: 90
B14: Start countdown time | C14: 10

Sheet Not to use qual template
E2: QUALIFIERS SCHEDULES | M2: ="TEAMS SCHEDULED : " & COUNTIF(J5:N36,"*") -> TEAMS SCHEDULED : 3
H3: UTC+0
E4: Lobby | F4: Slots taken | G4: Date | H4: Time | I4: Referee | J4: Team 1 | K4: Team 2 | L4: Team 3 | M4: Team 4 | N4: Team 5 | O4: MP LINK
C5: Saturday | E5: A1 | F5: =IF(COUNTIF(J5:N5,"*") = 0, "-", COUNTIF(J5:N5,"*") &" / 15") -> 3 / 15 | G5: 44618 | H5: 0 | I5: -PeKora- | J5: sane players | K5: EG | L5: Fnatic
E6: A2 | F6: =IF(COUNTIF(J6:N6,"*") = 0, "-", COUNTIF(J6:N6,"*") &" / 15") -> - | G6: 44618 | H6: 0.083333333
E7: A3 | F7: =IF(COUNTIF(J7:N7,"*") = 0, "-", COUNTIF(J7:N7,"*") &" / 15") -> - | G7: 44618 | H7: 0.16666667
E8: A4 | F8: =IF(COUNTIF(J8:N8,"*") = 0, "-", COUNTIF(J8:N8,"*") &" / 15") -> - | G8: 44618 | H8: 0.25
E9: A5 | F9: =IF(COUNTIF(J9:N9,"*") = 0, "-", COUNTIF(J9:N9,"*") &" / 15") -> - | H9: 0.5
E10: A6 | F10: =IF(COUNTIF(J10:N10,"*") = 0, "-", COUNTIF(J10:N10,"*") &" / 15") -> - | H10: 0.58333333
E11: A7 | F11: =IF(COUNTIF(J11:N11,"*") = 0, "-", COUNTIF(J11:N11,"*") &" / 15") -> - | H11: 0.66666667
E12: A8 | F12: =IF(COUNTIF(J12:N12,"*") = 0, "-", COUNTIF(J12:N12,"*") &" / 15") -> - | H12: 0.75
E13: A9 | F13: =IF(COUNTIF(J13:N13,"*") = 0, "-", COUNTIF(J13:N13,"*") &" / 15") -> - | H13: 0.875
E14: A10 | F14: =IF(COUNTIF(J14:N14,"*") = 0, "-", COUNTIF(J14:N14,"*") &" / 15") -> - | H14: 0.99930556
C16: Sunday | E16: B1 | F16: =IF(COUNTIF(J16:N16,"*") = 0, "-", COUNTIF(J16:N16,"*") &" / 15") -> - | H16: 0
E17: B2 | F17: =IF(COUNTIF(J17:N17,"*") = 0, "-", COUNTIF(J17:N17,"*") &" / 15") -> - | H17: 0.083333333
E18: B3 | F18: =IF(COUNTIF(J18:N18,"*") = 0, "-", COUNTIF(J18:N18,"*") &" / 15") -> - | H18: 0.16666667
E19: B4 | F19: =IF(COUNTIF(J19:N19,"*") = 0, "-", COUNTIF(J19:N19,"*") &" / 15") -> - | H19: 0.25
E20: B5 | F20: =IF(COUNTIF(J20:N20,"*") = 0, "-", COUNTIF(J20:N20,"*") &" / 15") -> - | H20: 0.5
E21: B6 | F21: =IF(COUNTIF(J21:N21,"*") = 0, "-", COUNTIF(J21:N21,"*") &" / 15") -> - | H21: 0.58333333
E22: B7 | F22: =IF(COUNTIF(J22:N22,"*") = 0, "-", COUNTIF(J22:N22,"*") &" / 15") -> - | H22: 0.66666667
E23: B8 | F23: =IF(COUNTIF(J23:N23,"*") = 0, "-", COUNTIF(J23:N23,"*") &" / 15") -> - | H23: 0.75
E24: B9 | F24: =IF(COUNTIF(J24:N24,"*") = 0, "-", COUNTIF(J24:N24,"*") &" / 15") -> - | H24: 0.875
E25: B10 | F25: =IF(COUNTIF(J25:N25,"*") = 0, "-", COUNTIF(J25:N25,"*") &" / 15") -> - | H25: 0.99930556
C27: Custom Lobbies | E27: X1 | F27: =IF(COUNTIF(J27:N27,"*") = 0, "-", COUNTIF(J27:N27,"*") &" / 15") -> -
E28: X2 | F28: =IF(COUNTIF(J28:N28,"*") = 0, "-", COUNTIF(J28:N28,"*") &" / 15") -> -
E29: X3 | F29: =IF(COUNTIF(J29:N29,"*") = 0, "-", COUNTIF(J29:N29,"*") &" / 15") -> -
E30: X4 | F30: =IF(COUNTIF(J30:N30,"*") = 0, "-", COUNTIF(J30:N30,"*") &" / 15") -> -
E31: X5 | F31: =IF(COUNTIF(J31:N31,"*") = 0, "-", COUNTIF(J31:N31,"*") &" / 15") -> -
E32: X6 | F32: =IF(COUNTIF(J32:N32,"*") = 0, "-", COUNTIF(J32:N32,"*") &" / 15") -> -
E33: X7 | F33: =IF(COUNTIF(J33:N33,"*") = 0, "-", COUNTIF(J33:N33,"*") &" / 15") -> -
E34: X8 | F34: =IF(COUNTIF(J34:N34,"*") = 0, "-", COUNTIF(J34:N34,"*") &" / 15") -> -
E35: X9 | F35: =IF(COUNTIF(J35:N35,"*") = 0, "-", COUNTIF(J35:N35,"*") &" / 15") -> -
E36: X10 | F36: =IF(COUNTIF(J36:N36,"*") = 0, "-", COUNTIF(J36:N36,"*") &" / 15") -> -

Sheet - - - - -

Sheet Qualifiers Pool
D2: Mod# | E2: Song | F2: BeatmapID | H2: Beatmap String | I2: Map Command | J2: Mod Command
B3: Qualifier Pool | C3: {=MOD(SEQUENCE(9*25,1)-1,25)+1} -> 1 | D3: NM1 | E3: nonoc - Relive [Insane] | F3: 3924030 | H3: {=IF(D3:D177="","",HYPERLINK("https://osu.ppy.sh/b/"&F3:F177,D3:D177&": "&E3:E177))} -> NM1: nonoc - Relive [Insane] | I3: {=IF(F3:F177="","","!mp map "&F3:F177)} -> !mp map 3924030 | J3: {=IF(D3:D228="","","!mp mods "&IF(LEFT(D3:D177,2)="NM","NF",IF(LEFT(D3:D177,2)="FM","FreeMod",IF(LEFT(D3:D177,2)="TB","FreeMod",LEFT(D3:D177,2)&" NF"))))} -> !mp mods NF
C4: 2 | D4: NM2 | E4: void - Crisscrosser [Insane] | F4: 908887 | H4: NM2: void - Crisscrosser [Insane] | I4: !mp map 908887 | J4: !mp mods NF
C5: 3 | D5: NM3 | E5: Sangatsu no Phantasia - Koufuku na Wagamama [Insane] | F5: 3035501 | H5: NM3: Sangatsu no Phantasia - Koufuku na Wagamama [Insane] | I5: !mp map 3035501 | J5: !mp mods NF
C6: 4 | D6: NM4 | E6: PSYQUI - Education [sorciere's Insane] | F6: 3737825 | H6: NM4: PSYQUI - Education [sorciere's Insane] | I6: !mp map 3737825 | J6: !mp mods NF
C7: 5 | D7: HD1 | E7: Ax feat. Natsukawa Yoko - Sakimori Renka [Insane] | F7: 2094462 | H7: HD1: Ax feat. Natsukawa Yoko - Sakimori Renka [Insane] | I7: !mp map 2094462 | J7: !mp mods HD NF
C8: 6 | D8: HD2 | E8: Amane - BOOZEHOUND [Down's Insane] | F8: 2619929 | H8: HD2: Amane - BOOZEHOUND [Down's Insane] | I8: !mp map 2619929 | J8: !mp mods HD NF
C9: 7 | D9: HR1 | E9: THE ORAL CIGARETTES - Wagamama de Gomakasanaide [Panda & Melwoine's Insane] | F9: 2027623 | H9: HR1: THE ORAL CIGARETTES - Wagamama de Gomakasanaide [Panda & Melwoine's Insane] | I9: !mp map 2027623 | J9: !mp mods HR NF
C10: 8 | D10: HR2 | E10: Kajiura Yuki - Sis puella magica! [Tea Party] | F10: 1523138 | H10: HR2: Kajiura Yuki - Sis puella magica! [Tea Party] | I10: !mp map 1523138 | J10: !mp mods HR NF
C11: 9 | D11: DT1 | E11: ICHIKO - YOU'RE THE ONE [ANDREA & ASUKO'S HARD] | F11: 4105349 | H11: DT1: ICHIKO - YOU'RE THE ONE [ANDREA & ASUKO'S HARD] | I11: !mp map 4105349 | J11: !mp mods DT NF
C12: 10 | D12: DT2 | E12: DIANA - Beethoven Virus [Aranel's Hard] | F12: 3533589 | H12: DT2: DIANA - Beethoven Virus [Aranel's Hard] | I12: !mp map 3533589 | J12: !mp mods DT NF
C13: 11
C14: 12
C15: 13
C16: 14
C17: 15
C18: 16
C19: 17
C20: 18
C21: 19
C22: 20
C23: 21
C24: 22
... C27: 25
B28: Round of 64 | C28: 1
C29: 2
C30: 3
C31: 4
C32: 5
C33: 6
C34: 7
C35: 8
C36: 9
C37: 10
C38: 11
C39: 12
C40: 13
... C52: 25
B53: Round of 32 | C53: 1
C54: 2
...

Sheet Ref & Team list
B2: Referees | C2: Team Name | D2: {="Player "&SEQUENCE(1,3)} -> Player 1 | E2: Player 2 | F2: Player 3
B3: play hd3 | C3: =IFERROR(__xludf.DUMMYFUNCTION("IMPORTRANGE(""1HHAHmZTTDlyB4RHaHQ-2bhUchkHOEZhmcQrDYQXnxnw"",""filter_teams!B3:B65"")"),"PoorQuaIityMeatpilow") -> PoorQuaIityMeatpilow | D3: =IFERROR(__xludf.DUMMYFUNCTION("IMPORTRANGE(""1HHAHmZTTDlyB4RHaHQ-2bhUchkHOEZhmcQrDYQXnxnw"",""filter_teams!D3:D65"")"),"PoorQuaIityMeat") -> PoorQuaIityMeat | E3: =IFERROR(__xludf.DUMMYFUNCTION("IMPORTRANGE(""1HHAHmZTTDlyB4RHaHQ-2bhUchkHOEZhmcQrDYQXnxnw"",""filter_teams!J3:J65"")"),"Pilllow") -> Pilllow | F3: =IFERROR(__xludf.DUMMYFUNCTION("IMPORTRANGE(""1HHAHmZTTDlyB4RHaHQ-2bhUchkHOEZhmcQrDYQXnxnw"",""filter_teams!P3:P65"")"),"")
B4: Sedi | C4: =IFERROR(__xludf.DUMMYFUNCTION("""COMPUTED_VALUE"""),"Sightread Buff") -> Sightread Buff | D4: =IFERROR(__xludf.DUMMYFUNCTION("""COMPUTED_VALUE"""),"O_re_O") -> O_re_O | E4: =IFERROR(__xludf.DUMMYFUNCTION("""COMPUTED_VALUE"""),"depict1") -> depict1 | F4: =IFERROR(__xludf.DUMMYFUNCTION("""COMPUTED_VALUE"""),"NemiTrailRider") -> NemiTrailRider
B5: Pischok | C5: =IFERROR(__xludf.DUMMYFUNCTION("""COMPUTED_VALUE"""),"Ghost the Angel") -> Ghost the Angel | D5: =IFERROR(__xludf.DUMMYFUNCTION("""COMPUTED_VALUE"""),"BCraftMG") -> BCraftMG | E5: =IFERROR(__xludf.DUMMYFUNCTION("""COMPUTED_VALUE"""),"Lugost Angel") -> Lugost Angel | F5: =IFERROR(__xludf.DUMMYFUNCTION("""COMPUTED_VALUE"""),"quay4") -> quay4
B6: I hate EZ | C6: =IFERROR(__xludf.DUMMYFUNCTION("""COMPUTED_VALUE"""),"foxy1919191919's basement") -> foxy1919191919's basement | D6: =IFERROR(__xludf.DUMMYFUNCTION("""COMPUTED_VALUE"""),"Faceie") -> Faceie | E6: =IFERROR(__xludf.DUMMYFUNCTION("""COMPUTED_VALUE"""),"Flare_Drake") -> Flare_Drake | F6: =IFERROR(__xludf.DUMMYFUNCTION("""COMPUTED_VALUE"""),"vortexta") -> vortexta
B7: good girl | C7: =IFERROR(__xludf.DUMMYFUNCTION("""COMPUTED_VALUE"""),"Lovers + 3rd wheel") -> Lovers + 3rd wheel | D7: =IFERROR(__xludf.DUMMYFUNCTION("""COMPUTED_VALUE"""),"TeddyFine") -> TeddyFine | E7: =IFERROR(__xludf.DUMMYFUNCTION("""COMPUTED_VALUE"""),"Entro") -> Entro | F7: =IFERROR(__xludf.DUMMYFUNCTION("""COMPUTED_VALUE"""),"BubblyQT") -> BubblyQT
B8: Meiling Hong | C8: =IFERROR(__xludf.DUMMYFUNCTION("""COMPUTED_VALUE"""),"copium abusers") -> copium abusers | D8: =IFERROR(__xludf.DUMMYFUNCTION("""COMPUTED_VALUE"""),"PapaAinsley") -> PapaAinsley | E8: =IFERROR(__xludf.DUMMYFUNCTION("""COMPUTED_VALUE"""),"Josiper") -> Josiper
B9: RudderFish07 | C9: =IFERROR(__xludf.DUMMYFUNCTION("""COMPUTED_VALUE"""),"The One 100s") -> The One 100s | D9: =IFERROR(__xludf.DUMMYFUNCTION("""COMPUTED_VALUE"""),"Ugetora") -> Ugetora | E9: =IFERROR(__xludf.DUMMYFUNCTION("""COMPUTED_VALUE"""),"Zeon_beyond") -> Zeon_beyond | F9: =IFERROR(__xludf.DUMMYFUNCTION("""COMPUTED_VALUE"""),"bunnytoro") -> bunnytoro
B10: ShiruoX | C10: =IFERROR(__xludf.DUMMYFUNCTION("""COMPUTED_VALUE"""),"Nameless Waifulovers") -> Nameless Waifulovers | D10: =IFERROR(__xludf.DUMMYFUNCTION("""COMPUTED_VALUE"""),"Feroshi") -> Feroshi | E10: =IFERROR(__xludf.DUMMYFUNCTION("""COMPUTED_VALUE"""),"Scaly007") -> Scaly007 | F10: =IFERROR(__xludf.DUMMYFUNCTION("""COMPUTED_VALUE"""),"yunasky") -> yunasky
B11: Lunexia | C11: =IFERROR(__xludf.DUMMYFUNCTION("""COMPUTED_VALUE"""),"noodle team") -> noodle team | D11: =IFERROR(__xludf.DUMMYFUNCTION("""COMPUTED_VALUE"""),"Lowuki") -> Lowuki | E11: =IFERROR(__xludf.DUMMYFUNCTION("""COMPUTED_VALUE"""),"Kuw") -> Kuw
B12: Ninja Mejster | C12: =IFERROR(__xludf.DUMMYFUNCTION("""COMPUTED_VALUE"""),"Ahjin") -> Ahjin | D12: =IFERROR(__xludf.DUMMYFUNCTION("""COMPUTED_VALUE"""),"TzJake") -> TzJake | E12: =IFERROR(__xludf.DUMMYFUNCTION("""COMPUTED_VALUE"""),"rafaeldel7") -> rafaeldel7 | F12: =IFERROR(__xludf.DUMMYFUNCTION("""COMPUTED_VALUE"""),"-Darklune-") -> -Darklune-
B13: YaeMyMommy | C13: =IFERROR(__xludf.DUMMYFUNCTION("""COMPUTED_VALUE"""),"PES E9L9") -> PES E9L9 | D13: =IFERROR(__xludf.DUMMYFUNCTION("""COMPUTED_VALUE"""),"Kochindera") -> Kochindera | E13: =IFERROR(__xludf.DUMMYFUNCTION("""COMPUTED_VALUE"""),"Hoshifurii") -> Hoshifurii | F13: =IFERROR(__xludf.DUMMYFUNCTION("""COMPUTED_VALUE"""),"Gamillie") -> Gamillie
B14: Joon Yorigami | C14: =IFERROR(__xludf.DUMMYFUNCTION("""COMPUTED_VALUE"""),"phony :)") -> phony :) | D14: =IFERROR(__xludf.DUMMYFUNCTION("""COMPUTED_VALUE"""),"AZKi") -> AZKi | E14: =IFERROR(__xludf.DUMMYFUNCTION("""COMPUTED_VALUE"""),"SomeLongName") -> SomeLongName
B15: euouae_ | C15: =IFERROR(__xludf.DUMMYFUNCTION("""COMPUTED_VALUE"""),"BOCCHER") -> BOCCHER | D15: =IFERROR(__xludf.DUMMYFUNCTION("""COMPUTED_VALUE"""),"SkyprimeLp") -> SkyprimeLp | E15: =IFERROR(__xludf.DUMMYFUNCTION("""COMPUTED_VALUE"""),"Knax") -> Knax | F15: =IFERROR(__xludf.DUMMYFUNCTION("""COMPUTED_VALUE"""),"uhzyk") -> uhzyk
B16: Flare_Drake | C16: =IFERROR(__xludf.DUMMYFUNCTION("""COMPUTED_VALUE"""),"Mewo My Waifu") -> Mewo My Waifu | D16: =IFERROR(__xludf.DUMMYFUNCTION("""COMPUTED_VALUE"""),"Mewo_") -> Mewo_ | E16: =IFERROR(__xludf.DUMMYFUNCTION("""COMPUTED_VALUE"""),"Zertoaster") -> Zertoaster | F16: =IFERROR(__xludf.DUMMYFUNCTION("""COMPUTED_VALUE"""),"Lol3270") -> Lol3270
B17: Mewo_ | C17: =IFERROR(__xludf.DUMMYFUNCTION("""COMPUTED_VALUE"""),"Beancurd") -> Beancurd | D17: =IFERROR(__xludf.DUMMYFUNCTION("""COMPUTED_VALUE"""),"Tsekyro") -> Tsekyro | E17: =IFERROR(__xludf.DUMMYFUNCTION("""COMPUTED_VALUE"""),"GeneralMayo") -> GeneralMayo | F17: =IFERROR(__xludf.DUMMYFUNCTION("""COMPUTED_VALUE"""),"Carsoon") -> Carsoon
B18: Bo_Bandy | C18: =IFERROR(__xludf.DUMMYFUNCTION("""COMPUTED_VALUE"""),"Koteykaaa team") -> Koteykaaa team | D18: =IFERROR(__xludf.DUMMYFUNCTION("""COMPUTED_VALUE"""),"Aria Holmes") -> Aria Holmes | E18: =IFERROR(__xludf.DUMMYFUNCTION("""COMPUTED_VALUE"""),"Regihorn") -> Regihorn | F18: =IFERROR(__xludf.DUMMYFUNCTION("""COMPUTED_VALUE"""),"FurryWolf_RU") -> FurryWolf_RU
B19: Shogeki | C19: =IFERROR(__xludf.DUMMYFUNCTION("""COMPUTED_VALUE"""),"Retired Aces") -> Retired Aces | D19: =IFERROR(__xludf.DUMMYFUNCTION("""COMPUTED_VALUE"""),"Todi37") -> Todi37 | E19: =IFERROR(__xludf.DUMMYFUNCTION("""COMPUTED_VALUE"""),"Flaming_Galaxy") -> Flaming_Galaxy | F19: =IFERROR(__xludf.DUMMYFUNCTION("""COMPUTED_VALUE"""),"MomoNagi") -> MomoNagi
B20: reforna | C20: =IFERROR(__xludf.DUMMYFUNCTION("""COMPUTED_VALUE"""),"3000CombinedHours") -> 3000CombinedHours | D20: =IFERROR(__xludf.DUMMYFUNCTION("""COMPUTED_VALUE"""),"RakiMiku") -> RakiMiku | E20: =IFERROR(__xludf.DUMMYFUNCTION("""COMPUTED_VALUE"""),"WorstGamer") -> WorstGamer | F20: =IFERROR(__xludf.DUMMYFUNCTION("""COMPUTED_VALUE"""),"C L O N E") -> C L O N E
B21: BCraftMG | C21: =IFERROR(__xludf.DUMMYFUNCTION("""COMPUTED_VALUE"""),"Team name pending xd") -> Team name pending xd | D21: =IFERROR(__xludf.DUMMYFUNCTION("""COMPUTED_VALUE"""),"BlooMertz") -> BlooMertz | E21: =IFERROR(__xludf.DUMMYFUNCTION("""COMPUTED_VALUE"""),"cxyren") -> cxyren | F21: =IFERROR(__xludf.DUMMYFUNCTION("""COMPUTED_VALUE"""),"Dragonslash354") -> Dragonslash354
B22: Gamillie | C22: =IFERROR(__xludf.DUMMYFUNCTION("""COMPUTED_VALUE"""),"middle-schooler wife") -> middle-schooler wife | D22: =IFERROR(__xludf.DUMMYFUNCTION("""COMPUTED_VALUE"""),"euouae_") -> euouae_ | E22: =IFERROR(__xludf.DUMMYFUNCTION("""COMPUTED_VALUE"""),"HecaRegina") -> HecaRegina | F22: =IFERROR(__xludf.DUMMYFUNCTION("""COMPUTED_VALUE"""),"Onii karma") -> Onii karma
B23: BlooMertz | C23: =IFERROR(__xludf.DUMMYFUNCTION("""COMPUTED_VALUE"""),"Better HD Abusers") -> Better HD Abusers | D23: =IFERROR(__xludf.DUMMYFUNCTION("""COMPUTED_VALUE"""),"HD Abuser") -> HD Abuser | E23: =IFERROR(__xludf.DUMMYFUNCTION("""COMPUTED_VALUE"""),"Ultima_") -> Ultima_ | F23: =IFERROR(__xludf.DUMMYFUNCTION("""COMPUTED_VALUE"""),"Kaeldori") -> Kaeldori
B24: Azasapag | C24: =IFERROR(__xludf.DUMMYFUNCTION("""COMPUTED_VALUE"""),"DSE victims") -> DSE victims | D24: =IFERROR(__xludf.DUMMYFUNCTION("""COMPUTED_VALUE"""),"Himman") -> Himman | E24: =IFERROR(__xludf.DUMMYFUNCTION("""COMPUTED_VALUE"""),"C00KI3C00KIY") -> C00KI3C00KIY | F24: =IFERROR(__xludf.DUMMYFUNCTION("""COMPUTED_VALUE"""),"Cola1228") -> Cola1228
B25: Emerald Ages | C25: =IFERROR(__xludf.DUMMYFUNCTION("""COMPUTED_VALUE"""),"Flexgang") -> Flexgang | D25: =IFERROR(__xludf.DUMMYFUNCTION("""COMPUTED_VALUE"""),"lipefree") -> lipefree | E25: =IFERROR(__xludf.DUMMYFUNCTION("""COMPUTED_VALUE"""),"Darvgaea") -> Darvgaea
B26: -PeKoRa- | C26: =IFERROR(__xludf.DUMMYFUNCTION("""COMPUTED_VALUE"""),"blpka") -> blpka | D26: =IFERROR(__xludf.DUMMYFUNCTION("""COMPUTED_VALUE"""),"- Enkidu -") -> - Enkidu - | E26: =IFERROR(__xludf.DUMMYFUNCTION("""COMPUTED_VALUE"""),"dffTu") -> dffTu
B27: [-Gabys-] | C27: =IFERROR(__xludf.DUMMYFUNCTION("""COMPUTED_VALUE"""),"Side Characters") -> Side Characters | D27: =IFERROR(__xludf.DUMMYFUNCTION("""COMPUTED_VALUE"""),"Heaki") -> Heaki | E27: =IFERROR(__xludf.DUMMYFUNCTION("""COMPUTED_VALUE"""),"miimo__miimo") -> miimo__miimo | F27: =IFERROR(__xludf.DUMMYFUNCTION("""COMPUTED_VALUE"""),"karimovic") -> karimovic
C28: =IFERROR(__xludf.DUMMYFUNCTION("""COMPUTED_VALUE"""),"Homossexual Students") -> Homossexual Students | D28: =IFERROR(__xludf.DUMMYFUNCTION("""COMPUTED_VALUE"""),"DUM4L77") -> DUM4L77 | E28: =IFERROR(__xludf.DUMMYFUNCTION("""COMPUTED_VALUE"""),"Simabuco") -> Simabuco | F28: =IFERROR(__xludf.DUMMYFUNCTION("""COMPUTED_VALUE"""),"Loopyng") -> Loopyng
C29: =IFERROR(__xludf.DUMMYFUNCTION("""COMPUTED_VALUE"""),"Chocomaid") -> Chocomaid | D29: =IFERROR(__xludf.DUMMYFUNCTION("""COMPUTED_VALUE"""),"Frui Ludo") -> Frui Ludo | E29: =IFERROR(__xludf.DUMMYFUNCTION("""COMPUTED_VALUE"""),"Chokecomint") -> Chokecomint | F29: =IFERROR(__xludf.DUMMYFUNCTION("""COMPUTED_VALUE"""),"Azcazay") -> Azcazay
C30: =IFERROR(__xludf.DUMMYFUNCTION("""COMPUTED_VALUE"""),"Kittens") -> Kittens | D30: =IFERROR(__xludf.DUMMYFUNCTION("""COMPUTED_VALUE"""),"Rurup") -> Rurup | E30: =IFERROR(__xludf.DUMMYFUNCTION("""COMPUTED_VALUE"""),"Shaddie_") -> Shaddie_ | F30: =IFERROR(__xludf.DUMMYFUNCTION("""COMPUTED_VALUE"""),"DzikaSwinia") -> DzikaSwinia
C31: =IFERROR(__xludf.DUMMYFUNCTION("""COMPUTED_VALUE"""),"PLDT ANO NAAA") -> PLDT ANO NAAA | D31: =IFERROR(__xludf.DUMMYFUNCTION("""COMPUTED_VALUE"""),"Shion Yorigami") -> Shion Yorigami | E31: =IFERROR(__xludf.DUMMYFUNCTION("""COMPUTED_VALUE"""),"iSimp22") -> iSimp22 | F31: =IFERROR(__xludf.DUMMYFUNCTION("""COMPUTED_VALUE"""),"BluNuggets") -> BluNuggets
C32: =IFERROR(__xludf.DUMMYFUNCTION("""COMPUTED_VALUE"""),"lowrank is my love") -> lowrank is my love | D32: =IFERROR(__xludf.DUMMYFUNCTION("""COMPUTED_VALUE"""),"Rev1vall") -> Rev1vall | E32: =IFERROR(__xludf.DUMMYFUNCTION("""COMPUTED_VALUE"""),"Sosedov") -> Sosedov
C33: =IFERROR(__xludf.DUMMYFUNCTION("""COMPUTED_VALUE"""),"китирики") -> китирики | D33: =IFERROR(__xludf.DUMMYFUNCTION("""COMPUTED_VALUE"""),"Kl4dys") -> Kl4dys | E33: =IFERROR(__xludf.DUMMYFUNCTION("""COMPUTED_VALUE"""),"KWIzYiii") -> KWIzYiii | F33: =IFERROR(__xludf.DUMMYFUNCTION("""COMPUTED_VALUE"""),"Petrovkosta") -> Petrovkosta
C34: =IFERROR(__xludf.DUMMYFUNCTION("""COMPUTED_VALUE"""),"VN+1") -> VN+1 | D34: =IFERROR(__xludf.DUMMYFUNCTION("""COMPUTED_VALUE"""),"fnugus") -> fnugus | E34: =IFERROR(__xludf.DUMMYFUNCTION("""COMPUTED_VALUE"""),"RaiRei") -> RaiRei | F34: =IFERROR(__xludf.DUMMYFUNCTION("""COMPUTED_VALUE"""),"Elfie125") -> Elfie125
C35: =IFERROR(__xludf.DUMMYFUNCTION("""COMPUTED_VALUE"""),"hmmmm") -> hmmmm | D35: =IFERROR(__xludf.DUMMYFUNCTION("""COMPUTED_VALUE"""),"VMPR13") -> VMPR13 | E35: =IFERROR(__xludf.DUMMYFUNCTION("""COMPUTED_VALUE"""),"u-litay") -> u-litay | J35: c
C36: =IFERROR(__xludf.DUMMYFUNCTION("""COMPUTED_VALUE"""),"match in 15") -> match in 15 | D36: =IFERROR(__xludf.DUMMYFUNCTION("""COMPUTED_VALUE"""),"X-ill") -> X-ill | E36: =IFERROR(__xludf.DUMMYFUNCTION("""COMPUTED_VALUE"""),"marshysxn") -> marshysxn | F36: =IFERROR(__xludf.DUMMYFUNCTION("""COMPUTED_VALUE"""),"felixgg") -> felixgg
C37: =IFERROR(__xludf.DUMMYFUNCTION("""COMPUTED_VALUE"""),"animefoot69") -> animefoot69 | D37: =IFERROR(__xludf.DUMMYFUNCTION("""COMPUTED_VALUE"""),"cyclone290") -> cyclone290 | E37: =IFERROR(__xludf.DUMMYFUNCTION("""COMPUTED_VALUE"""),"Aever") -> Aever
C38: =IFERROR(__xludf.DUMMYFUNCTION("""COMPUTED_VALUE"""),"CocoaGoats") -> CocoaGoats | D38: =IFERROR(__xludf.DUMMYFUNCTION("""COMPUTED_VALUE"""),"Tohkura") -> Tohkura | E38: =IFERROR(__xludf.DUMMYFUNCTION("""COMPUTED_VALUE"""),"pika_Zero") -> pika_Zero | F38: =IFERROR(__xludf.DUMMYFUNCTION("""COMPUTED_VALUE"""),"Glaucia") -> Glaucia
C39: =IFERROR(__xludf.DUMMYFUNCTION("""COMPUTED_VALUE"""),"female ass wrestling") -> female ass wrestling | D39: =IFERROR(__xludf.DUMMYFUNCTION("""COMPUTED_VALUE"""),"aespect") -> aespect | E39: =IFERROR(__xludf.DUMMYFUNCTION("""COMPUTED_VALUE"""),"qiyo") -> qiyo | F39: =IFERROR(__xludf.DUMMYFUNCTION("""COMPUTED_VALUE"""),"not_peder") -> not_peder
C40: =IFERROR(__xludf.DUMMYFUNCTION("""COMPUTED_VALUE"""),"The Mat Munchers") -> The Mat Munchers | D40: =IFERROR(__xludf.DUMMYFUNCTION("""COMPUTED_VALUE"""),"foxy1919191919") -> foxy1919191919 | E40: =IFERROR(__xludf.DUMMYFUNCTION("""COMPUTED_VALUE"""),"SneakyDingus") -> SneakyDingus | F40: =IFERROR(__xludf.DUMMYFUNCTION("""COMPUTED_VALUE"""),"Gwnet") -> Gwnet
C41: =IFERROR(__xludf.DUMMYFUNCTION("""COMPUTED_VALUE"""),"Faz o L") -> Faz o L | D41: =IFERROR(__xludf.DUMMYFUNCTION("""COMPUTED_VALUE"""),"jujubinhas2") -> jujubinhas2 | E41: =IFERROR(__xludf.DUMMYFUNCTION("""COMPUTED_VALUE"""),"Iite") -> Iite | F41: =IFERROR(__xludf.DUMMYFUNCTION("""COMPUTED_VALUE"""),"Sporinho") -> Sporinho
...

Sheet Qualifier Lobbies
A1: z | M1: c
C2: QUALIFIERS SCHEDULES | K2: ="Teams Scheduled : " & COUNTA(H5:L51) -> Teams Scheduled : 58
E3: Double click dates | F3: UTC+0
C4: Lobby | D4: Slots taken | E4: Date | F4: Time | G4: Referee | H4: Team 1 | I4: Team 2 | J4: Team 3 | K4: Team 4 | L4: Team 5 | M4: MP LINK
A5: Saturday | C5: A1 | D5: =IF(COUNTIF(H5:L5,"*") = 0, "-", COUNTIF($H$5:$L$5,"*") &" / 5") -> - | E5: 45150 | F5: 0:00 | G5: Shogeki
C6: A2 | D6: =IF(COUNTIF(H6:L6,"*") = 0, "-", COUNTIF(H6:L6,"*") &" / 5") -> 3 / 5 | E6: 45150 | F6: 2:00 | G6: Shogeki | H6: :MIPINGA: | I6: Here Forever | J6: BallzDeep69 | M6: =iferror(INDIRECT("'"&C6&"'!C3"),"") -> https://osu.ppy.sh/community/matches/109952322 | N6: TRUE
C7: A3 | D7: =IF(COUNTIF(H7:L7,"*") = 0, "-", COUNTIF(H7:L7,"*") &" / 5") -> 1 / 5 | E7: 45150 | F7: 4:00 | G7: RudderFish07 | H7: phony :) | M7: =iferror(INDIRECT("'"&C7&"'!C3"),"") -> https://osu.ppy.sh/mp/109953545 | N7: TRUE
C8: A4 | D8: =IF(COUNTIF(H8:L8,"*") = 0, "-", COUNTIF(H8:L8,"*") &" / 5") -> 1 / 5 | E8: 45150 | F8: 6:00 | G8: Azasapag | H8: foxy1919191919's basement | M8: =iferror(INDIRECT("'"&C8&"'!C3"),"") -> https://osu.ppy.sh/community/matches/109954652 | N8: TRUE
C9: A5 | E9: 45150 | F9: 8:00 | G9: euouae_
C10: A6 | D10: =IF(COUNTIF(H10:L10,"*") = 0, "-", COUNTIF(H10:L10,"*") &" / 5") -> 1 / 5 | E10: 45150 | F10: 10:00 | G10: Gamillie | H10: PLDT ANO NAAA | M10: =iferror(INDIRECT("'"&C10&"'!C3"),"") -> https://osu.ppy.sh/mp/109956626 | N10: TRUE
C11: A7 | D11: =IF(COUNTIF(H11:L11,"*") = 0, "-", COUNTIF(H11:L11,"*") &" / 5") -> 3 / 5 | E11: 45150 | F11: 12:00 | G11: Gamillie | H11: Mewo My Waifu | I11: CocoaGoats | J11: PoorQuaIityMeatpilow | M11: =iferror(INDIRECT("'"&C11&"'!C3"),"") -> https://osu.ppy.sh/mp/109957596 | N11: TRUE
C12: A8 | D12: =IF(COUNTIF(H12:L12,"*") = 0, "-", COUNTIF(H12:L12,"*") &" / 5") -> 3 / 5 | E12: 45150 | F12: 14:00 | G12: Emerald Ages | H12: Beancurd | I12: 3000CombinedHours | J12: PES E9L9 | M12: =iferror(INDIRECT("'"&C12&"'!C3"),"") -> https://osu.ppy.sh/community/matches/109959176 | N12: TRUE
C13: A9 | D13: =IF(COUNTIF(H13:L13,"*") = 0, "-", COUNTIF(H13:L13,"*") &" / 5") -> - | E13: 45150 | F13: 16:00 | G13: Emerald Ages
C14: A10 | D14: =IF(COUNTIF(H14:L14,"*") = 0, "-", COUNTIF(H14:L14,"*") &" / 5") -> 1 / 5 | E14: 45150 | F14: 18:00 | G14: Pischok | H14: Nameless Waifulovers | M14: =iferror(INDIRECT("'"&C14&"'!C3"),"") -> https://osu.ppy.sh/community/matches/109962867 | N14: TRUE
C15: A11 | D15: =IF(COUNTIF(H15:L15,"*") = 0, "-", COUNTIF(H15:L15,"*") &" / 5") -> 3 / 5 | E15: 45150 | F15: 20:00 | G15: play hd3 | H15: cake | I15: copium abusers | J15: APELPIES MY MOMMY | M15: =iferror(INDIRECT("'"&C15&"'!C3"),"") -> https://osu.ppy.sh/community/matches/109964348 | N15: TRUE
C16: A12 | D16: =IF(COUNTIF(H16:L16,"*") = 0, "-", COUNTIF(H16:L16,"*") &" / 5") -> 1 / 5 | E16: 45150 | F16: 22:00 | G16: play hd3 | H16: The One 100s | M16: =iferror(INDIRECT("'"&C16&"'!C3"),"") -> https://osu.ppy.sh/community/matches/109966515 | N16: TRUE
A18: Sunday | C18: B1 | D18: =IF(COUNTIF(H18:L18,"*") = 0, "-", COUNTIF(H18:L18,"*") &" / 5") -> 2 / 5 | E18: 45151 | F18: 0:00 | G18: Shogeki | H18: Faz o L | I18: Better HD Abusers | M18: {=iferror(INDIRECT("'"&C18&"'!C3"),"")} -> https://osu.ppy.sh/community/matches/109967744 | N18: TRUE
C19: B2 | D19: =IF(COUNTIF(H19:L19,"*") = 0, "-", COUNTIF(H19:L19,"*") &" / 5") -> - | E19: 45151 | F19: 2:00 | G19: Shogeki
C20: B3 | D20: =IF(COUNTIF(H20:L20,"*") = 0, "-", COUNTIF(H20:L20,"*") &" / 5") -> 1 / 5 | E20: 45151 | F20: 4:00 | G20: Azasapag | H20: Lovers + 3rd wheel | M20: =iferror(INDIRECT("'"&C20&"'!C3"),"") -> https://osu.ppy.sh/community/matches/109970156 | N20: TRUE
C21: B4 | D21: =IF(COUNTIF(H21:L21,"*") = 0, "-", COUNTIF(H21:L21,"*") &" / 5") -> - | E21: 45151 | F21: 6:00 | G21: Azasapag | M21: =iferror(INDIRECT("'"&C21&"'!C3"),"")
C22: B5 | D22: =IF(COUNTIF(H22:L22,"*") = 0, "-", COUNTIF(H22:L22,"*") &" / 5") -> 1 / 5 | E22: 45151 | F22: 8:00 | G22: BlooMertz | H22: Minor assault squad | M22: =iferror(INDIRECT("'"&C22&"'!C3"),"") -> https://osu.ppy.sh/community/matches/109971985 | N22: TRUE
C23: B6 | D23: =IF(COUNTIF(H23:L23,"*") = 0, "-", COUNTIF(H23:L23,"*") &" / 5") -> 2 / 5 | E23: 45151 | F23: 10:00 | G23: Gamillie | H23: blpka | I23: Team name pending xd | M23: =iferror(INDIRECT("'"&C23&"'!C3"),"") -> https://osu.ppy.sh/mp/109973026 | N23: TRUE
C24: B7 | D24: =IF(COUNTIF(H24:L24,"*") = 0, "-", COUNTIF(H24:L24,"*") &" / 5") -> 3 / 5 | E24: 45151 | F24: 12:00 | G24: BlooMertz | H24: Tom and Jerry | I24: VN+1 | J24: LongTreep | M24: =iferror(INDIRECT("'"&C24&"'!C3"),"") -> https://osu.ppy.sh/community/matches/109973994 | N24: TRUE
C25: B8 | D25: =IF(COUNTIF(H25:L25,"*") = 0, "-", COUNTIF(H25:L25,"*") &" / 5") -> - | E25: 45151 | F25: 14:00 | M25: =iferror(INDIRECT("'"&C25&"'!C3"),"")
C26: B9 | D26: =IF(COUNTIF(H26:L26,"*") = 0, "-", COUNTIF(H26:L26,"*") &" / 5") -> 4 / 5 | E26: 45151 | F26: 16:00 | G26: Emerald Ages | H26: Koteykaaa team | I26: Angleseekers | J26: Ahjin | K26: The sleepers | M26: =iferror(INDIRECT("'"&C26&"'!C3"),"") -> https://osu.ppy.sh/community/matches/109977543 | N26: TRUE
C27: B10 | D27: =IF(COUNTIF(H27:L27,"*") = 0, "-", COUNTIF(H27:L27,"*") &" / 5") -> 3 / 5 | E27: 45151 | F27: 18:00 | G27: BCraftMG | H27: hmmmm | I27: The 3-star Threats | J27: Side Characters | M27: https://osu.ppy.sh/community/matches/109979426 | N27: TRUE
C28: B11 | D28: =IF(COUNTIF(H28:L28,"*") = 0, "-", COUNTIF(H28:L28,"*") &" / 5") -> 1 / 5 | E28: 45151 | F28: 20:00 | H28: Retired Aces | M28: https://osu.ppy.sh/community/matches/109980924 | N28: TRUE
C29: B12 | D29: =IF(COUNTIF(H29:L29,"*") = 0, "-", COUNTIF(H29:L29,"*") &" / 5") -> 2 / 5 | E29: 45151 | F29: 22:00 | G29: play hd3 | H29: The Michis Gang | I29: middle-schooler wife | M29: https://osu.ppy.sh/community/matches/109982967
C30: B13 | D30: =IF(COUNTIF(H30:L30,"*") = 0, "-", COUNTIF(H30:L30,"*") &" / 5") -> - | E30: 45151 | F30: 23:59 | M30: https://osu.ppy.sh/community/matches/109980360 | N30: TRUE
M31: ^2nd mp for b10
A32: Custom Lobbies | C32: C1 | D32: =IF(COUNTIF(H32:L32,"*") = 0, "-", COUNTIF(H32:L32,"*") &" / 5") -> 1 / 5 | E32: 45149 | F32: 10:00 | G32: BlooMertz | H32: Chocomaid | M32: =iferror(INDIRECT("'"&C32&"'!C3"),"") -> https://osu.ppy.sh/community/matches/109940745 | N32: TRUE
C33: C2 | D33: =IF(COUNTIF(H33:L33,"*") = 0, "-", COUNTIF(H33:L33,"*") &" / 5") -> 2 / 5 | E33: 45149 | F33: 18:00 | G33: Ninja Mejster | H33: Sightread Buff | I33: Flexgang | M33: =iferror(INDIRECT("'"&C33&"'!C3"),"") -> https://osu.ppy.sh/community/matches/109946357 | N33: TRUE
C34: C3 | D34: =IF(COUNTIF(H34:L34,"*") = 0, "-", COUNTIF(H34:L34,"*") &" / 5") -> 1 / 5 | E34: 45149 | F34: 15:00 | G34: Emerald Ages | H34: underdogs | M34: =iferror(INDIRECT("'"&C34&"'!C3"),"") -> https://osu.ppy.sh/community/matches/109944141 | N34: TRUE
C35: C4 | D35: =IF(COUNTIF(H35:L35,"*") = 0, "-", COUNTIF(H35:L35,"*") &" / 5") -> 1 / 5 | E35: Aug 11 (Friday) | F35: 14:30 | G35: BCraftMG | H35: small wiener club | M35: =iferror(INDIRECT("'"&C35&"'!C3"),"") -> https://osu.ppy.sh/mp/109943699 | N35: TRUE
C36: C5 | D36: =IF(COUNTIF(H36:L36,"*") = 0, "-", COUNTIF(H36:L36,"*") &" / 5") -> 3 / 5 | E36: Aug 12 (Saturday) | F36: 15:00 | G36: Emerald Ages | H36: The Mat Munchers | I36: match in 15 | J36: Ghost the Angel | M36: =iferror(INDIRECT("'"&C36&"'!C3"),"") -> https://osu.ppy.sh/community/matches/109960051 | N36: TRUE
C37: C6 | D37: =IF(COUNTIF(H37:L37,"*") = 0, "-", COUNTIF(H37:L37,"*") &" / 5") -> 1 / 5 | E37: Aug 11 (Friday) | F37: 3:00 | G37: -PeKoRa- | H37: Our team left us | M37: =iferror(INDIRECT("'"&C37&"'!C3"),"") -> https://osu.ppy.sh/community/matches/109937609 | N37: TRUE
C38: C7 | D38: =IF(COUNTIF(H38:L38,"*") = 0, "-", COUNTIF(H38:L38,"*") &" / 5") -> 1 / 5 | E38: Aug 9 (Wednesday) | F38: 20:00 | G38: play hd3 | H38: BOCCHER | M38: =iferror(INDIRECT("'"&C38&"'!C3"),"") -> https://osu.ppy.sh/community/matches/109917698 | N38: TRUE
C39: C8 | D39: =IF(COUNTIF(H39:L39,"*") = 0, "-", COUNTIF(H39:L39,"*") &" / 5") -> 1 / 5 | E39: Aug 13 (Sunday) | F39: 1:00 | G39: RudderFish07 | H39: animefoot69 | M39: =iferror(INDIRECT("'"&C39&"'!C3"),"") -> https://osu.ppy.sh/community/matches/109968332 | N39: TRUE
C40: C9 | D40: =IF(COUNTIF(H40:L40,"*") = 0, "-", COUNTIF(H40:L40,"*") &" / 5") -> - | E40: Aug 13 (Sunday) | F40: 15:30 | G40: -PeKoRa- | M40: =iferror(INDIRECT("'"&C40&"'!C3"),"")
C41: C10 | D41: =IF(COUNTIF(H41:L41,"*") = 0, "-", COUNTIF(H41:L41,"*") &" / 5") -> - | E41: Aug 13 (Sunday) | F41: 7:00 | G41: BlooMertz | M41: =iferror(INDIRECT("'"&C41&"'!C3"),"")
...

Sheet Templatee
B2: Lobby: | E2: Referee: | G2: Remarks (Late and Replays) | I2: mp timer 120 | J2: !mp settings | K2: Forum link : https://osu.ppy.sh/community/forums/topics/1790898?n=1?
B3: MP LINK: | E3: =VLOOKUP(C2,'Qualifier Lobbies'!C4:G42,5,0) -> #N/A | G3: :thumbsup: None | I3: !mp set 0 3 16 | J3: !mp abort
B4: Room Command: | C4: ="!mp make PTE : (Qualifiers) vs ("&C2&")" -> !mp make PTE : (Qualifiers) vs () | E4: =VLOOKUP(C2,'Qualifier Lobbies'!C4:F42,3,0) -> #N/A | I4: !mp start 10 | J4: !mp aborttimer | K4: Mainsheet link : https://docs.google.com/spreadsheets/d/1u1R-0YeX71qksHP7hWq8QkjcpECX-9LSvskalZ8hxdg/edit?usp=sharing
B5: Results: | C5: =IFS(C3="","Put the MP link first!",C3>"", "**Qualifier Lobby "&C2&"**" &CHAR(13)& " MP LINK: "&C3&" "&CHAR(13)&" Referee Notes: "&G3) &CHAR(13) -> Put the MP link first! | E5: =VLOOKUP(C2,'Qualifier Lobbies'!C4:F42,4,0)&" UTC" -> #N/A | I5: MP COMMANDS | J5: !mp addref (name)
B7: Mappool | G7: =IFERROR("!mp invite " & G9,"") -> !mp invite | I7: =IFERROR("!mp invite " & I9,"") -> !mp invite | J7: =IFERROR("!mp invite " & J9,"") -> !mp invite | K7: =IFERROR("!mp invite " & K9,"") -> !mp invite | L7: =IFERROR("!mp invite " & L9,"") -> !mp invite
B8: Mod Command | C8: Map Name | D8: Map Command | G8: =VLOOKUP(C2,'Qualifier Lobbies'!C5:L42,6,0) -> #N/A | I8: =VLOOKUP(C2,'Qualifier Lobbies'!C5:L42,7,0) -> #N/A | J8: =VLOOKUP(C2,'Qualifier Lobbies'!C5:L42,8,0) -> #N/A | K8: =VLOOKUP(C2,'Qualifier Lobbies'!C5:L42,9,0) -> #N/A | L8: =VLOOKUP(C2,'Qualifier Lobbies'!C5:L42,10,0) -> #N/A
B9: {='Qualifiers Pool'!J3:J12} -> !mp mods NF | C9: {='Qualifiers Pool'!H3:H12} -> NM1: nonoc - Relive [Insane] | D9: {='Qualifiers Pool'!I3:I12} -> !mp map 3924030 | G9: =IFERROR(VLOOKUP(G8,'Ref & Team list'!C3:F20,2,0),"") | I9: =IFERROR(VLOOKUP(I8,'Ref & Team list'!C3:F20,2,0),"") | J9: =IFERROR(VLOOKUP(J8,'Ref & Team list'!C3:F20,2,0),"") | K9: =IFERROR(VLOOKUP(K8,'Ref & Team list'!C3:F20,2,0),"") | L9: =IFERROR(VLOOKUP(L8,'Ref & Team list'!C3:F20,2,0),"")
B10: !mp mods NF | C10: NM2: void - Crisscrosser [Insane] | D10: !mp map 908887 | G10: =IFERROR(VLOOKUP(G8,'Ref & Team list'!C3:F20,3,0),"") | I10: =IFERROR(VLOOKUP(I8,'Ref & Team list'!C3:F20,3,0),"") | J10: =IFERROR(VLOOKUP(J8,'Ref & Team list'!C3:F20,3,0),"") | K10: =IFERROR(VLOOKUP(K8,'Ref & Team list'!C3:F20,3,0),"") | L10: =IFERROR(VLOOKUP(L8,'Ref & Team list'!C3:F20,3,0),"")
B11: !mp mods NF | C11: NM3: Sangatsu no Phantasia - Koufuku na Wagamama [Insane] | D11: !mp map 3035501 | G11: =IFERROR(VLOOKUP(G8,'Ref & Team list'!C3:F20,4,0),"") | I11: =IFERROR(VLOOKUP(I8,'Ref & Team list'!C3:F20,4,0),"") | J11: =IFERROR(VLOOKUP(J8,'Ref & Team list'!C3:F20,4,0),"") | K11: =IFERROR(VLOOKUP(K8,'Ref & Team list'!C3:F20,4,0),"") | L11: =IFERROR(VLOOKUP(L8,'Ref & Team list'!C3:F20,4,0),"")
B12: !mp mods NF | C12: NM4: PSYQUI - Education [sorciere's Insane] | D12: !mp map 3737825
B13: !mp mods HD NF | C13: HD1: Ax feat. Natsukawa Yoko - Sakimori Renka [Insane] | D13: !mp map 2094462
B14: !mp mods HD NF | C14: HD2: Amane - BOOZEHOUND [Down's Insane] | D14: !mp map 2619929
B15: !mp mods HR NF | C15: HR1: THE ORAL CIGARETTES - Wagamama de Gomakasanaide [Panda & Melwoine's Insane] | D15: !mp map 2027623
B16: !mp mods HR NF | C16: HR2: Kajiura Yuki - Sis puella magica! [Tea Party] | D16: !mp map 1523138
B17: !mp mods DT NF | C17: DT1: ICHIKO - YOU'RE THE ONE [ANDREA & ASUKO'S HARD] | D17: !mp map 4105349
B18: !mp mods DT NF | C18: DT2: DIANA - Beethoven Virus [Aranel's Hard] | D18: !mp map 3533589

Sheet A2
B2: Lobby: | C2: A2 | E2: Referee: | G2: Remarks (Late and Replays) | I2: mp timer 120 | J2: !mp settings | K2: Forum link : https://osu.ppy.sh/community/forums/topics/1790898?n=1?
B3: MP LINK: | C3: https://osu.ppy.sh/community/matches/109952322 | E3: =VLOOKUP(C2,'Qualifier Lobbies'!C4:G42,5,0) -> Shogeki | G3: :thumbsup: None | I3: !mp set 0 3 16 | J3: !mp abort
B4: Room Command: | C4: ="!mp make PTE : (Qualifiers) vs ("&C2&")" -> !mp make PTE : (Qualifiers) vs (A2) | E4: =VLOOKUP(C2,'Qualifier Lobbies'!C4:F42,3,0) -> 45150 | I4: !mp start 10 | J4: !mp aborttimer | K4: Mainsheet link : https://docs.google.com/spreadsheets/d/1u1R-0YeX71qksHP7hWq8QkjcpECX-9LSvskalZ8hxdg/edit?usp=sharing
B5: Results: | C5: =IFS(C3="","Put the MP link first!",C3>"", "**Qualifier Lobby "&C2&"**" &CHAR(13)& " MP LINK: "&C3&" "&CHAR(13)&" Referee Notes: "&G3) &CHAR(13) -> **Qualifier Lobby A2** MP LINK: https://osu.ppy.sh/community/matches/109952322 Referee Notes: :thumbsup: None | E5: =VLOOKUP(C2,'Qualifier Lobbies'!C4:F42,4,0)&" UTC" -> 2:00 UTC | I5: MP COMMANDS | J5: !mp addref (name)
B7: Mappool | G7: =IFERROR("!mp invite " & G9,"") -> !mp invite RAAPslimshady | I7: =IFERROR("!mp invite " & I9,"") -> !mp invite Riidolsk | J7: =IFERROR("!mp invite " & J9,"") -> !mp invite _BlackStar | K7: =IFERROR("!mp invite " & K9,"") -> !mp invite | L7: =IFERROR("!mp invite " & L9,"") -> !mp invite
B8: Mod Command | C8: Map Name | D8: Map Command | G8: =VLOOKUP(C2,'Qualifier Lobbies'!C5:L42,6,0) -> :MIPINGA: | I8: =VLOOKUP(C2,'Qualifier Lobbies'!C5:L42,7,0) -> Here Forever | J8: =VLOOKUP(C2,'Qualifier Lobbies'!C5:L42,8,0) -> BallzDeep69 | K8: =VLOOKUP(C2,'Qualifier Lobbies'!C5:L42,9,0) | L8: =VLOOKUP(C2,'Qualifier Lobbies'!C5:L42,10,0)
B9: {='Qualifiers Pool'!J3:J12} -> !mp mods NF | C9: {='Qualifiers Pool'!H3:H12} -> NM1: nonoc - Relive [Insane] | D9: {='Qualifiers Pool'!I3:I12} -> !mp map 3924030 | G9: =IFERROR(VLOOKUP(G8,'Ref & Team list'!C3:F20,2,0),"") -> RAAPslimshady | I9: =IFERROR(VLOOKUP(I8,'Ref & Team list'!C3:F20,2,0),"") -> Riidolsk | J9: =IFERROR(VLOOKUP(J8,'Ref & Team list'!C3:F20,2,0),"") -> _BlackStar | K9: =IFERROR(VLOOKUP(K8,'Ref & Team list'!C3:F20,2,0),"") | L9: =IFERROR(VLOOKUP(L8,'Ref & Team list'!C3:F20,2,0),"")
B10: !mp mods NF | C10: NM2: void - Crisscrosser [Insane] | D10: !mp map 908887 | G10: =IFERROR(VLOOKUP(G8,'Ref & Team list'!C3:F20,3,0),"") -> Isita | I10: =IFERROR(VLOOKUP(I8,'Ref & Team list'!C3:F20,3,0),"") -> Kyarma | J10: =IFERROR(VLOOKUP(J8,'Ref & Team list'!C3:F20,3,0),"") -> Iamthecabra | K10: =IFERROR(VLOOKUP(K8,'Ref & Team list'!C3:F20,3,0),"") | L10: =IFERROR(VLOOKUP(L8,'Ref & Team list'!C3:F20,3,0),"")
B11: !mp mods NF | C11: NM3: Sangatsu no Phantasia - Koufuku na Wagamama [Insane] | D11: !mp map 3035501 | G11: =IFERROR(VLOOKUP(G8,'Ref & Team list'!C3:F20,4,0),"") -> Lyxin | I11: =IFERROR(VLOOKUP(I8,'Ref & Team list'!C3:F20,4,0),"") -> stupid femboy | J11: =IFERROR(VLOOKUP(J8,'Ref & Team list'!C3:F20,4,0),"") -> Alogi | K11: =IFERROR(VLOOKUP(K8,'Ref & Team list'!C3:F20,4,0),"") | L11: =IFERROR(VLOOKUP(L8,'Ref & Team list'!C3:F20,4,0),"")
B12: !mp mods NF | C12: NM4: PSYQUI - Education [sorciere's Insane] | D12: !mp map 3737825
B13: !mp mods HD NF | C13: HD1: Ax feat. Natsukawa Yoko - Sakimori Renka [Insane] | D13: !mp map 2094462
B14: !mp mods HD NF | C14: HD2: Amane - BOOZEHOUND [Down's Insane] | D14: !mp map 2619929
B15: !mp mods HR NF | C15: HR1: THE ORAL CIGARETTES - Wagamama de Gomakasanaide [Panda & Melwoine's Insane] | D15: !mp map 2027623
B16: !mp mods HR NF | C16: HR2: Kajiura Yuki - Sis puella magica! [Tea Party] | D16: !mp map 1523138
B17: !mp mods DT NF | C17: DT1: ICHIKO - YOU'RE THE ONE [ANDREA & ASUKO'S HARD] | D17: !mp map 4105349
B18: !mp mods DT NF | C18: DT2: DIANA - Beethoven Virus [Aranel's Hard] | D18: !mp map 3533589

Sheet A3
B2: Lobby: | C2: A3 | E2: Referee: | G2: Remarks (Late and Replays) | I2: mp timer 120 | J2: !mp settings | K2: Forum link : https://osu.ppy.sh/community/forums/topics/1790898?n=1?
B3: MP LINK: | C3: https://osu.ppy.sh/mp/109953545 | E3: =VLOOKUP(C2,'Qualifier Lobbies'!C4:G42,5,0) -> RudderFish07 | G3: :thumbsup: None | I3: !mp set 0 3 16 | J3: !mp abort
B4: Room Command: | C4: ="!mp make PTE : (Qualifiers) vs ("&C2&")" -> !mp make PTE : (Qualifiers) vs (A3) | E4: =VLOOKUP(C2,'Qualifier Lobbies'!C4:F42,3,0) -> 45150 | I4: !mp start 10 | J4: !mp aborttimer | K4: Mainsheet link : https://docs.google.com/spreadsheets/d/1u1R-0YeX71qksHP7hWq8QkjcpECX-9LSvskalZ8hxdg/edit?usp=sharing
B5: Results: | C5: =IFS(C3="","Put the MP link first!",C3>"", "**Qualifier Lobby "&C2&"**" &CHAR(13)& " MP LINK: "&C3&" "&CHAR(13)&" Referee Notes: "&G3) &CHAR(13) -> **Qualifier Lobby A3** MP LINK: https://osu.ppy.sh/mp/109953545 Referee Notes: :thumbsup: None | E5: =VLOOKUP(C2,'Qualifier Lobbies'!C4:F42,4,0)&" UTC" -> 4:00 UTC | I5: MP COMMANDS | J5: !mp addref (name)
B7: Mappool | G7: =IFERROR("!mp invite " & G9,"") -> !mp invite AZKi | I7: =IFERROR("!mp invite " & I9,"") -> !mp invite | J7: =IFERROR("!mp invite " & J9,"") -> !mp invite | K7: =IFERROR("!mp invite " & K9,"") -> !mp invite | L7: =IFERROR("!mp invite " & L9,"") -> !mp invite
B8: Mod Command | C8: Map Name | D8: Map Command | G8: =VLOOKUP(C2,'Qualifier Lobbies'!C5:L42,6,0) -> phony :) | I8: =VLOOKUP(C2,'Qualifier Lobbies'!C5:L42,7,0) | J8: =VLOOKUP(C2,'Qualifier Lobbies'!C5:L42,8,0) | K8: =VLOOKUP(C2,'Qualifier Lobbies'!C5:L42,9,0) | L8: =VLOOKUP(C2,'Qualifier Lobbies'!C5:L42,10,0)
B9: {='Qualifiers Pool'!J3:J12} -> !mp mods NF | C9: {='Qualifiers Pool'!H3:H12} -> NM1: nonoc - Relive [Insane] | D9: {='Qualifiers Pool'!I3:I12} -> !mp map 3924030 | G9: =IFERROR(VLOOKUP(G8,'Ref & Team list'!C3:F20,2,0),"") -> AZKi | I9: =IFERROR(VLOOKUP(I8,'Ref & Team list'!C3:F20,2,0),"") | J9: =IFERROR(VLOOKUP(J8,'Ref & Team list'!C3:F20,2,0),"") | K9: =IFERROR(VLOOKUP(K8,'Ref & Team list'!C3:F20,2,0),"") | L9: =IFERROR(VLOOKUP(L8,'Ref & Team list'!C3:F20,2,0),"")
B10: !mp mods NF | C10: NM2: void - Crisscrosser [Insane] | D10: !mp map 908887 | G10: =IFERROR(VLOOKUP(G8,'Ref & Team list'!C3:F20,3,0),"") -> SomeLongName | I10: =IFERROR(VLOOKUP(I8,'Ref & Team list'!C3:F20,3,0),"") | J10: =IFERROR(VLOOKUP(J8,'Ref & Team list'!C3:F20,3,0),"") | K10: =IFERROR(VLOOKUP(K8,'Ref & Team list'!C3:F20,3,0),"") | L10: =IFERROR(VLOOKUP(L8,'Ref & Team list'!C3:F20,3,0),"")
B11: !mp mods NF | C11: NM3: Sangatsu no Phantasia - Koufuku na Wagamama [Insane] | D11: !mp map 3035501 | G11: =IFERROR(VLOOKUP(G8,'Ref & Team list'!C3:F20,4,0),"") | I11: =IFERROR(VLOOKUP(I8,'Ref & Team list'!C3:F20,4,0),"") | J11: =IFERROR(VLOOKUP(J8,'Ref & Team list'!C3:F20,4,0),"") | K11: =IFERROR(VLOOKUP(K8,'Ref & Team list'!C3:F20,4,0),"") | L11: =IFERROR(VLOOKUP(L8,'Ref & Team list'!C3:F20,4,0),"")
B12: !mp mods NF | C12: NM4: PSYQUI - Education [sorciere's Insane] | D12: !mp map 3737825
B13: !mp mods HD NF | C13: HD1: Ax feat. Natsukawa Yoko - Sakimori Renka [Insane] | D13: !mp map 2094462
B14: !mp mods HD NF | C14: HD2: Amane - BOOZEHOUND [Down's Insane] | D14: !mp map 2619929
B15: !mp mods HR NF | C15: HR1: THE ORAL CIGARETTES - Wagamama de Gomakasanaide [Panda & Melwoine's Insane] | D15: !mp map 2027623
B16: !mp mods HR NF | C16: HR2: Kajiura Yuki - Sis puella magica! [Tea Party] | D16: !mp map 1523138
B17: !mp mods DT NF | C17: DT1: ICHIKO - YOU'RE THE ONE [ANDREA & ASUKO'S HARD] | D17: !mp map 4105349
B18: !mp mods DT NF | C18: DT2: DIANA - Beethoven Virus [Aranel's Hard] | D18: !mp map 3533589

Sheet A4
B2: Lobby: | C2: A4 | E2: Referee: | G2: Remarks (Late and Replays) | I2: mp timer 120 | J2: !mp settings | K2: Forum link : https://osu.ppy.sh/community/forums/topics/1790898?n=1?
B3: MP LINK: | C3: https://osu.ppy.sh/community/matches/109954652 | E3: =VLOOKUP(C2,'Qualifier Lobbies'!C4:G42,5,0) -> Azasapag | G3: :thumbsup: None | I3: !mp set 0 3 16 | J3: !mp abort
B4: Room Command: | C4: ="!mp make PTE : (Qualifiers) vs ("&C2&")" -> !mp make PTE : (Qualifiers) vs (A4) | E4: =VLOOKUP(C2,'Qualifier Lobbies'!C4:F42,3,0) -> 45150 | I4: !mp start 10 | J4: !mp aborttimer | K4: Mainsheet link : https://docs.google.com/spreadsheets/d/1u1R-0YeX71qksHP7hWq8QkjcpECX-9LSvskalZ8hxdg/edit?usp=sharing
B5: Results: | C5: =IFS(C3="","Put the MP link first!",C3>"", "**Qualifier Lobby "&C2&"**" &CHAR(13)& " MP LINK: "&C3&" "&CHAR(13)&" Referee Notes: "&G3) &CHAR(13) -> **Qualifier Lobby A4** MP LINK: https://osu.ppy.sh/community/matches/109954652 Referee Notes: :thumbsup: None | E5: =VLOOKUP(C2,'Qualifier Lobbies'!C4:F42,4,0)&" UTC" -> 6:00 UTC | I5: MP COMMANDS | J5: !mp addref (name)
B7: Mappool | G7: =IFERROR("!mp invite " & G9,"") -> !mp invite Faceie | I7: =IFERROR("!mp invite " & I9,"") -> !mp invite | J7: =IFERROR("!mp invite " & J9,"") -> !mp invite | K7: =IFERROR("!mp invite " & K9,"") -> !mp invite | L7: =IFERROR("!mp invite " & L9,"") -> !mp invite
B8: Mod Command | C8: Map Name | D8: Map Command | G8: =VLOOKUP(C2,'Qualifier Lobbies'!C5:L42,6,0) -> foxy1919191919's basement | I8: =VLOOKUP(C2,'Qualifier Lobbies'!C5:L42,7,0) | J8: =VLOOKUP(C2,'Qualifier Lobbies'!C5:L42,8,0) | K8: =VLOOKUP(C2,'Qualifier Lobbies'!C5:L42,9,0) | L8: =VLOOKUP(C2,'Qualifier Lobbies'!C5:L42,10,0)
B9: {='Qualifiers Pool'!J3:J12} -> !mp mods NF | C9: {='Qualifiers Pool'!H3:H12} -> NM1: nonoc - Relive [Insane] | D9: {='Qualifiers Pool'!I3:I12} -> !mp map 3924030 | G9: =IFERROR(VLOOKUP(G8,'Ref & Team list'!C3:F20,2,0),"") -> Faceie | I9: =IFERROR(VLOOKUP(I8,'Ref & Team list'!C3:F20,2,0),"") | J9: =IFERROR(VLOOKUP(J8,'Ref & Team list'!C3:F20,2,0),"") | K9: =IFERROR(VLOOKUP(K8,'Ref & Team list'!C3:F20,2,0),"") | L9: =IFERROR(VLOOKUP(L8,'Ref & Team list'!C3:F20,2,0),"")
B10: !mp mods NF | C10: NM2: void - Crisscrosser [Insane] | D10: !mp map 908887 | G10: =IFERROR(VLOOKUP(G8,'Ref & Team list'!C3:F20,3,0),"") -> Flare_Drake | I10: =IFERROR(VLOOKUP(I8,'Ref & Team list'!C3:F20,3,0),"") | J10: =IFERROR(VLOOKUP(J8,'Ref & Team list'!C3:F20,3,0),"") | K10: =IFERROR(VLOOKUP(K8,'Ref & Team list'!C3:F20,3,0),"") | L10: =IFERROR(VLOOKUP(L8,'Ref & Team list'!C3:F20,3,0),"")
B11: !mp mods NF | C11: NM3: Sangatsu no Phantasia - Koufuku na Wagamama [Insane] | D11: !mp map 3035501 | G11: =IFERROR(VLOOKUP(G8,'Ref & Team list'!C3:F20,4,0),"") -> vortexta | I11: =IFERROR(VLOOKUP(I8,'Ref & Team list'!C3:F20,4,0),"") | J11: =IFERROR(VLOOKUP(J8,'Ref & Team list'!C3:F20,4,0),"") | K11: =IFERROR(VLOOKUP(K8,'Ref & Team list'!C3:F20,4,0),"") | L11: =IFERROR(VLOOKUP(L8,'Ref & Team list'!C3:F20,4,0),"")
B12: !mp mods NF | C12: NM4: PSYQUI - Education [sorciere's Insane] | D12: !mp map 3737825
B13: !mp mods HD NF | C13: HD1: Ax feat. Natsukawa Yoko - Sakimori Renka [Insane] | D13: !mp map 2094462
B14: !mp mods HD NF | C14: HD2: Amane - BOOZEHOUND [Down's Insane] | D14: !mp map 2619929
B15: !mp mods HR NF | C15: HR1: THE ORAL CIGARETTES - Wagamama de Gomakasanaide [Panda & Melwoine's Insane] | D15: !mp map 2027623
B16: !mp mods HR NF | C16: HR2: Kajiura Yuki - Sis puella magica! [Tea Party] | D16: !mp map 1523138
B17: !mp mods DT NF | C17: DT1: ICHIKO - YOU'RE THE ONE [ANDREA & ASUKO'S HARD] | D17: !mp map 4105349
B18: !mp mods DT NF | C18: DT2: DIANA - Beethoven Virus [Aranel's Hard] | D18: !mp map 3533589

Sheet A5
B2: Lobby: | C2: A5 | E2: Referee: | G2: Remarks (Late and Replays) | I2: mp timer 120 | J2: !mp settings | K2: Forum link : https://osu.ppy.sh/community/forums/topics/1790898?n=1?
B3: MP LINK: | E3: =VLOOKUP(C2,'Qualifier Lobbies'!C4:G42,5,0) -> euouae_ | G3: :thumbsup: None | I3: !mp set 0 3 16 | J3: !mp abort
B4: Room Command: | C4: ="!mp make PTE : (Qualifiers) vs ("&C2&")" -> !mp make PTE : (Qualifiers) vs (A5) | E4: =VLOOKUP(C2,'Qualifier Lobbies'!C4:F42,3,0) -> 45150 | I4: !mp start 10 | J4: !mp aborttimer | K4: Mainsheet link : https://docs.google.com/spreadsheets/d/1u1R-0YeX71qksHP7hWq8QkjcpECX-9LSvskalZ8hxdg/edit?usp=sharing
B5: Results: | C5: =IFS(C3="","Put the MP link first!",C3>"", "**Qualifier Lobby "&C2&"**" &CHAR(13)& " MP LINK: "&C3&" "&CHAR(13)&" Referee Notes: "&G3) &CHAR(13) -> Put the MP link first! | E5: =VLOOKUP(C2,'Qualifier Lobbies'!C4:F42,4,0)&" UTC" -> 8:00 UTC | I5: MP COMMANDS | J5: !mp addref (name)
B7: Mappool | G7: =IFERROR("!mp invite " & G9,"") -> !mp invite | I7: =IFERROR("!mp invite " & I9,"") -> !mp invite | J7: =IFERROR("!mp invite " & J9,"") -> !mp invite | K7: =IFERROR("!mp invite " & K9,"") -> !mp invite | L7: =IFERROR("!mp invite " & L9,"") -> !mp invite
B8: Mod Command | C8: Map Name | D8: Map Command | G8: =VLOOKUP(C2,'Qualifier Lobbies'!C5:L42,6,0) | I8: =VLOOKUP(C2,'Qualifier Lobbies'!C5:L42,7,0) | J8: =VLOOKUP(C2,'Qualifier Lobbies'!C5:L42,8,0) | K8: =VLOOKUP(C2,'Qualifier Lobbies'!C5:L42,9,0) | L8: =VLOOKUP(C2,'Qualifier Lobbies'!C5:L42,10,0)
B9: {='Qualifiers Pool'!J3:J12} -> !mp mods NF | C9: {='Qualifiers Pool'!H3:H12} -> NM1: nonoc - Relive [Insane] | D9: {='Qualifiers Pool'!I3:I12} -> !mp map 3924030 | G9: =IFERROR(VLOOKUP(G8,'Ref & Team list'!C3:F20,2,0),"") | I9: =IFERROR(VLOOKUP(I8,'Ref & Team list'!C3:F20,2,0),"") | J9: =IFERROR(VLOOKUP(J8,'Ref & Team list'!C3:F20,2,0),"") | K9: =IFERROR(VLOOKUP(K8,'Ref & Team list'!C3:F20,2,0),"") | L9: =IFERROR(VLOOKUP(L8,'Ref & Team list'!C3:F20,2,0),"")
B10: !mp mods NF | C10: NM2: void - Crisscrosser [Insane] | D10: !mp map 908887 | G10: =IFERROR(VLOOKUP(G8,'Ref & Team list'!C3:F20,3,0),"") | I10: =IFERROR(VLOOKUP(I8,'Ref & Team list'!C3:F20,3,0),"") | J10: =IFERROR(VLOOKUP(J8,'Ref & Team list'!C3:F20,3,0),"") | K10: =IFERROR(VLOOKUP(K8,'Ref & Team list'!C3:F20,3,0),"") | L10: =IFERROR(VLOOKUP(L8,'Ref & Team list'!C3:F20,3,0),"")
B11: !mp mods NF | C11: NM3: Sangatsu no Phantasia - Koufuku na Wagamama [Insane] | D11: !mp map 3035501 | G11: =IFERROR(VLOOKUP(G8,'Ref & Team list'!C3:F20,4,0),"") | I11: =IFERROR(VLOOKUP(I8,'Ref & Team list'!C3:F20,4,0),"") | J11: =IFERROR(VLOOKUP(J8,'Ref & Team list'!C3:F20,4,0),"") | K11: =IFERROR(VLOOKUP(K8,'Ref & Team list'!C3:F20,4,0),"") | L11: =IFERROR(VLOOKUP(L8,'Ref & Team list'!C3:F20,4,0),"")
B12: !mp mods NF | C12: NM4: PSYQUI - Education [sorciere's Insane] | D12: !mp map 3737825
B13: !mp mods HD NF | C13: HD1: Ax feat. Natsukawa Yoko - Sakimori Renka [Insane] | D13: !mp map 2094462
B14: !mp mods HD NF | C14: HD2: Amane - BOOZEHOUND [Down's Insane] | D14: !mp map 2619929
B15: !mp mods HR NF | C15: HR1: THE ORAL CIGARETTES - Wagamama de Gomakasanaide [Panda & Melwoine's Insane] | D15: !mp map 2027623
B16: !mp mods HR NF | C16: HR2: Kajiura Yuki - Sis puella magica! [Tea Party] | D16: !mp map 1523138
B17: !mp mods DT NF | C17: DT1: ICHIKO - YOU'RE THE ONE [ANDREA & ASUKO'S HARD] | D17: !mp map 4105349
B18: !mp mods DT NF | C18: DT2: DIANA - Beethoven Virus [Aranel's Hard] | D18: !mp map 3533589

Sheet A6
B2: Lobby: | C2: A6 | E2: Referee: | G2: Remarks (Late and Replays) | I2: mp timer 120 | J2: !mp settings | K2: Forum link : https://osu.ppy.sh/community/forums/topics/1790898?n=1?
B3: MP LINK: | C3: https://osu.ppy.sh/mp/109956626 | E3: =VLOOKUP(C2,'Qualifier Lobbies'!C4:G42,5,0) -> Gamillie | G3: :thumbsup: None | I3: !mp set 0 3 16 | J3: !mp abort
B4: Room Command: | C4: ="!mp make PTE : (Qualifiers) vs ("&C2&")" -> !mp make PTE : (Qualifiers) vs (A6) | E4: =VLOOKUP(C2,'Qualifier Lobbies'!C4:F42,3,0) -> 45150 | I4: !mp start 10 | J4: !mp aborttimer | K4: Mainsheet link : https://docs.google.com/spreadsheets/d/1u1R-0YeX71qksHP7hWq8QkjcpECX-9LSvskalZ8hxdg/edit?usp=sharing
B5: Results: | C5: =IFS(C3="","Put the MP link first!",C3>"", "**Qualifier Lobby "&C2&"**" &CHAR(13)& " MP LINK: "&C3&" "&CHAR(13)&" Referee Notes: "&G3) &CHAR(13) -> **Qualifier Lobby A6** MP LINK: https://osu.ppy.sh/mp/109956626 Referee Notes: :thumbsup: None | E5: =VLOOKUP(C2,'Qualifier Lobbies'!C4:F42,4,0)&" UTC" -> 10:00 UTC | I5: MP COMMANDS | J5: !mp addref (name)
B7: Mappool | G7: =IFERROR("!mp invite " & G9,"") -> !mp invite Shion Yorigami | I7: =IFERROR("!mp invite " & I9,"") -> !mp invite | J7: =IFERROR("!mp invite " & J9,"") -> !mp invite | K7: =IFERROR("!mp invite " & K9,"") -> !mp invite | L7: =IFERROR("!mp invite " & L9,"") -> !mp invite
B8: Mod Command | C8: Map Name | D8: Map Command | G8: =VLOOKUP(C2,'Qualifier Lobbies'!C5:L42,6,0) -> PLDT ANO NAAA | I8: =VLOOKUP(C2,'Qualifier Lobbies'!C5:L42,7,0) | J8: =VLOOKUP(C2,'Qualifier Lobbies'!C5:L42,8,0) | K8: =VLOOKUP(C2,'Qualifier Lobbies'!C5:L42,9,0) | L8: =VLOOKUP(C2,'Qualifier Lobbies'!C5:L42,10,0)
B9: {='Qualifiers Pool'!J3:J12} -> !mp mods NF | C9: {='Qualifiers Pool'!H3:H12} -> NM1: nonoc - Relive [Insane] | D9: {='Qualifiers Pool'!I3:I12} -> !mp map 3924030 | G9: =IFERROR(VLOOKUP(G8,'Ref & Team list'!C3:F20,2,0),"") -> Shion Yorigami | I9: =IFERROR(VLOOKUP(I8,'Ref & Team list'!C3:F20,2,0),"") | J9: =IFERROR(VLOOKUP(J8,'Ref & Team list'!C3:F20,2,0),"") | K9: =IFERROR(VLOOKUP(K8,'Ref & Team list'!C3:F20,2,0),"") | L9: =IFERROR(VLOOKUP(L8,'Ref & Team list'!C3:F20,2,0),"")
B10: !mp mods NF | C10: NM2: void - Crisscrosser [Insane] | D10: !mp map 908887 | G10: =IFERROR(VLOOKUP(G8,'Ref & Team list'!C3:F20,3,0),"") -> iSimp22 | I10: =IFERROR(VLOOKUP(I8,'Ref & Team list'!C3:F20,3,0),"") | J10: =IFERROR(VLOOKUP(J8,'Ref & Team list'!C3:F20,3,0),"") | K10: =IFERROR(VLOOKUP(K8,'Ref & Team list'!C3:F20,3,0),"") | L10: =IFERROR(VLOOKUP(L8,'Ref & Team list'!C3:F20,3,0),"")
B11: !mp mods NF | C11: NM3: Sangatsu no Phantasia - Koufuku na Wagamama [Insane] | D11: !mp map 3035501 | G11: =IFERROR(VLOOKUP(G8,'Ref & Team list'!C3:F20,4,0),"") -> BluNuggets | I11: =IFERROR(VLOOKUP(I8,'Ref & Team list'!C3:F20,4,0),"") | J11: =IFERROR(VLOOKUP(J8,'Ref & Team list'!C3:F20,4,0),"") | K11: =IFERROR(VLOOKUP(K8,'Ref & Team list'!C3:F20,4,0),"") | L11: =IFERROR(VLOOKUP(L8,'Ref & Team list'!C3:F20,4,0),"")
B12: !mp mods NF | C12: NM4: PSYQUI - Education [sorciere's Insane] | D12: !mp map 3737825
B13: !mp mods HD NF | C13: HD1: Ax feat. Natsukawa Yoko - Sakimori Renka [Insane] | D13: !mp map 2094462
B14: !mp mods HD NF | C14: HD2: Amane - BOOZEHOUND [Down's Insane] | D14: !mp map 2619929
B15: !mp mods HR NF | C15: HR1: THE ORAL CIGARETTES - Wagamama de Gomakasanaide [Panda & Melwoine's Insane] | D15: !mp map 2027623
B16: !mp mods HR NF | C16: HR2: Kajiura Yuki - Sis puella magica! [Tea Party] | D16: !mp map 1523138
B17: !mp mods DT NF | C17: DT1: ICHIKO - YOU'RE THE ONE [ANDREA & ASUKO'S HARD] | D17: !mp map 4105349
B18: !mp mods DT NF | C18: DT2: DIANA - Beethoven Virus [Aranel's Hard] | D18: !mp map 3533589

Sheet A7
B2: Lobby: | C2: A7 | E2: Referee: | G2: Remarks (Late and Replays) | I2: mp timer 120 | J2: !mp settings | K2: Forum link : https://osu.ppy.sh/community/forums/topics/1790898?n=1?
B3: MP LINK: | C3: https://osu.ppy.sh/mp/109957596 | E3: =VLOOKUP(C2,'Qualifier Lobbies'!C4:G42,5,0) -> Gamillie | G3: :thumbsup: None | I3: !mp set 0 3 16 | J3: !mp abort
B4: Room Command: | E4: =VLOOKUP(C2,'Qualifier Lobbies'!C4:F42,3,0) -> 45150 | I4: !mp start 10 | J4: !mp aborttimer | K4: Mainsheet link : https://docs.google.com/spreadsheets/d/1u1R-0YeX71qksHP7hWq8QkjcpECX-9LSvskalZ8hxdg/edit?usp=sharing
B5: Results: | C5: =IFS(C3="","Put the MP link first!",C3>"", "**Qualifier Lobby "&C2&"**" &CHAR(13)& " MP LINK: "&C3&" "&CHAR(13)&" Referee Notes: "&G3) &CHAR(13) -> **Qualifier Lobby A7** MP LINK: https://osu.ppy.sh/mp/109957596 Referee Notes: :thumbsup: None | E5: =VLOOKUP(C2,'Qualifier Lobbies'!C4:F42,4,0)&" UTC" -> 12:00 UTC | I5: MP COMMANDS | J5: !mp addref (name)
B7: Mappool | G7: =IFERROR("!mp invite " & G9,"") -> !mp invite Mewo_ | I7: =IFERROR("!mp invite " & I9,"") -> !mp invite Tohkura | J7: =IFERROR("!mp invite " & J9,"") -> !mp invite PoorQuaIityMeat | K7: =IFERROR("!mp invite " & K9,"") -> !mp invite | L7: =IFERROR("!mp invite " & L9,"") -> !mp invite
B8: Mod Command | C8: Map Name | D8: Map Command | G8: =VLOOKUP(C2,'Qualifier Lobbies'!C5:L42,6,0) -> Mewo My Waifu | I8: =VLOOKUP(C2,'Qualifier Lobbies'!C5:L42,7,0) -> CocoaGoats | J8: =VLOOKUP(C2,'Qualifier Lobbies'!C5:L42,8,0) -> PoorQuaIityMeatpilow | K8: =VLOOKUP(C2,'Qualifier Lobbies'!C5:L42,9,0) | L8: =VLOOKUP(C2,'Qualifier Lobbies'!C5:L42,10,0)
B9: {='Qualifiers Pool'!J3:J12} -> !mp mods NF | C9: {='Qualifiers Pool'!H3:H12} -> NM1: nonoc - Relive [Insane] | D9: {='Qualifiers Pool'!I3:I12} -> !mp map 3924030 | G9: =IFERROR(VLOOKUP(G8,'Ref & Team list'!C3:F20,2,0),"") -> Mewo_ | I9: =IFERROR(VLOOKUP(I8,'Ref & Team list'!C3:F20,2,0),"") -> Tohkura | J9: =IFERROR(VLOOKUP(J8,'Ref & Team list'!C3:F20,2,0),"") -> PoorQuaIityMeat | K9: =IFERROR(VLOOKUP(K8,'Ref & Team list'!C3:F20,2,0),"") | L9: =IFERROR(VLOOKUP(L8,'Ref & Team list'!C3:F20,2,0),"")
B10: !mp mods NF | C10: NM2: void - Crisscrosser [Insane] | D10: !mp map 908887 | G10: =IFERROR(VLOOKUP(G8,'Ref & Team list'!C3:F20,3,0),"") -> Zertoaster | I10: =IFERROR(VLOOKUP(I8,'Ref & Team list'!C3:F20,3,0),"") -> pika_Zero | J10: =IFERROR(VLOOKUP(J8,'Ref & Team list'!C3:F20,3,0),"") -> Pilllow | K10: =IFERROR(VLOOKUP(K8,'Ref & Team list'!C3:F20,3,0),"") | L10: =IFERROR(VLOOKUP(L8,'Ref & Team list'!C3:F20,3,0),"")
B11: !mp mods NF | C11: NM3: Sangatsu no Phantasia - Koufuku na Wagamama [Insane] | D11: !mp map 3035501 | G11: =IFERROR(VLOOKUP(G8,'Ref & Team list'!C3:F20,4,0),"") -> Lol3270 | I11: =IFERROR(VLOOKUP(I8,'Ref & Team list'!C3:F20,4,0),"") -> Glaucia | J11: =IFERROR(VLOOKUP(J8,'Ref & Team list'!C3:F20,4,0),"") | K11: =IFERROR(VLOOKUP(K8,'Ref & Team list'!C3:F20,4,0),"") | L11: =IFERROR(VLOOKUP(L8,'Ref & Team list'!C3:F20,4,0),"")
B12: !mp mods NF | C12: NM4: PSYQUI - Education [sorciere's Insane] | D12: !mp map 3737825
B13: !mp mods HD NF | C13: HD1: Ax feat. Natsukawa Yoko - Sakimori Renka [Insane] | D13: !mp map 2094462
B14: !mp mods HD NF | C14: HD2: Amane - BOOZEHOUND [Down's Insane] | D14: !mp map 2619929
B15: !mp mods HR NF | C15: HR1: THE ORAL CIGARETTES - Wagamama de Gomakasanaide [Panda & Melwoine's Insane] | D15: !mp map 2027623
B16: !mp mods HR NF | C16: HR2: Kajiura Yuki - Sis puella magica! [Tea Party] | D16: !mp map 1523138
B17: !mp mods DT NF | C17: DT1: ICHIKO - YOU'RE THE ONE [ANDREA & ASUKO'S HARD] | D17: !mp map 4105349
B18: !mp mods DT NF | C18: DT2: DIANA - Beethoven Virus [Aranel's Hard] | D18: !mp map 3533589

Sheet A8
B2: Lobby: | C2: A8 | E2: Referee: | G2: Remarks (Late and Replays) | I2: mp timer 120 | J2: !mp settings | K2: Forum link : https://osu.ppy.sh/community/forums/topics/1790898?n=1?
B3: MP LINK: | C3: https://osu.ppy.sh/community/matches/109959176 | E3: =VLOOKUP(C2,'Qualifier Lobbies'!C4:G42,5,0) -> Emerald Ages | G3: :thumbsup: None | I3: !mp set 0 3 16 | J3: !mp abort
B4: Room Command: | C4: ="!mp make PTE : (Qualifiers) vs ("&C2&")" -> !mp make PTE : (Qualifiers) vs (A8) | E4: =VLOOKUP(C2,'Qualifier Lobbies'!C4:F42,3,0) -> 45150 | I4: !mp start 10 | J4: !mp aborttimer | K4: Mainsheet link : https://docs.google.com/spreadsheets/d/1u1R-0YeX71qksHP7hWq8QkjcpECX-9LSvskalZ8hxdg/edit?usp=sharing
B5: Results: | C5: =IFS(C3="","Put the MP link first!",C3>"", "**Qualifier Lobby "&C2&"**" &CHAR(13)& " MP LINK: "&C3&" "&CHAR(13)&" Referee Notes: "&G3) &CHAR(13) -> **Qualifier Lobby A8** MP LINK: https://osu.ppy.sh/community/matches/109959176 Referee Notes: :thumbsup: None | E5: =VLOOKUP(C2,'Qualifier Lobbies'!C4:F42,4,0)&" UTC" -> 14:00 UTC | I5: MP COMMANDS | J5: !mp addref (name)
B7: Mappool | G7: =IFERROR("!mp invite " & G9,"") -> !mp invite Tsekyro | I7: =IFERROR("!mp invite " & I9,"") -> !mp invite RakiMiku | J7: =IFERROR("!mp invite " & J9,"") -> !mp invite Kochindera | K7: =IFERROR("!mp invite " & K9,"") -> !mp invite | L7: =IFERROR("!mp invite " & L9,"") -> !mp invite
B8: Mod Command | C8: Map Name | D8: Map Command | G8: =VLOOKUP(C2,'Qualifier Lobbies'!C5:L42,6,0) -> Beancurd | I8: =VLOOKUP(C2,'Qualifier Lobbies'!C5:L42,7,0) -> 3000CombinedHours | J8: =VLOOKUP(C2,'Qualifier Lobbies'!C5:L42,8,0) -> PES E9L9 | K8: =VLOOKUP(C2,'Qualifier Lobbies'!C5:L42,9,0) | L8: =VLOOKUP(C2,'Qualifier Lobbies'!C5:L42,10,0)
B9: {='Qualifiers Pool'!J3:J12} -> !mp mods NF | C9: {='Qualifiers Pool'!H3:H12} -> NM1: nonoc - Relive [Insane] | D9: {='Qualifiers Pool'!I3:I12} -> !mp map 3924030 | G9: =IFERROR(VLOOKUP(G8,'Ref & Team list'!C3:F20,2,0),"") -> Tsekyro | I9: =IFERROR(VLOOKUP(I8,'Ref & Team list'!C3:F20,2,0),"") -> RakiMiku | J9: =IFERROR(VLOOKUP(J8,'Ref & Team list'!C3:F20,2,0),"") -> Kochindera | K9: =IFERROR(VLOOKUP(K8,'Ref & Team list'!C3:F20,2,0),"") | L9: =IFERROR(VLOOKUP(L8,'Ref & Team list'!C3:F20,2,0),"")
B10: !mp mods NF | C10: NM2: void - Crisscrosser [Insane] | D10: !mp map 908887 | G10: =IFERROR(VLOOKUP(G8,'Ref & Team list'!C3:F20,3,0),"") -> GeneralMayo | I10: =IFERROR(VLOOKUP(I8,'Ref & Team list'!C3:F20,3,0),"") -> WorstGamer | J10: =IFERROR(VLOOKUP(J8,'Ref & Team list'!C3:F20,3,0),"") -> Hoshifurii | K10: =IFERROR(VLOOKUP(K8,'Ref & Team list'!C3:F20,3,0),"") | L10: =IFERROR(VLOOKUP(L8,'Ref & Team list'!C3:F20,3,0),"")
B11: !mp mods NF | C11: NM3: Sangatsu no Phantasia - Koufuku na Wagamama [Insane] | D11: !mp map 3035501 | G11: =IFERROR(VLOOKUP(G8,'Ref & Team list'!C3:F20,4,0),"") -> Carsoon | I11: =IFERROR(VLOOKUP(I8,'Ref & Team list'!C3:F20,4,0),"") -> C L O N E | J11: =IFERROR(VLOOKUP(J8,'Ref & Team list'!C3:F20,4,0),"") -> Gamillie | K11: =IFERROR(VLOOKUP(K8,'Ref & Team list'!C3:F20,4,0),"") | L11: =IFERROR(VLOOKUP(L8,'Ref & Team list'!C3:F20,4,0),"")
B12: !mp mods NF | C12: NM4: PSYQUI - Education [sorciere's Insane] | D12: !mp map 3737825
B13: !mp mods HD NF | C13: HD1: Ax feat. Natsukawa Yoko - Sakimori Renka [Insane] | D13: !mp map 2094462
B14: !mp mods HD NF | C14: HD2: Amane - BOOZEHOUND [Down's Insane] | D14: !mp map 2619929
B15: !mp mods HR NF | C15: HR1: THE ORAL CIGARETTES - Wagamama de Gomakasanaide [Panda & Melwoine's Insane] | D15: !mp map 2027623
B16: !mp mods HR NF | C16: HR2: Kajiura Yuki - Sis puella magica! [Tea Party] | D16: !mp map 1523138
B17: !mp mods DT NF | C17: DT1: ICHIKO - YOU'RE THE ONE [ANDREA & ASUKO'S HARD] | D17: !mp map 4105349
B18: !mp mods DT NF | C18: DT2: DIANA - Beethoven Virus [Aranel's Hard] | D18: !mp map 3533589

Sheet A9
B2: Lobby: | C2: A9 | E2: Referee: | G2: Remarks (Late and Replays) | I2: mp timer 120 | J2: !mp settings | K2: Forum link : https://osu.ppy.sh/community/forums/topics/1790898?n=1?
B3: MP LINK: | E3: =VLOOKUP(C2,'Qualifier Lobbies'!C4:G42,5,0) -> Emerald Ages | G3: :thumbsup: None | I3: !mp set 0 3 16 | J3: !mp abort
B4: Room Command: | C4: ="!mp make PTE : (Qualifiers) vs ("&C2&")" -> !mp make PTE : (Qualifiers) vs (A9) | E4: =VLOOKUP(C2,'Qualifier Lobbies'!C4:F42,3,0) -> 45150 | I4: !mp start 10 | J4: !mp aborttimer | K4: Mainsheet link : https://docs.google.com/spreadsheets/d/1u1R-0YeX71qksHP7hWq8QkjcpECX-9LSvskalZ8hxdg/edit?usp=sharing
B5: Results: | C5: =IFS(C3="","Put the MP link first!",C3>"", "**Qualifier Lobby "&C2&"**" &CHAR(13)& " MP LINK: "&C3&" "&CHAR(13)&" Referee Notes: "&G3) &CHAR(13) -> Put the MP link first! | E5: =VLOOKUP(C2,'Qualifier Lobbies'!C4:F42,4,0)&" UTC" -> 16:00 UTC | I5: MP COMMANDS | J5: !mp addref (name)
B7: Mappool | G7: =IFERROR("!mp invite " & G9,"") -> !mp invite | I7: =IFERROR("!mp invite " & I9,"") -> !mp invite | J7: =IFERROR("!mp invite " & J9,"") -> !mp invite | K7: =IFERROR("!mp invite " & K9,"") -> !mp invite | L7: =IFERROR("!mp invite " & L9,"") -> !mp invite
B8: Mod Command | C8: Map Name | D8: Map Command | G8: =VLOOKUP(C2,'Qualifier Lobbies'!C5:L42,6,0) | I8: =VLOOKUP(C2,'Qualifier Lobbies'!C5:L42,7,0) | J8: =VLOOKUP(C2,'Qualifier Lobbies'!C5:L42,8,0) | K8: =VLOOKUP(C2,'Qualifier Lobbies'!C5:L42,9,0) | L8: =VLOOKUP(C2,'Qualifier Lobbies'!C5:L42,10,0)
