Workbook
Name Scoremode: 'Tourney settings'!$C$7
Name Gamemode: 'Tourney settings'!$C$5
Name TourneyAbb: 'Tourney settings'!$C$3
Name TeamList: 'Copy of Team List'!$B$3:$E$38
Name Maps: 'IceDynamixConditionalFormat (no'!$F$4:$H$510
Name RefNotes: 'Progress 1'!$G$3:$G$5

Sheet Team Qualifier format
B2: Team Name | C2: Captain | D2: Player 2 | E2: Player 3
B3: Pekora slaves | C3: Ha | D3: Joyplush | E3: Kekw
B4: Harambe | C4: K | D4: Hak | E4: Dog

Sheet Tourney settings
B2: Tournament Name | C2: Pekora's Tourney
B3: Tournament Abbereviation | C3: PT
B4: Scoremode | C4: 0
B5: Gamemode | C5: 3
B6: No. of players max in lobby | C6: 15
B8: Use NF | C8: TRUE
B10: Forum Post Link | C10: https://osu.ppy.sh/community/forums/topics/1619006?n=1
B11: Mainsheet Link | C11: https://docs.google.com/spreadsheets/d/1Nc4rE3ik1IsfNmEqylu9WdZVyIXj5kHImLweaCQgjZM/edit#gid=1476597357
B13: Time preparing for each map | C13: 90
B14: Start countdown time | C14: 5

Sheet Individual Qualifier format
B2: Players List | C2: Discord User
B3: Man | C3: Man#0000
B4: Pain | C4: Pain#7270
B5: What | C5: What#0000
B6: Damn | C6: Damn#4424
B7: 556353 | C7: euouae#0944
B8: Holy_Shit | C8: euouae2#3122
B9: Pekor_a | C9: Fuwub#0186
B10: Unreal | C10: Mihari Oyama#7203
B11: Seals | C11: Nebula#1652
B12: Android | C12: Smato#1999
B13: Craphead | C13: Sweeet#9205
B14: Retard | C14: Ѧ𝖕ѳӄαℜȡїѻꪑέᾗɸక#9610
B15: Whatchat | C15: 𝔇ῗ𝓼ɢϑʂȶℑҋℊ#8986
B16: Malding | C16: kryptic#6400
B17: Halves | C17: ashwagafu#0002 DaijobuDes#0870
B18: Chin | C18: Nance#0001
B19: Horse | C19: mechadoodle#2614
... B21: Morse | C21: Chirijiraden#4992

Sheet Pekosign Individual Qualifier f
B2: Players List | C2: Discord User
B3: Man | C3: Man#0000
B4: Pain | C4: Pain#7270
B5: What | C5: What#0000
B6: Damn | C6: Damn#4424
B7: 556353 | C7: euouae#0944
B8: Holy_Shit | C8: euouae2#3122
B9: Pekor_a | C9: Fuwub#0186
B10: Unreal | C10: Mihari Oyama#7203
B11: Seals | C11: Nebula#1652
B12: Android | C12: Smato#1999
B13: Craphead | C13: Sweeet#9205
B14: Retard | C14: Ѧ𝖕ѳӄαℜȡїѻꪑέᾗɸక#9610
B15: Whatchat | C15: 𝔇ῗ𝓼ɢϑʂȶℑҋℊ#8986
B16: Malding | C16: kryptic#6400
B17: Halves | C17: ashwagafu#0002 DaijobuDes#0870
B18: Chin | C18: Nance#0001
B19: Horse | C19: mechadoodle#2614
... B21: Morse | C21: Chirijiraden#4992

Sheet PoolSample
D2: Mod# | E2: Song | F2: BeatmapID | H2: Beatmap String | I2: Map Command | J2: Mod Command
B3: Qualifier | C3: {=MOD(SEQUENCE(9*25,1)-1,25)+1} -> 1 | D3: NM1 | E3: Imy - Divine's Game [Extra] | F3: 3276259 | H3: {=IF(D3:D177="","",HYPERLINK("https://osu.ppy.sh/b/"&F3:F177,D3:D177&": "&E3:E177))} -> NM1: Imy - Divine's Game [Extra] | I3: {=IF(F3:F177="","","!mp map "&F3:F177)} -> !mp map 3276259 | J3: {=IF(D3:D228="","","!mp mods "&IF(LEFT(D3:D177,2)="NM","NF",IF(LEFT(D3:D177,2)="FM","FreeMod",IF(LEFT(D3:D177,2)="TB","FreeMod",LEFT(D3:D177,2)&" NF"))))} -> !mp mods NF
C4: 2 | D4: NM2 | E4: technoplanet - Juvenile [Extreme] | F4: 2826730 | H4: NM2: technoplanet - Juvenile [Extreme] | I4: !mp map 2826730 | J4: !mp mods NF
C5: 3 | D5: NM3 | E5: Nanahoshi Kangengakudan - Andromeda [Galaxy] | F5: 2347615 | H5: NM3: Nanahoshi Kangengakudan - Andromeda [Galaxy] | I5: !mp map 2347615 | J5: !mp mods NF
C6: 4 | D6: NM4 | E6: Function Phantom - Euclid [Fifth Postulate] | F6: 908093 | H6: NM4: Function Phantom - Euclid [Fifth Postulate] | I6: !mp map 908093 | J6: !mp mods NF
C7: 5 | D7: HD1 | E7: la la larks - ego-izm [bro-ken] | F7: 2514176 | H7: HD1: la la larks - ego-izm [bro-ken] | I7: !mp map 2514176 | J7: !mp mods HD NF
C8: 6 | D8: HD2 | E8: Wednesday Campanella - Nishi Tamao [Corsace] | F8: 3167107 | H8: HD2: Wednesday Campanella - Nishi Tamao [Corsace] | I8: !mp map 3167107 | J8: !mp mods HD NF
C9: 7 | D9: HR1 | E9: TUYU - Namikare [Koori's Extra] | F9: 2349954 | H9: HR1: TUYU - Namikare [Koori's Extra] | I9: !mp map 2349954 | J9: !mp mods HR NF
C10: 8 | D10: HR2 | E10: Chitose Kudou - CHO-DARI- [Darui~] | F10: 2108442 | H10: HR2: Chitose Kudou - CHO-DARI- [Darui~] | I10: !mp map 2108442 | J10: !mp mods HR NF
C11: 9 | D11: DT1 | E11: Kola Kid - timer [Insane] | F11: 2277128 | H11: DT1: Kola Kid - timer [Insane] | I11: !mp map 2277128 | J11: !mp mods DT NF
C12: 10 | D12: DT2 | E12: 3L - Spring of Dreams [Lunatic] | F12: 1559749 | H12: DT2: 3L - Spring of Dreams [Lunatic] | I12: !mp map 1559749 | J12: !mp mods DT NF
C13: 11
C14: 12
C15: 13
C16: 14
C17: 15
C18: 16
C19: 17
C20: 18
C21: 19
C22: 20
C23: 21
C24: 22
... C27: 25
B28: Round of 64 | C28: 1
C29: 2
C30: 3
C31: 4
C32: 5
C33: 6
C34: 7
C35: 8
C36: 9
C37: 10
C38: 11
C39: 12
C40: 13
... C52: 25
B53: Round of 32 | C53: 1
C54: 2
...

Sheet RefList
B2: Referee List
B3: RemIscute07
B4: Tsukime
B5: - S a y o -
B6: you got eczema
B7: Dragbit 5
B8: MCshitacc
B9: InnProve
B10: lelxdme
B11: -Pekora-
B12: Fuwub
B13: Social_Distance
B14: ShadeCegLgMn

Sheet Adjust -Pekora-s Solo-Qualifier
B2: Lobby: | C2: A | E2: Referee: | G2: Remarks (Late and Replays) | I2: mp timer 120 | J2: !mp settings
B3: MP LINK: | E3: =VLOOKUP(C2,'Pekosign Individual qualifier s'!C5:V37,4,0) -> #N/A | G3: :thumbsup: None | I3: !mp set 0 3 16 | J3: !mp abort
B4: Room Command: | C4: ="!mp make "&TourneyAbb&" : (Qualifiers) vs ("&C2&")" -> !mp make PT : (Qualifiers) vs (A) | E4: =VLOOKUP(C2,'Pekosign Individual qualifier s'!C5:V37,2,0) -> #N/A | I4: !mp start 10 | J4: !mp aborttimer
B5: Results: | C5: =IFS(C3="","Put the MP link first!",C3>"", "**Qualifier Lobby "&C2&"**" &CHAR(13)& " MP LINK: "&C3&" "&CHAR(13)&" Referee Notes: "&G3) &CHAR(13) -> Put the MP link first! | E5: =CONCATENATE(VLOOKUP(C2,'Pekosign Individual qualifier s'!C5:V37,3,0)," UTC") -> #N/A | I5: MP COMMANDS | J5: !mp addref (name)
B7: Player Name | C7: Command | E7: Present? | G7: Mappool
B8: =(VLOOKUP($C$2,'Pekosign Individual qualifier s'!$C$5:$V$37,5,0)) -> #N/A | C8: =IFS(B8="","",B8<>"","!mp invite "&B8) -> #N/A | E8: FALSE | G8: Map Command | I8: Mod Command | J8: Map Name
B9: =(VLOOKUP($C$2,'Pekosign Individual qualifier s'!$C$5:$V$37,6,0)) -> #N/A | C9: =IFS(B9="","",B9<>"","!mp invite "&B9) -> #N/A | E9: FALSE | G9: {=PoolSample!I3:I12} -> !mp map 3276259 | I9: {=PoolSample!J3:J12} -> !mp mods NF | J9: {=PoolSample!H3:H12} -> NM1: Imy - Divine's Game [Extra]
B10: =(VLOOKUP($C$2,'Pekosign Individual qualifier s'!$C$5:$V$37,7,0)) -> #N/A | C10: =IFS(B10="","",B10<>"","!mp invite "&B10) -> #N/A | E10: FALSE | G10: !mp map 2826730 | I10: !mp mods NF | J10: NM2: technoplanet - Juvenile [Extreme]
B11: =(VLOOKUP($C$2,'Pekosign Individual qualifier s'!$C$5:$V$37,8,0)) -> #N/A | C11: =IFS(B11="","",B11<>"","!mp invite "&B11) -> #N/A | E11: FALSE | G11: !mp map 2347615 | I11: !mp mods NF | J11: NM3: Nanahoshi Kangengakudan - Andromeda [Galaxy]
B12: =(VLOOKUP($C$2,'Pekosign Individual qualifier s'!$C$5:$V$37,9,0)) -> #N/A | C12: =IFS(B12="","",B12<>"","!mp invite "&B12) -> #N/A | E12: FALSE | G12: !mp map 908093 | I12: !mp mods NF | J12: NM4: Function Phantom - Euclid [Fifth Postulate]
B13: =(VLOOKUP($C$2,'Pekosign Individual qualifier s'!$C$5:$V$37,5,0)) -> #N/A | C13: =IFS(B13="","",B13<>"","!mp invite "&B13) -> #N/A | E13: FALSE | G13: !mp map 2514176 | I13: !mp mods HD NF | J13: HD1: la la larks - ego-izm [bro-ken]
B14: =(VLOOKUP($C$2,'Pekosign Individual qualifier s'!$C$5:$V$37,10,0)) -> #N/A | C14: =IFS(B14="","",B14<>"","!mp invite "&B14) -> #N/A | E14: FALSE | G14: !mp map 3167107 | I14: !mp mods HD NF | J14: HD2: Wednesday Campanella - Nishi Tamao [Corsace]
B15: =(VLOOKUP($C$2,'Pekosign Individual qualifier s'!$C$5:$V$37,11,0)) -> #N/A | C15: =IFS(B15="","",B15<>"","!mp invite "&B15) -> #N/A | E15: FALSE | G15: !mp map 2349954 | I15: !mp mods HR NF | J15: HR1: TUYU - Namikare [Koori's Extra]
B16: =(VLOOKUP($C$2,'Pekosign Individual qualifier s'!$C$5:$V$37,12,0)) -> #N/A | C16: =IFS(B16="","",B16<>"","!mp invite "&B16) -> #N/A | E16: FALSE | G16: !mp map 2108442 | I16: !mp mods HR NF | J16: HR2: Chitose Kudou - CHO-DARI- [Darui~]
B17: =(VLOOKUP($C$2,'Pekosign Individual qualifier s'!$C$5:$V$37,13,0)) -> #N/A | C17: =IFS(B17="","",B17<>"","!mp invite "&B17) -> #N/A | E17: FALSE | G17: !mp map 2277128 | I17: !mp mods DT NF | J17: DT1: Kola Kid - timer [Insane]
B18: =(VLOOKUP($C$2,'Pekosign Individual qualifier s'!$C$5:$V$37,14,0)) -> #N/A | C18: =IFS(B18="","",B18<>"","!mp invite "&B18) -> #N/A | E18: FALSE | G18: !mp map 1559749 | I18: !mp mods DT NF | J18: DT2: 3L - Spring of Dreams [Lunatic]
B19: =(VLOOKUP($C$2,'Pekosign Individual qualifier s'!$C$5:$V$37,15,0)) -> #N/A | C19: =IFS(B19="","",B19<>"","!mp invite "&B19) -> #N/A | E19: FALSE
B20: =(VLOOKUP($C$2,'Pekosign Individual qualifier s'!$C$5:$V$37,16,0)) -> #N/A | C20: =IFS(B20="","",B20<>"","!mp invite "&B20) -> #N/A | E20: FALSE
B21: =(VLOOKUP($C$2,'Pekosign Individual qualifier s'!$C$5:$V$37,17,0)) -> #N/A | C21: =IFS(B21="","",B21<>"","!mp invite "&B21) -> #N/A | E21: FALSE
B22: =(VLOOKUP($C$2,'Pekosign Individual qualifier s'!$C$5:$V$37,18,0)) -> #N/A | C22: =IFS(B22="","",B22<>"","!mp invite "&B22) -> #N/A | E22: FALSE

Sheet v2 adjustment possibilities and
B2: Lobby: | C2: A1 | E2: Referee: | G2: Remarks (Late and Replays) | I2: mp timer 120 | J2: !mp settings
B3: MP LINK: | E3: =VLOOKUP(C2,'Pekosign Individual qualifier s'!C5:V37,4,0) -> 0 | G3: :thumbsup: None | I3: !mp set 0 3 16 | J3: !mp abort
B4: Room Command: | C4: ="!mp make "&TourneyAbb&" : (Qualifiers) vs ("&C2&")" -> !mp make PT : (Qualifiers) vs (A1) | E4: =VLOOKUP(C2,'Pekosign Individual qualifier s'!C5:V37,2,0) -> 12 / 15 | I4: !mp start 10 | J4: !mp aborttimer
B5: Results: | C5: =IFS(C3="","Put the MP link first!",C3>"", "**Qualifier Lobby "&C2&"**" &CHAR(13)& " MP LINK: "&C3&" "&CHAR(13)&" Referee Notes: "&G3) &CHAR(13) -> Put the MP link first! | E5: =CONCATENATE(VLOOKUP(C2,'Pekosign Individual qualifier s'!C5:V37,3,0)," UTC") -> 44618 UTC | I5: MP COMMANDS | J5: !mp addref (name)
B7: Player Name | C7: Command | E7: Present? < shows Discord user here | G7: Mappool
B8: =(VLOOKUP($C$2,'Pekosign Individual qualifier s'!$C$5:$V$37,5,0)) -> -Pekora- | C8: =IFS(B8="","",B8<>"","!mp invite "&B8) -> !mp invite -Pekora- | E8: FALSE | G8: MC < musat be same color as well the other 2 columns | I8: Mod Command | J8: Map Name
B9: =(VLOOKUP($C$2,'Pekosign Individual qualifier s'!$C$5:$V$37,6,0)) -> Retard | C9: =IFS(B9="","",B9<>"","!mp invite "&B9) -> !mp invite Retard | E9: FALSE | G9: {=PoolSample!I3:I12} -> !mp map 3276259 | I9: {=PoolSample!J3:J12} -> !mp mods NF | J9: {=PoolSample!H3:H12} -> NM1: Imy - Divine's Game [Extra]
B10: =(VLOOKUP($C$2,'Pekosign Individual qualifier s'!$C$5:$V$37,7,0)) -> 556353 | C10: =IFS(B10="","",B10<>"","!mp invite "&B10) -> !mp invite 556353 | E10: FALSE | G10: !mp map 2826730 | I10: !mp mods NF | J10: NM2: technoplanet - Juvenile [Extreme]
B11: =(VLOOKUP($C$2,'Pekosign Individual qualifier s'!$C$5:$V$37,8,0)) -> Whatchat | C11: =IFS(B11="","",B11<>"","!mp invite "&B11) -> !mp invite Whatchat | E11: FALSE | G11: !mp map 2347615 | I11: !mp mods NF | J11: NM3: Nanahoshi Kangengakudan - Andromeda [Galaxy]
B12: =(VLOOKUP($C$2,'Pekosign Individual qualifier s'!$C$5:$V$37,9,0)) -> Chin | C12: =IFS(B12="","",B12<>"","!mp invite "&B12) -> !mp invite Chin | E12: FALSE | G12: !mp map 908093 | I12: !mp mods NF | J12: NM4: Function Phantom - Euclid [Fifth Postulate]
B13: =(VLOOKUP($C$2,'Pekosign Individual qualifier s'!$C$5:$V$37,5,0)) -> -Pekora- | C13: =IFS(B13="","",B13<>"","!mp invite "&B13) -> !mp invite -Pekora- | E13: FALSE | G13: !mp map 2514176 | I13: !mp mods HD NF | J13: HD1: la la larks - ego-izm [bro-ken]
B14: =(VLOOKUP($C$2,'Pekosign Individual qualifier s'!$C$5:$V$37,10,0)) -> 556353 | C14: =IFS(B14="","",B14<>"","!mp invite "&B14) -> !mp invite 556353 | E14: FALSE | G14: !mp map 3167107 | I14: !mp mods HD NF | J14: HD2: Wednesday Campanella - Nishi Tamao [Corsace]
B15: =(VLOOKUP($C$2,'Pekosign Individual qualifier s'!$C$5:$V$37,11,0)) -> Holy_Shit | C15: =IFS(B15="","",B15<>"","!mp invite "&B15) -> !mp invite Holy_Shit | E15: FALSE | G15: !mp map 2349954 | I15: !mp mods HR NF | J15: HR1: TUYU - Namikare [Koori's Extra]
B16: =(VLOOKUP($C$2,'Pekosign Individual qualifier s'!$C$5:$V$37,12,0)) -> Halves | C16: =IFS(B16="","",B16<>"","!mp invite "&B16) -> !mp invite Halves | E16: FALSE | G16: !mp map 2108442 | I16: !mp mods HR NF | J16: HR2: Chitose Kudou - CHO-DARI- [Darui~]
B17: =(VLOOKUP($C$2,'Pekosign Individual qualifier s'!$C$5:$V$37,13,0)) -> Damn | C17: =IFS(B17="","",B17<>"","!mp invite "&B17) -> !mp invite Damn | E17: FALSE | G17: !mp map 2277128 | I17: !mp mods DT NF | J17: DT1: Kola Kid - timer [Insane]
B18: =(VLOOKUP($C$2,'Pekosign Individual qualifier s'!$C$5:$V$37,14,0)) -> Morse | C18: =IFS(B18="","",B18<>"","!mp invite "&B18) -> !mp invite Morse | E18: FALSE | G18: !mp map 1559749 | I18: !mp mods DT NF | J18: DT2: 3L - Spring of Dreams [Lunatic]
B19: =(VLOOKUP($C$2,'Pekosign Individual qualifier s'!$C$5:$V$37,15,0)) -> What | C19: =IFS(B19="","",B19<>"","!mp invite "&B19) -> !mp invite What | E19: FALSE
B20: =(VLOOKUP($C$2,'Pekosign Individual qualifier s'!$C$5:$V$37,16,0)) -> Holy_Shit | C20: =IFS(B20="","",B20<>"","!mp invite "&B20) -> !mp invite Holy_Shit | E20: FALSE
B21: =(VLOOKUP($C$2,'Pekosign Individual qualifier s'!$C$5:$V$37,17,0)) -> Halves | C21: =IFS(B21="","",B21<>"","!mp invite "&B21) -> !mp invite Halves | E21: FALSE
B22: =(VLOOKUP($C$2,'Pekosign Individual qualifier s'!$C$5:$V$37,18,0)) -> Retard | C22: =IFS(B22="","",B22<>"","!mp invite "&B22) -> !mp invite Retard | E22: FALSE

Sheet FINALIZING Draft for Individual
B2: Lobby: | C2: A1 | E2: Referee: | G2: Remarks (Late and Replays) | I2: =HYPERLINK('Tourney settings'!C10,"Forum post") -> Forum post | J2: =HYPERLINK('Tourney settings'!C11,"Mainsheet") -> Mainsheet
B3: MP LINK: | C3: =VLOOKUP(C2,'Pekosign Individual qualifier s'!C5:W37,21,0) | E3: =VLOOKUP(C2,'Pekosign Individual qualifier s'!C5:V37,5,0) -> -Pekora- | G3: :thumbsup: None | I3: ="!mp timer " &'Tourney settings'!$C$13 -> !mp timer 90 | J3: ="!mp set " &'Tourney settings'!$C$4&" "&'Tourney settings'!$C$5&" "&'Tourney settings'!$C$6 -> !mp set 0 3 15
B4: Room Command: | C4: ="!mp make "&TourneyAbb&" : (Qualifiers) vs ("&C2&")" -> !mp make PT : (Qualifiers) vs (A1) | E4: =VLOOKUP(C2,'Pekosign Individual qualifier s'!C5:V37,3,0) -> 44618 | I4: !mp settings | J4: ="!mp start " &'Tourney settings'!$C$14 -> !mp start 5
B5: Results: | C5: =IFS(C3="","Put the MP link first @ Ref Schedule Qual sheet!",C3>"", "**Qualifier Lobby "&C2&"**" &CHAR(13)& " MP LINK: "&C3&" "&CHAR(13)&" Ref Notes: "&G3) &CHAR(13) -> Put the MP link first @ Ref Schedule Qual sheet! | E5: =VLOOKUP(C2,'Pekosign Individual qualifier s'!C5:V37,4,0) -> 0 | I5: !mp aborttimer | J5: !mp abort
B7: Player Name | C7: Invite commands/Discord user | D7: P? | E7: Tick for Disc ID | G7: Mappool
B8: =(VLOOKUP($C$2,'Pekosign Individual qualifier s'!$C$5:$V$37,6,0)) -> Retard | C8: =IFERROR(IF(E8=TRUE,VLOOKUP(B8,'Individual Qualifier format'!$B$3:$C$22,2,0),"!mp invite " & B8),"") -> !mp invite Retard | D8: FALSE | E8: FALSE | G8: Map ID | I8: Mods | J8: Map Name
B9: =(VLOOKUP($C$2,'Pekosign Individual qualifier s'!$C$5:$V$37,7,0)) -> 556353 | C9: =IFERROR(IF(E9=TRUE,VLOOKUP(B9,'Individual Qualifier format'!$B$3:$C$22,2,0),"!mp invite " & B9),"") -> !mp invite 556353 | D9: FALSE | E9: FALSE | G9: {=PoolSample!I3:I12} -> !mp map 3276259 | I9: {=PoolSample!J3:J12} -> !mp mods NF | J9: {=PoolSample!H3:H12} -> NM1: Imy - Divine's Game [Extra]
B10: =(VLOOKUP($C$2,'Pekosign Individual qualifier s'!$C$5:$V$37,8,0)) -> Whatchat | C10: =IFERROR(IF(E10=TRUE,VLOOKUP(B10,'Individual Qualifier format'!$B$3:$C$22,2,0),"!mp invite " & B10),"") -> !mp invite Whatchat | D10: FALSE | E10: FALSE | G10: !mp map 2826730 | I10: !mp mods NF | J10: NM2: technoplanet - Juvenile [Extreme]
B11: =(VLOOKUP($C$2,'Pekosign Individual qualifier s'!$C$5:$V$37,9,0)) -> Chin | C11: =IFERROR(IF(E11=TRUE,VLOOKUP(B11,'Individual Qualifier format'!$B$3:$C$22,2,0),"!mp invite " & B11),"") -> !mp invite Chin | D11: FALSE | E11: FALSE | G11: !mp map 2347615 | I11: !mp mods NF | J11: NM3: Nanahoshi Kangengakudan - Andromeda [Galaxy]
B12: =(VLOOKUP($C$2,'Pekosign Individual qualifier s'!$C$5:$V$37,10,0)) -> 556353 | C12: =IFERROR(IF(E12=TRUE,VLOOKUP(B12,'Individual Qualifier format'!$B$3:$C$22,2,0),"!mp invite " & B12),"") -> !mp invite 556353 | D12: FALSE | E12: FALSE | G12: !mp map 908093 | I12: !mp mods NF | J12: NM4: Function Phantom - Euclid [Fifth Postulate]
B13: =(VLOOKUP($C$2,'Pekosign Individual qualifier s'!$C$5:$V$37,11,0)) -> Holy_Shit | C13: =IFERROR(IF(E13=TRUE,VLOOKUP(B13,'Individual Qualifier format'!$B$3:$C$22,2,0),"!mp invite " & B13),"") -> !mp invite Holy_Shit | D13: FALSE | E13: FALSE | G13: !mp map 2514176 | I13: !mp mods HD NF | J13: HD1: la la larks - ego-izm [bro-ken]
B14: =(VLOOKUP($C$2,'Pekosign Individual qualifier s'!$C$5:$V$37,12,0)) -> Halves | C14: =IFERROR(IF(E14=TRUE,VLOOKUP(B14,'Individual Qualifier format'!$B$3:$C$22,2,0),"!mp invite " & B14),"") -> !mp invite Halves | D14: FALSE | E14: FALSE | G14: !mp map 3167107 | I14: !mp mods HD NF | J14: HD2: Wednesday Campanella - Nishi Tamao [Corsace]
B15: =(VLOOKUP($C$2,'Pekosign Individual qualifier s'!$C$5:$V$37,13,0)) -> Damn | C15: =IFERROR(IF(E15=TRUE,VLOOKUP(B15,'Individual Qualifier format'!$B$3:$C$22,2,0),"!mp invite " & B15),"") -> !mp invite Damn | D15: FALSE | E15: FALSE | G15: !mp map 2349954 | I15: !mp mods HR NF | J15: HR1: TUYU - Namikare [Koori's Extra]
B16: =(VLOOKUP($C$2,'Pekosign Individual qualifier s'!$C$5:$V$37,14,0)) -> Morse | C16: =IFERROR(IF(E16=TRUE,VLOOKUP(B16,'Individual Qualifier format'!$B$3:$C$22,2,0),"!mp invite " & B16),"") -> !mp invite Morse | D16: FALSE | E16: FALSE | G16: !mp map 2108442 | I16: !mp mods HR NF | J16: HR2: Chitose Kudou - CHO-DARI- [Darui~]
B17: =(VLOOKUP($C$2,'Pekosign Individual qualifier s'!$C$5:$V$37,15,0)) -> What | C17: =IFERROR(IF(E17=TRUE,VLOOKUP(B17,'Individual Qualifier format'!$B$3:$C$22,2,0),"!mp invite " & B17),"") -> !mp invite What | D17: FALSE | E17: FALSE | G17: !mp map 2277128 | I17: !mp mods DT NF | J17: DT1: Kola Kid - timer [Insane]
B18: =(VLOOKUP($C$2,'Pekosign Individual qualifier s'!$C$5:$V$37,16,0)) -> Holy_Shit | C18: =IFERROR(IF(E18=TRUE,VLOOKUP(B18,'Individual Qualifier format'!$B$3:$C$22,2,0),"!mp invite " & B18),"") -> !mp invite Holy_Shit | D18: FALSE | E18: FALSE | G18: !mp map 1559749 | I18: !mp mods DT NF | J18: DT2: 3L - Spring of Dreams [Lunatic]
B19: =(VLOOKUP($C$2,'Pekosign Individual qualifier s'!$C$5:$V$37,17,0)) -> Halves | C19: =IFERROR(IF(E19=TRUE,VLOOKUP(B19,'Individual Qualifier format'!$B$3:$C$22,2,0),"!mp invite " & B19),"") -> !mp invite Halves | D19: FALSE | E19: FALSE
B20: =(VLOOKUP($C$2,'Pekosign Individual qualifier s'!$C$5:$V$37,18,0)) -> Retard | C20: =IFERROR(IF(E20=TRUE,VLOOKUP(B20,'Individual Qualifier format'!$B$3:$C$22,2,0),"!mp invite " & B20),"") -> !mp invite Retard | D20: FALSE | E20: FALSE
B21: =(VLOOKUP($C$2,'Pekosign Individual qualifier s'!$C$5:$V$37,19,0)) -> 556353 | C21: =IFERROR(IF(E21=TRUE,VLOOKUP(B21,'Individual Qualifier format'!$B$3:$C$22,2,0),"!mp invite " & B21),"") -> !mp invite 556353 | D21: FALSE | E21: FALSE
B22: =(VLOOKUP($C$2,'Pekosign Individual qualifier s'!$C$5:$V$37,20,0)) -> Man | C22: =IFERROR(IF(E22=TRUE,VLOOKUP(B22,'Individual Qualifier format'!$B$3:$C$22,2,0),"!mp invite " & B22),"") -> !mp invite Man | D22: FALSE | E22: FALSE

Sheet Progress 0
B2: Lobby: | C2: A | F2: Referee: | H2: Mp commands
B3: MP LINK: | F3: Name of Referee | H3: mp timer 120 | I3: mp start 10
B4: Room Command: | C4: !mp make formula | F4: Time of the lobby | H4: !mp aborttimer | I4: !mp abort
B6: Results: | C6: Results formula | F6: Remarks (Late and Replays)
B8: Player Name | C8: Command | D8: Present? | F8: Mappool
B9: Player formula | C9: Formula for player invite | D9: FALSE | F9: Map Command | H9: Mod Command | I9: Map Name
D10: FALSE | F10: !mp map | H10: Mod commands w/format
C11: ***Cross line when present is checked | D11: FALSE
D12: FALSE
D13: FALSE
D14: FALSE | I14: Map Names w/format
D15: FALSE
D16: FALSE
D17: FALSE
D18: FALSE
D19: FALSE
D20: FALSE
D21: FALSE
D22: FALSE
D23: FALSE

Sheet Progress 2 (V1)
B2: Lobby: | C2: A | E2: Referee: | G2: Remarks (Late and Replays) | I2: mp timer 120 | J2: !mp settings
B3: MP LINK: | C3: https://osu.ppy.sh/mp/98134569 | E3: =VLOOKUP(C2,'Pekosign Individual qualifier s'!C5:V37,4,0) & " :3" -> #N/A | G3: :thumbsup: None | I3: !mp timer 90 | J3: !mp abort
B4: Room Command: | C4: ="!mp make "&TourneyAbb&" : (Qualifiers) vs ("&C2&")" -> !mp make PT : (Qualifiers) vs (A) | E4: =VLOOKUP(C2,'Pekosign Individual qualifier s'!C5:V37,2,0) -> #N/A | I4: !mp start 10 | J4: !mp aborttimer
B5: Results: | C5: =IFS(C3="","Put the MP link!",C3>"", "**Qualifier Lobby "&C2&"**" &CHAR(13)& " MP LINK: "&C3&" "&CHAR(13)&" Referee Notes: "&G3) &CHAR(13) -> **Qualifier Lobby A** MP LINK: https://osu.ppy.sh/mp/98134569 Referee Notes: :thumbsup: None | E5: =VLOOKUP(C2,'Pekosign Individual qualifier s'!C5:V37,3,0) -> #N/A | I5: MP COMMANDS | J5: !mp addref (name)
B7: Player Name | C7: Command | E7: Present? | G7: Mappool
B8: =(VLOOKUP($C$2,'Pekosign Individual qualifier s'!$C$5:$V$37,5,0)) -> #N/A | C8: =IFS(B8="","",B8<>"","!mp invite "&B8) -> #N/A | E8: TRUE | G8: Map Command | I8: Mod Command | J8: Map Name
B9: =(VLOOKUP($C$2,'Pekosign Individual qualifier s'!$C$5:$V$37,6,0)) -> #N/A | C9: =IFS(B9="","",B9<>"","!mp invite "&B9) -> #N/A | E9: TRUE | G9: {=PoolSample!I3:I12} -> !mp map 3276259 | I9: {=PoolSample!J3:J12} -> !mp mods NF | J9: {=PoolSample!H3:H12} -> NM1: Imy - Divine's Game [Extra]
B10: =(VLOOKUP($C$2,'Pekosign Individual qualifier s'!$C$5:$V$37,7,0)) -> #N/A | C10: =IFS(B10="","",B10<>"","!mp invite "&B10) -> #N/A | E10: TRUE | G10: !mp map 2826730 | I10: !mp mods NF | J10: NM2: technoplanet - Juvenile [Extreme]
B11: =(VLOOKUP($C$2,'Pekosign Individual qualifier s'!$C$5:$V$37,8,0)) -> #N/A | C11: =IFS(B11="","",B11<>"","!mp invite "&B11) -> #N/A | E11: TRUE | G11: !mp map 2347615 | I11: !mp mods NF | J11: NM3: Nanahoshi Kangengakudan - Andromeda [Galaxy]
B12: =(VLOOKUP($C$2,'Pekosign Individual qualifier s'!$C$5:$V$37,9,0)) -> #N/A | C12: =IFS(B12="","",B12<>"","!mp invite "&B12) -> #N/A | E12: FALSE | G12: !mp map 908093 | I12: !mp mods NF | J12: NM4: Function Phantom - Euclid [Fifth Postulate]
B13: =(VLOOKUP($C$2,'Pekosign Individual qualifier s'!$C$5:$V$37,5,0)) -> #N/A | C13: =IFS(B13="","",B13<>"","!mp invite "&B13) -> #N/A | E13: FALSE | G13: !mp map 2514176 | I13: !mp mods HD NF | J13: HD1: la la larks - ego-izm [bro-ken]
B14: =(VLOOKUP($C$2,'Pekosign Individual qualifier s'!$C$5:$V$37,10,0)) -> #N/A | C14: =IFS(B14="","",B14<>"","!mp invite "&B14) -> #N/A | E14: FALSE | G14: !mp map 3167107 | I14: !mp mods HD NF | J14: HD2: Wednesday Campanella - Nishi Tamao [Corsace]
B15: =(VLOOKUP($C$2,'Pekosign Individual qualifier s'!$C$5:$V$37,11,0)) -> #N/A | C15: =IFS(B15="","",B15<>"","!mp invite "&B15) -> #N/A | E15: FALSE | G15: !mp map 2349954 | I15: !mp mods HR NF | J15: HR1: TUYU - Namikare [Koori's Extra]
B16: =(VLOOKUP($C$2,'Pekosign Individual qualifier s'!$C$5:$V$37,12,0)) -> #N/A | C16: =IFS(B16="","",B16<>"","!mp invite "&B16) -> #N/A | E16: FALSE | G16: !mp map 2108442 | I16: !mp mods HR NF | J16: HR2: Chitose Kudou - CHO-DARI- [Darui~]
B17: =(VLOOKUP($C$2,'Pekosign Individual qualifier s'!$C$5:$V$37,13,0)) -> #N/A | C17: =IFS(B17="","",B17<>"","!mp invite "&B17) -> #N/A | E17: FALSE | G17: !mp map 2277128 | I17: !mp mods DT NF | J17: DT1: Kola Kid - timer [Insane]
B18: =(VLOOKUP($C$2,'Pekosign Individual qualifier s'!$C$5:$V$37,14,0)) -> #N/A | C18: =IFS(B18="","",B18<>"","!mp invite "&B18) -> #N/A | E18: FALSE | G18: !mp map 1559749 | I18: !mp mods DT NF | J18: DT2: 3L - Spring of Dreams [Lunatic]
B19: =(VLOOKUP($C$2,'Pekosign Individual qualifier s'!$C$5:$V$37,15,0)) -> #N/A | C19: =IFS(B19="","",B19<>"","!mp invite "&B19) -> #N/A | E19: FALSE
B20: =(VLOOKUP($C$2,'Pekosign Individual qualifier s'!$C$5:$V$37,16,0)) -> #N/A | C20: =IFS(B20="","",B20<>"","!mp invite "&B20) -> #N/A | E20: FALSE
B21: =(VLOOKUP($C$2,'Pekosign Individual qualifier s'!$C$5:$V$37,17,0)) -> #N/A | C21: =IFS(B21="","",B21<>"","!mp invite "&B21) -> #N/A | E21: FALSE
B22: =(VLOOKUP($C$2,'Pekosign Individual qualifier s'!$C$5:$V$37,18,0)) -> #N/A | C22: =IFS(B22="","",B22<>"","!mp invite "&B22) -> #N/A | E22: FALSE
G23: Heavily Inspired by Shade template, definitely did not copy formulas from there :tro:

Sheet Progress 1
B2: Lobby: | C2: D | E2: Referee: | G2: Remarks (Late and Replays) | I2: mp timer 120 | J2: !mp settings
B3: MP LINK: | E3: =VLOOKUP(C2,'Pekosign Individual qualifier s'!C5:V37,4,0) & " :3" -> #N/A | G3: I inted the quals unreal | I3: !mp timer 90 | J3: !mp abort
B4: Room Command: | C4: ="!mp make "&TourneyAbb&" : (Qualifiers) vs ("&C2&")" -> !mp make PT : (Qualifiers) vs (D) | E4: =VLOOKUP(C2,'Pekosign Individual qualifier s'!C5:V37,2,0) -> #N/A | I4: !mp start 10 | J4: !mp aborttimer
B5: Results: | C5: =IFS(C3="","Put the MP link!",C3>"","Qualifier Lobby "&C2&" results: "&C3&" Referee Notes: "&G5) -> Put the MP link! | E5: =VLOOKUP(C2,'Pekosign Individual qualifier s'!C5:V37,3,0) -> #N/A | I5: MP COMMANDS | J5: !mp addref #mp_(Number)
B7: Player Name | C7: Command | E7: Present? | G7: Mappool
B8: Player formula | C8: Formula for player invite | E8: FALSE | G8: Map Command | I8: Mod Command | J8: Map Name
E9: FALSE | G9: Importrange the mappool
E10: FALSE
E11: FALSE
E12: FALSE
E13: FALSE
E14: FALSE
E15: FALSE
E16: FALSE
E17: FALSE
E18: FALSE
E19: FALSE
E20: FALSE
E21: FALSE
E22: FALSE

Sheet Pekosign Individual qualifier s
C2: QUALIFIERS SCHEDULES
E3: Double click dates | F3: UTC+0
C4: Lobby | D4: Slots taken | E4: Date | F4: Time | G4: Referee | H4: Player 1 | I4: Player 2 | J4: Player 3 | K4: Player 4 | L4: Player 5 | M4: Player 6 | N4: Player 7 | O4: Player 8 | P4: Player 9 | Q4: Player 10 | R4: Player 11 | S4: Player 12 | T4: Player 13 | U4: Player 14 | V4: Player 15 | W4: MP LINK
A5: Saturday | C5: A1 | D5: =IF(COUNTIF(H5:V5,"*") = 0, "-", COUNTIF(H5:V5,"*") &" / 15") -> 12 / 15 | E5: 44618 | F5: 0 | G5: -Pekora- | H5: Retard | I5: 556353 | J5: Whatchat | K5: Chin | L5: 556353 | M5: Holy_Shit | N5: Halves | O5: Damn | P5: Morse | Q5: What | R5: Holy_Shit | S5: Halves | T5: Retard | U5: 556353 | V5: Man
C6: A2 | D6: =IF(COUNTIF(H6:V6,"*") = 0, "-", COUNTIF(H6:V6,"*") &" / 15") -> 1 / 15 | E6: 44618 | F6: 0.083333333 | G6: Fuwub | H6: ShizuVoice
C7: A3 | D7: =IF(COUNTIF(H7:V7,"*") = 0, "-", COUNTIF(H7:V7,"*") &" / 15") -> - | E7: 44618 | F7: 0.16666667 | G7: Social_Distance
C8: A4 | D8: =IF(COUNTIF(H8:V8,"*") = 0, "-", COUNTIF(H8:V8,"*") &" / 15") -> - | E8: 44618 | F8: 0.25 | G8: ShadeCegLgMn
C9: A5 | D9: =IF(COUNTIF(H9:V9,"*") = 0, "-", COUNTIF(H9:V9,"*") &" / 15") -> - | F9: 0.5
C10: A6 | D10: =IF(COUNTIF(H10:V10,"*") = 0, "-", COUNTIF(H10:V10,"*") &" / 15") -> - | F10: 0.58333333
C11: A7 | D11: =IF(COUNTIF(H11:V11,"*") = 0, "-", COUNTIF(H11:V11,"*") &" / 15") -> - | F11: 0.66666667
C12: A8 | D12: =IF(COUNTIF(H12:V12,"*") = 0, "-", COUNTIF(H12:V12,"*") &" / 15") -> - | F12: 0.75
C13: A9 | D13: =IF(COUNTIF(H13:V13,"*") = 0, "-", COUNTIF(H13:V13,"*") &" / 15") -> - | F13: 0.875
C14: A10 | D14: =IF(COUNTIF(H14:V14,"*") = 0, "-", COUNTIF(H14:V14,"*") &" / 15") -> - | F14: 0.99930556
A16: Sunday | C16: B1 | D16: =IF(COUNTIF(H16:V16,"*") = 0, "-", COUNTIF(H16:V16,"*") &" / 15") -> - | F16: 0
C17: B2 | D17: =IF(COUNTIF(H17:V17,"*") = 0, "-", COUNTIF(H17:V17,"*") &" / 15") -> - | F17: 0.083333333
C18: B3 | D18: =IF(COUNTIF(H18:V18,"*") = 0, "-", COUNTIF(H18:V18,"*") &" / 15") -> - | F18: 0.16666667
C19: B4 | D19: =IF(COUNTIF(H19:V19,"*") = 0, "-", COUNTIF(H19:V19,"*") &" / 15") -> - | F19: 0.25
C20: B5 | D20: =IF(COUNTIF(H20:V20,"*") = 0, "-", COUNTIF(H20:V20,"*") &" / 15") -> - | F20: 0.5
C21: B6 | D21: =IF(COUNTIF(H21:V21,"*") = 0, "-", COUNTIF(H21:V21,"*") &" / 15") -> - | F21: 0.58333333
C22: B7 | D22: =IF(COUNTIF(H22:V22,"*") = 0, "-", COUNTIF(H22:V22,"*") &" / 15") -> - | F22: 0.66666667
C23: B8 | D23: =IF(COUNTIF(H23:V23,"*") = 0, "-", COUNTIF(H23:V23,"*") &" / 15") -> - | F23: 0.75
C24: B9 | D24: =IF(COUNTIF(H24:V24,"*") = 0, "-", COUNTIF(H24:V24,"*") &" / 15") -> - | F24: 0.875
C25: B10 | D25: =IF(COUNTIF(H25:V25,"*") = 0, "-", COUNTIF(H25:V25,"*") &" / 15") -> - | F25: 0.99930556
A27: Custom Lobbies | C27: X1 | D27: =IF(COUNTIF(H27:V27,"*") = 0, "-", COUNTIF(H27:V27,"*") &" / 15") -> -
C28: X2 | D28: =IF(COUNTIF(H28:V28,"*") = 0, "-", COUNTIF(H28:V28,"*") &" / 15") -> -
C29: X3 | D29: =IF(COUNTIF(H29:V29,"*") = 0, "-", COUNTIF(H29:V29,"*") &" / 15") -> -
C30: X4 | D30: =IF(COUNTIF(H30:V30,"*") = 0, "-", COUNTIF(H30:V30,"*") &" / 15") -> -
C31: X5 | D31: =IF(COUNTIF(H31:V31,"*") = 0, "-", COUNTIF(H31:V31,"*") &" / 15") -> -
C32: X6 | D32: =IF(COUNTIF(H32:V32,"*") = 0, "-", COUNTIF(H32:V32,"*") &" / 15") -> -
C33: X7 | D33: =IF(COUNTIF(H33:V33,"*") = 0, "-", COUNTIF(H33:V33,"*") &" / 15") -> -
C34: X8 | D34: =IF(COUNTIF(H34:V34,"*") = 0, "-", COUNTIF(H34:V34,"*") &" / 15") -> -
C35: X9 | D35: =IF(COUNTIF(H35:V35,"*") = 0, "-", COUNTIF(H35:V35,"*") &" / 15") -> -
C36: X10 | D36: =IF(COUNTIF(H36:V36,"*") = 0, "-", COUNTIF(H36:V36,"*") &" / 15") -> -

Sheet IceDynamixConditionalFormat (no
B2: Input | F2: Auto-generated
B3: Stage | C3: Mod# | D3: Map ID | E3: Map Name | F3: String | G3: Map Command | H3: Mod Command
B4: Qualifiers | C4: NM1 | D4: 397535 | E4: Kuba Oms - My Love [Insane] | F4: {=IF(C4:C510="",,HYPERLINK("https://osu.ppy.sh/b/"&D4:D510,C4:C510&": "&E4:E510))} -> NM1: Kuba Oms - My Love [Insane] | G4: {=IF(D4:D510="",,"!mp map "&D4:D510&" "&Gamemode)} -> #NAME? | H4: {=IF(C4:C510="",,"!mp mods "&IFS(LEFT(C4:C510,2)="NM",IF(#REF!,"NF",""),LEFT(C4:C510,2)="FM","Freemod",LEFT(C4:C510,2)="TB","Freemod",TRUE,TRIM(LEFT(C4:C510,2)&" "&IF(#REF!,"NF",""))))} -> #REF!
B5: Qualifiers | C5: NM2 | D5: 397535 | E5: Kuba Oms - My Love [Insane] | F5: NM2: Kuba Oms - My Love [Insane] | G5: #NAME? | H5: #REF!
B6: Qualifiers | C6: NM3 | D6: 397535 | E6: Kuba Oms - My Love [Insane] | F6: NM3: Kuba Oms - My Love [Insane] | G6: #NAME? | H6: #REF!
B7: Qualifiers | C7: NM4 | D7: 397535 | E7: Kuba Oms - My Love [Insane] | F7: NM4: Kuba Oms - My Love [Insane] | G7: #NAME? | H7: #REF!
B8: Qualifiers | C8: HD1 | D8: 397535 | E8: Kuba Oms - My Love [Insane] | F8: HD1: Kuba Oms - My Love [Insane] | G8: #NAME? | H8: #REF!
B9: Qualifiers | C9: HD2 | D9: 397535 | E9: Kuba Oms - My Love [Insane] | F9: HD2: Kuba Oms - My Love [Insane] | G9: #NAME? | H9: #REF!
B10: Qualifiers | C10: HR1 | D10: 397535 | E10: Kuba Oms - My Love [Insane] | F10: HR1: Kuba Oms - My Love [Insane] | G10: #NAME? | H10: #REF!
B11: Qualifiers | C11: HR2 | D11: 397535 | E11: Kuba Oms - My Love [Insane] | F11: HR2: Kuba Oms - My Love [Insane] | G11: #NAME? | H11: #REF!
B12: Qualifiers | C12: DT1 | D12: 397535 | E12: Kuba Oms - My Love [Insane] | F12: DT1: Kuba Oms - My Love [Insane] | G12: #NAME? | H12: #REF!
B13: Qualifiers | C13: DT2 | D13: 397535 | E13: Kuba Oms - My Love [Insane] | F13: DT2: Kuba Oms - My Love [Insane] | G13: #NAME? | H13: #REF!
B14: Qualifiers | C14: FM1 | D14: 397535 | E14: Kuba Oms - My Love [Insane] | F14: FM1: Kuba Oms - My Love [Insane] | G14: #NAME? | H14: !mp mods Freemod
B15: Qualifiers | C15: FM2 | D15: 397535 | E15: Kuba Oms - My Love [Insane] | F15: FM2: Kuba Oms - My Love [Insane] | G15: #NAME? | H15: !mp mods Freemod
B16: Qualifiers | C16: FM3 | D16: 397535 | E16: Kuba Oms - My Love [Insane] | F16: FM3: Kuba Oms - My Love [Insane] | G16: #NAME? | H16: !mp mods Freemod
B17: Qualifiers | C17: FM4 | D17: 397535 | E17: Kuba Oms - My Love [Insane] | F17: FM4: Kuba Oms - My Love [Insane] | G17: #NAME? | H17: !mp mods Freemod
B18: Qualifiers | C18: TB1 | D18: 397535 | E18: Kuba Oms - My Love [Insane] | F18: TB1: Kuba Oms - My Love [Insane] | G18: #NAME? | H18: !mp mods Freemod

Sheet Team Qualifier Schedules
C2: QUALIFIERS SCHEDULES
E3: Double click dates | F3: UTC+0
C4: Lobby | D4: Slots taken | E4: Date | F4: Time | G4: Referee | H4: Team 1 | I4: Team 2 | J4: Team 3 | K4: Team 4 | L4: Team 5 | M4: MP LINK
A5: Saturday | C5: A1 | D5: =IF(COUNTIF(H5:L5,"*") = 0, "-", COUNTIF(H5:L5,"*") &" / 15") -> 4 / 15 | E5: 44618 | F5: 0 | G5: -Pekora- | H5: W gaming | I5: Snails | J5: Fnatic | K5: EG | M5: https://osu.ppy.sh/community/matches/88396460
C6: A2 | D6: =IF(COUNTIF(H6:L6,"*") = 0, "-", COUNTIF(H6:L6,"*") &" / 15") -> - | E6: 44618 | F6: 0.083333333 | G6: Fuwub
C7: A3 | D7: =IF(COUNTIF(H7:L7,"*") = 0, "-", COUNTIF(H7:L7,"*") &" / 15") -> - | E7: 44618 | F7: 0.16666667 | G7: Social_Distance
C8: A4 | D8: =IF(COUNTIF(H8:L8,"*") = 0, "-", COUNTIF(H8:L8,"*") &" / 15") -> - | E8: 44618 | F8: 0.25 | G8: ShadeCegLgMn
C9: A5 | D9: =IF(COUNTIF(H9:L9,"*") = 0, "-", COUNTIF(H9:L9,"*") &" / 15") -> - | F9: 0.5
C10: A6 | D10: =IF(COUNTIF(H10:L10,"*") = 0, "-", COUNTIF(H10:L10,"*") &" / 15") -> - | F10: 0.58333333
C11: A7 | D11: =IF(COUNTIF(H11:L11,"*") = 0, "-", COUNTIF(H11:L11,"*") &" / 15") -> - | F11: 0.66666667
C12: A8 | D12: =IF(COUNTIF(H12:L12,"*") = 0, "-", COUNTIF(H12:L12,"*") &" / 15") -> - | F12: 0.75
C13: A9 | D13: =IF(COUNTIF(H13:L13,"*") = 0, "-", COUNTIF(H13:L13,"*") &" / 15") -> - | F13: 0.875
C14: A10 | D14: =IF(COUNTIF(H14:L14,"*") = 0, "-", COUNTIF(H14:L14,"*") &" / 15") -> - | F14: 0.99930556
A16: Sunday | C16: B1 | D16: =IF(COUNTIF(H16:L16,"*") = 0, "-", COUNTIF(H16:L16,"*") &" / 15") -> - | F16: 0
C17: B2 | D17: =IF(COUNTIF(H17:L17,"*") = 0, "-", COUNTIF(H17:L17,"*") &" / 15") -> - | F17: 0.083333333
C18: B3 | D18: =IF(COUNTIF(H18:L18,"*") = 0, "-", COUNTIF(H18:L18,"*") &" / 15") -> - | F18: 0.16666667
C19: B4 | D19: =IF(COUNTIF(H19:L19,"*") = 0, "-", COUNTIF(H19:L19,"*") &" / 15") -> - | F19: 0.25
C20: B5 | D20: =IF(COUNTIF(H20:L20,"*") = 0, "-", COUNTIF(H20:L20,"*") &" / 15") -> - | F20: 0.5
C21: B6 | D21: =IF(COUNTIF(H21:L21,"*") = 0, "-", COUNTIF(H21:L21,"*") &" / 15") -> - | F21: 0.58333333
C22: B7 | D22: =IF(COUNTIF(H22:L22,"*") = 0, "-", COUNTIF(H22:L22,"*") &" / 15") -> - | F22: 0.66666667
C23: B8 | D23: =IF(COUNTIF(H23:L23,"*") = 0, "-", COUNTIF(H23:L23,"*") &" / 15") -> - | F23: 0.75
C24: B9 | D24: =IF(COUNTIF(H24:L24,"*") = 0, "-", COUNTIF(H24:L24,"*") &" / 15") -> - | F24: 0.875
C25: B10 | D25: =IF(COUNTIF(H25:L25,"*") = 0, "-", COUNTIF(H25:L25,"*") &" / 15") -> - | F25: 0.99930556
A27: Custom Lobbies | C27: X1 | D27: =IF(COUNTIF(H27:L27,"*") = 0, "-", COUNTIF(H27:L27,"*") &" / 15") -> -
C28: X2 | D28: =IF(COUNTIF(H28:L28,"*") = 0, "-", COUNTIF(H28:L28,"*") &" / 15") -> -
C29: X3 | D29: =IF(COUNTIF(H29:L29,"*") = 0, "-", COUNTIF(H29:L29,"*") &" / 15") -> -
C30: X4 | D30: =IF(COUNTIF(H30:L30,"*") = 0, "-", COUNTIF(H30:L30,"*") &" / 15") -> -
C31: X5 | D31: =IF(COUNTIF(H31:L31,"*") = 0, "-", COUNTIF(H31:L31,"*") &" / 15") -> -
C32: X6 | D32: =IF(COUNTIF(H32:L32,"*") = 0, "-", COUNTIF(H32:L32,"*") &" / 15") -> -
C33: X7 | D33: =IF(COUNTIF(H33:L33,"*") = 0, "-", COUNTIF(H33:L33,"*") &" / 15") -> -
C34: X8 | D34: =IF(COUNTIF(H34:L34,"*") = 0, "-", COUNTIF(H34:L34,"*") &" / 15") -> -
C35: X9 | D35: =IF(COUNTIF(H35:L35,"*") = 0, "-", COUNTIF(H35:L35,"*") &" / 15") -> -
C36: X10 | D36: =IF(COUNTIF(H36:L36,"*") = 0, "-", COUNTIF(H36:L36,"*") &" / 15") -> -

Sheet Copy of Team List
B2: Team Name | C2: {="Player "&SEQUENCE(1,3)} -> Player 1 | D2: Player 2 | E2: Player 3
B3: W gaming | C3: 1p1 | D3: 1p2 | E3: 1p3
B4: Snails | C4: 2p1 | D4: 2p2
B5: Fnatic | C5: boaster | D5: derke
B6: EG | C6: demon1 | D6: boostio | E6: jawgemo
