Workbook

Sheet Sheet1

Sheet Copy of Team List Template
C3: NO OF TEAMS : - 64 - | E3: =IMAGE("https://a.ppy.sh/17959882?1687932364.jpeg") | F3: CAPTAIN | G3: =IMAGE("https://a.ppy.sh/14238097?1686376598.jpeg)") | H3: PLAYER 2 | I3: =IMAGE("https://a.ppy.sh/17959882?1687932364.jpeg") | J3: PLAYER 3 | K3: - THE TEAM's MOTTO HERE -
F4: #105,555 | H4: #103,415 | J4: #133,041
C6: TEAM A | E6: =IMAGE("https://a.ppy.sh/17959882?1687932364.jpeg") | F6: CAPTAIN | G6: =IMAGE("https://a.ppy.sh/14238097?1686376598.jpeg)") | H6: PLAYER 2 | I6: =IMAGE("https://a.ppy.sh/17959882?1687932364.jpeg") | J6: PLAYER 3 | K6: WE ARE THE TRIO-GOATS !
F7: #105,555 | H7: #103,415 | J7: #133,041
C9: TEAM A | E9: =IMAGE("https://a.ppy.sh/17959882?1687932364.jpeg") | F9: CAPTAIN | G9: =IMAGE("https://a.ppy.sh/14238097?1686376598.jpeg)") | H9: PLAYER 2 | I9: =IMAGE("https://a.ppy.sh/17959882?1687932364.jpeg") | J9: PLAYER 3 | K9: WE ARE THE TRIO-GOATS !
F10: #105,555 | H10: #103,415 | J10: #133,041
C12: TEAM A | E12: =IMAGE("https://a.ppy.sh/17959882?1687932364.jpeg") | F12: CAPTAIN | G12: =IMAGE("https://a.ppy.sh/14238097?1686376598.jpeg)") | H12: PLAYER 2 | I12: =IMAGE("https://a.ppy.sh/17959882?1687932364.jpeg") | J12: PLAYER 3 | K12: WE ARE THE TRIO-GOATS !
F13: #105,555 | H13: #103,415 | J13: #133,041
C15: TEAM A | E15: =IMAGE("https://a.ppy.sh/17959882?1687932364.jpeg") | F15: CAPTAIN | G15: =IMAGE("https://a.ppy.sh/14238097?1686376598.jpeg)") | H15: PLAYER 2 | I15: =IMAGE("https://a.ppy.sh/17959882?1687932364.jpeg") | J15: PLAYER 3 | K15: WE ARE THE TRIO-GOATS !
F16: #105,555 | H16: #103,415 | J16: #133,041
C18: TEAM A | E18: =IMAGE("https://a.ppy.sh/17959882?1687932364.jpeg") | F18: CAPTAIN | G18: =IMAGE("https://a.ppy.sh/14238097?1686376598.jpeg)") | H18: PLAYER 2 | I18: =IMAGE("https://a.ppy.sh/17959882?1687932364.jpeg") | J18: PLAYER 3 | K18: WE ARE THE TRIO-GOATS !
F19: #105,555 | H19: #103,415 | J19: #133,041
C21: TEAM A | E21: =IMAGE("https://a.ppy.sh/17959882?1687932364.jpeg") | F21: CAPTAIN | G21: =IMAGE("https://a.ppy.sh/14238097?1686376598.jpeg)") | H21: PLAYER 2 | I21: =IMAGE("https://a.ppy.sh/17959882?1687932364.jpeg") | J21: PLAYER 3 | K21: WE ARE THE TRIO-GOATS !
F22: #105,555 | H22: #103,415 | J22: #133,041
C24: TEAM A | E24: =IMAGE("https://a.ppy.sh/17959882?1687932364.jpeg") | F24: CAPTAIN | G24: =IMAGE("https://a.ppy.sh/14238097?1686376598.jpeg)") | H24: PLAYER 2 | I24: =IMAGE("https://a.ppy.sh/17959882?1687932364.jpeg") | J24: PLAYER 3 | K24: WE ARE THE TRIO-GOATS !
F25: #105,555 | H25: #103,415 | J25: #133,041
C27: TEAM A | E27: =IMAGE("https://a.ppy.sh/17959882?1687932364.jpeg") | F27: CAPTAIN | G27: =IMAGE("https://a.ppy.sh/14238097?1686376598.jpeg)") | H27: PLAYER 2 | I27: =IMAGE("https://a.ppy.sh/17959882?1687932364.jpeg") | J27: PLAYER 3 | K27: WE ARE THE TRIO-GOATS !
F28: #105,555 | H28: #103,415 | J28: #133,041
C30: TEAM A | E30: =IMAGE("https://a.ppy.sh/17959882?1687932364.jpeg") | F30: CAPTAIN | G30: =IMAGE("https://a.ppy.sh/14238097?1686376598.jpeg)") | H30: PLAYER 2 | I30: =IMAGE("https://a.ppy.sh/17959882?1687932364.jpeg") | J30: PLAYER 3 | K30: WE ARE THE TRIO-GOATS !
F31: #105,555 | H31: #103,415 | J31: #133,041
C33: TEAM A | E33: =IMAGE("https://a.ppy.sh/17959882?1687932364.jpeg") | F33: CAPTAIN | G33: =IMAGE("https://a.ppy.sh/14238097?1686376598.jpeg)") | H33: PLAYER 2 | I33: =IMAGE("https://a.ppy.sh/17959882?1687932364.jpeg") | J33: PLAYER 3 | K33: WE ARE THE TRIO-GOATS !
F34: #105,555 | H34: #103,415 | J34: #133,041
C36: TEAM A | E36: =IMAGE("https://a.ppy.sh/17959882?1687932364.jpeg") | F36: CAPTAIN | G36: =IMAGE("https://a.ppy.sh/14238097?1686376598.jpeg)") | H36: PLAYER 2 | I36: =IMAGE("https://a.ppy.sh/17959882?1687932364.jpeg") | J36: PLAYER 3 | K36: WE ARE THE TRIO-GOATS !
F37: #105,555 | H37: #103,415 | J37: #133,041
C39: TEAM A | E39: =IMAGE("https://a.ppy.sh/17959882?1687932364.jpeg") | F39: CAPTAIN | G39: =IMAGE("https://a.ppy.sh/14238097?1686376598.jpeg)") | H39: PLAYER 2 | I39: =IMAGE("https://a.ppy.sh/17959882?1687932364.jpeg") | J39: PLAYER 3 | K39: WE ARE THE TRIO-GOATS !
F40: #105,555 | H40: #103,415 | J40: #133,041
C42: TEAM A | E42: =IMAGE("https://a.ppy.sh/17959882?1687932364.jpeg") | F42: CAPTAIN | G42: =IMAGE("https://a.ppy.sh/14238097?1686376598.jpeg)") | H42: PLAYER 2 | I42: =IMAGE("https://a.ppy.sh/17959882?1687932364.jpeg") | J42: PLAYER 3 | K42: WE ARE THE TRIO-GOATS !
F43: #105,555 | H43: #103,415 | J43: #133,041
C45: TEAM A | E45: =IMAGE("https://a.ppy.sh/17959882?1687932364.jpeg") | F45: CAPTAIN | G45: =IMAGE("https://a.ppy.sh/14238097?1686376598.jpeg)") | H45: PLAYER 2 | I45: =IMAGE("https://a.ppy.sh/17959882?1687932364.jpeg") | J45: PLAYER 3 | K45: WE ARE THE TRIO-GOATS !
F46: #105,555 | H46: #103,415 | J46: #133,041
C48: TEAM A | E48: =IMAGE("https://a.ppy.sh/17959882?1687932364.jpeg") | F48: CAPTAIN | G48: =IMAGE("https://a.ppy.sh/14238097?1686376598.jpeg)") | H48: PLAYER 2 | I48: =IMAGE("https://a.ppy.sh/17959882?1687932364.jpeg") | J48: PLAYER 3 | K48: WE ARE THE TRIO-GOATS !
F49: #105,555 | H49: #103,415 | J49: #133,041
C51: TEAM A | E51: =IMAGE("https://a.ppy.sh/17959882?1687932364.jpeg") | F51: CAPTAIN | G51: =IMAGE("https://a.ppy.sh/14238097?1686376598.jpeg)") | H51: PLAYER 2 | I51: =IMAGE("https://a.ppy.sh/17959882?1687932364.jpeg") | J51: PLAYER 3 | K51: WE ARE THE TRIO-GOATS !
F52: #105,555 | H52: #103,415 | J52: #133,041
C54: TEAM A | E54: =IMAGE("https://a.ppy.sh/17959882?1687932364.jpeg") | F54: CAPTAIN | G54: =IMAGE("https://a.ppy.sh/14238097?1686376598.jpeg)") | H54: PLAYER 2 | I54: =IMAGE("https://a.ppy.sh/17959882?1687932364.jpeg") | J54: PLAYER 3 | K54: WE ARE THE TRIO-GOATS !
F55: #105,555 | H55: #103,415 | J55: #133,041
C57: TEAM A | E57: =IMAGE("https://a.ppy.sh/17959882?1687932364.jpeg") | F57: CAPTAIN | G57: =IMAGE("https://a.ppy.sh/14238097?1686376598.jpeg)") | H57: PLAYER 2 | I57: =IMAGE("https://a.ppy.sh/17959882?1687932364.jpeg") | J57: PLAYER 3 | K57: WE ARE THE TRIO-GOATS !
F58: #105,555 | H58: #103,415 | J58: #133,041
C60: TEAM A | E60: =IMAGE("https://a.ppy.sh/17959882?1687932364.jpeg") | F60: CAPTAIN | G60: =IMAGE("https://a.ppy.sh/14238097?1686376598.jpeg)") | H60: PLAYER 2 | I60: =IMAGE("https://a.ppy.sh/17959882?1687932364.jpeg") | J60: PLAYER 3 | K60: WE ARE THE TRIO-GOATS !
F61: #105,555 | H61: #103,415 | J61: #133,041
...

Sheet Map Pool Template
A2: c | D2: GRANDFINALS | F2: BO 9 <> 5.4 Ave. SR <> 3:00 AVE. LENGTH | O2: - mAPPOOL PACK -
D4: Banner | E4: Mod | F4: Artist - Song [Difficulty] | G4: SR | H4: BPM | I4: Length | J4: CS | K4: AR | L4: OD | M4: Map ID | N4: Suggester | O4: Comments
E5: c
A27: c | D27: FINALS | F27: BO 9 <> 5.4 Ave. SR <> 3:00 AVE. LENGTH | O27: - mAPPOOL PACK -
D29: Banner | E29: Mod | F29: Artist - Song [Difficulty] | G29: SR | H29: BPM | I29: Length | J29: CS | K29: AR | L29: OD | M29: Map ID | N29: Suggester | O29: Comments
E30: c
A53: c | D53: SEMIFINALS | F53: BO 9 <> 5.4 Ave. SR <> 3:00 AVE. LENGTH | O53: - mAPPOOL PACK -
D55: Banner | E55: Mod | F55: Artist - Song [Difficulty] | G55: SR | H55: BPM | I55: Length | J55: CS | K55: AR | L55: OD | M55: Map ID | N55: Suggester | O55: Comments
E56: c
A79: c | D79: QUARTERFINALS | F79: BO 9 <> 5.4 Ave. SR <> 3:00 AVE. LENGTH | O79: - mAPPOOL PACK -
D81: Banner | E81: Mod | F81: Artist - Song [Difficulty] | G81: SR | H81: BPM | I81: Length | J81: CS | K81: AR | L81: OD | M81: Map ID | N81: Suggester | O81: Comments
E82: c
A105: c | D105: RO 16 | F105: BO 9 <> 5.4 Ave. SR <> 3:00 AVE. LENGTH | O105: - mAPPOOL PACK -
D107: Banner | E107: Mod | F107: Artist - Song [Difficulty] | G107: SR | H107: BPM | I107: Length | J107: CS | K107: AR | L107: OD | M107: Map ID | N107: Suggester | O107: Comments
E108: c
A131: c | D131: RO 32 | F131: BO 9 <> 5.4 Ave. SR <> 3:00 AVE. LENGTH | O131: - mAPPOOL PACK -
D133: Banner | E133: Mod | F133: Artist - Song [Difficulty] | G133: SR | H133: BPM | I133: Length | J133: CS | K133: AR | L133: OD | M133: Map ID | N133: Suggester | O133: Comments
E134: c
F156: c
A157: c | D157: Qualifiers | F157: BO 9 <> 5.4 Ave. SR <> 3:00 AVE. LENGTH | O157: - mAPPOOL PACK -
D159: Banner | E159: Mod | F159: Artist - Song [Difficulty] | G159: SR | H159: BPM | I159: Length | J159: CS | K159: AR | L159: OD | M159: Map ID | N159: Suggester | O159: Comments
E160: c
D161: =IFERROR(__xludf.DUMMYFUNCTION("IMPORTRANGE(""1WeVYxODFFkAmdP-uHAXnUhNm6E5Mao-pWS0UkDdVoEY"",""GF!L5:W24"")"),"#REF!") -> #REF!

Sheet Bracket Schedule
M6: BRACKET MATCHES | S6: Upper Bracket | T6: Lower Bracket | U6: Bracket Reset
C9: c | D9: c | E9: c | J9: c | K9: c | L9: c | M9: c | N9: c | O9: c | P9: c | Q9: c | R9: c | S9: c | T9: c | U9: c
C10: Progress | J10: ID | K10: Date | L10: Time | M10: Team 1 | N10: Score | P10: Team 2 | Q10: Referee | R10: Streamer | S10: Commentator 1 | T10: Commentator 2 | U10: MP Link
C11: c | D11: c | E11: c | J11: c | K11: c | L11: c | M11: c | N11: c | O11: c | P11: c | Q11: c | R11: c | S11: c | T11: c | U11: c
J12: =IFERROR(__xludf.DUMMYFUNCTION("IMPORTRANGE(""https://docs.google.com/spreadsheets/d/1furEKtJ5gEFQB_8CRy1iNCTi7QIoca2qGHOcFGl5QjU/edit#gid=1684621565"",""Schedule!D4:G67"") "),1.0) -> 1 | K12: =IFERROR(__xludf.DUMMYFUNCTION("""COMPUTED_VALUE"""),45156.0) -> 45156 | L12: =IFERROR(__xludf.DUMMYFUNCTION("""COMPUTED_VALUE"""),0.5833333333333334) -> 0.58333333 | M12: =IFERROR(__xludf.DUMMYFUNCTION("""COMPUTED_VALUE"""),"small wiener club") -> small wiener club | N12: =IFERROR(__xludf.DUMMYFUNCTION("IMPORTRANGE(""https://docs.google.com/spreadsheets/d/1furEKtJ5gEFQB_8CRy1iNCTi7QIoca2qGHOcFGl5QjU/edit#gid=1684621565"",""Schedule!M4:N67"")"),"5") -> 5 | O12: =IFERROR(__xludf.DUMMYFUNCTION("""COMPUTED_VALUE"""),"0") -> 0 | P12: =IFERROR(__xludf.DUMMYFUNCTION("IMPORTRANGE(""https://docs.google.com/spreadsheets/d/1furEKtJ5gEFQB_8CRy1iNCTi7QIoca2qGHOcFGl5QjU/edit#gid=1684621565"",""Schedule!H4:L66"") "),"lowrank is my love") -> lowrank is my love | Q12: =IFERROR(__xludf.DUMMYFUNCTION("""COMPUTED_VALUE"""),"Emerald Ages") -> Emerald Ages | U12: =IFERROR(__xludf.DUMMYFUNCTION("IMPORTRANGE(""https://docs.google.com/spreadsheets/d/1furEKtJ5gEFQB_8CRy1iNCTi7QIoca2qGHOcFGl5QjU/edit#gid=1684621565"",""Schedule!O4:O67"") "),"https://osu.ppy.sh/community/matches/110051880") -> https://osu.ppy.sh/community/matches/110051880
G13: c | J13: =IFERROR(__xludf.DUMMYFUNCTION("""COMPUTED_VALUE"""),2.0) -> 2 | K13: =IFERROR(__xludf.DUMMYFUNCTION("""COMPUTED_VALUE"""),45157.0) -> 45157 | L13: =IFERROR(__xludf.DUMMYFUNCTION("""COMPUTED_VALUE"""),0.5) -> 0.5 | M13: =IFERROR(__xludf.DUMMYFUNCTION("""COMPUTED_VALUE"""),"middle-schooler wife") -> middle-schooler wife | N13: =IFERROR(__xludf.DUMMYFUNCTION("""COMPUTED_VALUE"""),"5") -> 5 | O13: =IFERROR(__xludf.DUMMYFUNCTION("""COMPUTED_VALUE"""),"1") -> 1 | P13: =IFERROR(__xludf.DUMMYFUNCTION("""COMPUTED_VALUE"""),"PLDT ANO NAAA") -> PLDT ANO NAAA | Q13: =IFERROR(__xludf.DUMMYFUNCTION("""COMPUTED_VALUE"""),"Gamillie") -> Gamillie | U13: =IFERROR(__xludf.DUMMYFUNCTION("""COMPUTED_VALUE"""),"https://osu.ppy.sh/mp/110066290") -> https://osu.ppy.sh/mp/110066290
D14: Round of 32 | G14: c | J14: =IFERROR(__xludf.DUMMYFUNCTION("""COMPUTED_VALUE"""),3.0) -> 3 | K14: =IFERROR(__xludf.DUMMYFUNCTION("""COMPUTED_VALUE"""),45158.0) -> 45158 | L14: =IFERROR(__xludf.DUMMYFUNCTION("""COMPUTED_VALUE"""),0.875) -> 0.875 | M14: =IFERROR(__xludf.DUMMYFUNCTION("""COMPUTED_VALUE"""),"The 3-star Threats") -> The 3-star Threats | N14: =IFERROR(__xludf.DUMMYFUNCTION("""COMPUTED_VALUE"""),"5") -> 5 | O14: =IFERROR(__xludf.DUMMYFUNCTION("""COMPUTED_VALUE"""),"1") -> 1 | P14: =IFERROR(__xludf.DUMMYFUNCTION("""COMPUTED_VALUE"""),"The sleepers") -> The sleepers | Q14: =IFERROR(__xludf.DUMMYFUNCTION("""COMPUTED_VALUE"""),"Mewo_") -> Mewo_ | U14: =IFERROR(__xludf.DUMMYFUNCTION("""COMPUTED_VALUE"""),"https://osu.ppy.sh/mp/110090518") -> https://osu.ppy.sh/mp/110090518
G15: c | J15: =IFERROR(__xludf.DUMMYFUNCTION("""COMPUTED_VALUE"""),4.0) -> 4 | K15: =IFERROR(__xludf.DUMMYFUNCTION("""COMPUTED_VALUE"""),45156.0) -> 45156 | L15: =IFERROR(__xludf.DUMMYFUNCTION("""COMPUTED_VALUE"""),0.5416666666666666) -> 0.54166667 | M15: =IFERROR(__xludf.DUMMYFUNCTION("""COMPUTED_VALUE"""),"placeholder teamname") -> placeholder teamname | N15: =IFERROR(__xludf.DUMMYFUNCTION("""COMPUTED_VALUE"""),"5") -> 5 | O15: =IFERROR(__xludf.DUMMYFUNCTION("""COMPUTED_VALUE"""),"1") -> 1 | P15: =IFERROR(__xludf.DUMMYFUNCTION("""COMPUTED_VALUE"""),"Mewo My Waifu") -> Mewo My Waifu | Q15: =IFERROR(__xludf.DUMMYFUNCTION("""COMPUTED_VALUE"""),"Emerald Ages") -> Emerald Ages | U15: =IFERROR(__xludf.DUMMYFUNCTION("""COMPUTED_VALUE"""),"https://osu.ppy.sh/community/matches/110051132") -> https://osu.ppy.sh/community/matches/110051132
G16: c | J16: =IFERROR(__xludf.DUMMYFUNCTION("""COMPUTED_VALUE"""),5.0) -> 5 | K16: =IFERROR(__xludf.DUMMYFUNCTION("""COMPUTED_VALUE"""),45158.0) -> 45158 | L16: =IFERROR(__xludf.DUMMYFUNCTION("""COMPUTED_VALUE"""),0.75) -> 0.75 | M16: =IFERROR(__xludf.DUMMYFUNCTION("""COMPUTED_VALUE"""),"Homossexual Students") -> Homossexual Students | N16: =IFERROR(__xludf.DUMMYFUNCTION("""COMPUTED_VALUE"""),"5") -> 5 | O16: =IFERROR(__xludf.DUMMYFUNCTION("""COMPUTED_VALUE"""),"2") -> 2 | P16: =IFERROR(__xludf.DUMMYFUNCTION("""COMPUTED_VALUE"""),"Better HD Abusers") -> Better HD Abusers | Q16: =IFERROR(__xludf.DUMMYFUNCTION("""COMPUTED_VALUE"""),"Mewo_") -> Mewo_ | U16: =IFERROR(__xludf.DUMMYFUNCTION("""COMPUTED_VALUE"""),"https://osu.ppy.sh/community/matches/110087766") -> https://osu.ppy.sh/community/matches/110087766
G17: c | J17: =IFERROR(__xludf.DUMMYFUNCTION("""COMPUTED_VALUE"""),6.0) -> 6 | K17: =IFERROR(__xludf.DUMMYFUNCTION("""COMPUTED_VALUE"""),45158.0) -> 45158 | L17: =IFERROR(__xludf.DUMMYFUNCTION("""COMPUTED_VALUE"""),0.041666666666666664) -> 0.041666667 | M17: =IFERROR(__xludf.DUMMYFUNCTION("""COMPUTED_VALUE"""),"cake") -> cake | N17: =IFERROR(__xludf.DUMMYFUNCTION("""COMPUTED_VALUE"""),"5") -> 5 | O17: =IFERROR(__xludf.DUMMYFUNCTION("""COMPUTED_VALUE"""),"1") -> 1 | P17: =IFERROR(__xludf.DUMMYFUNCTION("""COMPUTED_VALUE"""),"equipe câo") -> equipe câo | Q17: =IFERROR(__xludf.DUMMYFUNCTION("""COMPUTED_VALUE"""),"Emerald Ages") -> Emerald Ages | U17: =IFERROR(__xludf.DUMMYFUNCTION("""COMPUTED_VALUE"""),"https://osu.ppy.sh/community/matches/110076817") -> https://osu.ppy.sh/community/matches/110076817
G18: c | J18: =IFERROR(__xludf.DUMMYFUNCTION("""COMPUTED_VALUE"""),7.0) -> 7 | K18: =IFERROR(__xludf.DUMMYFUNCTION("""COMPUTED_VALUE"""),45157.0) -> 45157 | L18: =IFERROR(__xludf.DUMMYFUNCTION("""COMPUTED_VALUE"""),0.5416666666666666) -> 0.54166667 | M18: =IFERROR(__xludf.DUMMYFUNCTION("""COMPUTED_VALUE"""),"female ass wrestling") -> female ass wrestling | N18: =IFERROR(__xludf.DUMMYFUNCTION("""COMPUTED_VALUE"""),"5") -> 5 | O18: =IFERROR(__xludf.DUMMYFUNCTION("""COMPUTED_VALUE"""),"1") -> 1 | P18: =IFERROR(__xludf.DUMMYFUNCTION("""COMPUTED_VALUE"""),"BOCCHER") -> BOCCHER | Q18: =IFERROR(__xludf.DUMMYFUNCTION("""COMPUTED_VALUE"""),"Pischok") -> Pischok | U18: =IFERROR(__xludf.DUMMYFUNCTION("""COMPUTED_VALUE"""),"https://osu.ppy.sh/mp/110067010") -> https://osu.ppy.sh/mp/110067010
G19: c | J19: =IFERROR(__xludf.DUMMYFUNCTION("""COMPUTED_VALUE"""),8.0) -> 8 | K19: =IFERROR(__xludf.DUMMYFUNCTION("""COMPUTED_VALUE"""),45157.0) -> 45157 | L19: =IFERROR(__xludf.DUMMYFUNCTION("""COMPUTED_VALUE"""),0.5833333333333334) -> 0.58333333 | M19: =IFERROR(__xludf.DUMMYFUNCTION("""COMPUTED_VALUE"""),"Sightread Buff") -> Sightread Buff | N19: =IFERROR(__xludf.DUMMYFUNCTION("""COMPUTED_VALUE"""),"2") -> 2 | O19: =IFERROR(__xludf.DUMMYFUNCTION("""COMPUTED_VALUE"""),"5") -> 5 | P19: =IFERROR(__xludf.DUMMYFUNCTION("""COMPUTED_VALUE"""),"VN+1") -> VN+1 | Q19: =IFERROR(__xludf.DUMMYFUNCTION("""COMPUTED_VALUE"""),"Gamillie") -> Gamillie | U19: =IFERROR(__xludf.DUMMYFUNCTION("""COMPUTED_VALUE"""),"https://osu.ppy.sh/mp/110067659") -> https://osu.ppy.sh/mp/110067659
G20: c | J20: =IFERROR(__xludf.DUMMYFUNCTION("""COMPUTED_VALUE"""),9.0) -> 9 | K20: =IFERROR(__xludf.DUMMYFUNCTION("""COMPUTED_VALUE"""),45158.0) -> 45158 | L20: =IFERROR(__xludf.DUMMYFUNCTION("""COMPUTED_VALUE"""),0.125) -> 0.125 | M20: =IFERROR(__xludf.DUMMYFUNCTION("""COMPUTED_VALUE"""),":MIPINGA:") -> :MIPINGA: | N20: =IFERROR(__xludf.DUMMYFUNCTION("""COMPUTED_VALUE"""),"5") -> 5 | O20: =IFERROR(__xludf.DUMMYFUNCTION("""COMPUTED_VALUE"""),"0") -> 0 | P20: =IFERROR(__xludf.DUMMYFUNCTION("""COMPUTED_VALUE"""),"Beancurd") -> Beancurd | Q20: =IFERROR(__xludf.DUMMYFUNCTION("""COMPUTED_VALUE"""),"play hd3") -> play hd3 | U20: =IFERROR(__xludf.DUMMYFUNCTION("""COMPUTED_VALUE"""),"https://osu.ppy.sh/community/matches/110077688") -> https://osu.ppy.sh/community/matches/110077688
G21: c | J21: =IFERROR(__xludf.DUMMYFUNCTION("""COMPUTED_VALUE"""),10.0) -> 10 | K21: =IFERROR(__xludf.DUMMYFUNCTION("""COMPUTED_VALUE"""),45157.0) -> 45157 | L21: =IFERROR(__xludf.DUMMYFUNCTION("""COMPUTED_VALUE"""),0.625) -> 0.625 | M21: =IFERROR(__xludf.DUMMYFUNCTION("""COMPUTED_VALUE"""),"Dino Nuggies") -> Dino Nuggies | N21: =IFERROR(__xludf.DUMMYFUNCTION("""COMPUTED_VALUE"""),"1") -> 1 | O21: =IFERROR(__xludf.DUMMYFUNCTION("""COMPUTED_VALUE"""),"5") -> 5 | P21: =IFERROR(__xludf.DUMMYFUNCTION("""COMPUTED_VALUE"""),"Chocomaid") -> Chocomaid | Q21: =IFERROR(__xludf.DUMMYFUNCTION("""COMPUTED_VALUE"""),"Fuwub") -> Fuwub | U21: =IFERROR(__xludf.DUMMYFUNCTION("""COMPUTED_VALUE"""),"https://osu.ppy.sh/community/matches/110068687") -> https://osu.ppy.sh/community/matches/110068687
G22: c | J22: =IFERROR(__xludf.DUMMYFUNCTION("""COMPUTED_VALUE"""),11.0) -> 11 | K22: =IFERROR(__xludf.DUMMYFUNCTION("""COMPUTED_VALUE"""),45158.0) -> 45158 | L22: =IFERROR(__xludf.DUMMYFUNCTION("""COMPUTED_VALUE"""),0.625) -> 0.625 | M22: =IFERROR(__xludf.DUMMYFUNCTION("""COMPUTED_VALUE"""),"The Mat Munchers") -> The Mat Munchers | N22: =IFERROR(__xludf.DUMMYFUNCTION("""COMPUTED_VALUE"""),"0") -> 0 | O22: =IFERROR(__xludf.DUMMYFUNCTION("""COMPUTED_VALUE"""),"5") -> 5 | P22: =IFERROR(__xludf.DUMMYFUNCTION("""COMPUTED_VALUE"""),"Team name pending xd") -> Team name pending xd | Q22: =IFERROR(__xludf.DUMMYFUNCTION("""COMPUTED_VALUE"""),"Emerald Ages") -> Emerald Ages | U22: =IFERROR(__xludf.DUMMYFUNCTION("""COMPUTED_VALUE"""),"https://osu.ppy.sh/community/matches/110085247") -> https://osu.ppy.sh/community/matches/110085247
G23: c | J23: =IFERROR(__xludf.DUMMYFUNCTION("""COMPUTED_VALUE"""),12.0) -> 12 | K23: =IFERROR(__xludf.DUMMYFUNCTION("""COMPUTED_VALUE"""),45156.0) -> 45156 | L23: =IFERROR(__xludf.DUMMYFUNCTION("""COMPUTED_VALUE"""),0.5833333333333334) -> 0.58333333 | M23: =IFERROR(__xludf.DUMMYFUNCTION("""COMPUTED_VALUE"""),"Ghost the Angel") -> Ghost the Angel | N23: =IFERROR(__xludf.DUMMYFUNCTION("""COMPUTED_VALUE"""),"5") -> 5 | O23: =IFERROR(__xludf.DUMMYFUNCTION("""COMPUTED_VALUE"""),"3") -> 3 | P23: =IFERROR(__xludf.DUMMYFUNCTION("""COMPUTED_VALUE"""),"PES E9L9") -> PES E9L9 | Q23: =IFERROR(__xludf.DUMMYFUNCTION("""COMPUTED_VALUE"""),"Emerald Ages") -> Emerald Ages | U23: =IFERROR(__xludf.DUMMYFUNCTION("""COMPUTED_VALUE"""),"https://osu.ppy.sh/community/matches/110051882") -> https://osu.ppy.sh/community/matches/110051882
G24: c | J24: =IFERROR(__xludf.DUMMYFUNCTION("""COMPUTED_VALUE"""),13.0) -> 13 | K24: =IFERROR(__xludf.DUMMYFUNCTION("""COMPUTED_VALUE"""),45158.0) -> 45158 | L24: =IFERROR(__xludf.DUMMYFUNCTION("""COMPUTED_VALUE"""),0.08333333333333333) -> 0.083333333 | M24: =IFERROR(__xludf.DUMMYFUNCTION("""COMPUTED_VALUE"""),"foxy1919191919's basement") -> foxy1919191919's basement | N24: =IFERROR(__xludf.DUMMYFUNCTION("""COMPUTED_VALUE"""),"5") -> 5 | O24: =IFERROR(__xludf.DUMMYFUNCTION("""COMPUTED_VALUE"""),"1") -> 1 | P24: =IFERROR(__xludf.DUMMYFUNCTION("""COMPUTED_VALUE"""),"Here Forever") -> Here Forever | Q24: =IFERROR(__xludf.DUMMYFUNCTION("""COMPUTED_VALUE"""),"BlooMertz") -> BlooMertz | U24: =IFERROR(__xludf.DUMMYFUNCTION("""COMPUTED_VALUE"""),"https://osu.ppy.sh/community/matches/110077387") -> https://osu.ppy.sh/community/matches/110077387
G25: c | J25: =IFERROR(__xludf.DUMMYFUNCTION("""COMPUTED_VALUE"""),14.0) -> 14 | K25: =IFERROR(__xludf.DUMMYFUNCTION("""COMPUTED_VALUE"""),45157.0) -> 45157 | L25: =IFERROR(__xludf.DUMMYFUNCTION("""COMPUTED_VALUE"""),0.5833333333333334) -> 0.58333333 | M25: =IFERROR(__xludf.DUMMYFUNCTION("""COMPUTED_VALUE"""),"match in 15") -> match in 15 | N25: =IFERROR(__xludf.DUMMYFUNCTION("""COMPUTED_VALUE"""),"5") -> 5 | O25: =IFERROR(__xludf.DUMMYFUNCTION("""COMPUTED_VALUE"""),"2") -> 2 | P25: =IFERROR(__xludf.DUMMYFUNCTION("""COMPUTED_VALUE"""),"3000CombinedHours") -> 3000CombinedHours | Q25: =IFERROR(__xludf.DUMMYFUNCTION("""COMPUTED_VALUE"""),"Gamillie") -> Gamillie | U25: =IFERROR(__xludf.DUMMYFUNCTION("""COMPUTED_VALUE"""),"https://osu.ppy.sh/community/matches/110067582") -> https://osu.ppy.sh/community/matches/110067582
G26: c | J26: =IFERROR(__xludf.DUMMYFUNCTION("""COMPUTED_VALUE"""),15.0) -> 15 | K26: =IFERROR(__xludf.DUMMYFUNCTION("""COMPUTED_VALUE"""),45157.0) -> 45157 | L26: =IFERROR(__xludf.DUMMYFUNCTION("""COMPUTED_VALUE"""),0.25) -> 0.25 | M26: =IFERROR(__xludf.DUMMYFUNCTION("""COMPUTED_VALUE"""),"Tom and Jerry") -> Tom and Jerry | N26: =IFERROR(__xludf.DUMMYFUNCTION("""COMPUTED_VALUE"""),"5") -> 5 | O26: =IFERROR(__xludf.DUMMYFUNCTION("""COMPUTED_VALUE"""),"4") -> 4 | P26: =IFERROR(__xludf.DUMMYFUNCTION("""COMPUTED_VALUE"""),"Lovers + 3rd wheel") -> Lovers + 3rd wheel | Q26: =IFERROR(__xludf.DUMMYFUNCTION("""COMPUTED_VALUE"""),"Mewo_") -> Mewo_ | U26: =IFERROR(__xludf.DUMMYFUNCTION("""COMPUTED_VALUE"""),"https://osu.ppy.sh/community/matches/110063252") -> https://osu.ppy.sh/community/matches/110063252
G27: c | J27: =IFERROR(__xludf.DUMMYFUNCTION("""COMPUTED_VALUE"""),16.0) -> 16 | K27: =IFERROR(__xludf.DUMMYFUNCTION("""COMPUTED_VALUE"""),45158.0) -> 45158 | L27: =IFERROR(__xludf.DUMMYFUNCTION("""COMPUTED_VALUE"""),0.8125) -> 0.8125 | M27: =IFERROR(__xludf.DUMMYFUNCTION("""COMPUTED_VALUE"""),"Faz o L") -> Faz o L | N27: =IFERROR(__xludf.DUMMYFUNCTION("""COMPUTED_VALUE"""),"3") -> 3 | O27: =IFERROR(__xludf.DUMMYFUNCTION("""COMPUTED_VALUE"""),"5") -> 5 | P27: =IFERROR(__xludf.DUMMYFUNCTION("""COMPUTED_VALUE"""),"Kittens") -> Kittens | Q27: =IFERROR(__xludf.DUMMYFUNCTION("""COMPUTED_VALUE"""),"-PeKoRa-") -> -PeKoRa- | U27: =IFERROR(__xludf.DUMMYFUNCTION("""COMPUTED_VALUE"""),"https://osu.ppy.sh/community/matches/110089262") -> https://osu.ppy.sh/community/matches/110089262
G28: c | J28: =IFERROR(__xludf.DUMMYFUNCTION("""COMPUTED_VALUE"""),17.0) -> 17 | K28: =IFERROR(__xludf.DUMMYFUNCTION("""COMPUTED_VALUE"""),45166.0) -> 45166 | L28: =IFERROR(__xludf.DUMMYFUNCTION("""COMPUTED_VALUE"""),0.5416666666666666) -> 0.54166667 | M28: =IFERROR(__xludf.DUMMYFUNCTION("""COMPUTED_VALUE"""),"lowrank is my love") -> lowrank is my love | N28: =IFERROR(__xludf.DUMMYFUNCTION("""COMPUTED_VALUE"""),"1") -> 1 | O28: =IFERROR(__xludf.DUMMYFUNCTION("""COMPUTED_VALUE"""),"5") -> 5 | P28: =IFERROR(__xludf.DUMMYFUNCTION("""COMPUTED_VALUE"""),"PLDT ANO NAAA") -> PLDT ANO NAAA | Q28: =IFERROR(__xludf.DUMMYFUNCTION("""COMPUTED_VALUE"""),"Azasapag") -> Azasapag | U28: =IFERROR(__xludf.DUMMYFUNCTION("""COMPUTED_VALUE"""),"https://osu.ppy.sh/community/matches/110206456") -> https://osu.ppy.sh/community/matches/110206456
G29: c | J29: =IFERROR(__xludf.DUMMYFUNCTION("""COMPUTED_VALUE"""),18.0) -> 18 | K29: =IFERROR(__xludf.DUMMYFUNCTION("""COMPUTED_VALUE"""),45164.0) -> 45164 | L29: =IFERROR(__xludf.DUMMYFUNCTION("""COMPUTED_VALUE"""),0.75) -> 0.75 | M29: =IFERROR(__xludf.DUMMYFUNCTION("""COMPUTED_VALUE"""),"The sleepers") -> The sleepers | N29: =IFERROR(__xludf.DUMMYFUNCTION("""COMPUTED_VALUE"""),"5") -> 5 | O29: =IFERROR(__xludf.DUMMYFUNCTION("""COMPUTED_VALUE"""),"2") -> 2 | P29: =IFERROR(__xludf.DUMMYFUNCTION("""COMPUTED_VALUE"""),"Mewo My Waifu") -> Mewo My Waifu | Q29: =IFERROR(__xludf.DUMMYFUNCTION("""COMPUTED_VALUE"""),"play hd3") -> play hd3 | U29: =IFERROR(__xludf.DUMMYFUNCTION("""COMPUTED_VALUE"""),"https://osu.ppy.sh/community/matches/110178185") -> https://osu.ppy.sh/community/matches/110178185
G30: c | J30: =IFERROR(__xludf.DUMMYFUNCTION("""COMPUTED_VALUE"""),19.0) -> 19 | K30: =IFERROR(__xludf.DUMMYFUNCTION("""COMPUTED_VALUE"""),45165.0) -> 45165 | L30: =IFERROR(__xludf.DUMMYFUNCTION("""COMPUTED_VALUE"""),0.5416666666666666) -> 0.54166667 | M30: =IFERROR(__xludf.DUMMYFUNCTION("""COMPUTED_VALUE"""),"Better HD Abusers") -> Better HD Abusers | N30: =IFERROR(__xludf.DUMMYFUNCTION("""COMPUTED_VALUE"""),"0") -> 0 | O30: =IFERROR(__xludf.DUMMYFUNCTION("""COMPUTED_VALUE"""),"5") -> 5 | P30: =IFERROR(__xludf.DUMMYFUNCTION("""COMPUTED_VALUE"""),"equipe câo") -> equipe câo | Q30: =IFERROR(__xludf.DUMMYFUNCTION("""COMPUTED_VALUE"""),"reforna") -> reforna | U30: =IFERROR(__xludf.DUMMYFUNCTION("""COMPUTED_VALUE"""),"https://osu.ppy.sh/community/matches/110190490") -> https://osu.ppy.sh/community/matches/110190490
D31: Round of 16 | G31: c | J31: =IFERROR(__xludf.DUMMYFUNCTION("""COMPUTED_VALUE"""),20.0) -> 20 | K31: =IFERROR(__xludf.DUMMYFUNCTION("""COMPUTED_VALUE"""),45165.0) -> 45165 | L31: =IFERROR(__xludf.DUMMYFUNCTION("""COMPUTED_VALUE"""),0.75) -> 0.75 | M31: =IFERROR(__xludf.DUMMYFUNCTION("""COMPUTED_VALUE"""),"BOCCHER") -> BOCCHER | N31: =IFERROR(__xludf.DUMMYFUNCTION("""COMPUTED_VALUE"""),"1") -> 1 | O31: =IFERROR(__xludf.DUMMYFUNCTION("""COMPUTED_VALUE"""),"5") -> 5 | P31: =IFERROR(__xludf.DUMMYFUNCTION("""COMPUTED_VALUE"""),"Sightread Buff") -> Sightread Buff | Q31: =IFERROR(__xludf.DUMMYFUNCTION("""COMPUTED_VALUE"""),"Ninja Mejster") -> Ninja Mejster | U31: =IFERROR(__xludf.DUMMYFUNCTION("""COMPUTED_VALUE"""),"https://osu.ppy.sh/community/matches/110194908") -> https://osu.ppy.sh/community/matches/110194908
G32: c | J32: =IFERROR(__xludf.DUMMYFUNCTION("""COMPUTED_VALUE"""),21.0) -> 21 | K32: =IFERROR(__xludf.DUMMYFUNCTION("""COMPUTED_VALUE"""),45164.0) -> 45164 | L32: =IFERROR(__xludf.DUMMYFUNCTION("""COMPUTED_VALUE"""),0.625) -> 0.625 | M32: =IFERROR(__xludf.DUMMYFUNCTION("""COMPUTED_VALUE"""),"Beancurd") -> Beancurd | N32: =IFERROR(__xludf.DUMMYFUNCTION("""COMPUTED_VALUE"""),"2") -> 2 | O32: =IFERROR(__xludf.DUMMYFUNCTION("""COMPUTED_VALUE"""),"5") -> 5 | P32: =IFERROR(__xludf.DUMMYFUNCTION("""COMPUTED_VALUE"""),"Dino Nuggies") -> Dino Nuggies | Q32: =IFERROR(__xludf.DUMMYFUNCTION("""COMPUTED_VALUE"""),"reforna") -> reforna | U32: =IFERROR(__xludf.DUMMYFUNCTION("""COMPUTED_VALUE"""),"https://osu.ppy.sh/community/matches/110175433") -> https://osu.ppy.sh/community/matches/110175433
G33: c | J33: =IFERROR(__xludf.DUMMYFUNCTION("""COMPUTED_VALUE"""),22.0) -> 22 | K33: =IFERROR(__xludf.DUMMYFUNCTION("""COMPUTED_VALUE"""),45164.0) -> 45164 | L33: =IFERROR(__xludf.DUMMYFUNCTION("""COMPUTED_VALUE"""),0.5833333333333334) -> 0.58333333 | M33: =IFERROR(__xludf.DUMMYFUNCTION("""COMPUTED_VALUE"""),"The Mat Munchers") -> The Mat Munchers | N33: =IFERROR(__xludf.DUMMYFUNCTION("""COMPUTED_VALUE"""),"2") -> 2 | O33: =IFERROR(__xludf.DUMMYFUNCTION("""COMPUTED_VALUE"""),"5") -> 5 | P33: =IFERROR(__xludf.DUMMYFUNCTION("""COMPUTED_VALUE"""),"PES E9L9") -> PES E9L9 | Q33: =IFERROR(__xludf.DUMMYFUNCTION("""COMPUTED_VALUE"""),"reforna") -> reforna | U33: =IFERROR(__xludf.DUMMYFUNCTION("""COMPUTED_VALUE"""),"https://osu.ppy.sh/community/matches/110174567") -> https://osu.ppy.sh/community/matches/110174567
G34: c | J34: =IFERROR(__xludf.DUMMYFUNCTION("""COMPUTED_VALUE"""),23.0) -> 23 | K34: =IFERROR(__xludf.DUMMYFUNCTION("""COMPUTED_VALUE"""),45164.0) -> 45164 | L34: =IFERROR(__xludf.DUMMYFUNCTION("""COMPUTED_VALUE"""),0.7083333333333334) -> 0.70833333 | M34: =IFERROR(__xludf.DUMMYFUNCTION("""COMPUTED_VALUE"""),"Here Forever") -> Here Forever | N34: =IFERROR(__xludf.DUMMYFUNCTION("""COMPUTED_VALUE"""),"5") -> 5 | O34: =IFERROR(__xludf.DUMMYFUNCTION("""COMPUTED_VALUE"""),"0") -> 0 | P34: =IFERROR(__xludf.DUMMYFUNCTION("""COMPUTED_VALUE"""),"3000CombinedHours") -> 3000CombinedHours | Q34: =IFERROR(__xludf.DUMMYFUNCTION("""COMPUTED_VALUE"""),"play hd3") -> play hd3 | U34: =IFERROR(__xludf.DUMMYFUNCTION("""COMPUTED_VALUE"""),"https://osu.ppy.sh/community/matches/110177686") -> https://osu.ppy.sh/community/matches/110177686
G35: c | J35: =IFERROR(__xludf.DUMMYFUNCTION("""COMPUTED_VALUE"""),24.0) -> 24 | K35: =IFERROR(__xludf.DUMMYFUNCTION("""COMPUTED_VALUE"""),45165.0) -> 45165 | L35: =IFERROR(__xludf.DUMMYFUNCTION("""COMPUTED_VALUE"""),0.16666666666666666) -> 0.16666667 | M35: =IFERROR(__xludf.DUMMYFUNCTION("""COMPUTED_VALUE"""),"Lovers + 3rd wheel") -> Lovers + 3rd wheel | N35: =IFERROR(__xludf.DUMMYFUNCTION("""COMPUTED_VALUE"""),"2") -> 2 | O35: =IFERROR(__xludf.DUMMYFUNCTION("""COMPUTED_VALUE"""),"5") -> 5 | P35: =IFERROR(__xludf.DUMMYFUNCTION("""COMPUTED_VALUE"""),"Faz o L") -> Faz o L | U35: =IFERROR(__xludf.DUMMYFUNCTION("""COMPUTED_VALUE"""),"https://osu.ppy.sh/community/matches/110185577") -> https://osu.ppy.sh/community/matches/110185577
G36: c | J36: =IFERROR(__xludf.DUMMYFUNCTION("""COMPUTED_VALUE"""),25.0) -> 25 | K36: =IFERROR(__xludf.DUMMYFUNCTION("""COMPUTED_VALUE"""),45165.0) -> 45165 | L36: =IFERROR(__xludf.DUMMYFUNCTION("""COMPUTED_VALUE"""),0.5416666666666666) -> 0.54166667 | M36: =IFERROR(__xludf.DUMMYFUNCTION("""COMPUTED_VALUE"""),"small wiener club") -> small wiener club | N36: =IFERROR(__xludf.DUMMYFUNCTION("""COMPUTED_VALUE"""),"5") -> 5 | O36: =IFERROR(__xludf.DUMMYFUNCTION("""COMPUTED_VALUE"""),"3") -> 3 | P36: =IFERROR(__xludf.DUMMYFUNCTION("""COMPUTED_VALUE"""),"middle-schooler wife") -> middle-schooler wife | Q36: =IFERROR(__xludf.DUMMYFUNCTION("""COMPUTED_VALUE"""),"reforna") -> reforna | U36: =IFERROR(__xludf.DUMMYFUNCTION("""COMPUTED_VALUE"""),"https://osu.ppy.sh/community/matches/110190477") -> https://osu.ppy.sh/community/matches/110190477
J37: =IFERROR(__xludf.DUMMYFUNCTION("""COMPUTED_VALUE"""),26.0) -> 26 | K37: =IFERROR(__xludf.DUMMYFUNCTION("""COMPUTED_VALUE"""),45164.0) -> 45164 | L37: =IFERROR(__xludf.DUMMYFUNCTION("""COMPUTED_VALUE"""),0.6666666666666666) -> 0.66666667 | M37: =IFERROR(__xludf.DUMMYFUNCTION("""COMPUTED_VALUE"""),"The 3-star Threats") -> The 3-star Threats | N37: =IFERROR(__xludf.DUMMYFUNCTION("""COMPUTED_VALUE"""),"1") -> 1 | O37: =IFERROR(__xludf.DUMMYFUNCTION("""COMPUTED_VALUE"""),"5") -> 5 | P37: =IFERROR(__xludf.DUMMYFUNCTION("""COMPUTED_VALUE"""),"placeholder teamname") -> placeholder teamname | Q37: =IFERROR(__xludf.DUMMYFUNCTION("""COMPUTED_VALUE"""),"reforna") -> reforna | U37: =IFERROR(__xludf.DUMMYFUNCTION("""COMPUTED_VALUE"""),"https://osu.ppy.sh/community/matches/110176380") -> https://osu.ppy.sh/community/matches/110176380
J38: =IFERROR(__xludf.DUMMYFUNCTION("""COMPUTED_VALUE"""),27.0) -> 27 | K38: =IFERROR(__xludf.DUMMYFUNCTION("""COMPUTED_VALUE"""),45164.0) -> 45164 | L38: =IFERROR(__xludf.DUMMYFUNCTION("""COMPUTED_VALUE"""),0.7916666666666666) -> 0.79166667 | M38: =IFERROR(__xludf.DUMMYFUNCTION("""COMPUTED_VALUE"""),"Homossexual Students") -> Homossexual Students | N38: =IFERROR(__xludf.DUMMYFUNCTION("""COMPUTED_VALUE"""),"5") -> 5 | O38: =IFERROR(__xludf.DUMMYFUNCTION("""COMPUTED_VALUE"""),"4") -> 4 | P38: =IFERROR(__xludf.DUMMYFUNCTION("""COMPUTED_VALUE"""),"cake") -> cake | Q38: =IFERROR(__xludf.DUMMYFUNCTION("""COMPUTED_VALUE"""),"play hd3") -> play hd3 | U38: =IFERROR(__xludf.DUMMYFUNCTION("""COMPUTED_VALUE"""),"https://osu.ppy.sh/community/matches/110179406") -> https://osu.ppy.sh/community/matches/110179406
J39: =IFERROR(__xludf.DUMMYFUNCTION("""COMPUTED_VALUE"""),28.0) -> 28 | K39: =IFERROR(__xludf.DUMMYFUNCTION("""COMPUTED_VALUE"""),45165.0) -> 45165 | L39: =IFERROR(__xludf.DUMMYFUNCTION("""COMPUTED_VALUE"""),0.5833333333333334) -> 0.58333333 | M39: =IFERROR(__xludf.DUMMYFUNCTION("""COMPUTED_VALUE"""),"female ass wrestling") -> female ass wrestling | N39: =IFERROR(__xludf.DUMMYFUNCTION("""COMPUTED_VALUE"""),"5") -> 5 | O39: =IFERROR(__xludf.DUMMYFUNCTION("""COMPUTED_VALUE"""),"1") -> 1 | P39: =IFERROR(__xludf.DUMMYFUNCTION("""COMPUTED_VALUE"""),"VN+1") -> VN+1 | Q39: =IFERROR(__xludf.DUMMYFUNCTION("""COMPUTED_VALUE"""),"RudderFish07") -> RudderFish07 | U39: =IFERROR(__xludf.DUMMYFUNCTION("""COMPUTED_VALUE"""),"https://osu.ppy.sh/community/matches/110191205") -> https://osu.ppy.sh/community/matches/110191205
J40: =IFERROR(__xludf.DUMMYFUNCTION("""COMPUTED_VALUE"""),29.0) -> 29 | K40: =IFERROR(__xludf.DUMMYFUNCTION("""COMPUTED_VALUE"""),45165.0) -> 45165 | L40: =IFERROR(__xludf.DUMMYFUNCTION("""COMPUTED_VALUE"""),0.10416666666666667) -> 0.10416667 | M40: =IFERROR(__xludf.DUMMYFUNCTION("""COMPUTED_VALUE"""),":MIPINGA:") -> :MIPINGA: | N40: =IFERROR(__xludf.DUMMYFUNCTION("""COMPUTED_VALUE"""),"5") -> 5 | O40: =IFERROR(__xludf.DUMMYFUNCTION("""COMPUTED_VALUE"""),"1") -> 1 | P40: =IFERROR(__xludf.DUMMYFUNCTION("""COMPUTED_VALUE"""),"Chocomaid") -> Chocomaid | Q40: =IFERROR(__xludf.DUMMYFUNCTION("""COMPUTED_VALUE"""),"play hd3") -> play hd3 | U40: =IFERROR(__xludf.DUMMYFUNCTION("""COMPUTED_VALUE"""),"https://osu.ppy.sh/community/matches/110184531") -> https://osu.ppy.sh/community/matches/110184531
J41: =IFERROR(__xludf.DUMMYFUNCTION("""COMPUTED_VALUE"""),30.0) -> 30 | K41: =IFERROR(__xludf.DUMMYFUNCTION("""COMPUTED_VALUE"""),45163.0) -> 45163 | L41: =IFERROR(__xludf.DUMMYFUNCTION("""COMPUTED_VALUE"""),0.5416666666666666) -> 0.54166667 | M41: =IFERROR(__xludf.DUMMYFUNCTION("""COMPUTED_VALUE"""),"Team name pending xd") -> Team name pending xd | N41: =IFERROR(__xludf.DUMMYFUNCTION("""COMPUTED_VALUE"""),"2") -> 2 | O41: =IFERROR(__xludf.DUMMYFUNCTION("""COMPUTED_VALUE"""),"5") -> 5 | P41: =IFERROR(__xludf.DUMMYFUNCTION("""COMPUTED_VALUE"""),"Ghost the Angel") -> Ghost the Angel | Q41: =IFERROR(__xludf.DUMMYFUNCTION("""COMPUTED_VALUE"""),"Lunexia") -> Lunexia | U41: =IFERROR(__xludf.DUMMYFUNCTION("""COMPUTED_VALUE"""),"https://osu.ppy.sh/community/matches/110157424") -> https://osu.ppy.sh/community/matches/110157424
J42: =IFERROR(__xludf.DUMMYFUNCTION("""COMPUTED_VALUE"""),31.0) -> 31 | K42: =IFERROR(__xludf.DUMMYFUNCTION("""COMPUTED_VALUE"""),45163.0) -> 45163 | L42: =IFERROR(__xludf.DUMMYFUNCTION("""COMPUTED_VALUE"""),0.4583333333333333) -> 0.45833333 | M42: =IFERROR(__xludf.DUMMYFUNCTION("""COMPUTED_VALUE"""),"foxy1919191919's basement") -> foxy1919191919's basement | N42: =IFERROR(__xludf.DUMMYFUNCTION("""COMPUTED_VALUE"""),"2") -> 2 | O42: =IFERROR(__xludf.DUMMYFUNCTION("""COMPUTED_VALUE"""),"5") -> 5 | P42: =IFERROR(__xludf.DUMMYFUNCTION("""COMPUTED_VALUE"""),"match in 15") -> match in 15 | Q42: =IFERROR(__xludf.DUMMYFUNCTION("""COMPUTED_VALUE"""),"Azasapag") -> Azasapag | U42: =IFERROR(__xludf.DUMMYFUNCTION("""COMPUTED_VALUE"""),"https://osu.ppy.sh/community/matches/110156344") -> https://osu.ppy.sh/community/matches/110156344
J43: =IFERROR(__xludf.DUMMYFUNCTION("""COMPUTED_VALUE"""),32.0) -> 32 | K43: =IFERROR(__xludf.DUMMYFUNCTION("""COMPUTED_VALUE"""),45164.0) -> 45164 | L43: =IFERROR(__xludf.DUMMYFUNCTION("""COMPUTED_VALUE"""),0.5833333333333334) -> 0.58333333 | M43: =IFERROR(__xludf.DUMMYFUNCTION("""COMPUTED_VALUE"""),"Tom and Jerry") -> Tom and Jerry | N43: =IFERROR(__xludf.DUMMYFUNCTION("""COMPUTED_VALUE"""),"5") -> 5 | O43: =IFERROR(__xludf.DUMMYFUNCTION("""COMPUTED_VALUE"""),"3") -> 3 | P43: =IFERROR(__xludf.DUMMYFUNCTION("""COMPUTED_VALUE"""),"Kittens") -> Kittens | Q43: =IFERROR(__xludf.DUMMYFUNCTION("""COMPUTED_VALUE"""),"reforna") -> reforna | U43: =IFERROR(__xludf.DUMMYFUNCTION("""COMPUTED_VALUE"""),"https://osu.ppy.sh/community/matches/110174570") -> https://osu.ppy.sh/community/matches/110174570
J44: =IFERROR(__xludf.DUMMYFUNCTION("""COMPUTED_VALUE"""),33.0) -> 33 | K44: =IFERROR(__xludf.DUMMYFUNCTION("""COMPUTED_VALUE"""),45172.0) -> 45172 | L44: =IFERROR(__xludf.DUMMYFUNCTION("""COMPUTED_VALUE"""),0.5833333333333334) -> 0.58333333 | M44: =IFERROR(__xludf.DUMMYFUNCTION("""COMPUTED_VALUE"""),"middle-schooler wife") -> middle-schooler wife | N44: =IFERROR(__xludf.DUMMYFUNCTION("""COMPUTED_VALUE"""),"6") -> 6 | O44: =IFERROR(__xludf.DUMMYFUNCTION("""COMPUTED_VALUE"""),"2") -> 2 | P44: =IFERROR(__xludf.DUMMYFUNCTION("""COMPUTED_VALUE"""),"Faz o L") -> Faz o L | U44: =IFERROR(__xludf.DUMMYFUNCTION("""COMPUTED_VALUE"""),"https://osu.ppy.sh/community/matches/110301082") -> https://osu.ppy.sh/community/matches/110301082
G45: c | J45: =IFERROR(__xludf.DUMMYFUNCTION("""COMPUTED_VALUE"""),34.0) -> 34 | K45: =IFERROR(__xludf.DUMMYFUNCTION("""COMPUTED_VALUE"""),45171.0) -> 45171 | L45: =IFERROR(__xludf.DUMMYFUNCTION("""COMPUTED_VALUE"""),0.9583333333333334) -> 0.95833333 | M45: =IFERROR(__xludf.DUMMYFUNCTION("""COMPUTED_VALUE"""),"The 3-star Threats") -> The 3-star Threats | N45: =IFERROR(__xludf.DUMMYFUNCTION("""COMPUTED_VALUE"""),"6") -> 6 | O45: =IFERROR(__xludf.DUMMYFUNCTION("""COMPUTED_VALUE"""),"3") -> 3 | P45: =IFERROR(__xludf.DUMMYFUNCTION("""COMPUTED_VALUE"""),"Here Forever") -> Here Forever | Q45: =IFERROR(__xludf.DUMMYFUNCTION("""COMPUTED_VALUE"""),"play hd3") -> play hd3 | U45: =IFERROR(__xludf.DUMMYFUNCTION("""COMPUTED_VALUE"""),"https://osu.ppy.sh/community/matches/110291479") -> https://osu.ppy.sh/community/matches/110291479
G46: c | J46: =IFERROR(__xludf.DUMMYFUNCTION("""COMPUTED_VALUE"""),35.0) -> 35 | K46: =IFERROR(__xludf.DUMMYFUNCTION("""COMPUTED_VALUE"""),45172.0) -> 45172 | L46: =IFERROR(__xludf.DUMMYFUNCTION("""COMPUTED_VALUE"""),0.6041666666666666) -> 0.60416667 | M46: =IFERROR(__xludf.DUMMYFUNCTION("""COMPUTED_VALUE"""),"cake") -> cake | N46: =IFERROR(__xludf.DUMMYFUNCTION("""COMPUTED_VALUE"""),"4") -> 4 | O46: =IFERROR(__xludf.DUMMYFUNCTION("""COMPUTED_VALUE"""),"6") -> 6 | P46: =IFERROR(__xludf.DUMMYFUNCTION("""COMPUTED_VALUE"""),"PES E9L9") -> PES E9L9 | Q46: =IFERROR(__xludf.DUMMYFUNCTION("""COMPUTED_VALUE"""),"Pischok") -> Pischok | U46: =IFERROR(__xludf.DUMMYFUNCTION("""COMPUTED_VALUE"""),"https://osu.ppy.sh/community/matches/110301327") -> https://osu.ppy.sh/community/matches/110301327
D47: Quarterfinals | G47: c | J47: =IFERROR(__xludf.DUMMYFUNCTION("""COMPUTED_VALUE"""),36.0) -> 36 | K47: =IFERROR(__xludf.DUMMYFUNCTION("""COMPUTED_VALUE"""),45171.0) -> 45171 | L47: =IFERROR(__xludf.DUMMYFUNCTION("""COMPUTED_VALUE"""),0.0625) -> 0.0625 | M47: =IFERROR(__xludf.DUMMYFUNCTION("""COMPUTED_VALUE"""),"VN+1") -> VN+1 | N47: =IFERROR(__xludf.DUMMYFUNCTION("""COMPUTED_VALUE"""),"6") -> 6 | O47: =IFERROR(__xludf.DUMMYFUNCTION("""COMPUTED_VALUE"""),"0") -> 0 | P47: =IFERROR(__xludf.DUMMYFUNCTION("""COMPUTED_VALUE"""),"Dino Nuggies") -> Dino Nuggies | Q47: =IFERROR(__xludf.DUMMYFUNCTION("""COMPUTED_VALUE"""),"play hd3") -> play hd3 | U47: =IFERROR(__xludf.DUMMYFUNCTION("""COMPUTED_VALUE"""),"https://osu.ppy.sh/community/matches/110275875") -> https://osu.ppy.sh/community/matches/110275875
...

Sheet Staff List
C2: HOST | U2: GFX
AJ3: c
G4: =IMAGE("https://a.ppy.sh/17959882?1687932364.jpeg") | Y4: =IMAGE("https://a.ppy.sh/17959882?1687932364.jpeg")
G5: =HYPERLINK("osu.ppy.sh/users/17959882","-PeKoRa-") -> -PeKoRa- | Y5: =HYPERLINK("osu.ppy.sh/users/17959882","-PeKoRa-") -> -PeKoRa-
C8: ADMINS | U8: SHEETS
G10: =IMAGE("https://a.ppy.sh/14238097?1686376598.jpeg)") | I10: =IMAGE("https://a.ppy.sh/17959882?1687932364.jpeg") | K10: =IMAGE("https://a.ppy.sh/17959882?1687932364.jpeg") | M10: =IMAGE("https://a.ppy.sh/17959882?1687932364.jpeg") | O10: =IMAGE("https://a.ppy.sh/17959882?1687932364.jpeg") | Y10: =IMAGE("https://a.ppy.sh/14238097?1686376598.jpeg)") | AA10: =IMAGE("https://a.ppy.sh/17959882?1687932364.jpeg") | AC10: =IMAGE("https://a.ppy.sh/17959882?1687932364.jpeg") | AE10: =IMAGE("https://a.ppy.sh/17959882?1687932364.jpeg") | AG10: =IMAGE("https://a.ppy.sh/17959882?1687932364.jpeg")
G11: =HYPERLINK("osu.ppy.sh/users/17959882","fuwub") -> fuwub | I11: =HYPERLINK("osu.ppy.sh/users/17959882","-PeKoRa-") -> -PeKoRa- | K11: =HYPERLINK("osu.ppy.sh/users/17959882","-PeKoRa-") -> -PeKoRa- | M11: =HYPERLINK("osu.ppy.sh/users/17959882","-PeKoRa-") -> -PeKoRa- | O11: =HYPERLINK("osu.ppy.sh/users/17959882","-PeKoRa-") -> -PeKoRa- | Y11: =HYPERLINK("osu.ppy.sh/users/17959882","fuwub") -> fuwub | AA11: =HYPERLINK("osu.ppy.sh/users/17959882","-PeKoRa-") -> -PeKoRa- | AC11: =HYPERLINK("osu.ppy.sh/users/17959882","-PeKoRa-") -> -PeKoRa- | AE11: =HYPERLINK("osu.ppy.sh/users/17959882","-PeKoRa-") -> -PeKoRa- | AG11: =HYPERLINK("osu.ppy.sh/users/17959882","-PeKoRa-") -> -PeKoRa-
C14: POOLERS
G16: =IMAGE("https://a.ppy.sh/14238097?1686376598.jpeg)") | I16: =IMAGE("https://a.ppy.sh/17959882?1687932364.jpeg") | K16: =IMAGE("https://a.ppy.sh/17959882?1687932364.jpeg") | M16: =IMAGE("https://a.ppy.sh/17959882?1687932364.jpeg") | O16: =IMAGE("https://a.ppy.sh/17959882?1687932364.jpeg")
G17: =HYPERLINK("osu.ppy.sh/users/17959882","fuwub") -> fuwub | I17: =HYPERLINK("osu.ppy.sh/users/17959882","-PeKoRa-") -> -PeKoRa- | K17: =HYPERLINK("osu.ppy.sh/users/17959882","-PeKoRa-") -> -PeKoRa- | M17: =HYPERLINK("osu.ppy.sh/users/17959882","-PeKoRa-") -> -PeKoRa- | O17: =HYPERLINK("osu.ppy.sh/users/17959882","-PeKoRa-") -> -PeKoRa-
C20: PLAY TESTERS | U20: REPLAYERS
G22: =IMAGE("https://a.ppy.sh/17959882?1687932364.jpeg") | I22: =IMAGE("https://a.ppy.sh/17959882?1687932364.jpeg") | K22: =IMAGE("https://a.ppy.sh/17959882?1687932364.jpeg") | M22: =IMAGE("https://a.ppy.sh/17959882?1687932364.jpeg") | O22: =IMAGE("https://a.ppy.sh/17959882?1687932364.jpeg") | Y22: =IMAGE("https://a.ppy.sh/17959882?1687932364.jpeg") | AA22: =IMAGE("https://a.ppy.sh/17959882?1687932364.jpeg") | AC22: =IMAGE("https://a.ppy.sh/17959882?1687932364.jpeg") | AE22: =IMAGE("https://a.ppy.sh/17959882?1687932364.jpeg") | AG22: =IMAGE("https://a.ppy.sh/17959882?1687932364.jpeg")
G23: =HYPERLINK("osu.ppy.sh/users/17959882","-PeKoRa-") -> -PeKoRa- | I23: =HYPERLINK("osu.ppy.sh/users/17959882","-PeKoRa-") -> -PeKoRa- | K23: =HYPERLINK("osu.ppy.sh/users/17959882","-PeKoRa-") -> -PeKoRa- | M23: =HYPERLINK("osu.ppy.sh/users/17959882","-PeKoRa-") -> -PeKoRa- | O23: =HYPERLINK("osu.ppy.sh/users/17959882","-PeKoRa-") -> -PeKoRa- | Y23: =HYPERLINK("osu.ppy.sh/users/17959882","-PeKoRa-") -> -PeKoRa- | AA23: =HYPERLINK("osu.ppy.sh/users/17959882","-PeKoRa-") -> -PeKoRa- | AC23: =HYPERLINK("osu.ppy.sh/users/17959882","-PeKoRa-") -> -PeKoRa- | AE23: =HYPERLINK("osu.ppy.sh/users/17959882","-PeKoRa-") -> -PeKoRa- | AG23: =HYPERLINK("osu.ppy.sh/users/17959882","-PeKoRa-") -> -PeKoRa-
G25: =IMAGE("https://a.ppy.sh/17959882?1687932364.jpeg") | I25: =IMAGE("https://a.ppy.sh/17959882?1687932364.jpeg") | K25: =IMAGE("https://a.ppy.sh/17959882?1687932364.jpeg") | M25: =IMAGE("https://a.ppy.sh/17959882?1687932364.jpeg") | O25: =IMAGE("https://a.ppy.sh/17959882?1687932364.jpeg") | Y25: =IMAGE("https://a.ppy.sh/17959882?1687932364.jpeg") | AA25: =IMAGE("https://a.ppy.sh/17959882?1687932364.jpeg") | AC25: =IMAGE("https://a.ppy.sh/17959882?1687932364.jpeg") | AE25: =IMAGE("https://a.ppy.sh/17959882?1687932364.jpeg") | AG25: =IMAGE("https://a.ppy.sh/17959882?1687932364.jpeg")
G26: =HYPERLINK("osu.ppy.sh/users/17959882","-PeKoRa-") -> -PeKoRa- | I26: =HYPERLINK("osu.ppy.sh/users/17959882","-PeKoRa-") -> -PeKoRa- | K26: =HYPERLINK("osu.ppy.sh/users/17959882","-PeKoRa-") -> -PeKoRa- | M26: =HYPERLINK("osu.ppy.sh/users/17959882","-PeKoRa-") -> -PeKoRa- | O26: =HYPERLINK("osu.ppy.sh/users/17959882","-PeKoRa-") -> -PeKoRa- | Y26: =HYPERLINK("osu.ppy.sh/users/17959882","-PeKoRa-") -> -PeKoRa- | AA26: =HYPERLINK("osu.ppy.sh/users/17959882","-PeKoRa-") -> -PeKoRa- | AC26: =HYPERLINK("osu.ppy.sh/users/17959882","-PeKoRa-") -> -PeKoRa- | AE26: =HYPERLINK("osu.ppy.sh/users/17959882","-PeKoRa-") -> -PeKoRa- | AG26: =HYPERLINK("osu.ppy.sh/users/17959882","-PeKoRa-") -> -PeKoRa-
C30: STREAMERS | U30: COMMENTATORS
G32: =IMAGE("https://a.ppy.sh/14238097?1686376598.jpeg)") | I32: =IMAGE("https://a.ppy.sh/17959882?1687932364.jpeg") | K32: =IMAGE("https://a.ppy.sh/17959882?1687932364.jpeg") | M32: =IMAGE("https://a.ppy.sh/17959882?1687932364.jpeg") | O32: =IMAGE("https://a.ppy.sh/17959882?1687932364.jpeg") | Y32: =IMAGE("https://a.ppy.sh/14238097?1686376598.jpeg)") | AA32: =IMAGE("https://a.ppy.sh/17959882?1687932364.jpeg") | AC32: =IMAGE("https://a.ppy.sh/17959882?1687932364.jpeg") | AE32: =IMAGE("https://a.ppy.sh/17959882?1687932364.jpeg") | AG32: =IMAGE("https://a.ppy.sh/17959882?1687932364.jpeg")
G33: =HYPERLINK("osu.ppy.sh/users/17959882","fuwub") -> fuwub | I33: =HYPERLINK("osu.ppy.sh/users/17959882","-PeKoRa-") -> -PeKoRa- | K33: =HYPERLINK("osu.ppy.sh/users/17959882","-PeKoRa-") -> -PeKoRa- | M33: =HYPERLINK("osu.ppy.sh/users/17959882","-PeKoRa-") -> -PeKoRa- | O33: =HYPERLINK("osu.ppy.sh/users/17959882","-PeKoRa-") -> -PeKoRa- | Y33: =HYPERLINK("osu.ppy.sh/users/17959882","fuwub") -> fuwub | AA33: =HYPERLINK("osu.ppy.sh/users/17959882","-PeKoRa-") -> -PeKoRa- | AC33: =HYPERLINK("osu.ppy.sh/users/17959882","-PeKoRa-") -> -PeKoRa- | AE33: =HYPERLINK("osu.ppy.sh/users/17959882","-PeKoRa-") -> -PeKoRa- | AG33: =HYPERLINK("osu.ppy.sh/users/17959882","-PeKoRa-") -> -PeKoRa-
G35: =IMAGE("https://a.ppy.sh/17959882?1687932364.jpeg") | I35: =IMAGE("https://a.ppy.sh/17959882?1687932364.jpeg") | K35: =IMAGE("https://a.ppy.sh/17959882?1687932364.jpeg") | M35: =IMAGE("https://a.ppy.sh/17959882?1687932364.jpeg") | O35: =IMAGE("https://a.ppy.sh/17959882?1687932364.jpeg") | Y35: =IMAGE("https://a.ppy.sh/17959882?1687932364.jpeg") | AA35: =IMAGE("https://a.ppy.sh/17959882?1687932364.jpeg") | AC35: =IMAGE("https://a.ppy.sh/17959882?1687932364.jpeg") | AE35: =IMAGE("https://a.ppy.sh/17959882?1687932364.jpeg") | AG35: =IMAGE("https://a.ppy.sh/17959882?1687932364.jpeg")
G36: =HYPERLINK("osu.ppy.sh/users/17959882","-PeKoRa-") -> -PeKoRa- | I36: =HYPERLINK("osu.ppy.sh/users/17959882","-PeKoRa-") -> -PeKoRa- | K36: =HYPERLINK("osu.ppy.sh/users/17959882","-PeKoRa-") -> -PeKoRa- | M36: =HYPERLINK("osu.ppy.sh/users/17959882","-PeKoRa-") -> -PeKoRa- | O36: =HYPERLINK("osu.ppy.sh/users/17959882","-PeKoRa-") -> -PeKoRa- | Y36: =HYPERLINK("osu.ppy.sh/users/17959882","-PeKoRa-") -> -PeKoRa- | AA36: =HYPERLINK("osu.ppy.sh/users/17959882","-PeKoRa-") -> -PeKoRa- | AC36: =HYPERLINK("osu.ppy.sh/users/17959882","-PeKoRa-") -> -PeKoRa- | AE36: =HYPERLINK("osu.ppy.sh/users/17959882","-PeKoRa-") -> -PeKoRa- | AG36: =HYPERLINK("osu.ppy.sh/users/17959882","-PeKoRa-") -> -PeKoRa-
G38: =IMAGE("https://a.ppy.sh/17959882?1687932364.jpeg") | I38: =IMAGE("https://a.ppy.sh/17959882?1687932364.jpeg") | K38: =IMAGE("https://a.ppy.sh/17959882?1687932364.jpeg") | M38: =IMAGE("https://a.ppy.sh/17959882?1687932364.jpeg") | O38: =IMAGE("https://a.ppy.sh/17959882?1687932364.jpeg") | Y38: =IMAGE("https://a.ppy.sh/17959882?1687932364.jpeg") | AA38: =IMAGE("https://a.ppy.sh/17959882?1687932364.jpeg") | AC38: =IMAGE("https://a.ppy.sh/17959882?1687932364.jpeg") | AE38: =IMAGE("https://a.ppy.sh/17959882?1687932364.jpeg") | AG38: =IMAGE("https://a.ppy.sh/17959882?1687932364.jpeg")
G39: =HYPERLINK("osu.ppy.sh/users/17959882","-PeKoRa-") -> -PeKoRa- | I39: =HYPERLINK("osu.ppy.sh/users/17959882","-PeKoRa-") -> -PeKoRa- | K39: =HYPERLINK("osu.ppy.sh/users/17959882","-PeKoRa-") -> -PeKoRa- | M39: =HYPERLINK("osu.ppy.sh/users/17959882","-PeKoRa-") -> -PeKoRa- | O39: =HYPERLINK("osu.ppy.sh/users/17959882","-PeKoRa-") -> -PeKoRa- | Y39: =HYPERLINK("osu.ppy.sh/users/17959882","-PeKoRa-") -> -PeKoRa- | AA39: =HYPERLINK("osu.ppy.sh/users/17959882","-PeKoRa-") -> -PeKoRa- | AC39: =HYPERLINK("osu.ppy.sh/users/17959882","-PeKoRa-") -> -PeKoRa- | AE39: =HYPERLINK("osu.ppy.sh/users/17959882","-PeKoRa-") -> -PeKoRa- | AG39: =HYPERLINK("osu.ppy.sh/users/17959882","-PeKoRa-") -> -PeKoRa-
C43: REFEREES
G45: =IMAGE("https://a.ppy.sh/14238097?1686376598.jpeg)") | I45: =IMAGE("https://a.ppy.sh/17959882?1687932364.jpeg") | K45: =IMAGE("https://a.ppy.sh/17959882?1687932364.jpeg") | M45: =IMAGE("https://a.ppy.sh/17959882?1687932364.jpeg") | O45: =IMAGE("https://a.ppy.sh/17959882?1687932364.jpeg")
G46: =HYPERLINK("osu.ppy.sh/users/17959882","fuwub") -> fuwub | I46: =HYPERLINK("osu.ppy.sh/users/17959882","-PeKoRa-") -> -PeKoRa- | K46: =HYPERLINK("osu.ppy.sh/users/17959882","-PeKoRa-") -> -PeKoRa- | M46: =HYPERLINK("osu.ppy.sh/users/17959882","-PeKoRa-") -> -PeKoRa- | O46: =HYPERLINK("osu.ppy.sh/users/17959882","-PeKoRa-") -> -PeKoRa-
G48: =IMAGE("https://a.ppy.sh/17959882?1687932364.jpeg") | I48: =IMAGE("https://a.ppy.sh/17959882?1687932364.jpeg") | K48: =IMAGE("https://a.ppy.sh/17959882?1687932364.jpeg") | M48: =IMAGE("https://a.ppy.sh/17959882?1687932364.jpeg") | O48: =IMAGE("https://a.ppy.sh/17959882?1687932364.jpeg")
G49: =HYPERLINK("osu.ppy.sh/users/17959882","-PeKoRa-") -> -PeKoRa- | I49: =HYPERLINK("osu.ppy.sh/users/17959882","-PeKoRa-") -> -PeKoRa- | K49: =HYPERLINK("osu.ppy.sh/users/17959882","-PeKoRa-") -> -PeKoRa- | M49: =HYPERLINK("osu.ppy.sh/users/17959882","-PeKoRa-") -> -PeKoRa- | O49: =HYPERLINK("osu.ppy.sh/users/17959882","-PeKoRa-") -> -PeKoRa-
G51: =IMAGE("https://a.ppy.sh/17959882?1687932364.jpeg") | I51: =IMAGE("https://a.ppy.sh/17959882?1687932364.jpeg") | K51: =IMAGE("https://a.ppy.sh/17959882?1687932364.jpeg") | M51: =IMAGE("https://a.ppy.sh/17959882?1687932364.jpeg") | O51: =IMAGE("https://a.ppy.sh/17959882?1687932364.jpeg")
G52: =HYPERLINK("osu.ppy.sh/users/17959882","-PeKoRa-") -> -PeKoRa- | I52: =HYPERLINK("osu.ppy.sh/users/17959882","-PeKoRa-") -> -PeKoRa- | K52: =HYPERLINK("osu.ppy.sh/users/17959882","-PeKoRa-") -> -PeKoRa- | M52: =HYPERLINK("osu.ppy.sh/users/17959882","-PeKoRa-") -> -PeKoRa- | O52: =HYPERLINK("osu.ppy.sh/users/17959882","-PeKoRa-") -> -PeKoRa-

Sheet Main Sheet
U1: c
Q2: CURRENT PHASE : REGISTRATIONS
V3: c
Q6: PREVIOUS PHASE : | U6: NEXT PHASE :
Q7: TEAMS REGISTERED : - NO. OF TEAMS - | U7: no. of free agents : - NO. OF fa -
Q8: =NOW() -> 45946.806 | U8: =now() -> 45946.806
Q9: =NOW() -> 45946.806
V10: c | W10: c
W12: c
K20: c
F21: Schedule | Q21: TEAM REGS. FORM
U22: STAFF REGS. FORM
F23: QUALIFIERS | H23: < < < > > > | I23: JULY 13-25
F24: RO32 | H24: < < < > > > | I24: JULY 13-25 | Q24: FORUM POST
F25: RO16 | H25: < < < > > > | I25: JULY 13-25
F26: QUARTERFINALS | H26: < < < > > > | I26: JULY 13-25 | U26: DISCORD SERVER
F27: SEMI-FINALS | H27: < < < > > > | I27: JULY 13-25
F28: FINALS | H28: < < < > > > | I28: JULY 13-25 | Q28: RULE BOOK | U28: TEAM LISTS >>>
F29: GRAND FINALS | H29: < < < > > > | I29: JULY 13-25 | U29: STAFF LISTS >>>
U30: STAT SHEET >>>

Sheet Team List
C3: ="NO OF TEAMS ( " & COUNTIF(C6:C185,"*") & " )" -> NO OF TEAMS ( 0 ) | E3: =IMAGE("https://a.ppy.sh/17959882?1687932364.jpeg") | F3: CAPTAIN | G3: =IMAGE("https://a.ppy.sh/14238097?1686376598.jpeg)") | H3: PLAYER 2 | I3: =IMAGE("https://a.ppy.sh/17959882?1687932364.jpeg") | J3: PLAYER 3 | K3: - THE TEAM's MOTTO HERE -
F4: #105,555 | H4: #103,415 | J4: #133,041
C6: =IFERROR(__xludf.DUMMYFUNCTION("IMPORTRANGE(""1HHAHmZTTDlyB4RHaHQ-2bhUchkHOEZhmcQrDYQXnxnw"",""importrange!R3:Z"")"),"#REF!") -> #REF!

Sheet Copy of Template
B2: Lobby: | C2: A1 | E2: Referee: | G2: Remarks (Late and Replays) | I2: mp timer 120 | J2: !mp settings | K2: Forum link : https://osu.ppy.sh/community/forums/topics/1790898?n=1?
B3: MP LINK: | E3: =VLOOKUP(C2,'Qualifier Lobbies'!C4:G42,5,0) -> #REF! | G3: :thumbsup: None | I3: !mp set 0 3 16 | J3: !mp abort
B4: Room Command: | C4: ="!mp make PTE : (Qualifiers) vs ("&C2&")" -> !mp make PTE : (Qualifiers) vs (A1) | E4: =VLOOKUP(C2,'Qualifier Lobbies'!C4:F42,3,0) -> #REF! | I4: !mp start 10 | J4: !mp aborttimer | K4: Mainsheet link : https://docs.google.com/spreadsheets/d/1u1R-0YeX71qksHP7hWq8QkjcpECX-9LSvskalZ8hxdg/edit?usp=sharing
B5: Results: | C5: =IFS(C3="","Put the MP link first!",C3>"", "**Qualifier Lobby "&C2&"**" &CHAR(13)& " MP LINK: "&C3&" "&CHAR(13)&" Referee Notes: "&G3) &CHAR(13) -> Put the MP link first! | E5: =VLOOKUP(C2,'Qualifier Lobbies'!C4:F42,4,0)&" UTC" -> #REF! | I5: MP COMMANDS | J5: !mp addref (name)
B7: Mappool | G7: =IFERROR("!mp invite " & G9,"") -> !mp invite | I7: =IFERROR("!mp invite " & I9,"") -> !mp invite | J7: =IFERROR("!mp invite " & J9,"") -> !mp invite | K7: =IFERROR("!mp invite " & K9,"") -> !mp invite | L7: =IFERROR("!mp invite " & L9,"") -> !mp invite
B8: Mod Command | C8: Map Name | D8: Map Command | G8: =VLOOKUP(C2,'Qualifier Lobbies'!C5:L42,6,0) -> #REF! | I8: =VLOOKUP(C2,'Qualifier Lobbies'!C5:L42,7,0) -> #REF! | J8: =VLOOKUP(C2,'Qualifier Lobbies'!C5:L42,8,0) -> #REF! | K8: =VLOOKUP(C2,'Qualifier Lobbies'!C5:L42,9,0) -> #REF! | L8: =VLOOKUP(C2,'Qualifier Lobbies'!C5:L42,10,0) -> #REF!
B9: {='Qualifiers Pool'!J3:J12} -> #REF! | C9: {='Qualifiers Pool'!H3:H12} -> #REF! | D9: {='Qualifiers Pool'!I3:I12} -> #REF! | G9: =IFERROR(VLOOKUP(G8,'Ref & Team list'!C3:F20,2,0),"") | I9: =IFERROR(VLOOKUP(I8,'Ref & Team list'!C3:F20,2,0),"") | J9: =IFERROR(VLOOKUP(J8,'Ref & Team list'!C3:F20,2,0),"") | K9: =IFERROR(VLOOKUP(K8,'Ref & Team list'!C3:F20,2,0),"") | L9: =IFERROR(VLOOKUP(L8,'Ref & Team list'!C3:F20,2,0),"")
G10: =IFERROR(VLOOKUP(G8,'Ref & Team list'!C3:F20,3,0),"") | I10: =IFERROR(VLOOKUP(I8,'Ref & Team list'!C3:F20,3,0),"") | J10: =IFERROR(VLOOKUP(J8,'Ref & Team list'!C3:F20,3,0),"") | K10: =IFERROR(VLOOKUP(K8,'Ref & Team list'!C3:F20,3,0),"") | L10: =IFERROR(VLOOKUP(L8,'Ref & Team list'!C3:F20,3,0),"")
G11: =IFERROR(VLOOKUP(G8,'Ref & Team list'!C3:F20,4,0),"") | I11: =IFERROR(VLOOKUP(I8,'Ref & Team list'!C3:F20,4,0),"") | J11: =IFERROR(VLOOKUP(J8,'Ref & Team list'!C3:F20,4,0),"") | K11: =IFERROR(VLOOKUP(K8,'Ref & Team list'!C3:F20,4,0),"") | L11: =IFERROR(VLOOKUP(L8,'Ref & Team list'!C3:F20,4,0),"")
